Workbook
Name _dma1: #REF!
Name _dma2: #REF!
Name _dma3: #REF!
Name _dmb1: #REF!
Name _dmb2: #REF!
Name _dmc1: #REF!
Name _dmc2: #REF!
Name _dmd1: #REF!
Name _dmd2: #REF!
Name _Lag1: #REF!
Name _Lag2: #REF!
Name _PV1: 7
Name a: #REF!
Name A1loss: #REF!
Name A2loss: #REF!
Name A3loss: #REF!
Name AB: #REF!
Name AB_H: #REF!
Name AB_Orig: #REF!
Name ABS_Senior_____10: "FitchRecoverybyType"
Name ActiveRows: #REF!
Name Actual: #REF!
Name Actual12moChargeoffRatio: #REF!
Name Actual3moChargeoffRatio: #REF!
Name Actual3moDefaultRatio: #REF!
Name AdjAdvRate: #REF!
Name adv_rate: #REF!
Name adv_rate_reduced: #REF!
Name adv_rate_type: #REF!
Name advance_outstanding: #REF!
Name AdvancesOS: #REF!
Name agg_commit_bal: #REF!
Name AggregateAdjustedBalanceUSD: #REF!
Name AgingsDetail: #REF!
Name agreed_currency: #REF!
Name amort_adv_outstanding: #REF!
Name amort_period: #REF!
Name AOLB: #REF!
Name AOLBrange: #REF!
Name applicable_margin: #REF!
Name asfsdf: #REF!
Name ASH: #REF!
Name ASL: #REF!
Name asset_rating: #REF!
Name asset_types: #REF!
Name asset_value: #REF!
Name AUSTRALIA_NET: 110
Name AUSTRIA_NET: 107
Name AvailableCollections: #REF!
Name AverageABAgg: #REF!
Name AverageABL: #REF!
Name averageABL2: #REF!
Name AverageAgg: #REF!
Name b: #REF!
Name B1loss: #REF!
Name B2loss: #REF!
Name BackupServiceFee: #REF!
Name balances: #REF!
Name BeginningABAgg: #REF!
Name BeginningABL: #REF!

Sheet Summary
C2: PennantPark Investment Funding I, LLC
B7: Reconciliation Date | C7: 45777
B9: Account Balances
B10: Account | C10: Currency | D10: FX Rate | E10: Account Number | F10: Cash Date (Currency) | G10: Pending Trades (Currency) | H10: Trade Date (Currency)
B11: Trust Account | C11: USD | D11: 1 | E11: 10107500 | F11: 0 | G11: 0 | H11: 0
B12: Interest Collection Subaccount | C12: USD | D12: 1 | E12: 10107501 | F12: 616421.06 | G12: 0 | H12: 616421.06
B13: Principal Collection Subaccount | C13: USD | D13: 1 | E13: 10107502 | F13: 25110258 | G13: 13006000 | H13: 38116258
B14: Payment Account | C14: USD | D14: 1 | E14: 10107503 | F14: 0 | G14: 0 | H14: 0
B16: Outstanding Payments
C17: Number of Items
B18: Unapplied Transactions | C18: 9
B19: Past Due Receivables | C19: 55
B21: Holdings
B22: Positions | C22: Currency | D22: FX Rate | E22: Settle Date (Currency) | F22: Pending Trades (Currency) | G22: Trade Date (Currency)
B23: Funded | C23: USD | D23: 1 | E23: 4.1360387e+08 | F23: -13100000 | G23: 4.0050387e+08
B24: Unfunded | C24: USD | D24: 1 | E24: -0.05 | F24: 1.0728836e-07 | G24: -0.049999893
B25: Committed | C25: USD | D25: 1 | E25: 4.1360387e+08 | F25: -13100000 | G25: 4.0050387e+08

Sheet Transactions
A7: Transactions as of 04/30/2025
A8: Transaction Data | N8: Account Balances | R8: Collateral Balance
A9: Applied Date | B9: Settle Date | C9: Trade Date | D9: Issuer/Borrower | E9: Facility/Security | F9: Identifier | G9: Transaction Type | H9: Account | I9: Currency | J9: Transaction Amount | K9: Price | L9: Funded par | M9: Unfunded par | N9: Trust Account | O9: Interest Collection Subaccount | P9: Principal Collection Subaccount | Q9: Payment Account | R9: Funded Collateral | S9: Unfunded Collateral | T9: Committed Collateral
N10: USD | O10: USD | P10: USD | Q10: USD | R10: USD | S10: USD | T10: USD
D11: Beginning Balance | N11: 0 | O11: 0 | P11: 0 | Q11: 0 | R11: 0 | S11: 0 | T11: 0
A12: 45642 | B12: 45642 | C12: 45642 | D12: PennantPark Investment Funding I, LLC | E12: PennantPark Investment Funding I LLC | G12: Facility - Sale | I12: USD | J12: 0 | K12: 1 | L12: 0 | M12: 0 | N12: 0 | O12: 0 | P12: 0 | Q12: 0 | R12: 0 | S12: 0 | T12: 0
A13: 45688 | B13: 45678 | C13: 45678 | D13: Historic Borrowing Offset | G13: Cash Adjustment (R) | H13: Principal Collection Subaccount | I13: USD | J13: -142600000 | K13: 0 | L13: 0 | M13: 0 | N13: 0 | O13: 0 | P13: -142600000 | Q13: 0 | R13: 0 | S13: 0 | T13: 0
A14: 45688 | B14: 45678 | C14: 45678 | D14: PennantPark Investment Funding I, LLC | E14: PennantPark Investment Funding I LLC | G14: Facility - Borrowing (R) | H14: Principal Collection Subaccount | I14: USD | J14: 142600000 | K14: 1 | L14: 0 | M14: 0 | N14: 0 | O14: 0 | P14: 0 | Q14: 0 | R14: 0 | S14: 0 | T14: 0
A15: 45688 | B15: 45688 | C15: 45688 | D15: PennantPark Investment Funding I, LLC | E15: PennantPark Investment Funding I LLC | G15: Facility - Borrowing (R) | H15: Principal Collection Subaccount | I15: USD | J15: 72000000 | K15: 1 | L15: 0 | M15: 0 | N15: 0 | O15: 0 | P15: 72000000 | Q15: 0 | R15: 0 | S15: 0 | T15: 0
A16: 45692 | B16: 45686 | C16: 45686 | D16: Michael Baker International LLC | E16: New Term B Loan | F16: LX234003 | G16: Facility - Payoff | I16: USD | J16: 0 | K16: 0 | L16: -491762.96 | M16: 0 | N16: 0 | O16: 0 | P16: 72000000 | Q16: 0 | R16: -491762.96 | S16: 0 | T16: -491762.96
A17: 45693 | B17: 45660 | C17: 45660 | D17: STG Distribution LLC | E17: First Out New Money Term Loan | F17: LX249176 | G17: Facility - Commitment Increase | I17: USD | J17: 0 | K17: 0 | L17: 8327.77 | M17: 0 | N17: 0 | O17: 0 | P17: 72000000 | Q17: 0 | R17: -483435.19 | S17: 0 | T17: -483435.19
A18: 45693 | B18: 45691 | C18: 45691 | D18: STG Distribution LLC | E18: First Out New Money Term Loan | F18: LX249176 | G18: Facility - Commitment Increase | I18: USD | J18: 0 | K18: 0 | L18: 8657.36 | M18: 0 | N18: 0 | O18: 0 | P18: 72000000 | Q18: 0 | R18: -474777.83 | S18: 0 | T18: -474777.83
A19: 45693 | B19: 45657 | C19: 45657 | D19: 48Forty Intermediate Holdings Inc | E19: 48forty Common Equity | G19: Shares/Units - Purchase | I19: USD | J19: 0 | K19: 0 | L19: 522.15 | N19: 0 | O19: 0 | P19: 72000000 | Q19: 0 | R19: -474255.68 | S19: 0 | T19: -474255.68
A20: 45693 | B20: 45659 | C20: 45659 | D20: Alpine Acquisition Corp II | E20: Amend 4 TLA-2 | F20: LX207291 | G20: Facility - Commitment Increase | I20: USD | J20: 0 | K20: 0 | L20: 28686.7 | M20: 0 | N20: 0 | O20: 0 | P20: 72000000 | Q20: 0 | R20: -445568.98 | S20: 0 | T20: -445568.98
A21: 45693 | B21: 45691 | C21: 45691 | D21: Alpine Acquisition Corp II | E21: Amend 4 TLA-2 | F21: LX207291 | G21: Facility - Commitment Increase | I21: USD | J21: 0 | K21: 0 | L21: 29089.33 | M21: 0 | N21: 0 | O21: 0 | P21: 72000000 | Q21: 0 | R21: -416479.65 | S21: 0 | T21: -416479.65
A22: 45693 | B22: 45688 | C22: 45688 | D22: Carnegie Dartlet LLC | E22: Initial Term Loan | G22: Loan - Interest Payment (R) | H22: Interest Collection Subaccount | I22: USD | J22: 58716.25 | K22: 0 | L22: 0 | M22: 0 | N22: 0 | O22: 58716.25 | P22: 72000000 | Q22: 0 | R22: -416479.65 | S22: 0 | T22: -416479.65
A23: 45693 | B23: 45688 | C23: 45688 | D23: Eval Home Health Solutions Intermediate LLC | E23: Initial Term Loan | F23: LX233420 | G23: Loan - Interest Payment (R) | H23: Interest Collection Subaccount | I23: USD | J23: 12119.62 | K23: 0 | L23: 0 | M23: 0 | N23: 0 | O23: 70835.87 | P23: 72000000 | Q23: 0 | R23: -416479.65 | S23: 0 | T23: -416479.65
A24: 45693 | B24: 45688 | C24: 45688 | D24: Transgo LLC | E24: Initial Term Loan | F24: LX225916 | G24: Loan - Interest Payment (R) | H24: Interest Collection Subaccount | I24: USD | J24: 28603.02 | K24: 0 | L24: 0 | M24: 0 | N24: 0 | O24: 99438.89 | P24: 72000000 | Q24: 0 | R24: -416479.65 | S24: 0 | T24: -416479.65
A25: 45693 | B25: 45688 | C25: 45688 | D25: Transgo LLC | E25: Initial Term Loan | F25: LX225916 | G25: Facility - Paydown (R) | H25: Principal Collection Subaccount | I25: USD | J25: 22715.13 | K25: 1 | L25: -22715.13 | M25: 0 | N25: 0 | O25: 99438.89 | P25: 72022715 | Q25: 0 | R25: -439194.78 | S25: 0 | T25: -439194.78
A26: 45693 | B26: 45688 | C26: 45688 | D26: Transgo LLC | E26: Initial Term Loan | F26: LX225916 | G26: Facility - Upfront Fee (R) | H26: Principal Collection Subaccount | I26: USD | J26: 227.15 | K26: 0 | L26: 0 | M26: 0 | N26: 0 | O26: 99438.89 | P26: 72022942 | Q26: 0 | R26: -439194.78 | S26: 0 | T26: -439194.78
A27: 45693 | B27: 45688 | C27: 45674 | D27: Arcfield Acquisition Corp | E27: REFI Term Loan | F27: LX251125 | G27: Facility - Purchase (D) | H27: Principal Collection Subaccount | I27: USD | J27: -14973750 | K27: 0.9982 | L27: 15000000 | M27: 0 | N27: 0 | O27: 99438.89 | P27: 57049192 | Q27: 0 | R27: 14560805 | S27: 0 | T27: 14560805
A28: 45693 | B28: 45657 | C28: 45657 | D28: 12.31.24 Trades/Position Offset | G28: Cash Adjustment (R) | H28: Principal Collection Subaccount | I28: USD | J28: 2.986352e+08 | K28: 0 | L28: 0 | M28: 0 | N28: 0 | O28: 99438.89 | P28: 3.5568439e+08 | Q28: 0 | R28: 14560805 | S28: 0 | T28: 14560805
A29: 45693 | B29: 45685 | C29: 45646 | D29: CF512 Inc | E29: Initial Term Loan | F29: LX205355 | G29: Facility - Purchase (D) | H29: Principal Collection Subaccount | I29: USD | J29: -3879466.4 | K29: 0.985 | L29: 3940540.6 | M29: 0 | N29: 0 | O29: 99438.89 | P29: 3.5180492e+08 | Q29: 0 | R29: 18501346 | S29: 0 | T29: 18501346
A30: 45693 | B30: 45665 | C30: 45593 | D30: Dr. Squatch LLC | E30: 2022-1 Incremental Term Loan | F30: LX203689 | G30: Facility - Purchase (D) | H30: Principal Collection Subaccount | I30: USD | J30: -1719796.1 | K30: 1 | L30: 1719796.1 | M30: 0 | N30: 0 | O30: 99438.89 | P30: 3.5008513e+08 | Q30: 0 | R30: 20221142 | S30: 0 | T30: 20221142
A31: 45693 | B31: 45665 | C31: 45593 | D31: Dr. Squatch LLC | E31: Delayed Draw Term Loan | F31: LX203614 | G31: Facility - Purchase (D) | H31: Principal Collection Subaccount | I31: USD | J31: -6365000 | K31: 1 | L31: 6365000 | M31: 0 | N31: 0 | O31: 99438.89 | P31: 3.4372013e+08 | Q31: 0 | R31: 26586142 | S31: 0 | T31: 26586142
A32: 45693 | B32: 45657 | C32: 45657 | D32: AFC-Dell Holding Corp | E32: Term Loan | G32: Facility - Purchase (D) | H32: Principal Collection Subaccount | I32: USD | J32: -1612929.6 | K32: 1 | L32: 1612929.6 | M32: 0 | N32: 0 | O32: 99438.89 | P32: 3.421072e+08 | Q32: 0 | R32: 28199072 | S32: 0 | T32: 28199072
A33: 45693 | B33: 45657 | C33: 45657 | D33: Watchtower Buyer LLC | E33: Initial Term Loan | F33: LX221597 | G33: Facility - Purchase (D) | H33: Principal Collection Subaccount | I33: USD | J33: -2275337 | K33: 1 | L33: 2275337 | M33: 0 | N33: 0 | O33: 99438.89 | P33: 3.3983186e+08 | Q33: 0 | R33: 30474409 | S33: 0 | T33: 30474409
A34: 45693 | B34: 45657 | C34: 45657 | D34: Transgo LLC | E34: Initial Term Loan | F34: LX225916 | G34: Facility - Purchase (D) | H34: Principal Collection Subaccount | I34: USD | J34: -3286471 | K34: 1 | L34: 3286471 | M34: 0 | N34: 0 | O34: 99438.89 | P34: 3.3654539e+08 | Q34: 0 | R34: 33760880 | S34: 0 | T34: 33760880
A35: 45693 | B35: 45657 | C35: 45657 | D35: AFC-Dell Holding Corp | E35: 5th AMD Delayed Draw Term Loan | F35: LX194355 | G35: Facility - Purchase (D) | H35: Principal Collection Subaccount | I35: USD | J35: -2377281.1 | K35: 1 | L35: 2377281.1 | M35: 0 | N35: 0 | O35: 99438.89 | P35: 3.3416811e+08 | Q35: 0 | R35: 36138161 | S35: 0 | T35: 36138161
A36: 45693 | B36: 45657 | C36: 45657 | D36: BlackHawk Industrial Distribution Inc | E36: Initial Term Loan | F36: LX176035 | G36: Facility - Purchase (D) | H36: Principal Collection Subaccount | I36: USD | J36: -5060290.4 | K36: 1 | L36: 5060290.4 | M36: 0 | N36: 0 | O36: 99438.89 | P36: 3.2910782e+08 | Q36: 0 | R36: 41198451 | S36: 0 | T36: 41198451
A37: 45693 | B37: 45657 | C37: 45657 | D37: Bluebird Group LLC, The | E37: Term Loan | F37: LX206792 | G37: Facility - Purchase (D) | H37: Principal Collection Subaccount | I37: USD | J37: -3642206.1 | K37: 1 | L37: 3642206.1 | M37: 0 | N37: 0 | O37: 99438.89 | P37: 3.2546561e+08 | Q37: 0 | R37: 44840657 | S37: 0 | T37: 44840657
A38: 45693 | B38: 45657 | C38: 45657 | D38: BlueHalo Global Holdings LLC | E38: Initial Term Loan | F38: LX189087 | G38: Facility - Purchase (D) | H38: Principal Collection Subaccount | I38: USD | J38: -2193219.3 | K38: 1 | L38: 2193219.3 | M38: 0 | N38: 0 | O38: 99438.89 | P38: 3.2327239e+08 | Q38: 0 | R38: 47033876 | S38: 0 | T38: 47033876
A39: 45693 | B39: 45657 | C39: 45657 | D39: TCG 3.0 Jogger Acquisitionco Inc | E39: Initial Term Loan | F39: LX226175 | G39: Facility - Purchase (D) | H39: Principal Collection Subaccount | I39: USD | J39: -3940075.4 | K39: 1 | L39: 3940075.4 | M39: 0 | N39: 0 | O39: 99438.89 | P39: 3.1933232e+08 | Q39: 0 | R39: 50973952 | S39: 0 | T39: 50973952
A40: 45693 | B40: 45657 | C40: 45657 | D40: Carisk Buyer Inc | E40: Initial Term Loan | F40: LX221535 | G40: Facility - Purchase (D) | H40: Principal Collection Subaccount | I40: USD | J40: -1119537 | K40: 1 | L40: 1119537 | M40: 0 | N40: 0 | O40: 99438.89 | P40: 3.1821278e+08 | Q40: 0 | R40: 52093489 | S40: 0 | T40: 52093489
A41: 45693 | B41: 45657 | C41: 45657 | D41: Carnegie Dartlet LLC | E41: Initial Term Loan | G41: Facility - Purchase (D) | H41: Principal Collection Subaccount | I41: USD | J41: -6917575.4 | K41: 1 | L41: 6917575.4 | M41: 0 | N41: 0 | O41: 99438.89 | P41: 3.1129521e+08 | Q41: 0 | R41: 59011064 | S41: 0 | T41: 59011064
A42: 45693 | B42: 45657 | C42: 45657 | D42: Sigma Defense Systems LLC | E42: Initial Term Loan | F42: LX193132 | G42: Facility - Purchase (D) | H42: Principal Collection Subaccount | I42: USD | J42: -18537394 | K42: 1 | L42: 18537394 | M42: 0 | N42: 0 | O42: 99438.89 | P42: 2.9275781e+08 | Q42: 0 | R42: 77548458 | S42: 0 | T42: 77548458
A43: 45693 | B43: 45657 | C43: 45657 | D43: Dr. Squatch LLC | E43: Initial Term Loan | F43: LX197743 | G43: Facility - Purchase (D) | H43: Principal Collection Subaccount | I43: USD | J43: -1159.44 | K43: 1 | L43: 1159.44 | M43: 0 | N43: 0 | O43: 99438.89 | P43: 2.9275665e+08 | Q43: 0 | R43: 77549618 | S43: 0 | T43: 77549618
A44: 45693 | B44: 45657 | C44: 45657 | D44: Seaway Buyer LLC | E44: Initial Term Loan | F44: LX206101 | G44: Facility - Purchase (D) | H44: Principal Collection Subaccount | I44: USD | J44: -609654.28 | K44: 1 | L44: 609654.28 | M44: 0 | N44: 0 | O44: 99438.89 | P44: 2.92147e+08 | Q44: 0 | R44: 78159272 | S44: 0 | T44: 78159272
A45: 45693 | B45: 45657 | C45: 45657 | D45: HW Holdco LLC | E45: Third Amendment Incremental Term Loan | F45: LX205427 | G45: Facility - Purchase (D) | H45: Principal Collection Subaccount | I45: USD | J45: -2338198.5 | K45: 1 | L45: 2338198.5 | M45: 0 | N45: 0 | O45: 99438.89 | P45: 2.898088e+08 | Q45: 0 | R45: 80497471 | S45: 0 | T45: 80497471
A46: 45693 | B46: 45657 | C46: 45657 | D46: Infolinks Media Buyco LLC | E46: Delayed Draw Term Loan | F46: LX200854 | G46: Facility - Purchase (D) | H46: Principal Collection Subaccount | I46: USD | J46: -1402092.3 | K46: 1 | L46: 1402092.3 | M46: 0 | N46: 0 | O46: 99438.89 | P46: 2.8840671e+08 | Q46: 0 | R46: 81899563 | S46: 0 | T46: 81899563
...

Sheet Outstanding Payments
A7: Outstanding Payments as of 04/30/2025
A8: Unapplied Cash Transactions
A9: Date | B9: Issuer/Borrower | C9: Facility/Security | D9: Amount | E9: Wire Details | F9: Notes
A10: 45698 | B10: TWS Acquisition Corporation (dba Stratatch Education Group) | D10: 2601.86 | E10: FFC:10107500 PENNANTPARK INVESTMENTFUNDING I, LLC: TRUST ACCOUNTTWS ACQUISITION9070000001WATC CLEARINGPENNANTPARK LOAN AGENCY SERVICING,18899
A11: 45742 | B11: HW Holdco LLC | D11: 1899.64 | E11: 10107500 - PENNANTPARK INVESTMENT FHW HOLDCO, LLCPENNANTPARK INVESTMENT FUNDING I, LLOAN - INTEREST PAYMENT9070000001WATC CLEARING590 MADISON AVENUE NEW YORK NY 100HW HOLDCO, LLC250326B01XF3
A12: 45747 | B12: EDS Buyer LLC | D12: 186686.87 | E12: FFC:10107500 PENNANTPARK INVESTMENTFUNDING I, LLC: TRUST ACCOUNTEDS BUYER, LLC9070000001WATC CLEARINGPENNANTPARK LOAN AGENCY SERVICING,19114
A13: 45747 | B13: MDI Buyer Inc | D13: 1868.15 | E13: FFC 10107500 PENNANTPARK INVESTMENTFUNDING I LLC TRUST ACCOUNT REF MDIBUYER9070000001WATC CLEARING590 MADISON AVENUE 15TH FLOORCHURCHILL AGENCY SERVICES, LLC5031699
A14: 45747 | B14: MDI Buyer Inc | D14: 10515.81 | E14: FFC 10107500 PENNANTPARK INVESTMENTFUNDING I LLC TRUST ACCOUNT REF MDIBUYER9070000001WATC CLEARING590 MADISON AVENUE 15TH FLOORCHURCHILL AGENCY SERVICES, LLC5031690
A15: 45756 | B15: CJX Borrower LLC | D15: 2365.7 | E15: AC WATC CLEARING FFC 10107500 - PENNANTPARK INV FUNDING I, LLC TRUST AC REF CONNATIX9070000001PENNANTPARK INVESTMT FD I LLCCJX BORROWER, LLC
A16: 45762 | B16: HW Holdco LLC | D16: 6149.3 | E16: 10107500 - PENNANTPARK INVESTMENT FHW HOLDCO, LLCPENNANTPARK INVESTMENT FUNDING I, LLOAN - INTEREST PAYMENT9070000001WATC CLEARING590 MADISON AVENUE NEW YORK NY 100HW HOLDCO, LLC250415B01GKN
A17: 45762 | B17: HW Holdco LLC | D17: 19866.14 | E17: 10107500 - PENNANTPARK INVESTMENT FHW HOLDCO, LLCPENNANTPARK INVESTMENT FUNDING I, LLOAN - INTEREST PAYMENT9070000001WATC CLEARING590 MADISON AVENUE NEW YORK NY 100HW HOLDCO, LLC250415B01GNX
A18: 45771 | B18: EDS Buyer LLC | D18: 6.41 | E18: FFC 10107500 PENNANTPARK INVESTMENT FUNDING I LLC TRUST ACCOUNT REF EDS BUYER, LLC9070000001WATC CLEARINGPENNANTPARK CLO IV, LLC
D19: 231959.88
A22: Past Due Receivables
A23: Transaction ID | B23: Asset ID | C23: Currency | D23: Date | E23: Issuer/Borrower | F23: Facility/Security | G23: Identifier | H23: Transaction Type | I23: Account | J23: Participation Counterparty | K23: Transaction Amount | L23: Cash Not Applied | M23: Research | N23: Notes
K24: 1541425.3 | L24: 997245.67
A25: 219522 | B25: 12194 | C25: USD | D25: 45657 | E25: Amsive Holdings Corporation | F25: Incremental TL 75MM PIK Fee | H25: Facility - Paydown - Unscheduled Optional | I25: Principal Collection Subaccount | K25: 38.28 | L25: 38.28
A26: 190877 | B26: 5628 | C26: USD | D26: 45657 | E26: Burgess Point Purchaser Corporation | F26: Initial Term Loan | G26: LX205817 | H26: Facility - Paydown - Scheduled | I26: Principal Collection Subaccount | K26: 635.11 | L26: 635.11
A27: 164205 | B27: 10508 | C27: USD | D27: 45657 | E27: Dr. Squatch LLC | F27: 2024-1 Incremental Term Loan | G27: LX239333 | H27: Facility - Paydown - Unscheduled Optional | I27: Principal Collection Subaccount | K27: 16054.4 | L27: 16054.4
A28: 164311 | B28: 11795 | C28: USD | D28: 45659 | E28: Alpine Acquisition Corp II | F28: Amend 4 TLA-2 | G28: LX207291 | H28: Loan - Interest Payment | I28: Interest Collection Subaccount | K28: 10.71 | L28: 10.71
A29: 164309 | B29: 11795 | C29: USD | D29: 45659 | E29: Alpine Acquisition Corp II | F29: Amend 4 TLA-2 | G29: LX207291 | H29: Loan - Interest Payment | I29: Interest Collection Subaccount | K29: 417.08 | L29: 417.08
A30: 163541 | B30: 3273 | C30: USD | D30: 45659 | E30: Rancho Health MSO Inc | F30: Initial Term Loan | G30: LX191986 | H30: Loan - Interest Payment | I30: Interest Collection Subaccount | K30: 5246.07 | L30: 5246.07
A31: 163545 | B31: 3377 | C31: USD | D31: 45659 | E31: Rancho Health MSO Inc | F31: Second Amendment Funded Delayed Draw Term Loan | H31: Loan - Interest Payment | I31: Interest Collection Subaccount | K31: 135.76 | L31: 135.76
A32: 163544 | B32: 3377 | C32: USD | D32: 45659 | E32: Rancho Health MSO Inc | F32: Second Amendment Funded Delayed Draw Term Loan | H32: Loan - Interest Payment | I32: Interest Collection Subaccount | K32: 134.54 | L32: 134.54
A33: 163543 | B33: 3377 | C33: USD | D33: 45659 | E33: Rancho Health MSO Inc | F33: Second Amendment Funded Delayed Draw Term Loan | H33: Loan - Interest Payment | I33: Interest Collection Subaccount | K33: 1077.44 | L33: 1077.44
A34: 163542 | B34: 3377 | C34: USD | D34: 45659 | E34: Rancho Health MSO Inc | F34: Second Amendment Funded Delayed Draw Term Loan | H34: Loan - Interest Payment | I34: Interest Collection Subaccount | K34: 1317.05 | L34: 1317.05
A35: 163550 | B35: 11022 | C35: USD | D35: 45659 | E35: Rancho Health MSO Inc | F35: Sixth Amendment Delayed Draw Term Loan | H35: Loan - Interest Payment | I35: Interest Collection Subaccount | K35: 269.09 | L35: 269.09
A36: 163540 | B36: 3261 | C36: USD | D36: 45659 | E36: S101 Acquisition Inc | F36: Delayed Draw Term Loan B | H36: Loan - Interest Payment | I36: Interest Collection Subaccount | K36: 265.04 | L36: 265.04
A37: 163551 | B37: 11807 | C37: USD | D37: 45660 | E37: STG Distribution LLC | F37: First Out New Money Term Loan | G37: LX249176 | H37: Loan - Interest Payment | I37: Interest Collection Subaccount | K37: 646 | L37: 646
A38: 163552 | B38: 11809 | C38: USD | D38: 45663 | E38: Vertex Companies Inc, The | F38: Term Loan D | G38: LX256513 | H38: Loan - Interest Payment | I38: Interest Collection Subaccount | K38: 11111.3 | L38: 11111.3
A39: 207260 | B39: 10564 | C39: USD | D39: 45672 | E39: Radius Aerospace Inc | F39: Initial Term Loan | G39: LX179630 | H39: Facility - Paydown - Unscheduled Optional | I39: Principal Collection Subaccount | K39: 663518.63 | L39: 663518.63
A40: 163981 | B40: 9063 | C40: USD | D40: 45673 | E40: Argano LLC | F40: Term Loan | G40: LX246656 | H40: Loan - Interest Payment | I40: Interest Collection Subaccount | K40: 37534.74 | L40: 37534.74
A41: 163377 | B41: 4368 | C41: USD | D41: 45686 | E41: Michael Baker International LLC | F41: New Term B Loan | H41: Loan - Interest Payment | I41: Interest Collection Subaccount | K41: 3658.91 | L41: 3658.91
A42: 164060 | B42: 2495 | C42: USD | D42: 45688 | E42: AFC-Dell Holding Corp | F42: Term Loan | H42: Loan - Interest Payment | I42: Interest Collection Subaccount | K42: 15507.34 | L42: 15507.34
A43: 162884 | B43: 12770 | C43: USD | D43: 45688 | E43: Dr. Squatch LLC | F43: Delayed Draw Term Loan | G43: LX203614 | H43: Loan - Interest Payment | I43: Interest Collection Subaccount | K43: 6188.91 | L43: 6188.91
A44: 164787 | B44: 10550 | C44: USD | D44: 45688 | E44: Infinity Home Services Holdco Inc | F44: Closing Date Delayed Draw Term Loan | G44: LX210066 | H44: Loan - Interest Payment | I44: Interest Collection Subaccount | K44: 19831.28 | L44: 19831.28
A45: 163539 | B45: 3236 | C45: USD | D45: 45688 | E45: Inventus Power Inc | F45: Term Loan | G45: LX213612 | H45: Loan - Interest Payment | I45: Interest Collection Subaccount | K45: 20416.66 | L45: 20416.66
A46: 164790 | B46: 10568 | C46: USD | D46: 45688 | E46: Lash OpCo LLC | F46: Restatement Term Loan | G46: LX201224 | H46: Loan - Interest Payment | I46: Interest Collection Subaccount | K46: 22172.31 | L46: 22172.31
A47: 199238 | B47: 14717 | C47: USD | D47: 45688 | E47: LAV Gear Holdings Inc | F47: Twelfth Amendment Term Loan | G47: LX258942 | H47: Facility Trade - Miscellaneous Fee | I47: Interest Collection Subaccount | K47: 1264.03 | L47: 1264.03
A48: 164470 | B48: 12399 | C48: USD | D48: 45688 | E48: Michael Baker International LLC | F48: Term B-1 Loan | G48: LX258116 | H48: Loan - Interest Payment | I48: Interest Collection Subaccount | K48: 230.34 | L48: 230.34
...

Sheet Sheet1
A1: Asset Type | B1: Facility | K1: 1 | L1: =K1+1 -> 2 | M1: =L1+1 -> 3 | N1: =M1+1 -> 4 | O1: =N1+1 -> 5 | P1: =O1+1 -> 6 | Q1: =P1+1 -> 7 | R1: =Q1+1 -> 8 | S1: =R1+1 -> 9 | ... W1: =V1+1 -> 13
E2: =SUM(E4:E76) -> 4.1352401e+08 | L2: =M3-E2 -> 0.0099999905 | M2: WA | N2: BB | O2: SOI | Q2: Coupon | R2: Spread | S2: Date of Latest Financial Reporting | T2: Net Senior Lev Ratio | U2: EBITDA ($m) | V2: Total Leverage Ratio (current) | W2: Cash Interest Coverage Ratio (current)
A3: Row Labels | B3: Sum of Settled Funded | I3: SOI | J3: Western Alliance | K3: Borrowing Base | L3: Master Comps | M3: =SUM(M4:M79) -> 4.1352401e+08 | N3: =SUM(N4:N79) -> 4.0044313e+08 | O3: =SUM(O4:O79) -> 4.0044313e+08
A4: AFC-Dell Holding Corp | B4: 269595.43 | D4: AFC-Dell Holding Corp | E4: 269595.43 | F4: =VLOOKUP(D4, $J$4:$K$79, 2, FALSE) -> AFC - Dell Holding Corp. | I4: A1 Garage Merger Sub, LLC | J4: =+VLOOKUP(K4,'[2]Sheet2 (2)'!$G$1:$H$73, 2, FALSE) -> TMII Enterprises LLC | K4: A1 Garage Merger Sub, LLC | L4: A1 Garage Merger Sub, LLC | M4: =VLOOKUP(J4, $D$4:$E$78, 2, FALSE) -> 3192037.2 | N4: =VLOOKUP(K4, 'Loan List '!$A$6:$H$82, 8, FALSE) -> 3192037.3 | O4: =VLOOKUP(I4, Sheet2!$A$1:$D$78, 4, FALSE) -> 3192037.3 | P4: =N4-O4 -> 0 | Q4: =VLOOKUP(I4, Sheet2!$A$1:$E$78, 5, FALSE) -> 0.090083815 | R4: =VLOOKUP($L4, '[3]BNP Borrowing Base PSLF JV (PIF'!$A$8:$AI$181, 11, FALSE) -> 0.0475 | S4: =VLOOKUP($L4, '[3]BNP Borrowing Base PSLF JV (PIF'!$A$8:$AI$181, 20, FALSE) -> 45716 | T4: =VLOOKUP($L4, '[3]BNP Borrowing Base PSLF JV (PIF'!$A$8:$AI$181, 22, FALSE) -> 2.3958956 | U4: =VLOOKUP($L4, '[3]BNP Borrowing Base PSLF JV (PIF'!$A$8:$AI$181, 23, FALSE) -> 60.907 | V4: =VLOOKUP($L4, '[3]BNP Borrowing Base PSLF JV (PIF'!$A$8:$AI$181, 32, FALSE) -> 2.3958956 | W4: =VLOOKUP($L4, '[3]BNP Borrowing Base PSLF JV (PIF'!$A$8:$AI$181, 34, FALSE) -> 3.1669615
A5: Alpine Acquisition Corp II | B5: 3958430.5 | D5: Alpine Acquisition Corp II | E5: 3958430.5 | F5: =VLOOKUP(D5, $J$4:$K$79, 2, FALSE) -> Alpine Acquisition Corp II | I5: AFC - Dell Holding Corp. | J5: =+VLOOKUP(K5,'[2]Sheet2 (2)'!$G$1:$H$73, 2, FALSE) -> AFC-Dell Holding Corp | K5: AFC - Dell Holding Corp. | L5: AFC - Dell Holding Corp. | M5: =VLOOKUP(J5, $D$4:$E$78, 2, FALSE) -> 269595.43 | N5: =VLOOKUP(K5, 'Loan List '!$A$6:$H$82, 8, FALSE) -> 269595.42 | O5: =VLOOKUP(I5, Sheet2!$A$1:$D$78, 4, FALSE) -> 269595.42 | P5: =N5-O5 -> 0 | Q5: =VLOOKUP(I5, Sheet2!$A$1:$E$78, 5, FALSE) -> 0.097908 | R5: =VLOOKUP($L5, '[3]BNP Borrowing Base PSLF JV (PIF'!$A$8:$AI$181, 11, FALSE) -> 0.0625 | S5: =VLOOKUP($L5, '[3]BNP Borrowing Base PSLF JV (PIF'!$A$8:$AI$181, 20, FALSE) -> 45716 | T5: =VLOOKUP($L5, '[3]BNP Borrowing Base PSLF JV (PIF'!$A$8:$AI$181, 22, FALSE) -> 6.0802911 | U5: =VLOOKUP($L5, '[3]BNP Borrowing Base PSLF JV (PIF'!$A$8:$AI$181, 23, FALSE) -> 76.694092 | V5: =VLOOKUP($L5, '[3]BNP Borrowing Base PSLF JV (PIF'!$A$8:$AI$181, 32, FALSE) -> 7.1419735 | W5: =VLOOKUP($L5, '[3]BNP Borrowing Base PSLF JV (PIF'!$A$8:$AI$181, 34, FALSE) -> 1.3690869
A6: Amsive Holdings Corporation | B6: 15083.03 | D6: Amsive Holdings Corporation | E6: 15083.03 | F6: =VLOOKUP(D6, $J$4:$K$79, 2, FALSE) -> Amsive Holding Corporation | I6: Alpine Acquisition Corp II | J6: =+VLOOKUP(K6,'[2]Sheet2 (2)'!$G$1:$H$73, 2, FALSE) -> Alpine Acquisition Corp II | K6: Alpine Acquisition Corp II | L6: Alpine Acquisition Corp II | M6: =VLOOKUP(J6, $D$4:$E$78, 2, FALSE) -> 3958430.5 | N6: =O6 -> 3958430.6 | O6: =VLOOKUP(I6, Sheet2!$A$1:$D$78, 4, FALSE) -> 3958430.6 | P6: =N6-O6 -> 0 | Q6: =VLOOKUP(I6, Sheet2!$A$1:$E$78, 5, FALSE) -> 0.1042 | R6: =VLOOKUP($L6, '[3]BNP Borrowing Base PSLF JV (PIF'!$A$8:$AI$181, 11, FALSE) -> 0 | S6: =VLOOKUP($L6, '[3]BNP Borrowing Base PSLF JV (PIF'!$A$8:$AI$181, 20, FALSE) -> 45716 | T6: =VLOOKUP($L6, '[3]BNP Borrowing Base PSLF JV (PIF'!$A$8:$AI$181, 22, FALSE) -> 17.877093 | U6: =VLOOKUP($L6, '[3]BNP Borrowing Base PSLF JV (PIF'!$A$8:$AI$181, 23, FALSE) -> 103.045 | V6: =VLOOKUP($L6, '[3]BNP Borrowing Base PSLF JV (PIF'!$A$8:$AI$181, 32, FALSE) -> 18.393702 | W6: =VLOOKUP($L6, '[3]BNP Borrowing Base PSLF JV (PIF'!$A$8:$AI$181, 34, FALSE) -> 0.67151292
A7: Arcfield Acquisition Corp | B7: 11620875 | D7: Arcfield Acquisition Corp | E7: 11620875 | F7: =VLOOKUP(D7, $J$4:$K$79, 2, FALSE) -> Arcfield | I7: Archer Lewis, LLC | J7: =+VLOOKUP(K7,'[2]Sheet2 (2)'!$G$1:$H$73, 2, FALSE) -> Archer Lewis LLC | K7: Archer Lewis | L7: Archer Lewis | M7: =VLOOKUP(J7, $D$4:$E$78, 2, FALSE) -> 8816867.8 | N7: =VLOOKUP(K7, 'Loan List '!$A$6:$H$82, 8, FALSE) -> 8816867.8 | O7: =VLOOKUP(I7, Sheet2!$A$1:$D$78, 4, FALSE) -> 8816867.8 | P7: =N7-O7 -> 0 | Q7: =VLOOKUP(I7, Sheet2!$A$1:$E$78, 5, FALSE) -> 0.10051621 | R7: =VLOOKUP($L7, '[3]BNP Borrowing Base PSLF JV (PIF'!$A$8:$AI$181, 11, FALSE) -> 0.0575 | S7: =VLOOKUP($L7, '[3]BNP Borrowing Base PSLF JV (PIF'!$A$8:$AI$181, 20, FALSE) -> 45716 | T7: =VLOOKUP($L7, '[3]BNP Borrowing Base PSLF JV (PIF'!$A$8:$AI$181, 22, FALSE) -> 4.5132407 | U7: =VLOOKUP($L7, '[3]BNP Borrowing Base PSLF JV (PIF'!$A$8:$AI$181, 23, FALSE) -> 14.222627 | V7: =VLOOKUP($L7, '[3]BNP Borrowing Base PSLF JV (PIF'!$A$8:$AI$181, 32, FALSE) -> 4.5132407 | W7: =VLOOKUP($L7, '[3]BNP Borrowing Base PSLF JV (PIF'!$A$8:$AI$181, 34, FALSE) -> 3.1751472
A8: Archer Lewis LLC | B8: 8816867.8 | D8: Archer Lewis LLC | E8: 8816867.8 | F8: =VLOOKUP(D8, $J$4:$K$79, 2, FALSE) -> Archer Lewis | I8: Argano, LLC | J8: =+VLOOKUP(K8,'[2]Sheet2 (2)'!$G$1:$H$73, 2, FALSE) -> Argano LLC | K8: Argano, LLC | L8: Argano, LLC | M8: =VLOOKUP(J8, $D$4:$E$78, 2, FALSE) -> 5472521.9 | N8: =VLOOKUP(K8, 'Loan List '!$A$6:$H$82, 8, FALSE) -> 5472500 | O8: =VLOOKUP(I8, Sheet2!$A$1:$D$78, 4, FALSE) -> 5472500 | P8: =N8-O8 -> 0 | Q8: =VLOOKUP(I8, Sheet2!$A$1:$E$78, 5, FALSE) -> 0.100664 | R8: =VLOOKUP($L8, '[3]BNP Borrowing Base PSLF JV (PIF'!$A$8:$AI$181, 11, FALSE) -> 0.0575 | S8: =VLOOKUP($L8, '[3]BNP Borrowing Base PSLF JV (PIF'!$A$8:$AI$181, 20, FALSE) -> 45716 | T8: =VLOOKUP($L8, '[3]BNP Borrowing Base PSLF JV (PIF'!$A$8:$AI$181, 22, FALSE) -> 3.9962264 | U8: =VLOOKUP($L8, '[3]BNP Borrowing Base PSLF JV (PIF'!$A$8:$AI$181, 23, FALSE) -> 61.919506 | V8: =VLOOKUP($L8, '[3]BNP Borrowing Base PSLF JV (PIF'!$A$8:$AI$181, 32, FALSE) -> 6.4187263 | W8: =VLOOKUP($L8, '[3]BNP Borrowing Base PSLF JV (PIF'!$A$8:$AI$181, 34, FALSE) -> 1.532529
A9: Argano LLC | B9: 5472521.9 | D9: Argano LLC | E9: 5472521.9 | F9: =VLOOKUP(D9, $J$4:$K$79, 2, FALSE) -> Argano, LLC | I9: Burgess Point Purchaser Corporation | J9: =+VLOOKUP(K9,'[2]Sheet2 (2)'!$G$1:$H$73, 2, FALSE) -> Burgess Point Purchaser Corporation | K9: BBB Industries | L9: BBB Industries | M9: =VLOOKUP(J9, $D$4:$E$78, 2, FALSE) -> 248327.5 | N9: =VLOOKUP(K9, 'Loan List '!$A$6:$H$82, 8, FALSE) -> 248327.5 | O9: =VLOOKUP(I9, Sheet2!$A$1:$D$78, 4, FALSE) -> 248327.5 | P9: =N9-O9 -> 0 | Q9: =VLOOKUP(I9, Sheet2!$A$1:$E$78, 5, FALSE) -> 0.096492 | R9: =VLOOKUP($L9, '[3]BNP Borrowing Base PSLF JV (PIF'!$A$8:$AI$181, 11, FALSE) -> 0.0525 | S9: =VLOOKUP($L9, '[3]BNP Borrowing Base PSLF JV (PIF'!$A$8:$AI$181, 20, FALSE) -> 45565 | T9: =VLOOKUP($L9, '[3]BNP Borrowing Base PSLF JV (PIF'!$A$8:$AI$181, 22, FALSE) -> 5.6274247 | U9: =VLOOKUP($L9, '[3]BNP Borrowing Base PSLF JV (PIF'!$A$8:$AI$181, 23, FALSE) -> 299 | V9: =VLOOKUP($L9, '[3]BNP Borrowing Base PSLF JV (PIF'!$A$8:$AI$181, 32, FALSE) -> 6.8197324 | W9: =VLOOKUP($L9, '[3]BNP Borrowing Base PSLF JV (PIF'!$A$8:$AI$181, 34, FALSE) -> 1.3906977
A10: Beacon Behavioral Support Services LLC | B10: 12170103 | D10: Beacon Behavioral Support Services LLC | E10: 12170103 | F10: =VLOOKUP(D10, $J$4:$K$79, 2, FALSE) -> Beacon Behavioral Support Services, LLC | I10: Beacon Behavioral Support Services, LLC | J10: =+VLOOKUP(K10,'[2]Sheet2 (2)'!$G$1:$H$73, 2, FALSE) -> Beacon Behavioral Support Services LLC | K10: Beacon Behavioral Support Services, LLC | L10: Beacon Behavioral | M10: =VLOOKUP(J10, $D$4:$E$78, 2, FALSE) -> 12170103 | N10: =VLOOKUP(K10, 'Loan List '!$A$6:$H$82, 8, FALSE) -> 12170103 | O10: =VLOOKUP(I10, Sheet2!$A$1:$D$78, 4, FALSE) -> 12170103 | P10: =N10-O10 -> 0 | Q10: =VLOOKUP(I10, Sheet2!$A$1:$E$78, 5, FALSE) -> 0.098011024 | R10: =VLOOKUP($L10, '[3]BNP Borrowing Base PSLF JV (PIF'!$A$8:$AI$181, 11, FALSE) -> 0.055 | S10: =VLOOKUP($L10, '[3]BNP Borrowing Base PSLF JV (PIF'!$A$8:$AI$181, 20, FALSE) -> 45716 | T10: =VLOOKUP($L10, '[3]BNP Borrowing Base PSLF JV (PIF'!$A$8:$AI$181, 22, FALSE) -> 4.9021373 | U10: =VLOOKUP($L10, '[3]BNP Borrowing Base PSLF JV (PIF'!$A$8:$AI$181, 23, FALSE) -> 22.015998 | V10: =VLOOKUP($L10, '[3]BNP Borrowing Base PSLF JV (PIF'!$A$8:$AI$181, 32, FALSE) -> 5.4872036 | W10: =VLOOKUP($L10, '[3]BNP Borrowing Base PSLF JV (PIF'!$A$8:$AI$181, 34, FALSE) -> 2.4399881
A11: Best Practice Associates LLC | B11: 10781438 | D11: Best Practice Associates LLC | E11: 10781438 | F11: =VLOOKUP(D11, $J$4:$K$79, 2, FALSE) -> Federal Advisory Partners | I11: Blackhawk Industrial Distribution, Inc. | J11: =+VLOOKUP(K11,'[2]Sheet2 (2)'!$G$1:$H$73, 2, FALSE) -> BlackHawk Industrial Distribution Inc | K11: BlackHawk Industrial | L11: BlackHawk Industrial | M11: =VLOOKUP(J11, $D$4:$E$78, 2, FALSE) -> 8649720.3 | N11: =VLOOKUP(K11, 'Loan List '!$A$6:$H$82, 8, FALSE) -> 8653790.5 | O11: =VLOOKUP(I11, Sheet2!$A$1:$D$78, 4, FALSE) -> 8653790.5 | P11: =N11-O11 -> 0 | Q11: =VLOOKUP(I11, Sheet2!$A$1:$E$78, 5, FALSE) -> 0.096992704 | R11: =VLOOKUP($L11, '[3]BNP Borrowing Base PSLF JV (PIF'!$A$8:$AI$181, 11, FALSE) -> 0.05 | S11: =VLOOKUP($L11, '[3]BNP Borrowing Base PSLF JV (PIF'!$A$8:$AI$181, 20, FALSE) -> 45716 | T11: =VLOOKUP($L11, '[3]BNP Borrowing Base PSLF JV (PIF'!$A$8:$AI$181, 22, FALSE) -> 5.8248222 | U11: =VLOOKUP($L11, '[3]BNP Borrowing Base PSLF JV (PIF'!$A$8:$AI$181, 23, FALSE) -> 51.188 | V11: =VLOOKUP($L11, '[3]BNP Borrowing Base PSLF JV (PIF'!$A$8:$AI$181, 32, FALSE) -> 6.4096273 | W11: =VLOOKUP($L11, '[3]BNP Borrowing Base PSLF JV (PIF'!$A$8:$AI$181, 34, FALSE) -> 1.2666221
A12: BlackHawk Industrial Distribution Inc | B12: 8649720.3 | D12: BlackHawk Industrial Distribution Inc | E12: 8649720.3 | F12: =VLOOKUP(D12, $J$4:$K$79, 2, FALSE) -> BlackHawk Industrial | I12: BlueHalo Global Holdings, LLC | J12: =+VLOOKUP(K12,'[2]Sheet2 (2)'!$G$1:$H$73, 2, FALSE) -> BlueHalo Global Holdings LLC | K12: BlueHalo Financing Holdings, LLC | L12: BlueHalo Financing Holdings, LLC | M12: =VLOOKUP(J12, $D$4:$E$78, 2, FALSE) -> 2628762.5 | N12: =VLOOKUP(K12, 'Loan List '!$A$6:$H$82, 8, FALSE) -> 2628762.5 | O12: =VLOOKUP(I12, Sheet2!$A$1:$D$78, 4, FALSE) -> 2628762.5 | P12: =N12-O12 -> 0 | Q12: =VLOOKUP(I12, Sheet2!$A$1:$E$78, 5, FALSE) -> 0.1029917 | R12: =VLOOKUP($L12, '[3]BNP Borrowing Base PSLF JV (PIF'!$A$8:$AI$181, 11, FALSE) -> 0.06 | S12: =VLOOKUP($L12, '[3]BNP Borrowing Base PSLF JV (PIF'!$A$8:$AI$181, 20, FALSE) -> 45657 | T12: =VLOOKUP($L12, '[3]BNP Borrowing Base PSLF JV (PIF'!$A$8:$AI$181, 22, FALSE) -> 7.6702881 | U12: =VLOOKUP($L12, '[3]BNP Borrowing Base PSLF JV (PIF'!$A$8:$AI$181, 23, FALSE) -> 103.7901 | V12: =VLOOKUP($L12, '[3]BNP Borrowing Base PSLF JV (PIF'!$A$8:$AI$181, 32, FALSE) -> 7.7329145 | W12: =VLOOKUP($L12, '[3]BNP Borrowing Base PSLF JV (PIF'!$A$8:$AI$181, 34, FALSE) -> 1.5967892
A13: BLC Holding Company Inc | B13: 2098550.6 | D13: BLC Holding Company Inc | E13: 2098550.6 | F13: =VLOOKUP(D13, $J$4:$K$79, 2, FALSE) -> Bland Landscaping | I13: C5MI Acquisition, LLC | J13: =+VLOOKUP(K13,'[2]Sheet2 (2)'!$G$1:$H$73, 2, FALSE) -> C5MI Acquisition LLC | K13: C5MI Acquisition, LLC | L13: C5MI | M13: =VLOOKUP(J13, $D$4:$E$78, 2, FALSE) -> 1492500 | N13: =VLOOKUP(K13, 'Loan List '!$A$6:$H$82, 8, FALSE) -> 1492500 | O13: =VLOOKUP(I13, Sheet2!$A$1:$D$78, 4, FALSE) -> 1492500 | P13: =N13-O13 -> 0 | Q13: =VLOOKUP(I13, Sheet2!$A$1:$E$78, 5, FALSE) -> 0.102992 | R13: =VLOOKUP($L13, '[3]BNP Borrowing Base PSLF JV (PIF'!$A$8:$AI$181, 11, FALSE) -> 0.06 | S13: =VLOOKUP($L13, '[3]BNP Borrowing Base PSLF JV (PIF'!$A$8:$AI$181, 20, FALSE) -> 45716 | T13: =VLOOKUP($L13, '[3]BNP Borrowing Base PSLF JV (PIF'!$A$8:$AI$181, 22, FALSE) -> 5.1127309 | U13: =VLOOKUP($L13, '[3]BNP Borrowing Base PSLF JV (PIF'!$A$8:$AI$181, 23, FALSE) -> 15.613157 | V13: =VLOOKUP($L13, '[3]BNP Borrowing Base PSLF JV (PIF'!$A$8:$AI$181, 32, FALSE) -> 5.5418561 | W13: =VLOOKUP($L13, '[3]BNP Borrowing Base PSLF JV (PIF'!$A$8:$AI$181, 34, FALSE) -> 1.7344098
A14: Bluebird Group LLC, The | B14: 3635030.3 | D14: Bluebird Group LLC, The | E14: 3635030.3 | F14: =VLOOKUP(D14, $J$4:$K$79, 2, FALSE) -> The Bluebird Group LLC | I14: CF512, Inc. | J14: =+VLOOKUP(K14,'[2]Sheet2 (2)'!$G$1:$H$73, 2, FALSE) -> CF512 Inc | K14: CF512, Inc. | L14: Gen3 Marketing | M14: =VLOOKUP(J14, $D$4:$E$78, 2, FALSE) -> 6298498.8 | N14: =VLOOKUP(K14, 'Loan List '!$A$6:$H$82, 8, FALSE) -> 6298498.8 | O14: =VLOOKUP(I14, Sheet2!$A$1:$D$78, 4, FALSE) -> 6298498.8 | P14: =N14-O14 -> 0 | Q14: =VLOOKUP(I14, Sheet2!$A$1:$E$78, 5, FALSE) -> 0.10501243 | R14: =VLOOKUP($L14, '[3]BNP Borrowing Base PSLF JV (PIF'!$A$8:$AI$181, 11, FALSE) -> 0.06 | S14: =VLOOKUP($L14, '[3]BNP Borrowing Base PSLF JV (PIF'!$A$8:$AI$181, 20, FALSE) -> 45747 | T14: =VLOOKUP($L14, '[3]BNP Borrowing Base PSLF JV (PIF'!$A$8:$AI$181, 22, FALSE) -> 5.6147306 | U14: =VLOOKUP($L14, '[3]BNP Borrowing Base PSLF JV (PIF'!$A$8:$AI$181, 23, FALSE) -> 11.88 | V14: =VLOOKUP($L14, '[3]BNP Borrowing Base PSLF JV (PIF'!$A$8:$AI$181, 32, FALSE) -> 5.6147306 | W14: =VLOOKUP($L14, '[3]BNP Borrowing Base PSLF JV (PIF'!$A$8:$AI$181, 34, FALSE) -> 1.3873642
A15: BlueHalo Global Holdings LLC | B15: 2628762.5 | D15: BlueHalo Global Holdings LLC | E15: 2628762.5 | F15: =VLOOKUP(D15, $J$4:$K$79, 2, FALSE) -> BlueHalo Financing Holdings, LLC | I15: Carnegie Dartlet, LLC | J15: =+VLOOKUP(K15,'[2]Sheet2 (2)'!$G$1:$H$73, 2, FALSE) -> Carnegie Dartlet LLC | K15: Carnegie Dartlet, LLC | L15: Carnegie Dartlet, LLC | M15: =VLOOKUP(J15, $D$4:$E$78, 2, FALSE) -> 6900150.8 | N15: =VLOOKUP(K15, 'Loan List '!$A$6:$H$82, 8, FALSE) -> 6900150.8 | O15: =VLOOKUP(I15, Sheet2!$A$1:$D$78, 4, FALSE) -> 6900150.8 | P15: =N15-O15 -> 0 | Q15: =VLOOKUP(I15, Sheet2!$A$1:$E$78, 5, FALSE) -> 0.098249 | R15: =VLOOKUP($L15, '[3]BNP Borrowing Base PSLF JV (PIF'!$A$8:$AI$181, 11, FALSE) -> 0.055 | S15: =VLOOKUP($L15, '[3]BNP Borrowing Base PSLF JV (PIF'!$A$8:$AI$181, 20, FALSE) -> 45716 | T15: =VLOOKUP($L15, '[3]BNP Borrowing Base PSLF JV (PIF'!$A$8:$AI$181, 22, FALSE) -> 4.6093662 | U15: =VLOOKUP($L15, '[3]BNP Borrowing Base PSLF JV (PIF'!$A$8:$AI$181, 23, FALSE) -> 19.453 | V15: =VLOOKUP($L15, '[3]BNP Borrowing Base PSLF JV (PIF'!$A$8:$AI$181, 32, FALSE) -> 4.6093662 | W15: =VLOOKUP($L15, '[3]BNP Borrowing Base PSLF JV (PIF'!$A$8:$AI$181, 34, FALSE) -> 2.2110269
A16: Boss Industries LLC | B16: 5985000 | D16: Boss Industries LLC | E16: 5985000 | F16: =VLOOKUP(D16, $J$4:$K$79, 2, FALSE) -> Boss Industries | I16: Carisk Buyer, Inc. | J16: =+VLOOKUP(K16,'[2]Sheet2 (2)'!$G$1:$H$73, 2, FALSE) -> Carisk Buyer Inc | K16: Carisk Buyer, Inc. | L16: Carisk Buyer, Inc. | M16: =VLOOKUP(J16, $D$4:$E$78, 2, FALSE) -> 1116738.2 | N16: =VLOOKUP(K16, 'Loan List '!$A$6:$H$82, 8, FALSE) -> 1116738.2 | O16: =VLOOKUP(I16, Sheet2!$A$1:$D$78, 4, FALSE) -> 1116738.2 | P16: =N16-O16 -> 0 | Q16: =VLOOKUP(I16, Sheet2!$A$1:$E$78, 5, FALSE) -> 0.095492 | R16: =VLOOKUP($L16, '[3]BNP Borrowing Base PSLF JV (PIF'!$A$8:$AI$181, 11, FALSE) -> 0.0575 | S16: =VLOOKUP($L16, '[3]BNP Borrowing Base PSLF JV (PIF'!$A$8:$AI$181, 20, FALSE) -> 45747 | T16: =VLOOKUP($L16, '[3]BNP Borrowing Base PSLF JV (PIF'!$A$8:$AI$181, 22, FALSE) -> 3.2892937 | U16: =VLOOKUP($L16, '[3]BNP Borrowing Base PSLF JV (PIF'!$A$8:$AI$181, 23, FALSE) -> 18.868362 | V16: =VLOOKUP($L16, '[3]BNP Borrowing Base PSLF JV (PIF'!$A$8:$AI$181, 32, FALSE) -> 3.2892937 | W16: =VLOOKUP($L16, '[3]BNP Borrowing Base PSLF JV (PIF'!$A$8:$AI$181, 34, FALSE) -> 2.1712655
A17: Burgess Point Purchaser Corporation | B17: 248327.5 | D17: Burgess Point Purchaser Corporation | E17: 248327.5 | F17: =VLOOKUP(D17, $J$4:$K$79, 2, FALSE) -> BBB Industries | I17: Cartessa Aesthetics, LLC | J17: =+VLOOKUP(K17,'[2]Sheet2 (2)'!$G$1:$H$73, 2, FALSE) -> Cartessa Aesthetics LLC | K17: Cartessa | L17: Cartessa | M17: =VLOOKUP(J17, $D$4:$E$78, 2, FALSE) -> 5205875.1 | N17: =VLOOKUP(K17, 'Loan List '!$A$6:$H$82, 8, FALSE) -> 5205875 | O17: =VLOOKUP(I17, Sheet2!$A$1:$D$78, 4, FALSE) -> 5205875 | P17: =N17-O17 -> 0 | Q17: =VLOOKUP(I17, Sheet2!$A$1:$E$78, 5, FALSE) -> 0.100492 | R17: =VLOOKUP($L17, '[3]BNP Borrowing Base PSLF JV (PIF'!$A$8:$AI$181, 11, FALSE) -> 0.06 | S17: =VLOOKUP($L17, '[3]BNP Borrowing Base PSLF JV (PIF'!$A$8:$AI$181, 20, FALSE) -> 45716 | T17: =VLOOKUP($L17, '[3]BNP Borrowing Base PSLF JV (PIF'!$A$8:$AI$181, 22, FALSE) -> 3.2680581 | U17: =VLOOKUP($L17, '[3]BNP Borrowing Base PSLF JV (PIF'!$A$8:$AI$181, 23, FALSE) -> 19.711492 | V17: =VLOOKUP($L17, '[3]BNP Borrowing Base PSLF JV (PIF'!$A$8:$AI$181, 32, FALSE) -> 3.2680581 | W17: =VLOOKUP($L17, '[3]BNP Borrowing Base PSLF JV (PIF'!$A$8:$AI$181, 34, FALSE) -> 2.5267405
A18: C5MI Acquisition LLC | B18: 1492500 | D18: C5MI Acquisition LLC | E18: 1492500 | F18: =VLOOKUP(D18, $J$4:$K$79, 2, FALSE) -> C5MI Acquisition, LLC | I18: Case Works, LLC | J18: =+VLOOKUP(K18,'[2]Sheet2 (2)'!$G$1:$H$73, 2, FALSE) -> Case Works LLC | K18: Case Works | L18: Case Works | M18: =VLOOKUP(J18, $D$4:$E$78, 2, FALSE) -> 4503279.2 | N18: =VLOOKUP(K18, 'Loan List '!$A$6:$H$82, 8, FALSE) -> 4503279.2 | O18: =VLOOKUP(I18, Sheet2!$A$1:$D$78, 4, FALSE) -> 4503279.2 | P18: =N18-O18 -> 0 | Q18: =VLOOKUP(I18, Sheet2!$A$1:$E$78, 5, FALSE) -> 0.095492 | R18: =VLOOKUP($L18, '[3]BNP Borrowing Base PSLF JV (PIF'!$A$8:$AI$181, 11, FALSE) -> 0.0525 | S18: =VLOOKUP($L18, '[3]BNP Borrowing Base PSLF JV (PIF'!$A$8:$AI$181, 20, FALSE) -> 45716 | T18: =VLOOKUP($L18, '[3]BNP Borrowing Base PSLF JV (PIF'!$A$8:$AI$181, 22, FALSE) -> 4.3945971 | U18: =VLOOKUP($L18, '[3]BNP Borrowing Base PSLF JV (PIF'!$A$8:$AI$181, 23, FALSE) -> 19.945156 | V18: =VLOOKUP($L18, '[3]BNP Borrowing Base PSLF JV (PIF'!$A$8:$AI$181, 32, FALSE) -> 4.3945971 | W18: =VLOOKUP($L18, '[3]BNP Borrowing Base PSLF JV (PIF'!$A$8:$AI$181, 34, FALSE) -> 1.579057
... A21: Cartessa Aesthetics LLC | B21: 5205875.1 | D21: Cartessa Aesthetics LLC | E21: 5205875.1 | F21: =VLOOKUP(D21, $J$4:$K$79, 2, FALSE) -> Cartessa | I21: Crane 1 Services, Inc. | J21: =+VLOOKUP(K21,'[2]Sheet2 (2)'!$G$1:$H$73, 2, FALSE) -> Crane 1 Acquisition Holdings Inc | K21: Crane 1 Services, Inc. | L21: Crane 1 Services, Inc. | M21: =VLOOKUP(J21, $D$4:$E$78, 2, FALSE) -> 995000 | N21: =VLOOKUP(K21, 'Loan List '!$A$6:$H$82, 8, FALSE) -> 995000 | O21: =VLOOKUP(I21, Sheet2!$A$1:$D$78, 4, FALSE) -> 995000 | P21: =N21-O21 -> 0 | Q21: =VLOOKUP(I21, Sheet2!$A$1:$E$78, 5, FALSE) -> 0.097571256 | R21: =VLOOKUP($L21, '[3]BNP Borrowing Base PSLF JV (PIF'!$A$8:$AI$181, 11, FALSE) -> 0.0575 | S21: =VLOOKUP($L21, '[3]BNP Borrowing Base PSLF JV (PIF'!$A$8:$AI$181, 20, FALSE) -> 45747 | T21: =VLOOKUP($L21, '[3]BNP Borrowing Base PSLF JV (PIF'!$A$8:$AI$181, 22, FALSE) -> 4.9018235 | U21: =VLOOKUP($L21, '[3]BNP Borrowing Base PSLF JV (PIF'!$A$8:$AI$181, 23, FALSE) -> 27.858 | V21: =VLOOKUP($L21, '[3]BNP Borrowing Base PSLF JV (PIF'!$A$8:$AI$181, 32, FALSE) -> 4.9018235 | W21: =VLOOKUP($L21, '[3]BNP Borrowing Base PSLF JV (PIF'!$A$8:$AI$181, 34, FALSE) -> 2.1485423
A22: Case Works LLC | B22: 4503279.2 | D22: Case Works LLC | E22: 4503279.2 | F22: =VLOOKUP(D22, $J$4:$K$79, 2, FALSE) -> Case Works | I22: Dr. Squatch, LLC | J22: =+VLOOKUP(K22,'[2]Sheet2 (2)'!$G$1:$H$73, 2, FALSE) -> Dr. Squatch LLC | K22: Dr. Squatch, LLC | L22: Dr. Squatch, LLC | M22: =VLOOKUP(J22, $D$4:$E$78, 2, FALSE) -> 14433540 | N22: =O22 -> 14433540 | O22: =VLOOKUP(I22, Sheet2!$A$1:$D$78, 4, FALSE) -> 14433540 | P22: =N22-O22 -> 0 | Q22: =VLOOKUP(I22, Sheet2!$A$1:$E$78, 5, FALSE) -> 0.10103333 | R22: =VLOOKUP($L22, '[3]BNP Borrowing Base PSLF JV (PIF'!$A$8:$AI$181, 11, FALSE) -> 0.0525 | S22: =VLOOKUP($L22, '[3]BNP Borrowing Base PSLF JV (PIF'!$A$8:$AI$181, 20, FALSE) -> 45657 | T22: =VLOOKUP($L22, '[3]BNP Borrowing Base PSLF JV (PIF'!$A$8:$AI$181, 22, FALSE) -> 1.2974759 | U22: =VLOOKUP($L22, '[3]BNP Borrowing Base PSLF JV (PIF'!$A$8:$AI$181, 23, FALSE) -> 96.404406 | V22: =VLOOKUP($L22, '[3]BNP Borrowing Base PSLF JV (PIF'!$A$8:$AI$181, 32, FALSE) -> 1.2974759 | W22: =VLOOKUP($L22, '[3]BNP Borrowing Base PSLF JV (PIF'!$A$8:$AI$181, 34, FALSE) -> 6.1659888
A23: CF512 Inc | B23: 6298498.8 | D23: CF512 Inc | E23: 6298498.8 | F23: =VLOOKUP(D23, $J$4:$K$79, 2, FALSE) -> CF512, Inc. | I23: EDS Buyer, LLC | J23: =+VLOOKUP(K23,'[2]Sheet2 (2)'!$G$1:$H$73, 2, FALSE) -> EDS Buyer LLC | K23: EDS Buyers, LLC | L23: EDS Buyers, LLC | M23: =VLOOKUP(J23, $D$4:$E$78, 2, FALSE) -> 5452662.2 | N23: =O23 -> 5452661.1 | O23: =VLOOKUP(I23, Sheet2!$A$1:$D$78, 4, FALSE) -> 5452661.1 | P23: =N23-O23 -> 0 | Q23: =VLOOKUP(I23, Sheet2!$A$1:$E$78, 5, FALSE) -> 0.099475564 | R23: =VLOOKUP($L23, '[3]BNP Borrowing Base PSLF JV (PIF'!$A$8:$AI$181, 11, FALSE) -> 0.0575 | S23: =VLOOKUP($L23, '[3]BNP Borrowing Base PSLF JV (PIF'!$A$8:$AI$181, 20, FALSE) -> 45716 | T23: =VLOOKUP($L23, '[3]BNP Borrowing Base PSLF JV (PIF'!$A$8:$AI$181, 22, FALSE) -> 3.1697908 | U23: =VLOOKUP($L23, '[3]BNP Borrowing Base PSLF JV (PIF'!$A$8:$AI$181, 23, FALSE) -> 26.727 | V23: =VLOOKUP($L23, '[3]BNP Borrowing Base PSLF JV (PIF'!$A$8:$AI$181, 32, FALSE) -> 3.1697908 | W23: =VLOOKUP($L23, '[3]BNP Borrowing Base PSLF JV (PIF'!$A$8:$AI$181, 34, FALSE) -> 2.3344397
A24: Crane 1 Acquisition Holdings Inc | B24: 995000 | D24: Crane 1 Acquisition Holdings Inc | E24: 995000 | F24: =VLOOKUP(D24, $J$4:$K$79, 2, FALSE) -> Crane 1 Services, Inc. | I24: Eval Home Health Solutions Intermediate, LLC | J24: =+VLOOKUP(K24,'[2]Sheet2 (2)'!$G$1:$H$73, 2, FALSE) -> Eval Home Health Solutions Intermediate LLC | K24: Eval Home Health Solutions Intermediate, LLC | L24: Eval | M24: =VLOOKUP(J24, $D$4:$E$78, 2, FALSE) -> 1362351.4 | N24: =VLOOKUP(K24, 'Loan List '!$A$6:$H$82, 8, FALSE) -> 1362351.4 | O24: =VLOOKUP(I24, Sheet2!$A$1:$D$78, 4, FALSE) -> 1362351.4 | P24: =N24-O24 -> 0 | Q24: =VLOOKUP(I24, Sheet2!$A$1:$E$78, 5, FALSE) -> 0.096512477 | R24: =VLOOKUP($L24, '[3]BNP Borrowing Base PSLF JV (PIF'!$A$8:$AI$181, 11, FALSE) -> 0.0575 | S24: =VLOOKUP($L24, '[3]BNP Borrowing Base PSLF JV (PIF'!$A$8:$AI$181, 20, FALSE) -> 45747 | T24: =VLOOKUP($L24, '[3]BNP Borrowing Base PSLF JV (PIF'!$A$8:$AI$181, 22, FALSE) -> 3.6690952 | U24: =VLOOKUP($L24, '[3]BNP Borrowing Base PSLF JV (PIF'!$A$8:$AI$181, 23, FALSE) -> 12.975206 | V24: =VLOOKUP($L24, '[3]BNP Borrowing Base PSLF JV (PIF'!$A$8:$AI$181, 32, FALSE) -> 3.6690952 | W24: =VLOOKUP($L24, '[3]BNP Borrowing Base PSLF JV (PIF'!$A$8:$AI$181, 34, FALSE) -> 2.5409656
A25: Dr. Squatch LLC | B25: 14433540 | D25: Dr. Squatch LLC | E25: 14433540 | F25: =VLOOKUP(D25, $J$4:$K$79, 2, FALSE) -> Dr. Squatch, LLC | I25: GGG Midco, LLC | J25: =+VLOOKUP(K25,'[2]Sheet2 (2)'!$G$1:$H$73, 2, FALSE) -> GGG Midco LLC | K25: GGG Midco, LLC | L25: GGG Midco, LLC | M25: =VLOOKUP(J25, $D$4:$E$78, 2, FALSE) -> 6578437.8 | N25: =VLOOKUP(K25, 'Loan List '!$A$6:$H$82, 8, FALSE) -> 6578437.8 | O25: =VLOOKUP(I25, Sheet2!$A$1:$D$78, 4, FALSE) -> 6578437.8 | P25: =N25-O25 -> 0 | Q25: =VLOOKUP(I25, Sheet2!$A$1:$E$78, 5, FALSE) -> 0.091839322 | R25: =VLOOKUP($L25, '[3]BNP Borrowing Base PSLF JV (PIF'!$A$8:$AI$181, 11, FALSE) -> 0.05 | S25: =VLOOKUP($L25, '[3]BNP Borrowing Base PSLF JV (PIF'!$A$8:$AI$181, 20, FALSE) -> 45716 | T25: =VLOOKUP($L25, '[3]BNP Borrowing Base PSLF JV (PIF'!$A$8:$AI$181, 22, FALSE) -> 3.5049196 | U25: =VLOOKUP($L25, '[3]BNP Borrowing Base PSLF JV (PIF'!$A$8:$AI$181, 23, FALSE) -> 19.61 | V25: =VLOOKUP($L25, '[3]BNP Borrowing Base PSLF JV (PIF'!$A$8:$AI$181, 32, FALSE) -> 3.8720792 | W25: =VLOOKUP($L25, '[3]BNP Borrowing Base PSLF JV (PIF'!$A$8:$AI$181, 34, FALSE) -> 2.7619718
A26: EDS Buyer LLC | B26: 5452662.2 | D26: EDS Buyer LLC | E26: 5452662.2 | F26: =VLOOKUP(D26, $J$4:$K$79, 2, FALSE) -> EDS Buyers, LLC | I26: HEC Purchaser Corp. | J26: =+VLOOKUP(K26,'[2]Sheet2 (2)'!$G$1:$H$73, 2, FALSE) -> HEC Purchaser Corp. | K26: HEC Purchaser Corp. | L26: Health-E Commerce | M26: =VLOOKUP(J26, $D$4:$E$78, 2, FALSE) -> 1970075.2 | N26: =VLOOKUP(K26, 'Loan List '!$A$6:$H$82, 8, FALSE) -> 1970075.2 | O26: =VLOOKUP(I26, Sheet2!$A$1:$D$78, 4, FALSE) -> 1970075.2 | P26: =N26-O26 -> 0 | Q26: =VLOOKUP(I26, Sheet2!$A$1:$E$78, 5, FALSE) -> 0.094027654 | R26: =VLOOKUP($L26, '[3]BNP Borrowing Base PSLF JV (PIF'!$A$8:$AI$181, 11, FALSE) -> 0.055 | S26: =VLOOKUP($L26, '[3]BNP Borrowing Base PSLF JV (PIF'!$A$8:$AI$181, 20, FALSE) -> 45716 | T26: =VLOOKUP($L26, '[3]BNP Borrowing Base PSLF JV (PIF'!$A$8:$AI$181, 22, FALSE) -> 3.9063922 | U26: =VLOOKUP($L26, '[3]BNP Borrowing Base PSLF JV (PIF'!$A$8:$AI$181, 23, FALSE) -> 58.283953 | V26: =VLOOKUP($L26, '[3]BNP Borrowing Base PSLF JV (PIF'!$A$8:$AI$181, 32, FALSE) -> 3.9063922 | W26: =VLOOKUP($L26, '[3]BNP Borrowing Base PSLF JV (PIF'!$A$8:$AI$181, 34, FALSE) -> 2.2577367
A27: Emergency Care Partners LLC | B27: 995000 | D27: Emergency Care Partners LLC | E27: 995000 | F27: =VLOOKUP(D27, $J$4:$K$79, 2, FALSE) -> Emergency Care Partners LLC | I27: Harris & Co. LLC | J27: =+VLOOKUP(K27,'[2]Sheet2 (2)'!$G$1:$H$73, 2, FALSE) -> Harris & Co. LLC | K27: Harris & Co. LLC | L27: Harris & Co. | M27: =VLOOKUP(J27, $D$4:$E$78, 2, FALSE) -> 8726327.5 | N27: =VLOOKUP(K27, 'Loan List '!$A$6:$H$82, 8, FALSE) -> 8726327.5 | O27: =VLOOKUP(I27, Sheet2!$A$1:$D$78, 4, FALSE) -> 8726327.5 | P27: =N27-O27 -> 0 | Q27: =VLOOKUP(I27, Sheet2!$A$1:$E$78, 5, FALSE) -> 0.091722796 | R27: =VLOOKUP($L27, '[3]BNP Borrowing Base PSLF JV (PIF'!$A$8:$AI$181, 11, FALSE) -> 0.05 | S27: =VLOOKUP($L27, '[3]BNP Borrowing Base PSLF JV (PIF'!$A$8:$AI$181, 20, FALSE) -> 45747 | T27: =VLOOKUP($L27, '[3]BNP Borrowing Base PSLF JV (PIF'!$A$8:$AI$181, 22, FALSE) -> 3.6245035 | U27: =VLOOKUP($L27, '[3]BNP Borrowing Base PSLF JV (PIF'!$A$8:$AI$181, 23, FALSE) -> 30.461 | V27: =VLOOKUP($L27, '[3]BNP Borrowing Base PSLF JV (PIF'!$A$8:$AI$181, 32, FALSE) -> 3.6245035 | W27: =VLOOKUP($L27, '[3]BNP Borrowing Base PSLF JV (PIF'!$A$8:$AI$181, 34, FALSE) -> 5.3721683
A28: Eval Home Health Solutions Intermediate LLC | B28: 1362351.4 | D28: Eval Home Health Solutions Intermediate LLC | E28: 1362351.4 | F28: =VLOOKUP(D28, $J$4:$K$79, 2, FALSE) -> Eval Home Health Solutions Intermediate, LLC | I28: HW Holdco, LLC | J28: =+VLOOKUP(K28,'[2]Sheet2 (2)'!$G$1:$H$73, 2, FALSE) -> HW Holdco LLC | K28: HW Holdco, LLC | L28: HW Holdco, LLC | M28: =VLOOKUP(J28, $D$4:$E$78, 2, FALSE) -> 7618243.3 | N28: =VLOOKUP(K28, 'Loan List '!$A$6:$H$82, 8, FALSE) -> 7618243.4 | O28: =VLOOKUP(I28, Sheet2!$A$1:$D$78, 4, FALSE) -> 7618243.4 | P28: =N28-O28 -> 0 | Q28: =VLOOKUP(I28, Sheet2!$A$1:$E$78, 5, FALSE) -> 0.10147808 | R28: =VLOOKUP($L28, '[3]BNP Borrowing Base PSLF JV (PIF'!$A$8:$AI$181, 11, FALSE) -> 0.05 | S28: =VLOOKUP($L28, '[3]BNP Borrowing Base PSLF JV (PIF'!$A$8:$AI$181, 20, FALSE) -> 45716 | T28: =VLOOKUP($L28, '[3]BNP Borrowing Base PSLF JV (PIF'!$A$8:$AI$181, 22, FALSE) -> 3.0055762 | U28: =VLOOKUP($L28, '[3]BNP Borrowing Base PSLF JV (PIF'!$A$8:$AI$181, 23, FALSE) -> 58.463 | V28: =VLOOKUP($L28, '[3]BNP Borrowing Base PSLF JV (PIF'!$A$8:$AI$181, 32, FALSE) -> 3.0055762 | W28: =VLOOKUP($L28, '[3]BNP Borrowing Base PSLF JV (PIF'!$A$8:$AI$181, 34, FALSE) -> 2.5529694
A29: GGG Midco LLC | B29: 6578437.8 | D29: GGG Midco LLC | E29: 6578437.8 | F29: =VLOOKUP(D29, $J$4:$K$79, 2, FALSE) -> GGG Midco, LLC | I29: Infinity Home Services Holdco, Inc. | J29: =+VLOOKUP(K29,'[2]Sheet2 (2)'!$G$1:$H$73, 2, FALSE) -> Infinity Home Services Holdco Inc | K29: Infinity Home Services Holdco, Inc. | L29: Infinity Home Services Holdco, Inc. | M29: =VLOOKUP(J29, $D$4:$E$78, 2, FALSE) -> 5118399.2 | N29: =VLOOKUP(K29, 'Loan List '!$A$6:$H$82, 8, FALSE) -> 5118399.2 | O29: =VLOOKUP(I29, Sheet2!$A$1:$D$78, 4, FALSE) -> 5118399.2 | P29: =N29-O29 -> 0 | Q29: =VLOOKUP(I29, Sheet2!$A$1:$E$78, 5, FALSE) -> 0.097992 | R29: =VLOOKUP($L29, '[3]BNP Borrowing Base PSLF JV (PIF'!$A$8:$AI$181, 11, FALSE) -> 0.0675 | S29: =VLOOKUP($L29, '[3]BNP Borrowing Base PSLF JV (PIF'!$A$8:$AI$181, 20, FALSE) -> 45716 | T29: =VLOOKUP($L29, '[3]BNP Borrowing Base PSLF JV (PIF'!$A$8:$AI$181, 22, FALSE) -> 5.1442629 | U29: =VLOOKUP($L29, '[3]BNP Borrowing Base PSLF JV (PIF'!$A$8:$AI$181, 23, FALSE) -> 63.211 | V29: =VLOOKUP($L29, '[3]BNP Borrowing Base PSLF JV (PIF'!$A$8:$AI$181, 32, FALSE) -> 5.1442629 | W29: =VLOOKUP($L29, '[3]BNP Borrowing Base PSLF JV (PIF'!$A$8:$AI$181, 34, FALSE) -> 2.0660565
A30: Harris & Co. LLC | B30: 8726327.5 | D30: Harris & Co. LLC | E30: 8726327.5 | F30: =VLOOKUP(D30, $J$4:$K$79, 2, FALSE) -> Harris & Co. LLC | I30: Infolinks Media Buyco, LLC | J30: =+VLOOKUP(K30,'[2]Sheet2 (2)'!$G$1:$H$73, 2, FALSE) -> Infolinks Media Buyco LLC | K30: Infolinks | L30: Infolinks | M30: =VLOOKUP(J30, $D$4:$E$78, 2, FALSE) -> 2051982.1 | N30: =VLOOKUP(K30, 'Loan List '!$A$6:$H$82, 8, FALSE) -> 2051982.1 | O30: =VLOOKUP(I30, Sheet2!$A$1:$D$78, 4, FALSE) -> 2051982.1 | P30: =N30-O30 -> 0 | Q30: =VLOOKUP(I30, Sheet2!$A$1:$E$78, 5, FALSE) -> 0.097619943 | R30: =VLOOKUP($L30, '[3]BNP Borrowing Base PSLF JV (PIF'!$A$8:$AI$181, 11, FALSE) -> 0.055 | S30: =VLOOKUP($L30, '[3]BNP Borrowing Base PSLF JV (PIF'!$A$8:$AI$181, 20, FALSE) -> 45716 | T30: =VLOOKUP($L30, '[3]BNP Borrowing Base PSLF JV (PIF'!$A$8:$AI$181, 22, FALSE) -> 3.2535092 | U30: =VLOOKUP($L30, '[3]BNP Borrowing Base PSLF JV (PIF'!$A$8:$AI$181, 23, FALSE) -> 49.399276 | V30: =VLOOKUP($L30, '[3]BNP Borrowing Base PSLF JV (PIF'!$A$8:$AI$181, 32, FALSE) -> 3.2535092 | W30: =VLOOKUP($L30, '[3]BNP Borrowing Base PSLF JV (PIF'!$A$8:$AI$181, 34, FALSE) -> 3.0077525
A31: HEC Purchaser Corp. | B31: 1970075.2 | D31: HEC Purchaser Corp. | E31: 1970075.2 | F31: =VLOOKUP(D31, $J$4:$K$79, 2, FALSE) -> HEC Purchaser Corp. | I31: Inventus Power, Inc. | J31: =+VLOOKUP(K31,'[2]Sheet2 (2)'!$G$1:$H$73, 2, FALSE) -> Inventus Power Inc | K31: Inventus Power Inc. | L31: Inventus Power Inc. | M31: =VLOOKUP(J31, $D$4:$E$78, 2, FALSE) -> 1975484.5 | N31: =VLOOKUP(K31, 'Loan List '!$A$6:$H$82, 8, FALSE) -> 1975484.5 | O31: =VLOOKUP(I31, Sheet2!$A$1:$D$78, 4, FALSE) -> 1975484.5 | P31: =N31-O31 -> 0 | Q31: =VLOOKUP(I31, Sheet2!$A$1:$E$78, 5, FALSE) -> 0.119394 | R31: =VLOOKUP($L31, '[3]BNP Borrowing Base PSLF JV (PIF'!$A$8:$AI$181, 11, FALSE) -> 0.075 | S31: =VLOOKUP($L31, '[3]BNP Borrowing Base PSLF JV (PIF'!$A$8:$AI$181, 20, FALSE) -> 45716 | T31: =VLOOKUP($L31, '[3]BNP Borrowing Base PSLF JV (PIF'!$A$8:$AI$181, 22, FALSE) -> 4.9069445 | U31: =VLOOKUP($L31, '[3]BNP Borrowing Base PSLF JV (PIF'!$A$8:$AI$181, 23, FALSE) -> 51.788 | V31: =VLOOKUP($L31, '[3]BNP Borrowing Base PSLF JV (PIF'!$A$8:$AI$181, 32, FALSE) -> 4.9069445 | W31: =VLOOKUP($L31, '[3]BNP Borrowing Base PSLF JV (PIF'!$A$8:$AI$181, 34, FALSE) -> 1.4563555
A32: HV Watterson Holdings LLC | B32: 9328396.7 | D32: HV Watterson Holdings LLC | E32: 9328396.7 | F32: =VLOOKUP(D32, $J$4:$K$79, 2, FALSE) -> Watterson | I32: Lash OpCo, LLC | J32: =+VLOOKUP(K32,'[2]Sheet2 (2)'!$G$1:$H$73, 2, FALSE) -> Lash OpCo LLC | K32: Lash OpCo, LLC | L32: Lash OpCo, LLC | M32: =VLOOKUP(J32, $D$4:$E$78, 2, FALSE) -> 3328030.8 | N32: =VLOOKUP(K32, 'Loan List '!$A$6:$H$82, 8, FALSE) -> 3328030.9 | O32: =VLOOKUP(I32, Sheet2!$A$1:$D$78, 4, FALSE) -> 3328030.9 | P32: =N32-O32 -> 0 | Q32: =VLOOKUP(I32, Sheet2!$A$1:$E$78, 5, FALSE) -> 0.11582122 | R32: =VLOOKUP($L32, '[3]BNP Borrowing Base PSLF JV (PIF'!$A$8:$AI$181, 11, FALSE) -> 0.07 | S32: =VLOOKUP($L32, '[3]BNP Borrowing Base PSLF JV (PIF'!$A$8:$AI$181, 20, FALSE) -> 45716 | T32: =VLOOKUP($L32, '[3]BNP Borrowing Base PSLF JV (PIF'!$A$8:$AI$181, 22, FALSE) -> 8.2594418 | U32: =VLOOKUP($L32, '[3]BNP Borrowing Base PSLF JV (PIF'!$A$8:$AI$181, 23, FALSE) -> 60.446582 | V32: =VLOOKUP($L32, '[3]BNP Borrowing Base PSLF JV (PIF'!$A$8:$AI$181, 32, FALSE) -> 8.2594418 | W32: =VLOOKUP($L32, '[3]BNP Borrowing Base PSLF JV (PIF'!$A$8:$AI$181, 34, FALSE) -> 0.91660285
A33: HW Holdco LLC | B33: 7618243.3 | D33: HW Holdco LLC | E33: 7618243.3 | F33: =VLOOKUP(D33, $J$4:$K$79, 2, FALSE) -> HW Holdco, LLC | I33: MDI Buyer Inc. | J33: =+VLOOKUP(K33,'[2]Sheet2 (2)'!$G$1:$H$73, 2, FALSE) -> MDI Buyer Inc | K33: MDI Buyer Inc. | L33: Molded Devices | M33: =VLOOKUP(J33, $D$4:$E$78, 2, FALSE) -> 4792248.3 | N33: =VLOOKUP(K33, 'Loan List '!$A$6:$H$82, 8, FALSE) -> 4792248.3 | O33: =VLOOKUP(I33, Sheet2!$A$1:$D$78, 4, FALSE) -> 4792248.3 | P33: =N33-O33 -> 0 | Q33: =VLOOKUP(I33, Sheet2!$A$1:$E$78, 5, FALSE) -> 0.10117766 | R33: =VLOOKUP($L33, '[3]BNP Borrowing Base PSLF JV (PIF'!$A$8:$AI$181, 11, FALSE) -> 0.06 | S33: =VLOOKUP($L33, '[3]BNP Borrowing Base PSLF JV (PIF'!$A$8:$AI$181, 20, FALSE) -> 45716 | T33: =VLOOKUP($L33, '[3]BNP Borrowing Base PSLF JV (PIF'!$A$8:$AI$181, 22, FALSE) -> 5.1521667 | U33: =VLOOKUP($L33, '[3]BNP Borrowing Base PSLF JV (PIF'!$A$8:$AI$181, 23, FALSE) -> 34.693125 | V33: =VLOOKUP($L33, '[3]BNP Borrowing Base PSLF JV (PIF'!$A$8:$AI$181, 32, FALSE) -> 6.689848 | W33: =VLOOKUP($L33, '[3]BNP Borrowing Base PSLF JV (PIF'!$A$8:$AI$181, 34, FALSE) -> 2.33
A34: Infinity Home Services Holdco Inc | B34: 5118399.2 | D34: Infinity Home Services Holdco Inc | E34: 5118399.2 | F34: =VLOOKUP(D34, $J$4:$K$79, 2, FALSE) -> Infinity Home Services Holdco, Inc. | I34: Megawatt Acquisitionco, Inc. | J34: =+VLOOKUP(K34,'[2]Sheet2 (2)'!$G$1:$H$73, 2, FALSE) -> Megawatt Acquisitionco Inc | K34: Megawatt Acquisitionco, Inc. | L34: Megawatt Acquisitionco, Inc. | M34: =VLOOKUP(J34, $D$4:$E$78, 2, FALSE) -> 4942556.4 | N34: =VLOOKUP(K34, 'Loan List '!$A$6:$H$82, 8, FALSE) -> 4942556.4 | O34: =VLOOKUP(I34, Sheet2!$A$1:$D$78, 4, FALSE) -> 4942556.4 | P34: =N34-O34 -> 0 | Q34: =VLOOKUP(I34, Sheet2!$A$1:$E$78, 5, FALSE) -> 0.097992 | R34: =VLOOKUP($L34, '[3]BNP Borrowing Base PSLF JV (PIF'!$A$8:$AI$181, 11, FALSE) -> 0.0525 | S34: =VLOOKUP($L34, '[3]BNP Borrowing Base PSLF JV (PIF'!$A$8:$AI$181, 20, FALSE) -> 45716 | T34: =VLOOKUP($L34, '[3]BNP Borrowing Base PSLF JV (PIF'!$A$8:$AI$181, 22, FALSE) -> 7.1829156 | U34: =VLOOKUP($L34, '[3]BNP Borrowing Base PSLF JV (PIF'!$A$8:$AI$181, 23, FALSE) -> 19.55 | V34: =VLOOKUP($L34, '[3]BNP Borrowing Base PSLF JV (PIF'!$A$8:$AI$181, 32, FALSE) -> 7.1829156 | W34: =VLOOKUP($L34, '[3]BNP Borrowing Base PSLF JV (PIF'!$A$8:$AI$181, 34, FALSE) -> 1.2849162
A35: Infolinks Media Buyco LLC | B35: 2051982.1 | D35: Infolinks Media Buyco LLC | E35: 2051982.1 | F35: =VLOOKUP(D35, $J$4:$K$79, 2, FALSE) -> Infolinks | I35: Michael Baker International, LLC | J35: =+VLOOKUP(K35,'[2]Sheet2 (2)'!$G$1:$H$73, 2, FALSE) -> Michael Baker International LLC | K35: Michael Baker International, LLC | L35: Michael Baker | M35: =VLOOKUP(J35, $D$4:$E$78, 2, FALSE) -> 497493.74 | N35: =VLOOKUP(K35, 'Loan List '!$A$6:$H$82, 8, FALSE) -> 497493.74 | O35: =VLOOKUP(I35, Sheet2!$A$1:$D$78, 4, FALSE) -> 497493.74 | P35: =N35-O35 -> 0 | Q35: =VLOOKUP(I35, Sheet2!$A$1:$E$78, 5, FALSE) -> 0.083249 | R35: =VLOOKUP($L35, '[3]BNP Borrowing Base PSLF JV (PIF'!$A$8:$AI$181, 11, FALSE) -> 0.0475 | S35: =VLOOKUP($L35, '[3]BNP Borrowing Base PSLF JV (PIF'!$A$8:$AI$181, 20, FALSE) -> 45657 | T35: =VLOOKUP($L35, '[3]BNP Borrowing Base PSLF JV (PIF'!$A$8:$AI$181, 22, FALSE) -> 3.7058168 | U35: =VLOOKUP($L35, '[3]BNP Borrowing Base PSLF JV (PIF'!$A$8:$AI$181, 23, FALSE) -> 175.112 | V35: =VLOOKUP($L35, '[3]BNP Borrowing Base PSLF JV (PIF'!$A$8:$AI$181, 32, FALSE) -> 3.7058168 | W35: =VLOOKUP($L35, '[3]BNP Borrowing Base PSLF JV (PIF'!$A$8:$AI$181, 34, FALSE) -> 3.0605425
... A42: MDI Buyer Inc | B42: 4792248.3 | D42: MDI Buyer Inc | E42: 4792248.3 | F42: =VLOOKUP(D42, $J$4:$K$79, 2, FALSE) -> MDI Buyer Inc. | I42: PL Acquisitionco, LLC | J42: =+VLOOKUP(K42,'[2]Sheet2 (2)'!$G$1:$H$73, 2, FALSE) -> Pink Lily Holdings LLC | K42: PL Acquisitionco, LLC | L42: PL Acquisitionco, LLC | M42: =VLOOKUP(J42, $D$4:$E$78, 2, FALSE) -> 8459233 | N42: =VLOOKUP(K42, 'Loan List '!$A$6:$H$82, 8, FALSE) -> 8459233 | O42: =VLOOKUP(I42, Sheet2!$A$1:$D$78, 4, FALSE) -> 8459233 | P42: =N42-O42 -> 0 | Q42: =VLOOKUP(I42, Sheet2!$A$1:$E$78, 5, FALSE) -> 0.115016 | R42: =VLOOKUP($L42, '[3]BNP Borrowing Base PSLF JV (PIF'!$A$8:$AI$181, 11, FALSE) -> 0.065 | S42: =VLOOKUP($L42, '[3]BNP Borrowing Base PSLF JV (PIF'!$A$8:$AI$181, 20, FALSE) -> 45716 | T42: =VLOOKUP($L42, '[3]BNP Borrowing Base PSLF JV (PIF'!$A$8:$AI$181, 22, FALSE) -> NM | U42: =VLOOKUP($L42, '[3]BNP Borrowing Base PSLF JV (PIF'!$A$8:$AI$181, 23, FALSE) -> -3.648616 | V42: =VLOOKUP($L42, '[3]BNP Borrowing Base PSLF JV (PIF'!$A$8:$AI$181, 32, FALSE) -> -18.2598 | W42: =VLOOKUP($L42, '[3]BNP Borrowing Base PSLF JV (PIF'!$A$8:$AI$181, 34, FALSE) -> -0.39253534
