Workbook
Name DDcommit: 'Balance Sheet'!$H$76

Sheet Balance Sheet
B1: PennantPark Investment Corporation
B2: Trial Balance / Sub Chapter M Test
B3: ='BDC post TB'!D6 -> 01/31/2026:23:59:59
D5: With | F5: Without
B6: Assets | D6: Unfunded | F6: Unfunded
A7: a | B7: Investments at fair value | D7: =SUMIF(Summary!O:O,'Balance Sheet'!A7,Summary!N:N) -> 9.6055743e+08 | F7: =SUMIF(Summary!O:O,'Balance Sheet'!A7,Summary!N:N) -> 9.6055743e+08
A8: b1 | B8: Cash (See Note 8) | D8: =SUMIF(Summary!O:O,'Balance Sheet'!A8,Summary!N:N) -> 17258028 | F8: =SUMIF(Summary!O:O,'Balance Sheet'!A8,Summary!N:N) -> 17258028 | I8: =D8+D9-(SUMIF('BDC post TB'!D:D,J8,'BDC post TB'!J:J)+SUMIF('SBICII post TB (closed)'!D:D,J8,'SBICII post TB (closed)'!J:J)+SUMIF('BDC post TB'!E:E,K8,'BDC post TB'!J:J)+SUMIF('SBICII post TB (closed)'!E:E,K8,'SBICII post TB (closed)'!J:J)) -> 0 | J8: Cash | K8: MoneyMarket
A9: b2 | B9: Cash Equivalents | D9: =SUMIF(Summary!O:O,'Balance Sheet'!A9,Summary!N:N) -> 30530529 | F9: =SUMIF(Summary!O:O,'Balance Sheet'!A9,Summary!N:N) -> 30530529
A10: c | B10: Interest receivable | D10: =SUMIF(Summary!O:O,'Balance Sheet'!A10,Summary!N:N) -> 9324098.6 | F10: =SUMIF(Summary!O:O,'Balance Sheet'!A10,Summary!N:N) -> 9324098.6
A11: d1 | B11: Receivable for investments sold | D11: =SUMIF(Summary!O:O,'Balance Sheet'!A11,Summary!N:N) -> 73832136 | F11: =D11 -> 73832136 | I11: =D11-'Rec-Pay-Month End'!M49 -> 0
A12: d2 | B12: DistributionsReceivable | D12: =SUMIF(Summary!O:O,'Balance Sheet'!A12,Summary!N:N) -> 230769 | F12: =SUMIF(Summary!O:O,'Balance Sheet'!A12,Summary!N:N) -> 230769
A13: dd | B13: Due From Affiliates | D13: =SUMIF(Summary!O:O,'Balance Sheet'!A13,Summary!N:N) -> 81285.15 | F13: =SUMIF(Summary!O:O,'Balance Sheet'!A13,Summary!N:N) -> 81285.15
A14: d | B14: Prepaid expenses and other assets | D14: =SUMIF(Summary!O:O,'Balance Sheet'!A14,Summary!N:N) -> 322349.9 | F14: =SUMIF(Summary!O:O,'Balance Sheet'!A14,Summary!N:N) -> 322349.9
B15: Total assets | D15: =SUM(D6:D14) -> 1.0921366e+09 | F15: =SUM(F6:F14) -> 1.0921366e+09
B17: Liabilities
A18: e | B18: Distributions payable | D18: =-SUMIF(Summary!O:O,'Balance Sheet'!A18,Summary!N:N) -> 5223687.5 | F18: =-SUMIF(Summary!O:O,'Balance Sheet'!A18,Summary!N:N) -> 5223687.5
A19: f | B19: Payable for investments purchased | D19: =-SUMIF(Summary!O:O,'Balance Sheet'!A19,Summary!N:N)+'Rec-Pay-Month End'!M69 -> 4900000 | F19: =D19 -> 4900000 | I19: =D19+'Rec-Pay-Month End'!M59 -> 0
A20: g | B20: Unfunded investments | D20: =-SUMIF(Summary!O:O,'Balance Sheet'!A20,Summary!N:N) -> 0 | F20: =-SUMIF(Summary!O:O,'Balance Sheet'!A20,Summary!N:N) -> 0
A21: h | B21: Credit Facility payable | D21: =-SUMIF(Summary!O:O,'Balance Sheet'!A21,Summary!N:N) -> 2.2146872e+08 | F21: =-SUMIF(Summary!O:O,'Balance Sheet'!A21,Summary!N:N) -> 2.2146872e+08 | H21: =F21+Summary!N20+Summary!N142 -> 2.2146872e+08
A22: i2 | B22: 2024 Notes Payable | C22: DUMPNNTG2024 | D22: =-SUMIF(Summary!O:O,'Balance Sheet'!A22,Summary!N:N)+-SUMIF('BDC Long Short'!D:D,'Balance Sheet'!C22,'BDC Long Short'!L:L) -> 0 | F22: =D22 -> 0 | H22: =-Summary!I28-Summary!I55-Summary!I56-Summary!I57+Summary!N20 -> 3.8899083e+08
A23: i3 | B23: 2026 Notes Payable | C23: DUMPNNTG2026 | D23: =-SUMIF(Summary!O:O,'Balance Sheet'!A23,Summary!N:N)+-SUMIF('BDC Long Short'!D:D,'Balance Sheet'!C23,'BDC Long Short'!L:L) -> 1.4977316e+08 | F23: =D23 -> 1.4977316e+08
A24: i4 | B24: Nov 2026 Notes Payable | C24: DUMPNNT112026 | D24: =-SUMIF(Summary!O:O,'Balance Sheet'!A24,Summary!N:N)+-SUMIF('BDC Long Short'!D:D,'Balance Sheet'!C24,'BDC Long Short'!L:L) -> 1.6421767e+08 | F24: =D24 -> 1.6421767e+08
A25: i5 | B25: Feb 2029 Notes Payable | C25: DUMPNNT022029 | D25: =-SUMIF(Summary!O:O,'Balance Sheet'!A25,Summary!N:N)+-SUMIF('BDC Long Short'!D:D,'Balance Sheet'!C25,'BDC Long Short'!L:L) -> 73607190 | F25: =D25 -> 73607190
A26: j | B26: Interest payable on Credit Facility, and Notes | D26: =-SUMIF(Summary!O:O,'Balance Sheet'!A26,Summary!N:N) -> 4211755.6 | F26: =D26 -> 4211755.6
A27: k | B27: Management fee payable | D27: =-SUMIF(Summary!O:O,'Balance Sheet'!A27,Summary!N:N) -> 3915499 | F27: =-SUMIF(Summary!O:O,'Balance Sheet'!A27,Summary!N:N) -> 3915499
A28: l | B28: Performance-based incentive fee payable | D28: =-SUMIF(Summary!O:O,'Balance Sheet'!A28,Summary!N:N) -> 0 | F28: =-SUMIF(Summary!O:O,'Balance Sheet'!A28,Summary!N:N) -> 0
A29: mm | B29: Deferred tax liability | D29: =-SUMIF(Summary!O:O,'Balance Sheet'!A29,Summary!N:N) -> 0 | F29: =D29 -> 0
A30: nn | B30: Due to Affiliates | D30: =-SUMIF(Summary!O:O,'Balance Sheet'!A30,Summary!N:N) -> 0 | F30: =-SUMIF(Summary!O:O,'Balance Sheet'!A30,Summary!N:N) -> 0
A31: m | B31: Accrued other expenses | D31: =-SUMIF(Summary!O:O,'Balance Sheet'!A31,Summary!N:N) -> 5559686.4 | F31: =-SUMIF(Summary!O:O,'Balance Sheet'!A31,Summary!N:N) -> 5559686.4
B32: Total liabilities | D32: =SUM(D17:D31) -> 6.3287737e+08 | F32: =SUM(F17:F31) -> 6.3287737e+08
B34: Net assets
A35: n | B35: Common stock, | D35: =-SUMIF(Summary!O:O,'Balance Sheet'!A35,Summary!N:N) -> 65296.14 | F35: =-SUMIF(Summary!O:O,'Balance Sheet'!A35,Summary!N:N) -> 65296.14 | I35: PRIOR YEAR
A36: o | B36: Paid-in capital in excess of par value | D36: =-SUMIF(Summary!O:O,'Balance Sheet'!A36,Summary!N:N)-I36 -> 7.405063e+08 | F36: =-SUMIF(Summary!O:O,'Balance Sheet'!A36,Summary!N:N)-I36 -> 7.405063e+08
A37: p | B37: Undistributed net investment income | D37: =-SUMIF(Summary!O:O,'Balance Sheet'!A37,Summary!N:N)+'Income Statement'!G25+'Balance Sheet'!I37 -> 40800451 | F37: =-SUMIF(Summary!O:O,'Balance Sheet'!A37,Summary!N:N)+'Income Statement'!G25+'Balance Sheet'!I37 -> 40800451 | I37: =47474252.5600001+3394442 -> 50868695
A38: q | B38: Accumulated net realized loss on investments | D38: =+I38+'Income Statement'!G28 -> -3.0449104e+08 | F38: =+I38+'Income Statement'!G28 -> -3.0449104e+08 | I38: =-365072732.94+67497 -> -3.6500524e+08
B39: Accumulated net realized FX loss | D39: =+I39+'Income Statement'!G29 -> -8839.89 | F39: =+I39+'Income Statement'!G29 -> -8839.89 | I39: 258362.51
B40: Accumulated net realized loss on debt | D40: =+I40+'Income Statement'!G30 -> -3211181.9 | F40: =+I40+'Income Statement'!G30 -> -3211181.9 | I40: -3211181.9
A41: r | B41: Net unrealized depreciation on investments | D41: =+I41+'Income Statement'!G33 -> -3449916.2 | F41: =+I41+'Income Statement'!G33 -> -3449916.2 | I41: 50415555
B42: Provision for taxes on unrealized appreciation (depreciation) on investments | D42: =+I42+'Income Statement'!G36 -> 0 | F42: =+I42+'Income Statement'!G36 -> 0 | I42: 0
B43: Provision for taxes on realized gain on investments | D43: =+I43+'Income Statement'!G37 -> -10939359 | F43: =+I43+'Income Statement'!G37 -> -10939359 | I43: -10926504
...

Sheet Income Statement
B1: PennantPark Investment Corporation
B2: Income Statement
C5: FY 2026 Quarter to Date | G5: FY 2026
B6: Investment income: | C6: December - 2025 | D6: March - 2026 | E6: June - 2026 | F6: September - 2026 | G6: YEAR TO DATE
A7: a | B7: Interest | C7: 22534987 | D7: =G7-C7 -> 7130703.9 | G7: =-SUMIF(Summary!P:P,'Income Statement'!A7,Summary!N:N) -> 29665691
A8: b1a | B8: PSLF Membership Dividend | C8: 4183813 | D8: =G8-C8 -> 0 | G8: =-SUMIF(Summary!P:P,'Income Statement'!A8,Summary!N:N) -> 4183813
A9: b1b | B9: PTSF II Membership Dividend | C9: 230769 | D9: =G9-C9 -> 0 | G9: =-SUMIF(Summary!P:P,'Income Statement'!A9,Summary!N:N) -> 230769
A10: b3 | B10: Dividend Distribution Income | C10: 3720.89 | D10: =G10-C10 -> 8383.08 | G10: =-SUMIF(Summary!P:P,'Income Statement'!A10,Summary!N:N) -> 12103.97
A11: b2 | B11: Other income | C11: 300732.16 | D11: =G11-C11 -> 21157.91 | G11: =-SUMIF(Summary!P:P,'Income Statement'!A11,Summary!N:N) -> 321890.07
B12: Total investment income | C12: 27254022 | D12: =SUM(D7:D11) -> 7160244.8 | E12: =SUM(E7:E11) -> 0 | F12: =SUM(F7:F11) -> 0 | G12: =SUM(G7:G11) -> 34414267
B14: Expenses:
A15: c | B15: Base management fee | C15: 3915499 | D15: =G15-C15 -> 0 | G15: =SUMIF(Summary!P:P,'Income Statement'!A15,Summary!N:N) -> 3915499
A16: c1 | B16: Base management fee - Waiver | C16: 0 | D16: =G16-C16 -> 0 | G16: =SUMIF(Summary!P:P,'Income Statement'!A16,Summary!N:N) -> 0
A17: d | B17: Performance-based incentive fee | C17: 0 | D17: =G17-C17 -> 0 | G17: =SUMIF(Summary!P:P,'Income Statement'!A17,Summary!N:N) -> 0
A18: e | B18: Interest and expenses on Credit Facility | C18: 10500807 | D18: =G18-C18 -> 2835768.7 | G18: =SUMIF(Summary!P:P,'Income Statement'!A18,Summary!N:N) -> 13336576
A19: f | B19: Administrative services expenses | C19: 450000 | D19: =G19-C19 -> 150000 | G19: =SUMIF(Summary!P:P,'Income Statement'!A19,Summary!N:N) -> 600000
A20: g | B20: Other general and administrative expenses | C20: 849999.99 | D20: =G20-C20 -> 320821.74 | G20: =SUMIF(Summary!P:P,'Income Statement'!A20,Summary!N:N) -> 1170821.7
B21: Expenses before excise taxes | C21: 15716306 | D21: =SUM(D14:D20) -> 3306590.5 | E21: =SUM(E14:E20) -> 0 | F21: =SUM(F14:F20) -> 0 | G21: =SUM(G14:G20) -> 19022897
A22: h | B22: Excise tax | C22: 660000 | D22: =G22-C22 -> 0 | G22: =SUMIF(Summary!P:P,'Income Statement'!A22,Summary!N:N) -> 660000
A23: h1 | B23: Debt issuance costs - Credit Facility Amendment Fee | C23: 3885199.9 | D23: =G23-C23 -> 19663.75 | G23: =SUMIF(Summary!P:P,'Income Statement'!A23,Summary!N:N) -> 3904863.6
B24: Total expenses | C24: 20261506 | D24: =SUM(D21:D23) -> 3326254.2 | E24: =SUM(E21:E23) -> 0 | F24: =SUM(F21:F23) -> 0 | G24: =SUM(G21:G23) -> 23587760
B25: Net investment income | C25: 6992515.9 | D25: =D12-D24 -> 3833990.6 | E25: =E12-E24 -> 0 | F25: =F12-F24 -> 0 | G25: =G12-G24 -> 10826507
B27: Realized gain (loss) on investments and debt:
A28: i | B28: Net realized gain (loss) on non-controlled, non-affiliated investments | C28: 59282326 | D28: =G28-C28 -> 1231874.1 | G28: =-SUMIF(Summary!P:P,'Income Statement'!A28,Summary!N:N) -> 60514200
A29: l | B29: Net realized FX gain (loss) on non-controlled, non-affiliated investments | C29: -267390.28 | D29: =G29-C29 -> 187.88 | G29: =-SUMIF(Summary!P:P,'Income Statement'!A29,Summary!N:N) -> -267202.4
A30: ii | B30: Net realized gain (loss) on debt | C30: 0 | D30: =G30-C30 -> 0 | G30: =-SUMIF(Summary!P:P,'Income Statement'!A30,Summary!N:N) -> 0
B31: Net change in Realized Gain (Loss) | C31: 59014935 | D31: =SUM(D28:D30) -> 1232062 | E31: =SUM(E28:E30) -> 0 | F31: =SUM(F28:F30) -> 0 | G31: =SUM(G28:G30) -> 60246997
B32: Net change in unrealized appreciation (depreciation) on:
A33: j | B33: Investments | C33: -57051550 | D33: =G33-C33 -> 3186079.1 | G33: =-SUMIF(Summary!P:P,'Income Statement'!A33,Summary!N:N) -> -53865471
A34: k | B34: Debt Appreciation | C34: 12884.28 | D34: =G34-C34 -> -1004240.4 | G34: =-SUMIF(Summary!P:P,'Income Statement'!A34,Summary!N:N) -> -991356.11
B35: Net change in unrealized appreciation | C35: -57038666 | D35: =SUM(D33:D34) -> 2181838.7 | E35: =SUM(E33:E34) -> 0 | F35: =SUM(F33:F34) -> 0 | G35: =SUM(G33:G34) -> -54856827
A36: jj | B36: Provision for taxes on unrealized appreciation (depreciation) on investments | C36: 0 | D36: =G36-C36 -> 0 | G36: =-SUMIF(Summary!P:P,'Income Statement'!A36,Summary!N:N) -> 0
A37: kk | B37: Provision for taxes on realized gain on investments | C37: -12855 | D37: =G37-C37 -> 0 | G37: =-SUMIF(Summary!P:P,'Income Statement'!A37,Summary!N:N) -> -12855
B39: Net Realized and unrealized gain (loss) on investments and debt: | C39: 1963414.1 | D39: =D31+D35+SUM(D36:D37) -> 3413900.7 | G39: =G31+G35+G36+G37 -> 5377314.9
B41: Net increase in net assets resulting from operations | C41: 8955930 | D41: =D25+D39 -> 7247891.3 | G41: =+G25+G39 -> 16203821 | I41: =SUMIF('BDC post TB'!C:C,"=Revenue",'BDC post TB'!J:J)+SUMIF('BDC post TB'!C:C,"=Expense",'BDC post TB'!J:J)+G41-G46 -> 0 | J41: income check
B42: Net increase in net assets resulting from operations per share | C42: 0.13715874 | D42: =D41/'Balance Sheet'!D48 -> 0.11100038 | G42: =+G41/'Balance Sheet'!D48 -> 0.24815912 | J42: must be 0
B44: Net investment income per common share | C44: 0.10708934 | D44: =D25/'Balance Sheet'!D48 -> 0.058716998 | G44: =+G25/'Balance Sheet'!D48 -> 0.16580634
A46: p | B46: Distributions | C46: 15671063 | D46: =G46-C46 -> 5223687.5 | G46: =+'Balance Sheet'!D51 -> 20894750
B49: This report (“Report”) is being provided to the Fund(s) identified above as (i) an accommodation to and (ii) solely for informational purposes at the direction of and is solely for the benefit of the Fund(s) and is subject to the terms, conditions and limitations set forth in the Administration Agreement between the Fund(s) and The Bank of New York Mellon (or its affiliates) (collectively, “BNYM”). Notwithstanding anything in this Report to the contrary, no other person, including but not limited to investors in the Fund(s), shall have any rights, interest or claims hereunder or be entitled to any benefits under or on account of the Administration Agreement as a third-party beneficiary or otherwise. The recipient acknowledges that the Report is confidential and may not be disclosed to any third party without the prior written consent of BNYM.
B50: While this Report was prepared using sources and data believed to be reliable, the information contained herein is preliminary, unaudited, subject to change or later reversal and is provided “AS IS.” Any and all data and information included in this Report (“Data”) was collected solely at the direction of the Fund(s) and in the format directed by the Fund(s); BNY Mellon has exercised no discretion or judgment as to how such Data was collected or organized. BNYM makes no representations or warranties of any kind with respect to the Report or the information or Data contained herein, express or implied, in fact or in law, including but not limited to warranties as to accuracy, completeness, timeliness, suitability, merchantability, use or fitness for a particular purpose, and BNYM undertakes no duty to update any information contained in the Report. UNDER NO CIRCUMSTANCES SHALL THE REPORT BE CONSIDERED ADVICE OR A RECOMMENDATION WITH RESPECT TO THE FUND(S), SOLICITATION OR OFFER TO SELL AND/OR PURCHASE ANY SECURITY OR OTHERWISE BE RELIED UPON AS A BASIS FOR ANY ANALYSIS OR INVESTMENT DECISIONS MADE WITH RESPECT TO THE FUND(S). IF ANY OFFER OF INTERESTS IS MADE WITH RESPECT AN INVESTMENT IN THE FUND(S), IT SHALL BE PURSUANT TO A DEFINITIVE OFFERING MEMORANDUM PREPARED BY OR ON BEHALF OF THE FUND WHICH WOULD CONTAIN MATERIAL INFORMATION NOT CONTAINED HEREIN AND WHICH WOULD SUPERSEDE THIS INFORMATION IN ITS ENTIRETY. Past Performance is not indicative of future results. Neither BNYM nor its affiliates or their respective directors, officers or employees shall be responsible or liable for results from any use of the Report, any information or analysis contained therein, or any losses (whether direct, indirect, in contract, tort or otherwise) arising from any decision made or action taken by any party in reliance upon the Report.

Sheet Summary
I1: Legend
I2: A | J2: Eliminates Intercompany Investment in Subsidiary Accounts & Balance Sheet Accounts.
I3: B | J3: Eliminates Intercompany Equity Accounts.
I4: C | J4: Eliminates Intercompany Income Accounts.
J6: Elimination Entries | N6: Consolidated Post-Elimination
B7: Section | C7: Group | D7: Financial Account | E7: Description | F7: BDC | G7: SBIC I | H7: SBIC II | I7: Total | J7: A | K7: B | L7: C | M7: Topside | N7: Closing Balance | O7: Balance Sheet | P7: Income Statement | Q7: Contra Liabilities
A8: =CONCATENATE(D8,E8) -> Debt InstrumentsAccrued Interest | B8: Assets | C8: Investments | D8: Debt Instruments | E8: Accrued Interest | F8: =SUMIF('BDC post TB'!B:B,Summary!A8,'BDC post TB'!J:J) -> 4549181.8 | G8: =SUMIF('SBIC post TB(Closed)'!B:B,Summary!A8,'SBIC post TB(Closed)'!J:J) -> 0 | H8: =SUMIF('SBICII post TB (closed)'!B:B,Summary!A8,'SBICII post TB (closed)'!J:J) -> 0 | I8: =SUM(F8:H8) -> 4549181.8 | N8: =SUM(I8:M8) -> 4549181.8 | O8: c | Q8: =IF(AND(B8="Liabilities",N8>0),N8,0) -> 0
A9: =CONCATENATE(D9,E9) -> Debt InstrumentsAmortization / Accretion | B9: Assets | C9: Investments | D9: Debt Instruments | E9: Amortization / Accretion | F9: =SUMIF('BDC post TB'!B:B,Summary!A9,'BDC post TB'!J:J) -> 1909351 | G9: =SUMIF('SBIC post TB(Closed)'!B:B,Summary!A9,'SBIC post TB(Closed)'!J:J) -> 0 | H9: =SUMIF('SBICII post TB (closed)'!B:B,Summary!A9,'SBICII post TB (closed)'!J:J) -> 0 | I9: =SUM(F9:H9) -> 1909351 | N9: =SUM(I9:M9) -> 1909351 | O9: a | Q9: =IF(AND(B9="Liabilities",N9>0),N9,0) -> 0
A10: =CONCATENATE(D10,E10) -> Debt InstrumentsCost | B10: Assets | C10: Investments | D10: Debt Instruments | E10: Cost | F10: =SUMIF('BDC post TB'!B:B,Summary!A10,'BDC post TB'!J:J) -> 5.3931032e+08 | G10: =SUMIF('SBIC post TB(Closed)'!B:B,Summary!A10,'SBIC post TB(Closed)'!J:J) -> 0 | H10: =SUMIF('SBICII post TB (closed)'!B:B,Summary!A10,'SBICII post TB (closed)'!J:J) -> 0 | I10: =SUM(F10:H10) -> 5.3931032e+08 | N10: =SUM(I10:M10) -> 5.3931032e+08 | O10: a | Q10: =IF(AND(B10="Liabilities",N10>0),N10,0) -> 0
A11: =CONCATENATE(D11,E11) -> Debt InstrumentsUnrealized FX GL | B11: Assets | C11: Investments | D11: Debt Instruments | E11: Unrealized FX GL | F11: =SUMIF('BDC post TB'!B:B,Summary!A11,'BDC post TB'!J:J) -> 184929.38 | G11: =SUMIF('SBIC post TB(Closed)'!B:B,Summary!A11,'SBIC post TB(Closed)'!J:J) -> 0 | H11: =SUMIF('SBICII post TB (closed)'!B:B,Summary!A11,'SBICII post TB (closed)'!J:J) -> 0 | I11: =SUM(F11:H11) -> 184929.38 | N11: =SUM(I11:M11) -> 184929.38 | O11: a | Q11: =IF(AND(B11="Liabilities",N11>0),N11,0) -> 0
A12: =CONCATENATE(D12,E12) -> Debt InstrumentsUnrealized Price G/L | B12: Assets | C12: Investments | D12: Debt Instruments | E12: Unrealized Price G/L | F12: =SUMIF('BDC post TB'!B:B,Summary!A12,'BDC post TB'!J:J) -> -20463819 | G12: =SUMIF('SBIC post TB(Closed)'!B:B,Summary!A12,'SBIC post TB(Closed)'!J:J) -> 0 | H12: =SUMIF('SBICII post TB (closed)'!B:B,Summary!A12,'SBICII post TB (closed)'!J:J) -> 0 | I12: =SUM(F12:H12) -> -20463819 | N12: =SUM(I12:M12) -> -20463819 | O12: a | Q12: =IF(AND(B12="Liabilities",N12>0),N12,0) -> 0
A13: =CONCATENATE(D13,E13) -> Equity InstrumentsAccrued Interest | B13: Assets | C13: Investments | D13: Equity Instruments | E13: Accrued Interest | F13: =SUMIF('BDC post TB'!B:B,Summary!A13,'BDC post TB'!J:J) -> 0 | G13: =SUMIF('SBIC post TB(Closed)'!B:B,Summary!A13,'SBIC post TB(Closed)'!J:J) -> 0 | H13: =SUMIF('SBICII post TB (closed)'!B:B,Summary!A13,'SBICII post TB (closed)'!J:J) -> 0 | I13: =SUM(F13:H13) -> 0 | N13: =SUM(I13:M13) -> 0 | O13: j | Q13: =IF(AND(B13="Liabilities",N13>0),N13,0) -> 0
A14: =CONCATENATE(D14,E14) -> Equity InstrumentsCost | B14: Assets | C14: Investments | D14: Equity Instruments | E14: Cost | F14: =SUMIF('BDC post TB'!B:B,Summary!A14,'BDC post TB'!J:J) -> 1.9228867e+08 | G14: =SUMIF('SBIC post TB(Closed)'!B:B,Summary!A14,'SBIC post TB(Closed)'!J:J) -> 0 | H14: =SUMIF('SBICII post TB (closed)'!B:B,Summary!A14,'SBICII post TB (closed)'!J:J) -> 0 | I14: =SUM(F14:H14) -> 1.9228867e+08 | N14: =SUM(I14:M14) -> 1.9228867e+08 | O14: a | Q14: =IF(AND(B14="Liabilities",N14>0),N14,0) -> 0
A15: =CONCATENATE(D15,E15) -> Equity InstrumentsUnrealized Price G/L | B15: Assets | C15: Investments | D15: Equity Instruments | E15: Unrealized Price G/L | F15: =SUMIF('BDC post TB'!B:B,Summary!A15,'BDC post TB'!J:J) -> 38819784 | G15: =SUMIF('SBIC post TB(Closed)'!B:B,Summary!A15,'SBIC post TB(Closed)'!J:J) -> 0 | H15: =SUMIF('SBICII post TB (closed)'!B:B,Summary!A15,'SBICII post TB (closed)'!J:J) -> 0 | I15: =SUM(F15:H15) -> 38819784 | N15: =SUM(I15:M15) -> 38819784 | O15: a | Q15: =IF(AND(B15="Liabilities",N15>0),N15,0) -> 0
A16: =CONCATENATE(D16,E16) -> Equity InstrumentsUnrealized FX GL | B16: Assets | C16: Investments | D16: Equity Instruments | E16: Unrealized FX GL | F16: =SUMIF('BDC post TB'!B:B,Summary!A16,'BDC post TB'!J:J) -> 217624.93 | G16: =SUMIF('SBIC post TB(Closed)'!B:B,Summary!A16,'SBIC post TB(Closed)'!J:J) -> 0 | H16: =SUMIF('SBICII post TB (closed)'!B:B,Summary!A16,'SBICII post TB (closed)'!J:J) -> 0 | I16: =SUM(F16:H16) -> 217624.93 | N16: =SUM(I16:M16) -> 217624.93 | O16: a | Q16: =IF(AND(B16="Liabilities",N16>0),N16,0) -> 0
A17: =CONCATENATE(D17,E17) -> FinancingAccrued Interest | B17: Assets | C17: Investments | D17: Financing | E17: Accrued Interest | F17: =SUMIF('BDC post TB'!B:B,Summary!A17,'BDC post TB'!J:J) -> -274954.52 | G17: =SUMIF('SBIC post TB(Closed)'!B:B,Summary!A17,'SBIC post TB(Closed)'!J:J) -> 0 | H17: =SUMIF('SBICII post TB (closed)'!B:B,Summary!A17,'SBICII post TB (closed)'!J:J) -> 0 | I17: =SUM(F17:H17) -> -274954.52 | N17: =SUM(I17:M17) -> -274954.52 | O17: j
A18: =CONCATENATE(D18,E18) -> FinancingCost | B18: Assets | C18: Investments | D18: Financing | E18: Cost | F18: =SUMIF('BDC post TB'!B:B,Summary!A18,'BDC post TB'!J:J) -> -51456264 | G18: =SUMIF('SBIC post TB(Closed)'!B:B,Summary!A18,'SBIC post TB(Closed)'!J:J) -> 0 | H18: =SUMIF('SBICII post TB (closed)'!B:B,Summary!A18,'SBICII post TB (closed)'!J:J) -> 0 | I18: =SUM(F18:H18) -> -51456264 | N18: =SUM(I18:M18) -> -51456264 | O18: h
A19: =CONCATENATE(D19,E19) -> FinancingUnrealized FX GL | B19: Assets | C19: Investments | D19: Financing | E19: Unrealized FX GL | F19: =SUMIF('BDC post TB'!B:B,Summary!A19,'BDC post TB'!J:J) -> -12454.14 | G19: =SUMIF('SBIC post TB(Closed)'!B:B,Summary!A19,'SBIC post TB(Closed)'!J:J) -> 0 | H19: =SUMIF('SBICII post TB (closed)'!B:B,Summary!A19,'SBICII post TB (closed)'!J:J) -> 0 | I19: =SUM(F19:H19) -> -12454.14 | N19: =SUM(I19:M19) -> -12454.14 | O19: h
A20: FinancingUnrealized Price G/L | B20: Assets | C20: Investments | D20: Financing | E20: Unrealized Price G/L | F20: =SUMIF('BDC post TB'!B:B,Summary!A20,'BDC post TB'!J:J) -> 0 | G20: =SUMIF('SBIC post TB(Closed)'!B:B,Summary!A20,'SBIC post TB(Closed)'!J:J) -> 0 | H20: =SUMIF('SBICII post TB (closed)'!B:B,Summary!A20,'SBICII post TB (closed)'!J:J) -> 0 | I20: =SUM(F20:H20) -> 0 | N20: =SUM(I20:M20) -> 0 | O20: h
A21: =CONCATENATE(D21,E21) -> MoneyMarketAccrued Interest | B21: Assets | C21: Investments | D21: MoneyMarket | E21: Accrued Interest | F21: =SUMIF('BDC post TB'!B:B,Summary!A21,'BDC post TB'!J:J) -> 0 | G21: =SUMIF('SBIC post TB(Closed)'!B:B,Summary!A21,'SBIC post TB(Closed)'!J:J) -> 0 | H21: =SUMIF('SBICII post TB (closed)'!B:B,Summary!A21,'SBICII post TB (closed)'!J:J) -> 0 | I21: =SUM(F21:H21) -> 0 | N21: =SUM(I21:M21) -> 0 | O21: a | Q21: =IF(AND(B21="Liabilities",N21>0),N21,0) -> 0
A22: =CONCATENATE(D22,E22) -> FundAccrued Interest | B22: Assets | C22: Investments | D22: Fund | E22: Accrued Interest | F22: =SUMIF('BDC post TB'!B:B,Summary!A22,'BDC post TB'!J:J) -> 4291063.6 | G22: =SUMIF('SBIC post TB(Closed)'!B:B,Summary!A22,'SBIC post TB(Closed)'!J:J) -> 0 | H22: =SUMIF('SBICII post TB (closed)'!B:B,Summary!A22,'SBICII post TB (closed)'!J:J) -> 0 | I22: =SUM(F22:H22) -> 4291063.6 | N22: =SUM(I22:M22) -> 4291063.6 | O22: c | Q22: =IF(AND(B22="Liabilities",N22>0),N22,0) -> 0
A23: =CONCATENATE(D23,E23) -> FundCost | B23: Assets | C23: Investments | D23: Fund | E23: Cost | F23: =SUMIF('BDC post TB'!B:B,Summary!A23,'BDC post TB'!J:J) -> 2.3076108e+08 | G23: =SUMIF('SBIC post TB(Closed)'!B:B,Summary!A23,'SBIC post TB(Closed)'!J:J) -> 0 | H23: =SUMIF('SBICII post TB (closed)'!B:B,Summary!A23,'SBICII post TB (closed)'!J:J) -> 0 | I23: =SUM(F23:H23) -> 2.3076108e+08 | N23: =SUM(I23:M23) -> 2.3076108e+08 | O23: a | Q23: =IF(AND(B23="Liabilities",N23>0),N23,0) -> 0
A24: =CONCATENATE(D24,E24) -> FundUnrealized Price G/L | B24: Assets | C24: Investments | D24: Fund | E24: Unrealized Price G/L | F24: =SUMIF('BDC post TB'!B:B,Summary!A24,'BDC post TB'!J:J) -> -22470518 | G24: =SUMIF('SBIC post TB(Closed)'!B:B,Summary!A24,'SBIC post TB(Closed)'!J:J) -> 0 | H24: =SUMIF('SBICII post TB (closed)'!B:B,Summary!A24,'SBICII post TB (closed)'!J:J) -> 0 | I24: =SUM(F24:H24) -> -22470518 | N24: =SUM(I24:M24) -> -22470518 | O24: a | Q24: =IF(AND(B24="Liabilities",N24>0),N24,0) -> 0
A25: =CONCATENATE(D25,E25) -> MoneyMarketCost | B25: Assets | C25: Investments | D25: MoneyMarket | E25: Cost | F25: =SUMIF('BDC post TB'!B:B,Summary!A25,'BDC post TB'!J:J) -> 30530529 | G25: =SUMIF('SBIC post TB(Closed)'!B:B,Summary!A25,'SBIC post TB(Closed)'!J:J) -> 0 | H25: =SUMIF('SBICII post TB (closed)'!B:B,Summary!A25,'SBICII post TB (closed)'!J:J) -> 0 | I25: =SUM(F25:H25) -> 30530529 | N25: =SUM(I25:M25) -> 30530529 | O25: b2 | Q25: =IF(AND(B25="Liabilities",N25>0),N25,0) -> 0
A26: =CONCATENATE(D26,E26) -> OtherAccrued Interest | B26: Assets | C26: Investments | D26: Other | E26: Accrued Interest | F26: =SUMIF('BDC post TB'!B:B,Summary!A26,'BDC post TB'!J:J) -> -3352083.3 | G26: =SUMIF('SBIC post TB(Closed)'!B:B,Summary!A26,'SBIC post TB(Closed)'!J:J) -> 0 | H26: =SUMIF('SBICII post TB (closed)'!B:B,Summary!A26,'SBICII post TB (closed)'!J:J) -> 0 | I26: =SUM(F26:H26) -> -3352083.3 | N26: =SUM(I26:M26) -> -3352083.3 | O26: j
A27: =CONCATENATE(D27,E27) -> OtherAmortization / Accretion | B27: Assets | C27: Investments | D27: Other | E27: Amortization / Accretion | F27: =SUMIF('BDC post TB'!B:B,Summary!A27,'BDC post TB'!J:J) -> 0 | G27: =SUMIF('SBIC post TB(Closed)'!B:B,Summary!A27,'SBIC post TB(Closed)'!J:J) -> 0 | H27: =SUMIF('SBICII post TB (closed)'!B:B,Summary!A27,'SBICII post TB (closed)'!J:J) -> 0 | I27: =SUM(F27:H27) -> 0 | N27: =SUM(I27:M27) -> 0
A28: =CONCATENATE(D28,E28) -> OtherCost | B28: Assets | C28: Investments | D28: Other | E28: Cost | F28: =SUMIF('BDC post TB'!B:B,Summary!A28,'BDC post TB'!J:J) -> -390000000 | G28: =SUMIF('SBIC post TB(Closed)'!B:B,Summary!A28,'SBIC post TB(Closed)'!J:J) -> 0 | H28: =SUMIF('SBICII post TB (closed)'!B:B,Summary!A28,'SBICII post TB (closed)'!J:J) -> 0 | I28: =SUM(F28:H28) -> -390000000 | N28: =SUM(I28:M28) -> -390000000
A29: =CONCATENATE(D29,E29) -> OtherUnrealized Price G/L | B29: Assets | C29: Investments | D29: Other | E29: Unrealized Price G/L | F29: =SUMIF('BDC post TB'!B:B,Summary!A29,'BDC post TB'!J:J) -> 0 | G29: =SUMIF('SBIC post TB(Closed)'!B:B,Summary!A29,'SBIC post TB(Closed)'!J:J) -> 0 | H29: =SUMIF('SBICII post TB (closed)'!B:B,Summary!A29,'SBICII post TB (closed)'!J:J) -> 0 | I29: =SUM(F29:H29) -> 0 | N29: =SUM(I29:M29) -> 0
A30: =CONCATENATE(D30,E30) -> CashCost | B30: Assets | C30: Investments | D30: Cash | E30: Cost | F30: =SUMIF('BDC post TB'!B:B,Summary!A30,'BDC post TB'!J:J) -> 17446868 | G30: =SUMIF('SBIC post TB(Closed)'!B:B,Summary!A30,'SBIC post TB(Closed)'!J:J) -> 0 | H30: =SUMIF('SBICII post TB (closed)'!B:B,Summary!A30,'SBICII post TB (closed)'!J:J) -> 0 | I30: =SUM(F30:H30) -> 17446868 | J30: =-'BDC post TB'!J31 -> -465074.15 | N30: =SUM(I30:M30) -> 16981793 | O30: b1 | Q30: =IF(AND(B30="Liabilities",N30>0),N30,0) -> 0
A31: =CONCATENATE(D31,E31) -> CashUnrealized FX GL | B31: Assets | C31: Investments | D31: Cash | E31: Unrealized FX GL | F31: =SUMIF('BDC post TB'!B:B,Summary!A31,'BDC post TB'!J:J) -> 276235.04 | G31: =SUMIF('SBIC post TB(Closed)'!B:B,Summary!A31,'SBIC post TB(Closed)'!J:J) -> 0 | H31: =SUMIF('SBICII post TB (closed)'!B:B,Summary!A31,'SBICII post TB (closed)'!J:J) -> 0 | I31: =SUM(F31:H31) -> 276235.04 | N31: =SUM(I31:M31) -> 276235.04 | O31: b1 | Q31: =IF(AND(B31="Liabilities",N31>0),N31,0) -> 0
A32: =CONCATENATE(D32,E32) -> DistributionsReceivable Cost | B32: Assets | C32: Receivables | D32: DistributionsReceivable | E32: Cost | F32: =SUMIF('BDC post TB'!B:B,Summary!A32,'BDC post TB'!J:J) -> 0 | G32: =SUMIF('SBIC post TB(Closed)'!B:B,Summary!A32,'SBIC post TB(Closed)'!J:J) -> 0 | H32: =SUMIF('SBICII post TB (closed)'!B:B,Summary!A32,'SBICII post TB (closed)'!J:J) -> 0 | I32: =SUM(F32:H32) -> 0 | N32: =SUM(I32:M32) -> 0 | O32: d2 | Q32: =IF(AND(B32="Liabilities",N32>0),N32,0) -> 0
A33: =CONCATENATE(D33,E33) -> Dividend Receivable Cost | B33: Assets | C33: Receivables | D33: Dividend Receivable | E33: Cost | F33: =SUMIF('BDC post TB'!B:B,Summary!A33,'BDC post TB'!J:J) -> 230769 | G33: =SUMIF('SBIC post TB(Closed)'!B:B,Summary!A33,'SBIC post TB(Closed)'!J:J) -> 0 | H33: =SUMIF('SBICII post TB (closed)'!B:B,Summary!A33,'SBICII post TB (closed)'!J:J) -> 0 | I33: =SUM(F33:H33) -> 230769 | N33: =SUM(I33:M33) -> 230769 | O33: d2
A34: =CONCATENATE(D34,E34) -> Due From PennantPark Admin Cost | B34: Assets | C34: Receivables | D34: Due From PennantPark Admin | E34: Cost | F34: =SUMIF('BDC post TB'!B:B,Summary!A34,'BDC post TB'!J:J) -> 81285.15 | G34: =SUMIF('SBIC post TB(Closed)'!B:B,Summary!A34,'SBIC post TB(Closed)'!J:J) -> 0 | H34: =SUMIF('SBICII post TB (closed)'!B:B,Summary!A34,'SBICII post TB (closed)'!J:J) -> 0 | I34: =SUM(F34:H34) -> 81285.15 | N34: =SUM(I34:M34) -> 81285.15 | O34: dd
A35: =CONCATENATE(D35,E35) -> Receivable Cost | B35: Assets | C35: Receivables | D35: Receivable | E35: Cost | F35: =SUMIF('BDC post TB'!B:B,Summary!A35,'BDC post TB'!J:J) -> 73832136 | G35: =SUMIF('SBIC post TB(Closed)'!B:B,Summary!A35,'SBIC post TB(Closed)'!J:J) -> 0 | H35: =SUMIF('SBICII post TB (closed)'!B:B,Summary!A35,'SBICII post TB (closed)'!J:J) -> 0 | I35: =SUM(F35:H35) -> 73832136 | N35: =SUM(I35:M35) -> 73832136 | O35: d1 | Q35: =IF(AND(B35="Liabilities",N35>0),N35,0) -> 0
A36: =CONCATENATE(D36,E36) -> ReceivablesCost | B36: Assets | C36: Receivables | D36: Receivables | E36: Cost | F36: =SUMIF('BDC post TB'!B:B,Summary!A36,'BDC post TB'!J:J) -> 0 | G36: =SUMIF('SBIC post TB(Closed)'!B:B,Summary!A36,'SBIC post TB(Closed)'!J:J) -> 0 | H36: =SUMIF('SBICII post TB (closed)'!B:B,Summary!A36,'SBICII post TB (closed)'!J:J) -> 0 | I36: =SUM(F36:H36) -> 0 | N36: =SUM(I36:M36) -> 0 | O36: d1 | Q36: =IF(AND(B36="Liabilities",N36>0),N36,0) -> 0
A37: =CONCATENATE(D37,E37) -> CouponInterestReceivable Cost | B37: Assets | C37: Receivables | D37: CouponInterestReceivable | E37: Cost | F37: =SUMIF('BDC post TB'!B:B,Summary!A37,'BDC post TB'!J:J) -> 0 | G37: =SUMIF('SBIC post TB(Closed)'!B:B,Summary!A37,'SBIC post TB(Closed)'!J:J) -> 0 | H37: =SUMIF('SBICII post TB (closed)'!B:B,Summary!A37,'SBICII post TB (closed)'!J:J) -> 0 | I37: =SUM(F37:H37) -> 0 | N37: =SUM(I37:M37) -> 0 | O37: c
A38: =CONCATENATE(D38,E38) -> Interest Receivable Cost | B38: Assets | C38: Receivables | D38: Interest Receivable | E38: Cost | F38: =SUMIF('BDC post TB'!B:B,Summary!A38,'BDC post TB'!J:J) -> 78891.41 | G38: =SUMIF('SBIC post TB(Closed)'!B:B,Summary!A38,'SBIC post TB(Closed)'!J:J) -> 0 | H38: =SUMIF('SBICII post TB (closed)'!B:B,Summary!A38,'SBICII post TB (closed)'!J:J) -> 0 | I38: =SUM(F38:H38) -> 78891.41 | J38: =-J30 -> 465074.15 | N38: =SUM(I38:M38) -> 543965.56 | O38: c | Q38: =IF(AND(B38="Liabilities",N38>0),N38,0) -> 0
A39: =CONCATENATE(D39,E39) -> Interest Receivable Sweep Cost | B39: Assets | C39: Receivables | D39: Interest Receivable Sweep | E39: Cost | F39: =SUMIF('BDC post TB'!B:B,Summary!A39,'BDC post TB'!J:J) -> 0 | G39: =SUMIF('SBIC post TB(Closed)'!B:B,Summary!A39,'SBIC post TB(Closed)'!J:J) -> 0 | H39: =SUMIF('SBICII post TB (closed)'!B:B,Summary!A39,'SBICII post TB (closed)'!J:J) -> 0 | I39: =SUM(F39:H39) -> 0 | N39: =SUM(I39:M39) -> 0 | O39: c | Q39: =IF(AND(B39="Liabilities",N39>0),N39,0) -> 0
A40: =CONCATENATE(D40,E40) -> PIK Interest Receivable Cost | B40: Assets | C40: Receivables | D40: PIK Interest Receivable | E40: Cost | F40: =SUMIF('BDC post TB'!B:B,Summary!A40,'BDC post TB'!J:J) -> 0 | G40: =SUMIF('SBIC post TB(Closed)'!B:B,Summary!A40,'SBIC post TB(Closed)'!J:J) -> 0 | H40: =SUMIF('SBICII post TB (closed)'!B:B,Summary!A40,'SBICII post TB (closed)'!J:J) -> 0 | I40: =SUM(F40:H40) -> 0 | N40: =SUM(I40:M40) -> 0 | O40: c | Q40: =IF(AND(B40="Liabilities",N40>0),N40,0) -> 0
A41: =CONCATENATE(D41,E41) -> Prepaid Admin Fee Cost | B41: Assets | C41: Receivables | D41: Prepaid Admin Fee | E41: Cost | F41: =SUMIF('BDC post TB'!B:B,Summary!A41,'BDC post TB'!J:J) -> 0 | G41: =SUMIF('SBIC post TB(Closed)'!B:B,Summary!A41,'SBIC post TB(Closed)'!J:J) -> 0 | H41: =SUMIF('SBICII post TB (closed)'!B:B,Summary!A41,'SBICII post TB (closed)'!J:J) -> 0 | I41: =SUM(F41:H41) -> 0 | N41: =SUM(I41:M41) -> 0 | O41: d | Q41: =IF(AND(B41="Liabilities",N41>0),N41,0) -> 0
...

Sheet BDC post TB
C1: Header | D1: Detail
C2: BNY
C3: Custom Trial Balance #304
B4: =IF(C4="PennantPark Investment Corp"," ","Not BDC") | C4: PennantPark Investment Corp
C5: Period Start Date | D5: 01/30/2026:00:00:00
C6: Period End Date | D6: 01/31/2026:23:59:59
C7: Prior Knowledge Date | D7: 01/30/2026:15:18:07
C8: Knowledge Date | D8: 02/09/2026:20:49:59
C9: U.S. Dollars
B10: =CONCATENATE(E10,F10)
A11: =VLOOKUP(B11,Summary!A:A,1,FALSE) -> #N/A | B11: =CONCATENATE(E11,F11) -> FinancialAccountDescription | C11: Section | D11: Group | E11: FinancialAccount | F11: Description | G11: OpeningBalance | H11: Debits | I11: Credits | J11: ClosingBalance
A12: =VLOOKUP(B12,Summary!A:A,1,FALSE) -> Debt InstrumentsAccrued Interest | B12: =CONCATENATE(E12,F12) -> Debt InstrumentsAccrued Interest | C12: Assets | D12: Investments | E12: Debt Instruments | F12: Accrued Interest | G12: 6190456.3 | H12: 0 | I12: -1641274.5 | J12: 4549181.8
A13: =VLOOKUP(B13,Summary!A:A,1,FALSE) -> Debt InstrumentsAmortization / Accretion | B13: =CONCATENATE(E13,F13) -> Debt InstrumentsAmortization / Accretion | C13: Assets | D13: Investments | E13: Debt Instruments | F13: Amortization / Accretion | G13: 2069483.7 | H13: 0 | I13: -160132.7 | J13: 1909351
A14: =VLOOKUP(B14,Summary!A:A,1,FALSE) -> Debt InstrumentsCost | B14: =CONCATENATE(E14,F14) -> Debt InstrumentsCost | C14: Assets | D14: Investments | E14: Debt Instruments | F14: Cost | G14: 6.1416209e+08 | H14: 0 | I14: -74851765 | J14: 5.3931032e+08
A15: =VLOOKUP(B15,Summary!A:A,1,FALSE) -> Debt InstrumentsUnrealized FX GL | B15: =CONCATENATE(E15,F15) -> Debt InstrumentsUnrealized FX GL | C15: Assets | D15: Investments | E15: Debt Instruments | F15: Unrealized FX GL | G15: 336267.1 | H15: 0 | I15: -151337.72 | J15: 184929.38
A16: =VLOOKUP(B16,Summary!A:A,1,FALSE) -> Debt InstrumentsUnrealized Price G/L | B16: =CONCATENATE(E16,F16) -> Debt InstrumentsUnrealized Price G/L | C16: Assets | D16: Investments | E16: Debt Instruments | F16: Unrealized Price G/L | G16: -20045950 | H16: 0 | I16: -417869.35 | J16: -20463819
A17: =VLOOKUP(B17,Summary!A:A,1,FALSE) -> Equity InstrumentsCost | B17: =CONCATENATE(E17,F17) -> Equity InstrumentsCost | C17: Assets | D17: Investments | E17: Equity Instruments | F17: Cost | G17: 1.9228867e+08 | H17: 0 | I17: 0 | J17: 1.9228867e+08
A18: =VLOOKUP(B18,Summary!A:A,1,FALSE) -> Equity InstrumentsUnrealized FX GL | B18: =CONCATENATE(E18,F18) -> Equity InstrumentsUnrealized FX GL | C18: Assets | D18: Investments | E18: Equity Instruments | F18: Unrealized FX GL | G18: 233440.48 | H18: 0 | I18: -15815.55 | J18: 217624.93
A19: =VLOOKUP(B19,Summary!A:A,1,FALSE) -> Equity InstrumentsUnrealized Price G/L | B19: =CONCATENATE(E19,F19) -> Equity InstrumentsUnrealized Price G/L | C19: Assets | D19: Investments | E19: Equity Instruments | F19: Unrealized Price G/L | G19: 38967360 | H19: 0 | I19: -147576.47 | J19: 38819784
A20: =VLOOKUP(B20,Summary!A:A,1,FALSE) -> FinancingAccrued Interest | B20: =CONCATENATE(E20,F20) -> FinancingAccrued Interest | C20: Assets | D20: Investments | E20: Financing | F20: Accrued Interest | G20: -265890.98 | H20: 0 | I20: -9063.54 | J20: -274954.52
A21: =VLOOKUP(B21,Summary!A:A,1,FALSE) -> FinancingCost | B21: =CONCATENATE(E21,F21) -> FinancingCost | C21: Assets | D21: Investments | E21: Financing | F21: Cost | G21: -51456264 | H21: 0 | I21: 0 | J21: -51456264
A22: =VLOOKUP(B22,Summary!A:A,1,FALSE) -> FinancingUnrealized FX GL | B22: =CONCATENATE(E22,F22) -> FinancingUnrealized FX GL | C22: Assets | D22: Investments | E22: Financing | F22: Unrealized FX GL | G22: -161518.62 | H22: 149064.48 | I22: 0 | J22: -12454.14
A23: =VLOOKUP(B23,Summary!A:A,1,FALSE) -> FundAccrued Interest | B23: =CONCATENATE(E23,F23) -> FundAccrued Interest | C23: Assets | D23: Investments | E23: Fund | F23: Accrued Interest | G23: 4198782.7 | H23: 92280.92 | I23: 0 | J23: 4291063.6
... A75: =VLOOKUP(B75,Summary!A:A,1,FALSE) -> Line of Credit - Liability Cost | B75: =CONCATENATE(E75,F75) -> Line of Credit - Liability Cost | C75: Liabilities | D75: Payables | E75: Line of Credit - Liability | F75: Cost | G75: -245000000 | H75: 75000000 | I75: 0 | J75: -170000000
A76: =VLOOKUP(B76,Summary!A:A,1,FALSE) -> Accumulated net realized gain loss on investments prior years | B76: =CONCATENATE(E76,F76) -> Accumulated net realized gain loss on investments prior years | C76: Capital | D76: Partners' Capital | E76: Accumulated net realized gain loss on investments prior years | G76: -67497 | H76: 0 | I76: 0 | J76: -67497
A77: =VLOOKUP(B77,Summary!A:A,1,FALSE) -> Accumulated net realized gl on investments prior years | B77: =CONCATENATE(E77,F77) -> Accumulated net realized gl on investments prior years | C77: Capital | D77: Partners' Capital | E77: Accumulated net realized gl on investments prior years | G77: 71543952 | H77: 0 | I77: 0 | J77: 71543952
A78: =VLOOKUP(B78,Summary!A:A,1,FALSE) -> Capital Stock | B78: =CONCATENATE(E78,F78) -> Capital Stock | C78: Capital | D78: Partners' Capital | E78: Capital Stock | G78: -65296.14 | H78: 0 | I78: 0 | J78: -65296.14
A79: =VLOOKUP(B79,Summary!A:A,1,FALSE) -> ContributedCost | B79: =CONCATENATE(E79,F79) -> ContributedCost | C79: Capital | D79: Partners' Capital | E79: ContributedCost | G79: -7.405063e+08 | H79: 0 | I79: 0 | J79: -7.405063e+08
A80: =VLOOKUP(B80,Summary!A:A,1,FALSE) -> Net unrealized app dep on debt prior years | B80: =CONCATENATE(E80,F80) -> Net unrealized app dep on debt prior years | C80: Capital | D80: Partners' Capital | E80: Net unrealized app dep on debt prior years | G80: -1551670 | H80: 0 | I80: 0 | J80: -1551670
A81: =VLOOKUP(B81,Summary!A:A,1,FALSE) -> Net unrealized app dep on investments prior years | B81: =CONCATENATE(E81,F81) -> Net unrealized app dep on investments prior years | C81: Capital | D81: Partners' Capital | E81: Net unrealized app dep on investments prior years | G81: 111763780 | H81: 0 | I81: 0 | J81: 111763780
A82: =VLOOKUP(B82,Summary!A:A,1,FALSE) -> Undistributed net investment income Prior Years | B82: =CONCATENATE(E82,F82) -> Undistributed net investment income Prior Years | C82: Capital | D82: Partners' Capital | E82: Undistributed net investment income Prior Years | G82: -42600718 | H82: 0 | I82: 0 | J82: -42600718
A83: =VLOOKUP(B83,Summary!A:A,1,FALSE) -> Retained Earnings | B83: =CONCATENATE(E83,F83) -> Retained Earnings | C83: Capital | D83: Retained Earnings | E83: Retained Earnings | G83: 1.3753356e+08 | H83: 0 | I83: 0 | J83: 1.3753356e+08
A84: =VLOOKUP(B84,Summary!A:A,1,FALSE) -> Change in Unrealized FX Gain/Loss | B84: =CONCATENATE(E84,F84) -> Change in Unrealized FX Gain/Loss | C84: Revenue | E84: Change in Unrealized FX Gain/Loss | G84: -257922.04 | H84: 0 | I84: -281259.24 | J84: -539181.28
A85: =VLOOKUP(B85,Summary!A:A,1,FALSE) -> Change in Unrealized Price Gain/Loss | B85: =CONCATENATE(E85,F85) -> Change in Unrealized Price Gain/Loss | C85: Revenue | E85: Change in Unrealized Price Gain/Loss | G85: 57296588 | H85: 0 | I85: -1900579.4 | J85: 55396009
A86: =VLOOKUP(B86,Summary!A:A,1,FALSE) -> ChangeInAccruedInterestLong | B86: =CONCATENATE(E86,F86) -> ChangeInAccruedInterestLong | C86: Revenue | E86: ChangeInAccruedInterestLong | G86: 856088.02 | H86: 0 | I86: -4418132.4 | J86: -3562044.4
A87: =VLOOKUP(B87,Summary!A:A,1,FALSE) -> ChangeInTotalDiscountBasisLong | B87: =CONCATENATE(E87,F87) -> ChangeInTotalDiscountBasisLong | C87: Revenue | E87: ChangeInTotalDiscountBasisLong | G87: 305402.27 | H87: 65564.35 | I87: 0 | J87: 370966.62
A88: =VLOOKUP(B88,Summary!A:A,1,FALSE) -> ChangeInUnfundedLiabilityAccruedInterestLong | B88: =CONCATENATE(E88,F88) -> ChangeInUnfundedLiabilityAccruedInterestLong | C88: Revenue | E88: ChangeInUnfundedLiabilityAccruedInterestLong | G88: 4081.63 | H88: 0 | I88: -35408.29 | J88: -31326.66
A89: =VLOOKUP(B89,Summary!A:A,1,FALSE) -> Dividend Distribution Income | B89: =CONCATENATE(E89,F89) -> Dividend Distribution Income | C89: Revenue | E89: Dividend Distribution Income | G89: -3720.89 | H89: 0 | I89: -8383.08 | J89: -12103.97
A90: =VLOOKUP(B90,Summary!A:A,1,FALSE) -> Dividend Income - PSLF Membership | B90: =CONCATENATE(E90,F90) -> Dividend Income - PSLF Membership | C90: Revenue | E90: Dividend Income - PSLF Membership | G90: -4183813 | H90: 0 | I90: 0 | J90: -4183813
A91: =VLOOKUP(B91,Summary!A:A,1,FALSE) -> Dividend Income - PTSF II Membership | B91: =CONCATENATE(E91,F91) -> Dividend Income - PTSF II Membership | C91: Revenue | E91: Dividend Income - PTSF II Membership | G91: -230769 | H91: 0 | I91: 0 | J91: -230769
...

Sheet BDC Long Short
A1: LongOrShort | B1: Currency | C1: InvestmentType | D1: InvestmentID | E1: TaxLotDescription | F1: Quantity | G1: TaxLotID | H1: LotDay | I1: UnitCost | J1: MarketPrice | K1: CostBook | L1: MarketValueBook | M1: PriceGainOrLoss | N1: FXGainOrLoss | O1: ExtendedDescription | P1: Description3 | Q1: AccruedDescription | R1: Accrued | S1: Coupon | T1: MatDate | U1: LXID
A2: Long Positions | B2: Canadian dollar | C2: Cash and Equivalents | D2: CAD | E2: Canadian dollar-NN_7100PP002 OnHand | F2: 362815.67 | I2: 1 | J2: 1 | K2: 261501.02 | L2: 267928.72 | M2: 0 | N2: 6427.7
A3: Long Positions | B3: Canadian dollar | C3: Bank Debt | D3: LX219880.PP | E3: Infinity Home Services Holdco, Inc. - Amendment No. 1 DDTL | F3: 2185389.8 | G3: 297781145 | H3: 45247 | I3: 98.75 | J3: 100 | K3: 1579569.6 | L3: 1613846.1 | M3: 12740.43 | N3: 21536.11 | P3: 11.00% of Global Commitment | Q3: Accrued Interest | R3: 11683.68 | S3: 0 | T3: 47115
A4: Long Positions | B4: Canadian dollar | C4: Bank Debt | D4: LX219880.PP3 | E4: Infinity Home Services Holdco, Inc. - Amendment No. 1 DDTL | F4: 350825.32 | G4: 305090121 | H4: 45436 | I4: 98.75 | J4: 100 | K4: 253858.66 | L4: 259074.19 | M4: 2348.01 | N4: 2867.52 | P4: 11.00% of Global Commitment | Q4: Accrued Interest | R4: 1875.6 | S4: 0 | T4: 47115
A5: Long Positions | B5: Canadian dollar | C5: Bank Debt | D5: LX219880.PP6 | E5: Infinity Home Services Holdco, Inc. - Amendment No. 1 DDTL | F5: 69244.14 | G5: 319126513 | H5: 45567 | I5: 98.75 | J5: 100 | K5: 50900.42 | L5: 51134.76 | M5: 451.55 | N5: -217.21 | P5: 11.00% of Global Commitment | Q5: Accrued Interest | R5: 370.2 | S5: 0 | T5: 47115
A6: Long Positions | B6: Euro | C6: Cash and Equivalents | D6: EUR | E6: Euro-NN_7100PP002 OnHand | F6: 25.11 | I6: 1 | J6: 1 | K6: 29.26 | L6: 29.87 | M6: 0 | N6: 0.61
A7: Long Positions | B7: U.K. pound | C7: Cash and Equivalents | D7: GBP | E7: U.K. pound-NN_7100PP002 OnHand | F7: 6033842.8 | I7: 1 | J7: 1 | K7: 8010134 | L7: 8279940.7 | M7: 0 | N7: 269806.73
A8: Long Positions | B8: U.K. pound | C8: Bank Debt | D8: LX175551.PP | E8: AKW Holdings Limited - Term Loan | F8: 253996.67 | G8: 297363470 | H8: 45107 | I8: 100 | J8: 100 | K8: 323118.1 | L8: 348546.93 | M8: 0 | N8: 25428.83 | P8: 0.70% of Global Commitment | Q8: Accrued Interest | R8: 3377.09 | S8: 0 | T8: 46461
A9: Long Positions | B9: U.K. pound | C9: Bank Debt | D9: LX175551.PP | E9: AKW Holdings Limited - Term Loan | F9: 326355.94 | G9: 297363552 | H9: 45198 | I9: 100 | J9: 100 | K9: 399210.94 | L9: 447841.93 | M9: 0 | N9: 48630.99 | P9: 0.89% of Global Commitment | Q9: Accrued Interest | R9: 4339.18 | S9: 0 | T9: 46461
A10: Long Positions | B10: U.K. pound | C10: Bank Debt | D10: LX175551.PP | E10: AKW Holdings Limited - Term Loan | F10: 442524.52 | G10: 297363644 | H10: 45289 | I10: 100 | J10: 100 | K10: 564420.54 | L10: 607254.27 | M10: 0 | N10: 42833.73 | P10: 1.21% of Global Commitment | Q10: Accrued Interest | R10: 5883.74 | S10: 0 | T10: 46461
A11: Long Positions | B11: U.K. pound | C11: Bank Debt | D11: LX175551.PP | E11: AKW Holdings Limited - Term Loan | F11: 446572.98 | G11: 297747816 | H11: 44021 | I11: 100 | J11: 100 | K11: 563888.71 | L11: 612809.75 | M11: 0 | N11: 48921.04 | P11: 1.22% of Global Commitment | Q11: Accrued Interest | R11: 5937.56 | S11: 0 | T11: 46461
A12: Long Positions | B12: U.K. pound | C12: Bank Debt | D12: LX175551.PP | E12: AKW Holdings Limited - Term Loan | F12: 446572.98 | G12: 297752234 | H12: 44106 | I12: 100 | J12: 100 | K12: 580330.35 | L12: 612809.75 | M12: 0 | N12: 32479.4 | P12: 1.22% of Global Commitment | Q12: Accrued Interest | R12: 5937.56 | S12: 0 | T12: 46461
A13: Long Positions | B13: U.K. pound | C13: Bank Debt | D13: LX175551.PP | E13: AKW Holdings Limited - Term Loan | F13: 446572.98 | G13: 297747818 | H13: 44179 | I13: 100 | J13: 100 | K13: 594020.98 | L13: 612809.77 | M13: 0 | N13: 18788.79 | P13: 1.22% of Global Commitment | Q13: Accrued Interest | R13: 5937.56 | S13: 0 | T13: 46461
A14: Long Positions | B14: U.K. pound | C14: Bank Debt | D14: LX175551.PP | E14: AKW Holdings Limited - Term Loan | F14: 446572.98 | G14: 297747819 | H14: 44266 | I14: 100 | J14: 100 | K14: 622068.48 | L14: 612809.76 | M14: 0 | N14: -9258.72 | P14: 1.22% of Global Commitment | Q14: Accrued Interest | R14: 5937.56 | S14: 0 | T14: 46461
A15: Long Positions | B15: U.K. pound | C15: Bank Debt | D15: LX175551.PP | E15: AKW Holdings Limited - Term Loan | F15: 446572.98 | G15: 297363117 | H15: 44452 | I15: 100 | J15: 100 | K15: 616931.82 | L15: 612809.76 | M15: 0 | N15: -4122.06 | P15: 1.22% of Global Commitment | Q15: Accrued Interest | R15: 5937.56 | S15: 0 | T15: 46461
A16: Long Positions | B16: U.K. pound | C16: Bank Debt | D16: LX175551.PP | E16: AKW Holdings Limited - Term Loan | F16: 446572.98 | G16: 297363145 | H16: 44543 | I16: 100 | J16: 100 | K16: 590281.31 | L16: 612809.75 | M16: 0 | N16: 22528.44 | P16: 1.22% of Global Commitment | Q16: Accrued Interest | R16: 5937.56 | S16: 0 | T16: 46461
A17: Long Positions | B17: U.K. pound | C17: Bank Debt | D17: LX175551.PP | E17: AKW Holdings Limited - Term Loan | F17: 446572.98 | G17: 297363174 | H17: 44629 | I17: 100 | J17: 100 | K17: 587143.42 | L17: 612809.75 | M17: 0 | N17: 25666.33 | P17: 1.22% of Global Commitment | Q17: Accrued Interest | R17: 5937.56 | S17: 0 | T17: 46461
A18: Long Positions | B18: U.K. pound | C18: Bank Debt | D18: LX175551.PP | E18: AKW Holdings Limited - Term Loan | F18: 475154.97 | G18: 297363383 | H18: 45016 | I18: 100 | J18: 100 | K18: 588499.55 | L18: 652031.4 | M18: 0 | N18: 63531.85 | P18: 1.30% of Global Commitment | Q18: Accrued Interest | R18: 6317.59 | S18: 0 | T18: 46461
A19: Long Positions | B19: U.K. pound | C19: Bank Debt | D19: LX175551.PP | E19: AKW Holdings Limited - Term Loan | F19: 4242443.4 | G19: 297363167 | H19: 44586 | I19: 100 | J19: 100 | K19: 5711803 | L19: 5821693 | M19: 0 | N19: 109890.02 | P19: 11.62% of Global Commitment | Q19: Accrued Interest | R19: 56406.87 | S19: 0 | T19: 46461
... A22: Long Positions | B22: U.K. pound | C22: Bank Debt | D22: LX175551.PP | E22: AKW Holdings Limited - Term Loan | F22: 25008088 | G22: 297745759 | H22: 43166 | I22: 100 | J22: 100 | K22: 34782879 | L22: 34317348 | M22: 0 | N22: -465530.83 | P22: 68.52% of Global Commitment | Q22: Accrued Interest | R22: 332503.63 | S22: 0 | T22: 46461
A23: Long Positions | B23: U.K. pound | C23: Common Stock | D23: 1199211 | E23: AKW Holdings Limited | F23: 938.529 | G23: 297363873 | H23: 43166 | I23: 101.2222 | J23: 35437.108 | K23: 132496.5 | L23: 45639324 | M23: 45508960 | N23: -2132.75
A24: Long Positions | B24: U.K. pound | C24: Common Stock | D24: 1199211A | E24: AKW Holdings Limited - Class B Common share | F24: 12.5 | G24: 345894253 | H24: 45859 | I24: 7333.3336 | J24: 38089.15 | K24: 123690.42 | L24: 653347.96 | M24: 527558.37 | N24: 2099.17
A25: Long Positions | B25: U.K. pound | C25: Common Stock | D25: 1199211B | E25: AKW Holdings Limited - Class C Common share | F25: 12.5 | G25: 345894255 | H25: 45859 | I25: 8666.6664 | J25: 45014.45 | K25: 146179.58 | L25: 772138.49 | M25: 623478.08 | N25: 2480.83
A26: Long Positions | B26: U.K. pound | C26: Common Stock | D26: 1199211C | E26: AKW Holdings Limited - Class D Common share | F26: 87.657 | G26: 356140519 | H26: 45967 | I26: 29173.81 | J26: 38712.117 | K26: 3350687.5 | L26: 4656576.8 | M26: 1147337.4 | N26: 158551.9
A27: Long Positions | B27: U.K. pound | C27: Common Stock | D27: 1199211D | E27: AKW Holdings Limited - Class E Common share | F27: 82.384 | G27: 356140525 | H27: 45967 | I27: 11086.12 | J27: 14710.701 | K27: 1196676.1 | L27: 1663066 | M27: 409764.08 | N27: 56625.78
A28: Long Positions | B28: U.S. Dollars | C28: Cash and Equivalents | D28: USD | E28: U.S. Dollars-NN_7100PP002 CouponInterestReceivable | F28: 465074.15 | I28: 1 | J28: 1 | K28: 465074.15 | L28: 465074.15 | M28: 0 | N28: 0
A29: Long Positions | B29: U.S. Dollars | C29: Cash and Equivalents | D29: USD | E29: U.S. Dollars-NN_7100PP002 OnHand | F29: 3252494.4 | I29: 1 | J29: 1 | K29: 3252494.4 | L29: 3252494.4 | M29: 0 | N29: 0
A30: Long Positions | B30: U.S. Dollars | C30: Cash and Equivalents | D30: USD | E30: U.S. Dollars-NN_7100PP002 Payable | F30: -5184433.4 | I30: 1 | J30: 1 | K30: -5184433.4 | L30: -5184433.4 | M30: 0 | N30: 0
A31: Long Positions | B31: U.S. Dollars | C31: Cash and Equivalents | D31: USD | E31: U.S. Dollars-NN_7100PP002 Receivable | F31: 82048076 | I31: 1 | J31: 1 | K31: 82048076 | L31: 82048076 | M31: 0 | N31: 0
A32: Long Positions | B32: U.S. Dollars | C32: Cash and Equivalents | D32: USD | E32: U.S. Dollars-NN_7100PP012 OnHand | F32: 5457634.7 | I32: 1 | J32: 1 | K32: 5457634.7 | L32: 5457634.7 | M32: 0 | N32: 0
A33: Long Positions | B33: U.S. Dollars | C33: Bank Debt | D33: 104739 | E33: PCS MIDCO INC. First Lien DDTL DDTL - CF | F33: 460869.74 | G33: 298204399 | H33: 45357 | I33: 99 | J33: 100.5 | K33: 457560.57 | L33: 463174.09 | M33: 5613.52 | N33: 0 | P33: 8.85% of Global Commitment | Q33: Accrued Interest | R33: 3859.81 | S33: 1 | T33: 47515 | U33: 104739
A34: Long Positions | B34: U.S. Dollars | C34: Bank Debt | D34: 104739A | E34: PCS MIDCO INC. First Lien DDTL DDTL - CF | F34: 1695434.3 | G34: 319228095 | H34: 45580 | I34: 99 | J34: 100.5 | K34: 1681963.8 | L34: 1703911.5 | M34: 21947.66 | N34: 0 | P34: 8.85% of Global Commitment | Q34: Accrued Interest | R34: 14199.36 | S34: 0 | T34: 47515
A35: Long Positions | B35: U.S. Dollars | C35: Bank Debt | D35: 104739B | E35: PCS MIDCO INC. First Lien DDTL DDTL - CF | F35: 160083.34 | G35: 350183040 | H35: 45911 | I35: 99 | J35: 100.5 | K35: 158619.94 | L35: 160883.76 | M35: 2263.82 | N35: 0 | P35: 8.85% of Global Commitment | Q35: Accrued Interest | R35: 1340.71 | S35: 0 | T35: 47515
A36: Long Positions | B36: U.S. Dollars | C36: Bank Debt | D36: 105214.PP | E36: GGG Midco, LLC - First Lien DDTL C Unfunded | F36: 5190209.1 | G36: 356351395 | H36: 45973 | I36: 99 | J36: 100 | K36: 5138307 | L36: 5190209.1 | M36: 51902.09 | N36: 0 | O36: S + 5.00%; 1.00% Floor | Q36: Accrued Interest | R36: 3460.14 | S36: 0.75 | T36: 47753
A37: Long Positions | B37: U.S. Dollars | C37: Bank Debt | D37: 1328.PP | E37: Ad.net Acquisition, LLC - Revolver | F37: 13333.33 | G37: 297363085 | H37: 44320 | I37: 100 | J37: 100 | K37: 0 | L37: 0 | M37: 0 | N37: 0 | P37: 0.27% of Global Commitment | Q37: Accrued Interest | R37: 5.93 | S37: 0.5 | T37: 46149
A38: Long Positions | B38: U.S. Dollars | C38: Bank Debt | D38: 1328.PP | E38: Ad.net Acquisition, LLC - Revolver | F38: 44444.44 | G38: 297363362 | H38: 44988 | I38: 100 | J38: 100 | K38: 0 | L38: 0 | M38: 0 | N38: 0 | P38: 0.89% of Global Commitment | Q38: Accrued Interest | R38: 19.75 | S38: 0.5 | T38: 46149
A39: Long Positions | B39: U.S. Dollars | C39: Bank Debt | D39: 1328.PP | E39: Ad.net Acquisition, LLC - Revolver | F39: 75555.56 | G39: 297363134 | H39: 44512 | I39: 100 | J39: 100 | K39: 0 | L39: 0 | M39: 0 | N39: 0 | P39: 1.51% of Global Commitment | Q39: Accrued Interest | R39: 33.58 | S39: 0.5 | T39: 46149
A40: Long Positions | B40: U.S. Dollars | C40: Bank Debt | D40: 1328.PP | E40: Ad.net Acquisition, LLC - Revolver | F40: 88888.89 | G40: 297363511 | H40: 45142 | I40: 100 | J40: 100 | K40: 0 | L40: 0 | M40: 0 | N40: 0 | P40: 1.78% of Global Commitment | Q40: Accrued Interest | R40: 39.51 | S40: 0.5 | T40: 46149
A41: Long Positions | B41: U.S. Dollars | C41: Bank Debt | D41: 1328.PP | E41: Ad.net Acquisition, LLC - Revolver | F41: 222222.23 | G41: 297363777 | H41: 45331 | I41: 100 | J41: 100 | K41: 0 | L41: 0 | M41: 0 | N41: 0 | P41: 4.44% of Global Commitment | Q41: Accrued Interest | R41: 98.77 | S41: 0.5 | T41: 46149
A42: Long Positions | B42: U.S. Dollars | C42: Bank Debt | D42: 1360.PP | E42: Connatix Buyer, Inc. - Revolver | F42: 15625 | G42: 297363476 | H42: 45107 | I42: 55.5333 | J42: 100 | K42: 8677.08 | L42: 8677.08 | M42: 0 | N42: 0 | P42: 0.83% of Global Commitment | Q42: Accrued Interest | R42: 62.94 | S42: 0.5 | T42: 46581
...

Sheet Rec-Pay-Month End
B3: 1 | C3: Run rec/pay
B4: 2 | C4: Run pur/sale
B5: 3 | C5: Add column K and formula
B6: 4 | C6: Sort by K
B7: 5 | C7: Add non-cash and transfer Broker
A14: Financial_Account | B14: Investment | C14: Investment_Desc | D14: Sec_ID | E14: Hold_ID | F14: Trade_Date | G14: Contractual_Settle_Date | H14: Actual_Settle_Date | I14: Tran_ID | J14: Tran_Description | L14: Local_Amount | M14: Book_Amount | N14: Fund_Legal_Entity | O14: Fund_Structure_Code | P14: Period_End_Date | Q14: Custodian | R14: CustodianAcct | S14: Units | T14: Price | U14: Relieved_IDs | V14: Relieved_Prices
A16: Receivable | B16: USD | C16: Aphix Buyer, Inc - DDTL A | D16: 8993.PP | F16: 46052 | G16: 46052 | H16: 46052 | I16: 365553948 | J16: AccountingRelated | L16: 381224.15 | M16: 381224.15 | N16: NN00-PP | O16: NN00-PP | P16: 46053 | Q16: BNYM | R16: NN_7100PP002 | T16: 100 | U16: 364901759 | V16: 100
A17: Receivable | B17: USD | C17: Aphix Buyer, Inc - Term Loan A | D17: 8979.PP | F17: 46052 | G17: 46052 | H17: 46052 | I17: 365553949 | J17: AccountingRelated | L17: 5747694.8 | M17: 5747694.8 | N17: NN00-PP | O17: NN00-PP | P17: 46053 | Q17: BNYM | R17: NN_7100PP002 | T17: 100 | U17: 364901769 | V17: 100
A18: Receivable | B18: USD | C18: BLC Holding Company, Inc. DDTL | D18: 7048.PP | F18: 46052 | G18: 46052 | H18: 46052 | I18: 365553950 | J18: AccountingRelated | L18: 2242811.9 | M18: 2242811.9 | N18: NN00-PP | O18: NN00-PP | P18: 46053 | Q18: BNYM | R18: NN_7100PP002 | T18: 100 | U18: 364901778 | V18: 100
A19: Receivable | B19: USD | C19: Cartessa Aesthetics, LLC - Term Loan | D19: LX206028.PP | F19: 46052 | G19: 46052 | H19: 46052 | I19: 365553952 | J19: AccountingRelated | L19: 7500000 | M19: 7500000 | N19: NN00-PP | O19: NN00-PP | P19: 46053 | Q19: BNYM | R19: NN_7100PP002 | T19: 100 | U19: 364901785 | V19: 100
A20: Receivable | B20: USD | C20: Halo Buyer, INC. - Refinanced Term Loan | D20: 7818.PP | F20: 46052 | G20: 46052 | H20: 46052 | I20: 365553953 | J20: AccountingRelated | L20: 7500000 | M20: 7500000 | N20: NN00-PP | O20: NN00-PP | P20: 46053 | Q20: BNYM | R20: NN_7100PP002 | T20: 100 | U20: 364901787 | V20: 100
A21: Receivable | B21: USD | C21: Harris & Co. LLC - DDTL B | D21: 6142.PP3 | F21: 46052 | G21: 46052 | H21: 46052 | I21: 365553954 | J21: AccountingRelated | L21: 5210471.2 | M21: 5210471.2 | N21: NN00-PP | O21: NN00-PP | P21: 46053 | Q21: BNYM | R21: NN_7100PP002 | T21: 99.25 | U21: 364901795 | V21: 99.25
A22: Receivable | B22: USD | C22: Highwire Public Relations, LLC Term Loan | D22: 9018.PP | F22: 46052 | G22: 46052 | H22: 46052 | I22: 365553956 | J22: AccountingRelated | L22: 2484375 | M22: 2484375 | N22: NN00-PP | O22: NN00-PP | P22: 46053 | Q22: BNYM | R22: NN_7100PP002 | T22: 99.375 | U22: 364901805 | V22: 99.375
A23: Receivable | B23: USD | C23: Loving Tan Intermediate II, Inc. - Term Loan | D23: LX213391.PP | F23: 46052 | G23: 46052 | H23: 46052 | I23: 365553997 | J23: AccountingRelated | L23: 4656663.9 | M23: 4656663.9 | N23: NN00-PP | O23: NN00-PP | P23: 46053 | Q23: BNYM | R23: NN_7100PP002 | T23: 99.5 | U23: 364901811 | V23: 99.5
A24: Receivable | B24: USD | C24: Loving Tan Intermediate II, Inc. - DDTL | D24: 2221.PP | F24: 46052 | G24: 46052 | H24: 46052 | I24: 365554014 | J24: AccountingRelated | L24: 2327965.9 | M24: 2327965.9 | N24: NN00-PP | O24: NN00-PP | P24: 46053 | Q24: BNYM | R24: NN_7100PP002 | T24: 99.5 | U24: 364901819 | V24: 99.5
A25: Receivable | B25: USD | C25: Loving Tan Intermediate II, Inc. - DDTL | D25: 2221.PP1 | F25: 46052 | G25: 46052 | H25: 46052 | I25: 365554028 | J25: AccountingRelated | L25: 477870.03 | M25: 477870.03 | N25: NN00-PP | O25: NN00-PP | P25: 46053 | Q25: BNYM | R25: NN_7100PP002 | T25: 99.5 | U25: 364901827 | V25: 99.5
A26: Receivable | B26: USD | C26: Marketplace Events Acquisition, LLC - DDTL | D26: 7138.PP | F26: 46052 | G26: 46052 | H26: 46052 | I26: 365554031 | J26: AccountingRelated | L26: 864328.55 | M26: 864328.55 | N26: NN00-PP | O26: NN00-PP | P26: 46053 | Q26: BNYM | R26: NN_7100PP002 | T26: 100 | U26: 364901887 | V26: 100
A27: Receivable | B27: USD | C27: Marketplace Events Acquisition, LLC - DDTL | D27: 7138.PP1 | F27: 46052 | G27: 46052 | H27: 46052 | I27: 365554033 | J27: AccountingRelated | L27: 369190.21 | M27: 369190.21 | N27: NN00-PP | O27: NN00-PP | P27: 46053 | Q27: BNYM | R27: NN_7100PP002 | T27: 100 | U27: 364902009 | V27: 100
... A46: Receivable | B46: USD | C46: The Vertex Companies, LLC - Term Loan B | D46: 3584.PP | F46: 46052 | G46: 46052 | H46: 46052 | I46: 365554177 | J46: AccountingRelated | L46: 180219.99 | M46: 180219.99 | N46: NN00-PP | O46: NN00-PP | P46: 46053 | Q46: BNYM | R46: NN_7100PP002 | T46: 99.4 | U46: 364902366 | V46: 99.4
M49: =SUM(M16:M46) -> 73832136
A58: Payable | B58: USD | C58: Beta Plus Technologies,Inc.- Term Loan | D58: LX206113.PP | F58: 46024 | G58: 46081 | H58: 46081 | I58: 364011657 | J58: Buy | L58: -4900000 | M58: -4900000 | N58: NN00-PP | O58: NN00-PP | P58: 46048 | Q58: BNYM | R58: NN_7100PP002 | S58: 5000000 | T58: 98
M59: =SUM(M51:M58) -> -4900000
M69: =SUM(M63:M68) -> 0
L78: SHOULD BE 0 | M78: =M49+M69 -> 73832136

Sheet SBICII post TB (closed)

Sheet PNNT SPV post TB

Sheet SBIC post TB(Closed)
B4: =IF(C4="PennantPark SBIC, L.L.P."," ","Not SBIC") -> Not SBIC
B10: =CONCATENATE(E10,F10)
B11: =CONCATENATE(E11,F11)
A12: =VLOOKUP(B12,Summary!A:A,1,FALSE) | B12: =CONCATENATE(E12,F12)
A13: =VLOOKUP(B13,Summary!A:A,1,FALSE) | B13: =CONCATENATE(E13,F13)
A14: =VLOOKUP(B14,Summary!A:A,1,FALSE) | B14: =CONCATENATE(E14,F14)
A15: =VLOOKUP(B15,Summary!A:A,1,FALSE) | B15: =CONCATENATE(E15,F15)
A16: =VLOOKUP(B16,Summary!A:A,1,FALSE) | B16: =CONCATENATE(E16,F16)
A17: =VLOOKUP(B17,Summary!A:A,1,FALSE) | B17: =CONCATENATE(E17,F17)
A18: =VLOOKUP(B18,Summary!A:A,1,FALSE) | B18: =CONCATENATE(E18,F18)
A19: =VLOOKUP(B19,Summary!A:A,1,FALSE) | B19: =CONCATENATE(E19,F19)
A20: =VLOOKUP(B20,Summary!A:A,1,FALSE) | B20: =CONCATENATE(E20,F20)
A21: =VLOOKUP(B21,Summary!A:A,1,FALSE) | B21: =CONCATENATE(E21,F21)
A22: =VLOOKUP(B22,Summary!A:A,1,FALSE) | B22: =CONCATENATE(E22,F22)
A23: =VLOOKUP(B23,Summary!A:A,1,FALSE) | B23: =CONCATENATE(E23,F23)
... A70: =VLOOKUP(B70,Summary!A:A,1,FALSE) | B70: =CONCATENATE(E70,F70)
