Workbook
Name _Principal: '[1]Summary - All Debt'!#REF!
Name _Principal: '[1]Summary - All Debt'!#REF!
Name _Principal: '[1]Summary - All Debt'!#REF!
Name _Regression_Int: 1
Name _Sr2: "Sr2"
Name AccountTotal1: #REF!
Name AccountTotal1: #REF!
Name AccountTotal2: #REF!
Name AccountTotal2: #REF!
Name AccountTotal3: #REF!
Name AccountTotal3: #REF!
Name AccountTotal4: #REF!
Name AccountTotal4: #REF!
Name AccountTotal5: #REF!
Name AccountTotal5: #REF!
Name AccountTotal6: #REF!
Name AccountTotal6: #REF!
Name AccountTotal7: #REF!
Name AccountTotal7: #REF!
Name AccountTotal8: #REF!
Name AccountTotal8: #REF!
Name AccountTotal9: #REF!
Name AccountTotal9: #REF!
Name AcctTotal: #REF!
Name AcctTotal: #REF!
Name ACPAAfter: #REF!
Name ACPAAfter: #REF!
Name ACPAAfter: #REF!
Name ACPABefore: #REF!
Name ACPABefore: #REF!
Name ACPABefore: #REF!
Name act_360: 2
Name Actual12moChargeoffRatio: #REF!
Name Actual12moChargeoffRatio: #REF!
Name Actual3moChargeoffRatio: #REF!
Name Actual3moChargeoffRatio: #REF!
Name Actual3moDefaultRatio: #REF!
Name Actual3moDefaultRatio: #REF!
Name AdjAdvRate: #REF!
Name AdjAdvRate: #REF!
Name AdvancesOS: #REF!
Name AdvancesOS: #REF!
Name AfterTrade: '[2]Portfolio Information'!$M$9:$M$500
Name AggNetMarkMktAmount: '[3]Borrowing Base Certificate'!$H$95
Name AgingsDetail: #REF!
Name AgingsDetail: #REF!
Name Angle: #REF!
Name Angle: #REF!
Name Angle: #REF!
Name Annual: "Annual"
Name AOLB: #REF!
Name AOLB: #REF!
Name AOLBrange: #REF!
Name AOLBrange: #REF!
Name AOPBAfter: #REF!
Name AOPBAfter: #REF!
Name AOPBAfter: #REF!
Name asset_step_up_coupon: [4]Bonds!#REF!
Name asset_step_up_coupon: [4]Bonds!#REF!
Name asset_step_up_coupon: [4]Bonds!#REF!

Sheet Availability Borrower
A1: A | B1: B
A2: Borrower: | B2: PennantPark Credit Opportunities Fund IV
A3: Date of determination: | B3: 45046
A4: Revolving Closing Date | B4: 44914
A5: Commitment Period (3 years from Final Closing Date, as defined in LPA) | B5: Yes
A6: (b) Facility Size | B6: 60000000
A7: Loans (USD) | B7: 48500000
A8: Loans (CAD) | B8: 0

Sheet Applicable Margin
C3: =TEXT(#REF!,0)&" - Applicable Margin - "&TEXT(#REF!,"mm/dd/yyyy") -> #REF!
C5: Revolving Closing Date | D5: =#REF! -> #REF!
C6: Date of Determination | D6: =#REF! -> #REF!
C7: Months since Revolving Closing Date | D7: =DATEDIF(D5,D6,"m") -> #REF!
C9: Applicable Floor | D9: 0
C11: Subscription Percentage:
C12: (A) Subscription BB / Total BB | D12: =#REF!/#REF! -> #REF!
C14: (y) 100% | D14: 1
C15: (z) Subscription BB / Facility Commitments | D15: =#REF!/#REF! -> #REF!
C16: (B) lower of (y) and (z) | D16: =MIN(D14:D15) -> #REF!
C18: Three years since Revolving Closing Date? | D18: =IF(D7>=36,"Yes","No") -> #REF!
C20: Subscription Percentage (greater of (A) and (B) or 0% after 3 years) | D20: =IF(D18="Yes",0,MAX(D12,D16)) -> #REF!
C22: Portfolio Leverage Percentage (100% minus Subscription Percentage) | D22: =1-D20 -> #REF!
C24: Applicable Margin | D24: =MAX(((D20*Inputs!D6)+(D22*IF(SUM('PL BB Results'!#REF!)>Inputs!D9,Inputs!D8,Inputs!D10))),D9) -> #REF!

Sheet Subscription BB
A1: Investor | B1: Master/Feeder | C1: Ultimate Investor Parent | D1: Designation | E1: Commitment | F1: Capital Called
A2: Kemper Corporation | D2: Institutional Investors | E2: 15000000 | F2: =E2*$J$4 -> 0
A3: Teamsters 120 | D3: Institutional Investors | E3: 20000000 | F3: =E3*$J$4 -> 0
A4: Pompano General | D4: Institutional Investors | E4: 5000000 | F4: =E4*$J$4 -> 0
A5: Miramar Police | D5: Institutional Investors | E5: 5000000 | F5: =E5*$J$4 -> 0
A6: Plantation Police | D6: Institutional Investors | E6: 3000000 | F6: =E6*$J$4 -> 0
A7: Lauderhill Police | D7: Institutional Investors | E7: 4000000 | F7: =E7*$J$4 -> 0
A8: Hollywood Police | D8: Institutional Investors | E8: 4000000 | F8: =E8*$J$4 -> 0
A9: Cape Coral Police | D9: Institutional Investors | E9: 5000000 | F9: =E9*$J$4 -> 0
A10: Simpson Estates | D10: High Net Worth Investors | E10: 5000000 | F10: =E10*$J$4 -> 0
A11: [Reserved] | D11: High Net Worth Investors | E11: 0 | F11: =E11*$J$4 -> 0
A12: Marc / Rosemary Reisch | D12: High Net Worth Investors | E12: 1500000 | F12: =E12*$J$4 -> 0
A13: Dr. Ray Irani | D13: High Net Worth Investors | E13: 8000000 | F13: =E13*$J$4 -> 0
... A15: Brandon Levin | D15: High Net Worth Investors | E15: 250000 | F15: =E15*$J$4 -> 0
D16: Excluded | F16: =E16*$J$4 -> 0

Sheet PL BB Build
A1: Investment Name | B1: Issuer | C1: Investment Investment Type | D1: Investment Industry | E1: Investment Closing Date | F1: Investment Maturity | G1: Investment Par | H1: Investment Cost | I1: Investment External Valuation | J1: Investment Internal Valuation | K1: Rates Fixed Coupon | L1: Rates Floating Cash Spread | M1: Rates Current LIBOR/Floor | N1: Rates PIK | O1: Rates Fixed / Floating | P1: Classifications Quoted / Unquoted | Q1: Classifications Warehouse Asset | R1: Classifications Warehouse Asset Inclusion Date | S1: Classifications Warehouse Asset Expected Rating | T1: Classifications Approved Foreign Jurisdiction | U1: Classifications LTV Transaction | V1: Classifications Noteless Assigned Loan | W1: Classifications Undelivered Note | X1: Classifications Structured Finance Obligation | Y1: Classifications Third Party Finance Company | Z1: Classifications Affiliate Investment | AA1: Classifications Defaulted / Restructured | AB1: Financials LTM Revenue ($MMs) | AC1: Financials LTM EBITDA ($MMs) | AD1: Leverage Revolver Commitment | AE1: Leverage Total Enterprise Value | AF1: Leverage Total Leverage | AG1: Leverage PCOF IV Leverage | AH1: Leverage Attachment Point | AI1: Leverage Total Capitalization | AJ1: Leverage LTV Thru PCOF IV | AK1: Final Eligibility Override | AL1: Final Comment | AM1: Concentration Adjustment | AN1: Concentration Comment | AO1: Borrowing Base Other Adjustment | AP1: Borrowing Base Industry Concentration | AQ1: Borrowing Base Comment | AR1: Is Eligible Issuer
A2: A1 Garage Merger Sub, LLC First Lien | B2: A1 Garage | C2: First Lien | D2: Consumer Products | E2: 44917 | F2: 48570 | G2: 4987500 | H2: 4893665.8 | I2: 4912687.5 | L2: 0.065 | M2: =MAX(4.62356,1)/100 -> 0.0462356 | O2: Floating | P2: Unquoted | Q2: No | T2: NA | U2: No | V2: No | W2: No | X2: No | Y2: No | Z2: No | AA2: No | AB2: 117.6 | AC2: 26.5 | AD2: 0 | AE2: =26.5*19.46 -> 515.69 | AF2: 4.92 | AG2: 4.92 | AJ2: 0.252 | AR2: Yes
A3: A1 Garage Merger Sub, LLC DDTL | B3: A1 Garage | C3: First Lien | D3: Consumer Products | E3: 44917 | F3: 47109 | G3: 3478875.9 | H3: 852609.97 | I3: 800426.83 | L3: 0.065 | M3: =MAX(4.62356,1)/100 -> 0.0462356 | O3: Floating | P3: Unquoted | Q3: No | T3: NA | U3: No | V3: No | W3: No | X3: No | Y3: No | Z3: No | AA3: No | AB3: 117.6 | AC3: 26.5 | AD3: 0 | AE3: =26.5*19.46 -> 515.69 | AF3: 4.92 | AG3: 4.92 | AJ3: 0.252 | AR3: Yes
A4: A1 Garage Merger Sub, LLC Revolver | B4: A1 Garage | C4: First Lien | D4: Consumer Products | E4: 44917 | F4: 47109 | G4: 1265822.8 | H4: 0 | I4: -18987.34 | L4: 0.065 | M4: =MAX(4.62356,1)/100 -> 0.0462356 | O4: Floating | P4: Unquoted | Q4: No | T4: NA | U4: No | V4: No | W4: No | X4: No | Y4: No | Z4: No | AA4: No | AB4: 117.6 | AC4: 26.5 | AD4: 0 | AE4: =26.5*19.46 -> 515.69 | AF4: 4.92 | AG4: 4.92 | AJ4: 0.252 | AR4: Yes
A5: EDS Buyer LLC | B5: EDS | C5: Warehouse First Lien | D5: Aerospace & Defense | E5: 44924 | F5: 47128 | G5: 3500000 | H5: 3450173.2 | I5: 3412500 | L5: 0.0625 | M5: =MAX(4.65554,1)/100 -> 0.0465554 | O5: Floating | P5: Unquoted | Q5: No | T5: NA | U5: No | V5: No | W5: No | X5: No | Y5: No | Z5: No | AA5: No | AB5: 33.3 | AC5: 12 | AD5: 0 | AE5: 208.7 | AF5: 4.17 | AG5: 4.17 | AJ5: 0.24 | AR5: Yes
A6: EDS Buyer LLC DDTL | B6: EDS | C6: Warehouse First Lien | D6: Aerospace & Defense | E6: 44924 | F6: 47128 | G6: 2625000 | H6: 0 | I6: -65625 | L6: 0.0625 | M6: =MAX(4.65554,1)/100 -> 0.0465554 | O6: Floating | P6: Unquoted | Q6: No | T6: NA | U6: No | V6: No | W6: No | X6: No | Y6: No | Z6: No | AA6: No | AB6: 33.3 | AC6: 12 | AD6: 0 | AE6: 208.7 | AF6: 4.17 | AG6: 4.17 | AJ6: 0.24 | AR6: Yes
A7: EDS Buyer LLC Revolver | B7: EDS | C7: Warehouse First Lien | D7: Aerospace & Defense | E7: 44924 | F7: 47128 | G7: 787500 | H7: 0 | I7: -19687.5 | L7: 0.0625 | M7: =MAX(4.65554,1)/100 -> 0.0465554 | O7: Floating | P7: Unquoted | Q7: No | T7: NA | U7: No | V7: No | W7: No | X7: No | Y7: No | Z7: No | AA7: No | AB7: 33.3 | AC7: 12 | AD7: 7.5 | AE7: 208.7 | AF7: 4.17 | AG7: 4.17 | AJ7: 0.24 | AR7: Yes
A8: Infinity Home Services | B8: Infinity Home Services | C8: First Lien | D8: Personal, Food & Miscellaneous Services | E8: 44923 | F8: 47115 | G8: 5000000 | H8: 4905656.9 | I8: 4899999 | L8: 0.0675 | M8: =MAX(4.62356,1)/100 -> 0.0462356 | O8: Floating | P8: Unquoted | Q8: No | T8: NA | U8: No | V8: No | W8: No | X8: No | Y8: No | Z8: No | AA8: No | AB8: 218.7 | AC8: 37 | AD8: 0 | AE8: 544 | AF8: 4.27 | AG8: 4.27 | AJ8: 0.25 | AR8: Yes
A9: Infinity Home Services DDTL | B9: Infinity Home Services | C9: First Lien | D9: Personal, Food & Miscellaneous Services | E9: 44923 | F9: 47115 | G9: 2631579 | H9: 873684.21 | I9: 821052.32 | L9: 0.0675 | M9: =MAX(4.62356,1)/100 -> 0.0462356 | O9: Floating | P9: Unquoted | Q9: No | T9: NA | U9: No | V9: No | W9: No | X9: No | Y9: No | Z9: No | AA9: No | AB9: 218.7 | AC9: 37 | AD9: 0 | AE9: 544 | AF9: 4.27 | AG9: 4.27 | AJ9: 0.25 | AR9: Yes
A10: Infinity Home Services Revolver | B10: Infinity Home Services | C10: First Lien | D10: Personal, Food & Miscellaneous Services | E10: 44923 | F10: 47115 | G10: 1052631.6 | H10: 78947.37 | I10: 57894.91 | L10: 0.0675 | M10: =MAX(4.62356,1)/100 -> 0.0462356 | O10: Floating | P10: Unquoted | Q10: No | T10: NA | U10: No | V10: No | W10: No | X10: No | Y10: No | Z10: No | AA10: No | AB10: 218.7 | AC10: 37 | AD10: 20 | AE10: 544 | AF10: 4.27 | AG10: 4.27 | AJ10: 0.25 | AR10: Yes
A11: Ardurra | B11: Ardurra | C11: First Lien | D11: Environmental Services | E11: 44957 | F11: 47149 | G11: 2000000 | H11: 1961407.9 | I11: 1960007 | L11: 0.065 | M11: =MAX(4.78,1)/100 -> 0.0478 | O11: Floating | P11: Unquoted | Q11: No | T11: NA | U11: No | V11: No | W11: No | X11: No | Y11: No | Z11: No | AA11: No | AB11: 192.4 | AC11: 38.3 | AD11: 0 | AE11: 460 | AF11: 4.83 | AG11: 4.83 | AJ11: 0.4 | AR11: Yes
A12: Ardurra DDTL | B12: Ardurra | C12: First Lien | D12: Environmental Services | E12: 44957 | F12: 47149 | G12: 2173913 | H12: 0 | I12: -43470.73 | L12: 0.065 | M12: =MAX(4.78,1)/100 -> 0.0478 | O12: Floating | P12: Unquoted | Q12: No | T12: NA | U12: No | V12: No | W12: No | X12: No | Y12: No | Z12: No | AA12: No | AB12: 192.4 | AC12: 38.3 | AD12: 0 | AE12: 460 | AF12: 4.83 | AG12: 4.83 | AJ12: 0.4 | AR12: Yes
A13: Ardurra Revolver | B13: Ardurra | C13: First Lien | D13: Environmental Services | E13: 44957 | F13: 47149 | G13: 869565.22 | H13: 0 | I13: -17388.29 | L13: 0.065 | M13: =MAX(4.78,1)/100 -> 0.0478 | O13: Floating | P13: Unquoted | Q13: No | T13: NA | U13: No | V13: No | W13: No | X13: No | Y13: No | Z13: No | AA13: No | AB13: 192.4 | AC13: 38.3 | AD13: 30 | AE13: 460 | AF13: 4.83 | AG13: 4.83 | AJ13: 0.4 | AR13: Yes
A14: BioDerm First Lien | B14: BioDerm | C14: First Lien | D14: Healthcare, Education & Childcare | E14: 44957 | F14: 46783 | G14: 3000000 | H14: 2964348.3 | I14: 2955000 | L14: 0.065 | M14: 0.01 | O14: Floating | P14: Unquoted | Q14: No | T14: NA | U14: No | V14: No | W14: No | X14: No | Y14: No | Z14: No | AA14: No | AB14: 57.9 | AC14: 19.5 | AD14: 0 | AE14: 227.4 | AF14: 4.84 | AG14: 4.84 | AJ14: 0.416 | AR14: Yes
A15: BioDerm Revolver | B15: BioDerm | C15: First Lien | D15: Healthcare, Education & Childcare | E15: 44957 | F15: 46783 | G15: 357142.86 | H15: 0 | I15: -5357.14 | L15: 0.065 | M15: 0.01 | O15: Floating | P15: Unquoted | Q15: No | T15: NA | U15: No | V15: No | W15: No | X15: No | Y15: No | Z15: No | AA15: No | AB15: 57.9 | AC15: 19.5 | AD15: 0 | AE15: 227.4 | AF15: 4.84 | AG15: 4.84 | AJ15: 0.416 | AR15: Yes
A16: ECL Entertainment | B16: ECL | C16: First Lien | D16: Hotel, Motels, Inns & Gaming | E16: 44595 | F16: 46843 | G16: 3491116.8 | H16: 3457792.5 | I16: 3458405 | L16: 0.075 | M16: =MAX(4.5561,1)/100 -> 0.045561 | O16: Floating | P16: Quoted | Q16: No | T16: NA | U16: No | V16: No | W16: No | X16: No | Y16: No | Z16: No | AA16: No | AB16: 185.7 | AC16: 81.4 | AD16: 20 | AE16: 403 | AF16: 2.95 | AG16: 2.95 | AJ16: 0.437 | AR16: Yes
A17: Urology Management Holdings DDTL | B17: Solaris | C17: First Lien | D17: Healthcare, Education & Childcare | E17: 44958 | F17: 46188 | G17: 1111111.1 | H17: 0 | I17: -33222.08 | L17: 0.0625 | M17: =MAX(5.012,1)/100 -> 0.05012 | O17: Floating | P17: Unquoted | Q17: No | T17: NA | U17: No | V17: No | W17: No | X17: No | Y17: No | Z17: No | AA17: No | AB17: 937.6 | AC17: 86.6 | AD17: 0 | AE17: 958.3 | AF17: 5.51 | AG17: 5.51 | AJ17: 0.498 | AR17: Yes
A18: Urology Management Holdings | B18: Solaris | C18: First Lien | D18: Healthcare, Education & Childcare | E18: 44958 | F18: 46188 | G18: 1662500 | H18: 1631655.9 | I18: 1612791.5 | L18: 0.0625 | M18: =MAX(5.012,1)/100 -> 0.05012 | O18: Floating | P18: Unquoted | Q18: No | T18: NA | U18: No | V18: No | W18: No | X18: No | Y18: No | Z18: No | AA18: No | AB18: 937.6 | AC18: 86.6 | AD18: 0 | AE18: 958.3 | AF18: 5.51 | AG18: 5.51 | AJ18: 0.498 | AR18: Yes
A19: Five Star Buyer | B19: Five Star | C19: First Lien | D19: Hotel, Motels, Inns & Gaming | E19: 44980 | F19: 46806 | G19: 3000000 | H19: 2942201.5 | I19: 2939999.5 | L19: 0.07 | M19: =MAX(4.66356,1)/100 -> 0.0466356 | O19: Floating | P19: Unquoted | Q19: No | T19: NA | U19: No | V19: No | W19: No | X19: No | Y19: No | Z19: No | AA19: No | AB19: 71.3 | AC19: 21.5 | AD19: 0 | AE19: 350 | AF19: 2.58 | AG19: 2.58 | AJ19: 0.364 | AR19: Yes
A20: Five Star Buyer DDTL | B20: Five Star | C20: First Lien | D20: Hotel, Motels, Inns & Gaming | E20: 44980 | F20: 46806 | G20: 728571.43 | H20: 0 | I20: -14571.55 | L20: 0.07 | M20: =MAX(4.66356,1)/100 -> 0.0466356 | O20: Floating | P20: Unquoted | Q20: No | T20: NA | U20: No | V20: No | W20: No | X20: No | Y20: No | Z20: No | AA20: No | AB20: 71.3 | AC20: 21.5 | AD20: 0 | AE20: 350 | AF20: 2.58 | AG20: 2.58 | AJ20: 0.364 | AR20: Yes
A21: Five Star Buyer Revolver | B21: Five Star | C21: First Lien | D21: Hotel, Motels, Inns & Gaming | E21: 44980 | F21: 46806 | G21: 342857.14 | H21: 0 | I21: -6857.2 | L21: 0.07 | M21: =MAX(4.66356,1)/100 -> 0.0466356 | O21: Floating | P21: Unquoted | Q21: No | T21: NA | U21: No | V21: No | W21: No | X21: No | Y21: No | Z21: No | AA21: No | AB21: 71.3 | AC21: 21.5 | AD21: 8 | AE21: 350 | AF21: 2.58 | AG21: 2.58 | AJ21: 0.364 | AR21: Yes
A22: Anteriad (FKA MeritDirect) | B22: MeritDirect | C22: First Lien | D22: Media | E22: 45016 | F22: 47054 | G22: 3000000 | H22: 2944439.1 | I22: 2939999.8 | L22: 0.065 | M22: 0.0495702 | O22: Floating | P22: Unquoted | Q22: No | T22: NA | U22: No | V22: No | W22: No | X22: No | Y22: No | Z22: No | AA22: No | AB22: 117.9 | AC22: 30.4 | AD22: 7 | AE22: 132.8 | AF22: 4.54 | AG22: 4.54 | AJ22: 0.494 | AR22: Yes
A23: Beta Plus Technologies, Inc. | B23: BetaPlus | C23: First Lien | D23: Business Services | E23: 45021 | F23: 47301 | G23: 2992481.2 | H23: 2636699.7 | I23: 2633383.5 | L23: 0.0575 | M23: 0.0480341 | O23: Floating | P23: Unquoted | Q23: No | T23: NA | U23: No | V23: No | W23: No | X23: No | Y23: No | Z23: No | AA23: No | AB23: 321 | AC23: 150 | AD23: 100 | AE23: 1270 | AF23: 4.99 | AG23: 4.99 | AJ23: 0.59 | AR23: Yes
A24: Simplicity Group First Lien | B24: Simplicity Group | C24: First Lien | D24: Financial Services | E24: 45021 | F24: 46358 | G24: 3603603.6 | H24: 3532933.1 | I24: 3531531.5 | L24: 0.0625 | M24: 0.0507063 | O24: Floating | P24: Unquoted | Q24: No | T24: NA | U24: No | V24: No | W24: No | X24: No | Y24: No | Z24: No | AA24: No | AB24: 489 | AC24: 103.2 | AD24: 23.5 | AE24: 774.7 | AF24: 5.13 | AG24: 5.13 | AJ24: 0.61 | AR24: Yes
A25: Simplicity Group DDTL | B25: Simplicity Group | C25: First Lien | D25: Financial Services | E25: 45021 | F25: 46358 | G25: 889639.64 | I25: -889639.64 | L25: 0.0625 | M25: 0.0507063 | O25: Floating | P25: Unquoted | Q25: No | T25: NA | U25: No | V25: No | W25: No | X25: No | Y25: No | Z25: No | AA25: No | AB25: 489 | AC25: 103.2 | AD25: 23.5 | AE25: 774.7 | AF25: 5.13 | AG25: 5.13 | AJ25: 0.61 | AR25: Yes
A26: Simplicity Group Revolver | B26: Simplicity Group | C26: First Lien | D26: Financial Services | E26: 45021 | F26: 46358 | G26: 236486.49 | I26: -236486.49 | L26: 0.0625 | M26: 0.0507063 | O26: Floating | P26: Unquoted | Q26: No | T26: NA | U26: No | V26: No | W26: No | X26: No | Y26: No | Z26: No | AA26: No | AB26: 489 | AC26: 103.2 | AD26: 23.5 | AE26: 774.7 | AF26: 5.13 | AG26: 5.13 | AJ26: 0.61 | AR26: Yes
A27: Cash | B27: Cash | C27: Cash | D27: Cash | G27: 4456822.2 | H27: =G27 -> 4456822.2 | I27: =H27 -> 4456822.2 | J27: =I27 -> 4456822.2 | P27: Quoted | T27: N/A | U27: No | V27: No | W27: No | X27: No | Y27: No | Z27: No | AA27: No | AK27: N/A | AR27: Yes
A28: EDS Topco Equity | B28: EDS | C28: Equity | D28: Aerospace & Defense | E28: 44924 | F28: 47116 | H28: 437500 | I28: 437500 | P28: Unquoted | Q28: No | T28: NA | U28: No | V28: No | W28: No | X28: No | Y28: No | Z28: No | AA28: No | AR28: No
A29: A1 Garage Equity LLC | B29: A1 Garage | C29: Equity | D29: Personal, Food & Miscellaneous Services | E29: 44917 | F29: 47109 | H29: 1096519 | I29: 1096519 | P29: Unquoted | Q29: No | T29: NA | U29: No | V29: No | W29: No | X29: No | Y29: No | Z29: No | AA29: No | AR29: No
A30: Ardurra Equity | B30: Ardurra | C30: Equity | D30: Environmental Services | E30: 44957 | F30: 47149 | H30: 1260869.6 | I30: 1260869.6 | P30: Unquoted | Q30: No | T30: NA | U30: No | V30: No | W30: No | X30: No | Y30: No | Z30: No | AA30: No | AR30: No
A31: BioDerm Equity | B31: BioDerm | C31: Equity | D31: Healthcare, Education & Childcare | E31: 44957 | F31: 47149 | H31: 437000 | I31: 437000 | P31: Unquoted | Q31: No | T31: NA | U31: No | V31: No | W31: No | X31: No | Y31: No | Z31: No | AA31: No | AR31: No
A32: Urology Partners Co | B32: Solaris | C32: Equity | D32: Healthcare, Education & Childcare | E32: 44958 | F32: 46188 | H32: 277777.78 | I32: 277777.78 | P32: Unquoted | Q32: No | T32: NA | U32: No | V32: No | W32: No | X32: No | Y32: No | Z32: No | AA32: No | AR32: No
A33: Five Star Buyer | B33: Five Star | C33: Equity | D33: Hotel, Motels, Inns & Gaming | E33: 44980 | F33: 46806 | H33: 488571.43 | I33: 488571.43 | P33: Unquoted | Q33: No | T33: NA | U33: No | V33: No | W33: No | X33: No | Y33: No | Z33: No | AA33: No | AR33: No
A34: Simplicity Group | B34: Simplicity Group | C34: Equity | D34: Financial Services | E34: 45021 | F34: 46358 | H34: 270270 | I34: 270270 | P34: Unquoted | Q34: No | T34: NA | U34: No | V34: No | W34: No | X34: No | Y34: No | Z34: No | AA34: No | AR34: No
A35: Infinity Home Services Equity | B35: Infinity Home Services | C35: Equity | D35: Personal, Food & Miscellaneous Services | E35: 44923 | F35: 47115 | H35: 992481.21 | I35: 992481.21 | P35: Unquoted | Q35: No | T35: NA | U35: No | V35: No | W35: No | X35: No | Y35: No | Z35: No | AA35: No | AR35: No

Sheet Principle Obligations
A1: Principal Obligations | B1: Currency | C1: Amount | D1: Spot Rate | E1: Dollar Equivalent
A2: Loans (USD) | B2: USD | C2: 48500000 | D2: 1 | E2: 48500000
A3: Loans (CAD) | B3: CAD

Sheet PL BB Output
C3: =TEXT(#REF!,0)&" - Portfolio Leverage Borrowing Base - "&TEXT(#REF!,"mm/dd/yyyy") -> #REF!
D5: Company | E5: Eligible | F5: Maturity | G5: Industry | H5: Quoted / Unquoted | I5: Security | J5: Cost | K5: FMV | L5: Ineligible Investments | M5: Eligible Investments | N5: Adjustments | O5: Adj. Eligible Investments | P5: Adj. Advance Rate | Q5: Contribution | R5: Adjustments | S5: Borrowing Base | U5: Adjustment Notes
D6: ='PL BB Build'!A2 -> A1 Garage Merger Sub, LLC First Lien | E6: ='PL BB Build'!#REF! -> #REF! | F6: ='PL BB Build'!F2 -> 48570 | G6: ='PL BB Build'!D2 -> Consumer Products | H6: ='PL BB Build'!P2 -> Unquoted | I6: ='PL BB Build'!#REF! -> #REF! | J6: ='PL BB Build'!H2 -> 4893665.8 | K6: ='PL BB Build'!#REF! -> #REF! | L6: =M6-K6 -> #REF! | M6: ='PL BB Build'!#REF! -> #REF! | N6: ='PL BB Build'!AM2 -> 0 | O6: =SUM(M6:N6) -> #REF! | P6: ='PL BB Build'!#REF! -> #REF! | Q6: =IFERROR(O6*P6,0) -> 0 | R6: ='PL BB Build'!#REF!+'PL BB Build'!AO2+'PL BB Build'!AP2 -> #REF! | S6: =SUM(Q6:R6) -> #REF!
D7: ='PL BB Build'!A3 -> A1 Garage Merger Sub, LLC DDTL | E7: ='PL BB Build'!#REF! -> #REF! | F7: ='PL BB Build'!F3 -> 47109 | G7: ='PL BB Build'!D3 -> Consumer Products | H7: ='PL BB Build'!P3 -> Unquoted | I7: ='PL BB Build'!#REF! -> #REF! | J7: ='PL BB Build'!H3 -> 852609.97 | K7: ='PL BB Build'!#REF! -> #REF! | L7: =M7-K7 -> #REF! | M7: ='PL BB Build'!#REF! -> #REF! | N7: ='PL BB Build'!AM3 -> 0 | O7: =SUM(M7:N7) -> #REF! | P7: ='PL BB Build'!#REF! -> #REF! | Q7: =IFERROR(O7*P7,0) -> 0 | R7: ='PL BB Build'!#REF!+'PL BB Build'!AO3+'PL BB Build'!AP3 -> #REF! | S7: =SUM(Q7:R7) -> #REF!
D8: ='PL BB Build'!A4 -> A1 Garage Merger Sub, LLC Revolver | E8: ='PL BB Build'!#REF! -> #REF! | F8: ='PL BB Build'!F4 -> 47109 | G8: ='PL BB Build'!D4 -> Consumer Products | H8: ='PL BB Build'!P4 -> Unquoted | I8: ='PL BB Build'!#REF! -> #REF! | J8: ='PL BB Build'!H4 -> 0 | K8: ='PL BB Build'!#REF! -> #REF! | L8: =M8-K8 -> #REF! | M8: ='PL BB Build'!#REF! -> #REF! | N8: ='PL BB Build'!AM4 -> 0 | O8: =SUM(M8:N8) -> #REF! | P8: ='PL BB Build'!#REF! -> #REF! | Q8: =IFERROR(O8*P8,0) -> 0 | R8: ='PL BB Build'!#REF!+'PL BB Build'!AO4+'PL BB Build'!AP4 -> #REF! | S8: =SUM(Q8:R8) -> #REF!
D9: ='PL BB Build'!A5 -> EDS Buyer LLC | E9: ='PL BB Build'!#REF! -> #REF! | F9: ='PL BB Build'!F5 -> 47128 | G9: ='PL BB Build'!D5 -> Aerospace & Defense | H9: ='PL BB Build'!P5 -> Unquoted | I9: ='PL BB Build'!#REF! -> #REF! | J9: ='PL BB Build'!H5 -> 3450173.2 | K9: ='PL BB Build'!#REF! -> #REF! | L9: =M9-K9 -> #REF! | M9: ='PL BB Build'!#REF! -> #REF! | N9: ='PL BB Build'!AM5 -> 0 | O9: =SUM(M9:N9) -> #REF! | P9: ='PL BB Build'!#REF! -> #REF! | Q9: =IFERROR(O9*P9,0) -> 0 | R9: ='PL BB Build'!#REF!+'PL BB Build'!AO5+'PL BB Build'!AP5 -> #REF! | S9: =SUM(Q9:R9) -> #REF!
D10: ='PL BB Build'!A6 -> EDS Buyer LLC DDTL | E10: ='PL BB Build'!#REF! -> #REF! | F10: ='PL BB Build'!F6 -> 47128 | G10: ='PL BB Build'!D6 -> Aerospace & Defense | H10: ='PL BB Build'!P6 -> Unquoted | I10: ='PL BB Build'!#REF! -> #REF! | J10: ='PL BB Build'!H6 -> 0 | K10: ='PL BB Build'!#REF! -> #REF! | L10: =M10-K10 -> #REF! | M10: ='PL BB Build'!#REF! -> #REF! | N10: ='PL BB Build'!AM6 -> 0 | O10: =SUM(M10:N10) -> #REF! | P10: ='PL BB Build'!#REF! -> #REF! | Q10: =IFERROR(O10*P10,0) -> 0 | R10: ='PL BB Build'!#REF!+'PL BB Build'!AO6+'PL BB Build'!AP6 -> #REF! | S10: =SUM(Q10:R10) -> #REF!
D11: ='PL BB Build'!A7 -> EDS Buyer LLC Revolver | E11: ='PL BB Build'!#REF! -> #REF! | F11: ='PL BB Build'!F7 -> 47128 | G11: ='PL BB Build'!D7 -> Aerospace & Defense | H11: ='PL BB Build'!P7 -> Unquoted | I11: ='PL BB Build'!#REF! -> #REF! | J11: ='PL BB Build'!H7 -> 0 | K11: ='PL BB Build'!#REF! -> #REF! | L11: =M11-K11 -> #REF! | M11: ='PL BB Build'!#REF! -> #REF! | N11: ='PL BB Build'!AM7 -> 0 | O11: =SUM(M11:N11) -> #REF! | P11: ='PL BB Build'!#REF! -> #REF! | Q11: =IFERROR(O11*P11,0) -> 0 | R11: ='PL BB Build'!#REF!+'PL BB Build'!AO7+'PL BB Build'!AP7 -> #REF! | S11: =SUM(Q11:R11) -> #REF!
D12: ='PL BB Build'!A8 -> Infinity Home Services | E12: ='PL BB Build'!#REF! -> #REF! | F12: ='PL BB Build'!F8 -> 47115 | G12: ='PL BB Build'!D8 -> Personal, Food & Miscellaneous Services | H12: ='PL BB Build'!P8 -> Unquoted | I12: ='PL BB Build'!#REF! -> #REF! | J12: ='PL BB Build'!H8 -> 4905656.9 | K12: ='PL BB Build'!#REF! -> #REF! | L12: =M12-K12 -> #REF! | M12: ='PL BB Build'!#REF! -> #REF! | N12: ='PL BB Build'!AM8 -> 0 | O12: =SUM(M12:N12) -> #REF! | P12: ='PL BB Build'!#REF! -> #REF! | Q12: =IFERROR(O12*P12,0) -> 0 | R12: ='PL BB Build'!#REF!+'PL BB Build'!AO8+'PL BB Build'!AP8 -> #REF! | S12: =SUM(Q12:R12) -> #REF!
D13: ='PL BB Build'!A9 -> Infinity Home Services DDTL | E13: ='PL BB Build'!#REF! -> #REF! | F13: ='PL BB Build'!F9 -> 47115 | G13: ='PL BB Build'!D9 -> Personal, Food & Miscellaneous Services | H13: ='PL BB Build'!P9 -> Unquoted | I13: ='PL BB Build'!#REF! -> #REF! | J13: ='PL BB Build'!H9 -> 873684.21 | K13: ='PL BB Build'!#REF! -> #REF! | L13: =M13-K13 -> #REF! | M13: ='PL BB Build'!#REF! -> #REF! | N13: ='PL BB Build'!AM9 -> 0 | O13: =SUM(M13:N13) -> #REF! | P13: ='PL BB Build'!#REF! -> #REF! | Q13: =IFERROR(O13*P13,0) -> 0 | R13: ='PL BB Build'!#REF!+'PL BB Build'!AO9+'PL BB Build'!AP9 -> #REF! | S13: =SUM(Q13:R13) -> #REF!
D14: ='PL BB Build'!A10 -> Infinity Home Services Revolver | E14: ='PL BB Build'!#REF! -> #REF! | F14: ='PL BB Build'!F10 -> 47115 | G14: ='PL BB Build'!D10 -> Personal, Food & Miscellaneous Services | H14: ='PL BB Build'!P10 -> Unquoted | I14: ='PL BB Build'!#REF! -> #REF! | J14: ='PL BB Build'!H10 -> 78947.37 | K14: ='PL BB Build'!#REF! -> #REF! | L14: =M14-K14 -> #REF! | M14: ='PL BB Build'!#REF! -> #REF! | N14: ='PL BB Build'!AM10 -> 0 | O14: =SUM(M14:N14) -> #REF! | P14: ='PL BB Build'!#REF! -> #REF! | Q14: =IFERROR(O14*P14,0) -> 0 | R14: ='PL BB Build'!#REF!+'PL BB Build'!AO10+'PL BB Build'!AP10 -> #REF! | S14: =SUM(Q14:R14) -> #REF!
D15: ='PL BB Build'!A11 -> Ardurra | E15: ='PL BB Build'!#REF! -> #REF! | F15: ='PL BB Build'!F11 -> 47149 | G15: ='PL BB Build'!D11 -> Environmental Services | H15: ='PL BB Build'!P11 -> Unquoted | I15: ='PL BB Build'!#REF! -> #REF! | J15: ='PL BB Build'!H11 -> 1961407.9 | K15: ='PL BB Build'!#REF! -> #REF! | L15: =M15-K15 -> #REF! | M15: ='PL BB Build'!#REF! -> #REF! | N15: ='PL BB Build'!AM11 -> 0 | O15: =SUM(M15:N15) -> #REF! | P15: ='PL BB Build'!#REF! -> #REF! | Q15: =IFERROR(O15*P15,0) -> 0 | R15: ='PL BB Build'!#REF!+'PL BB Build'!AO11+'PL BB Build'!AP11 -> #REF! | S15: =SUM(Q15:R15) -> #REF!
D16: ='PL BB Build'!A12 -> Ardurra DDTL | E16: ='PL BB Build'!#REF! -> #REF! | F16: ='PL BB Build'!F12 -> 47149 | G16: ='PL BB Build'!D12 -> Environmental Services | H16: ='PL BB Build'!P12 -> Unquoted | I16: ='PL BB Build'!#REF! -> #REF! | J16: ='PL BB Build'!H12 -> 0 | K16: ='PL BB Build'!#REF! -> #REF! | L16: =M16-K16 -> #REF! | M16: ='PL BB Build'!#REF! -> #REF! | N16: ='PL BB Build'!AM12 -> 0 | O16: =SUM(M16:N16) -> #REF! | P16: ='PL BB Build'!#REF! -> #REF! | Q16: =IFERROR(O16*P16,0) -> 0 | R16: ='PL BB Build'!#REF!+'PL BB Build'!AO12+'PL BB Build'!AP12 -> #REF! | S16: =SUM(Q16:R16) -> #REF!
D17: ='PL BB Build'!A13 -> Ardurra Revolver | E17: ='PL BB Build'!#REF! -> #REF! | F17: ='PL BB Build'!F13 -> 47149 | G17: ='PL BB Build'!D13 -> Environmental Services | H17: ='PL BB Build'!P13 -> Unquoted | I17: ='PL BB Build'!#REF! -> #REF! | J17: ='PL BB Build'!H13 -> 0 | K17: ='PL BB Build'!#REF! -> #REF! | L17: =M17-K17 -> #REF! | M17: ='PL BB Build'!#REF! -> #REF! | N17: ='PL BB Build'!AM13 -> 0 | O17: =SUM(M17:N17) -> #REF! | P17: ='PL BB Build'!#REF! -> #REF! | Q17: =IFERROR(O17*P17,0) -> 0 | R17: ='PL BB Build'!#REF!+'PL BB Build'!AO13+'PL BB Build'!AP13 -> #REF! | S17: =SUM(Q17:R17) -> #REF!
... D29: ='PL BB Build'!A25 -> Simplicity Group DDTL | E29: ='PL BB Build'!#REF! -> #REF! | F29: ='PL BB Build'!F25 -> 46358 | G29: ='PL BB Build'!D25 -> Financial Services | H29: ='PL BB Build'!P25 -> Unquoted | I29: ='PL BB Build'!#REF! -> #REF! | J29: ='PL BB Build'!H25 -> 0 | K29: ='PL BB Build'!#REF! -> #REF! | L29: =M29-K29 -> #REF! | M29: ='PL BB Build'!#REF! -> #REF! | N29: ='PL BB Build'!AM25 -> 0 | O29: =SUM(M29:N29) -> #REF! | P29: ='PL BB Build'!#REF! -> #REF! | Q29: =IFERROR(O29*P29,0) -> 0 | R29: ='PL BB Build'!#REF!+'PL BB Build'!AO25+'PL BB Build'!AP25 -> #REF! | S29: =SUM(Q29:R29) -> #REF!
D30: ='PL BB Build'!#REF! -> #REF! | E30: ='PL BB Build'!#REF! -> #REF! | F30: ='PL BB Build'!#REF! -> #REF! | G30: ='PL BB Build'!#REF! -> #REF! | H30: ='PL BB Build'!#REF! -> #REF! | I30: ='PL BB Build'!#REF! -> #REF! | J30: ='PL BB Build'!#REF! -> #REF! | K30: ='PL BB Build'!#REF! -> #REF! | L30: =M30-K30 -> #REF! | M30: ='PL BB Build'!#REF! -> #REF! | N30: ='PL BB Build'!#REF! -> #REF! | O30: =SUM(M30:N30) -> #REF! | P30: ='PL BB Build'!#REF! -> #REF! | Q30: =IFERROR(O30*P30,0) -> 0 | R30: ='PL BB Build'!#REF!+'PL BB Build'!#REF!+'PL BB Build'!#REF! -> #REF! | S30: =SUM(Q30:R30) -> #REF!
D31: ='PL BB Build'!#REF! -> #REF! | E31: ='PL BB Build'!#REF! -> #REF! | F31: ='PL BB Build'!#REF! -> #REF! | G31: ='PL BB Build'!#REF! -> #REF! | H31: ='PL BB Build'!#REF! -> #REF! | I31: ='PL BB Build'!#REF! -> #REF! | J31: ='PL BB Build'!#REF! -> #REF! | K31: ='PL BB Build'!#REF! -> #REF! | L31: =M31-K31 -> #REF! | M31: ='PL BB Build'!#REF! -> #REF! | N31: ='PL BB Build'!#REF! -> #REF! | O31: =SUM(M31:N31) -> #REF! | P31: ='PL BB Build'!#REF! -> #REF! | Q31: =IFERROR(O31*P31,0) -> 0 | R31: ='PL BB Build'!#REF!+'PL BB Build'!#REF!+'PL BB Build'!#REF! -> #REF! | S31: =SUM(Q31:R31) -> #REF!
D33: ='PL BB Build'!A27 -> Cash | E33: ='PL BB Build'!#REF! -> #REF! | G33: ='PL BB Build'!D27 -> Cash | H33: ='PL BB Build'!P27 -> Quoted | I33: ='PL BB Build'!#REF! -> #REF! | J33: ='PL BB Build'!H27 -> 4456822.2 | K33: ='PL BB Build'!#REF! -> #REF! | L33: =M33-K33 -> #REF! | M33: ='PL BB Build'!#REF! -> #REF! | N33: ='PL BB Build'!AM27 -> 0 | O33: =SUM(M33:N33) -> #REF! | P33: ='PL BB Build'!#REF! -> #REF! | Q33: =IFERROR(O33*P33,0) -> 0 | R33: ='PL BB Build'!#REF!+'PL BB Build'!AO27+'PL BB Build'!AP27 -> #REF! | S33: =SUM(Q33:R33) -> #REF!
C34: Total | J34: =SUM(J6:J33) -> #REF! | K34: =SUM(K6:K33) -> #REF! | L34: =SUM(L6:L33) -> #REF! | M34: =SUM(M6:M33) -> #REF! | N34: =SUM(N6:N33) -> #REF! | O34: =SUM(O6:O33) -> #REF! | Q34: =SUM(Q6:Q33) -> 0 | R34: =SUM(R6:R33) -> #REF! | S34: =SUM(S6:S33) -> #REF!
J37: =J34='PL BB Build'!#REF! -> #REF! | K37: =K34='PL BB Build'!#REF! -> #REF! | M37: =M34='PL BB Build'!#REF! -> #REF! | O37: =O34='PL BB Build'!#REF! -> #REF! | Q37: =Q34='PL BB Build'!#REF! -> #REF! | R37: =R34='PL BB Build'!#REF!+'PL BB Build'!#REF! -> #REF! | S37: =S34='PL BB Build'!#REF! -> #REF!

Sheet PL_BB_Results_Concentrations
A1: Concentration Tests | B1: Concentration Limit
A2: Min. Eligible Issuers (#) | B2: 8
A3: 8 or 9 Issuers?
A4: Max. Issuer Concentration (% BB) | B4: 0.1
A5: Max. Industry Concentration (Largest Industry, % BB) | B5: 0.25
A6: Max. Industry Concentration (2nd Largest Industry, % BB) | B6: 0.2
A7: Max. Industry Concentration (All Other Industries, % BB) | B7: 0.15
A8: Max. Weighted Average Maturity (Years) | B8: 6.5
A9: Max. Contribution to BB with Maturity > 8 years | B9: 0.15
A10: Max. Weighted Average Leverage thru Borrower | B10: 5
A11: Max. PIK, DIP | B11: 0.15
A12: Min. Cash, First Lien, and Cov-Lite | B12: 0.25
A13: Min. Senior Secured | B13: 0.8
A14: Min. Weighted Average Cash Fixed Coupon | B14: 0.08
A15: Min. Weighted Average Cash Floating Coupon | B15: 0.045
... A21: Max. Preferred Stock | B21: 0.05

Sheet PL_BB_Results_Security
A1: Security
A2: Cash
A3: First Lien
A4: Last Out
A5: Second Lien
A6: High Yield
A7: Mezzanine
A8: Cov-Lite
A9: PIK
A10: DIP
A11: Warehouse First Lien
A12: Equity

Sheet Obligors' Net Capital
A1: Obligors' Net Capital | B1: Values
A2: Equity Paid in Capital | B2: ='[12]Subscription BB'!I69 -> 0
A3: Distributions | B3: 0
A4: Retained Earnings | B4: 0
A5: (a) Partners' Capital | B5: =SUM(B2:B4) -> 0
A7: (b) Uncalled Capital Commitments (excl. Defaulting Investors) | B7: =IF([12]Availability!D11="Yes",'[12]Subscription BB'!J69,0) -> 0
A9: Obligors' Net Capital ((a) + (b)) | B9: =SUM(B5:B7) -> 0
A11: Debt / Equity | B11: 0

Sheet PL BB Results
A1: Concentration Tests | D1: Concentration Limit
A2: Min. Eligible Issuers (#) | D2: 8
A3: 8 or 9 Issuers?
A4: Max. Issuer Concentration (% BB) | D4: 0.1
A5: Max. Industry Concentration (Largest Industry, % BB) | D5: 0.25
A6: Max. Industry Concentration (2nd Largest Industry, % BB) | D6: 0.2
A7: Max. Industry Concentration (All Other Industries, % BB) | D7: 0.15
A8: Max. Weighted Average Maturity (Years) | D8: 6.5
A9: Max. Contribution to BB with Maturity > 8 years | D9: 0.15
A10: Max. Weighted Average Leverage thru Borrower | D10: 5
A11: Max. PIK, DIP | D11: 0.15
A12: Min. Cash, First Lien, and Cov-Lite | D12: 0.25
A13: Min. Senior Secured | D13: 0.8
A14: Min. Weighted Average Cash Fixed Coupon | D14: 0.08
A15: Min. Weighted Average Cash Floating Coupon | D15: 0.045
... A21: Max. Preferred Stock | D21: 0.05

Sheet PL BB FMV Rollforward
C3: =TEXT(#REF!,0)&" - Portfolio Leverage Borrowing Base Rollforward - "&TEXT(#REF!,"mm/dd/yyyy") -> #REF!
F5: FMV | G5: Net PIK | I5: Fee income | J5: OID | K5: Additions | M5: Valuation adjust | N5: FMV | O5: Adjustment to | Q5: Ineligible | R5: Eligible
D6: Company | E6: Security | F6: =N6-31 -> #REF! | G6: Income | H6: Paydown | I6: Activity | J6: Reversal | K6: (Uses) | L6: Amortization | M6: to GAAP FV | N6: =#REF! -> #REF! | O6: BB "Value" | P6: "Value" | Q6: Investments | R6: Investments | U6: Check
C7: 1 | D7: ='PL BB Build'!A2 -> A1 Garage Merger Sub, LLC First Lien | E7: =+'PL BB Build'!C2 -> First Lien | F7: 4912687.5 | N7: =SUM(F7:M7) -> 4912687.5 | O7: =P7-N7 -> #REF! | P7: =+'PL BB Build'!#REF! -> #REF! | Q7: =+'PL BB Output'!L6 -> #REF! | R7: =+P7+Q7 -> #REF! | U7: =+N7-'PL BB Build'!#REF! -> #REF!
C8: =C7+1 -> 2 | D8: ='PL BB Build'!A3 -> A1 Garage Merger Sub, LLC DDTL | E8: =+'PL BB Build'!C3 -> First Lien | F8: 800426.83 | N8: =SUM(F8:M8) -> 800426.83 | O8: =P8-N8 -> #REF! | P8: =+'PL BB Build'!#REF! -> #REF! | Q8: =+'PL BB Output'!L7 -> #REF! | R8: =+P8+Q8 -> #REF! | U8: =+N8-'PL BB Build'!#REF! -> #REF!
C9: =C8+1 -> 3 | D9: ='PL BB Build'!A4 -> A1 Garage Merger Sub, LLC Revolver | E9: =+'PL BB Build'!C4 -> First Lien | F9: -18987.34 | N9: =SUM(F9:M9) -> -18987.34 | O9: =P9-N9 -> #REF! | P9: =+'PL BB Build'!#REF! -> #REF! | Q9: =+'PL BB Output'!L8 -> #REF! | R9: =+P9+Q9 -> #REF! | U9: =+N9-'PL BB Build'!#REF! -> #REF!
C10: =C9+1 -> 4 | D10: ='PL BB Build'!A5 -> EDS Buyer LLC | E10: =+'PL BB Build'!C5 -> Warehouse First Lien | F10: 3412500 | N10: =SUM(F10:M10) -> 3412500 | O10: =P10-N10 -> #REF! | P10: =+'PL BB Build'!#REF! -> #REF! | Q10: =+'PL BB Output'!L9 -> #REF! | R10: =+P10+Q10 -> #REF! | U10: =+N10-'PL BB Build'!#REF! -> #REF!
C11: =C10+1 -> 5 | D11: ='PL BB Build'!A6 -> EDS Buyer LLC DDTL | E11: =+'PL BB Build'!C6 -> Warehouse First Lien | F11: -65625 | N11: =SUM(F11:M11) -> -65625 | O11: =P11-N11 -> #REF! | P11: =+'PL BB Build'!#REF! -> #REF! | Q11: =+'PL BB Output'!L10 -> #REF! | R11: =+P11+Q11 -> #REF! | U11: =+N11-'PL BB Build'!#REF! -> #REF!
C12: =C11+1 -> 6 | D12: ='PL BB Build'!A7 -> EDS Buyer LLC Revolver | E12: =+'PL BB Build'!C7 -> Warehouse First Lien | F12: -19687.5 | N12: =SUM(F12:M12) -> -19687.5 | O12: =P12-N12 -> #REF! | P12: =+'PL BB Build'!#REF! -> #REF! | Q12: =+'PL BB Output'!L11 -> #REF! | R12: =+P12+Q12 -> #REF! | U12: =+N12-'PL BB Build'!#REF! -> #REF!
C13: =C12+1 -> 7 | D13: ='PL BB Build'!A8 -> Infinity Home Services | E13: =+'PL BB Build'!C8 -> First Lien | F13: 4899999 | N13: =SUM(F13:M13) -> 4899999 | O13: =P13-N13 -> #REF! | P13: =+'PL BB Build'!#REF! -> #REF! | Q13: =+'PL BB Output'!L12 -> #REF! | R13: =+P13+Q13 -> #REF! | U13: =+N13-'PL BB Build'!#REF! -> #REF!
C14: =C13+1 -> 8 | D14: ='PL BB Build'!A9 -> Infinity Home Services DDTL | E14: =+'PL BB Build'!C9 -> First Lien | F14: 368421 | K14: 452631 | N14: =SUM(F14:M14) -> 821052 | O14: =P14-N14 -> #REF! | P14: =+'PL BB Build'!#REF! -> #REF! | Q14: =+'PL BB Output'!L13 -> #REF! | R14: =+P14+Q14 -> #REF! | U14: =+N14-'PL BB Build'!#REF! -> #REF!
C15: =C14+1 -> 9 | D15: ='PL BB Build'!A10 -> Infinity Home Services Revolver | E15: =+'PL BB Build'!C10 -> First Lien | F15: 57894.91 | N15: =SUM(F15:M15) -> 57894.91 | O15: =P15-N15 -> #REF! | P15: =+'PL BB Build'!#REF! -> #REF! | Q15: =+'PL BB Output'!L14 -> #REF! | R15: =+P15+Q15 -> #REF! | U15: =+N15-'PL BB Build'!#REF! -> #REF!
C16: =C15+1 -> 10 | D16: ='PL BB Build'!A11 -> Ardurra | E16: =+'PL BB Build'!C11 -> First Lien | F16: 1960007 | N16: =SUM(F16:M16) -> 1960007 | O16: =P16-N16 -> #REF! | P16: =+'PL BB Build'!#REF! -> #REF! | Q16: =+'PL BB Output'!L15 -> #REF! | R16: =+P16+Q16 -> #REF! | U16: =+N16-'PL BB Build'!#REF! -> #REF!
C17: =C16+1 -> 11 | D17: ='PL BB Build'!A12 -> Ardurra DDTL | E17: =+'PL BB Build'!C12 -> First Lien | F17: -43470.73 | N17: =SUM(F17:M17) -> -43470.73 | O17: =P17-N17 -> #REF! | P17: =+'PL BB Build'!#REF! -> #REF! | Q17: =+'PL BB Output'!L16 -> #REF! | R17: =+P17+Q17 -> #REF! | U17: =+N17-'PL BB Build'!#REF! -> #REF!
C18: =C17+1 -> 12 | D18: ='PL BB Build'!A13 -> Ardurra Revolver | E18: =+'PL BB Build'!C13 -> First Lien | F18: -17388.29 | N18: =SUM(F18:M18) -> -17388.29 | O18: =P18-N18 -> #REF! | P18: =+'PL BB Build'!#REF! -> #REF! | Q18: =+'PL BB Output'!L17 -> #REF! | R18: =+P18+Q18 -> #REF! | U18: =+N18-'PL BB Build'!#REF! -> #REF!
C19: =C18+1 -> 13 | D19: ='PL BB Build'!A14 -> BioDerm First Lien | E19: =+'PL BB Build'!C14 -> First Lien | F19: 2955000 | N19: =SUM(F19:M19) -> 2955000 | O19: =P19-N19 -> #REF! | P19: =+'PL BB Build'!#REF! -> #REF! | Q19: =+'PL BB Output'!L18 -> #REF! | R19: =+P19+Q19 -> #REF! | U19: =+N19-'PL BB Build'!#REF! -> #REF!
C20: =C19+1 -> 14 | D20: ='PL BB Build'!A15 -> BioDerm Revolver | E20: =+'PL BB Build'!C15 -> First Lien | F20: -5357.14 | N20: =SUM(F20:M20) -> -5357.14 | O20: =P20-N20 -> #REF! | P20: =+'PL BB Build'!#REF! -> #REF! | Q20: =+'PL BB Output'!L19 -> #REF! | R20: =+P20+Q20 -> #REF! | U20: =+N20-'PL BB Build'!#REF! -> #REF!
C21: =C20+1 -> 15 | D21: ='PL BB Build'!A16 -> ECL Entertainment | E21: =+'PL BB Build'!C16 -> First Lien | F21: 3467205 | H21: -8800 | N21: =SUM(F21:M21) -> 3458405 | O21: =P21-N21 -> #REF! | P21: =+'PL BB Build'!#REF! -> #REF! | Q21: =+'PL BB Output'!L20 -> #REF! | R21: =+P21+Q21 -> #REF! | U21: =+N21-'PL BB Build'!#REF! -> #REF!
C22: =C21+1 -> 16 | D22: ='PL BB Build'!A17 -> Urology Management Holdings DDTL | E22: =+'PL BB Build'!C17 -> First Lien | F22: -33222.08 | N22: =SUM(F22:M22) -> -33222.08 | O22: =P22-N22 -> #REF! | P22: =+'PL BB Build'!#REF! -> #REF! | Q22: =+'PL BB Output'!L21 -> #REF! | R22: =+P22+Q22 -> #REF! | U22: =+N22-'PL BB Build'!#REF! -> #REF!
C23: =C22+1 -> 17 | D23: ='PL BB Build'!A18 -> Urology Management Holdings | E23: =+'PL BB Build'!C18 -> First Lien | F23: 1612791.5 | N23: =SUM(F23:M23) -> 1612791.5 | O23: =P23-N23 -> #REF! | P23: =+'PL BB Build'!#REF! -> #REF! | Q23: =+'PL BB Output'!L22 -> #REF! | R23: =+P23+Q23 -> #REF! | U23: =+N23-'PL BB Build'!#REF! -> #REF!
C24: =C23+1 -> 18 | D24: ='PL BB Build'!A19 -> Five Star Buyer | E24: =+'PL BB Build'!C19 -> First Lien | F24: 2939999.5 | N24: =SUM(F24:M24) -> 2939999.5 | O24: =P24-N24 -> #REF! | P24: =+'PL BB Build'!#REF! -> #REF! | Q24: =+'PL BB Output'!L23 -> #REF! | R24: =+P24+Q24 -> #REF! | U24: =+N24-'PL BB Build'!#REF! -> #REF!
C25: =C24+1 -> 19 | D25: ='PL BB Build'!A20 -> Five Star Buyer DDTL | E25: =+'PL BB Build'!C20 -> First Lien | F25: -14571.55 | N25: =SUM(F25:M25) -> -14571.55 | O25: =P25-N25 -> #REF! | P25: =+'PL BB Build'!#REF! -> #REF! | Q25: =+'PL BB Output'!L24 -> #REF! | R25: =+P25+Q25 -> #REF! | U25: =+N25-'PL BB Build'!#REF! -> #REF!
C26: =C25+1 -> 20 | D26: ='PL BB Build'!A21 -> Five Star Buyer Revolver | E26: =+'PL BB Build'!C21 -> First Lien | F26: -6857.2 | N26: =SUM(F26:M26) -> -6857.2 | O26: =P26-N26 -> #REF! | P26: =+'PL BB Build'!#REF! -> #REF! | Q26: =+'PL BB Output'!L25 -> #REF! | R26: =+P26+Q26 -> #REF! | U26: =+N26-'PL BB Build'!#REF! -> #REF!
C27: =C26+1 -> 21 | D27: ='PL BB Build'!A22 -> Anteriad (FKA MeritDirect) | E27: =+'PL BB Build'!C22 -> First Lien | F27: 2939999.8 | N27: =SUM(F27:M27) -> 2939999.8 | O27: =P27-N27 -> #REF! | P27: =+'PL BB Build'!#REF! -> #REF! | Q27: =+'PL BB Output'!L26 -> #REF! | R27: =+P27+Q27 -> #REF! | U27: =+N27-'PL BB Build'!#REF! -> #REF!
C28: =C27+1 -> 22 | D28: ='PL BB Build'!A23 -> Beta Plus Technologies, Inc. | E28: =+'PL BB Build'!C23 -> First Lien | F28: N.A | N28: =SUM(F28:M28) -> 0 | O28: =P28-N28 -> #REF! | P28: =+'PL BB Build'!#REF! -> #REF! | Q28: =+'PL BB Output'!L27 -> #REF! | R28: =+P28+Q28 -> #REF! | U28: =+N28-'PL BB Build'!#REF! -> #REF!
C29: =C28+1 -> 23 | D29: ='PL BB Build'!A24 -> Simplicity Group First Lien | E29: =+'PL BB Build'!C24 -> First Lien | F29: N.A | N29: =SUM(F29:M29) -> 0 | O29: =P29-N29 -> #REF! | P29: =+'PL BB Build'!#REF! -> #REF! | Q29: =+'PL BB Output'!L28 -> #REF! | R29: =+P29+Q29 -> #REF! | U29: =+N29-'PL BB Build'!#REF! -> #REF!
C30: =C29+1 -> 24 | D30: ='PL BB Build'!A25 -> Simplicity Group DDTL | E30: =+'PL BB Build'!C25 -> First Lien | F30: N.A | N30: =SUM(F30:M30) -> 0 | O30: =P30-N30 -> #REF! | P30: =+'PL BB Build'!#REF! -> #REF! | Q30: =+'PL BB Output'!L29 -> #REF! | R30: =+P30+Q30 -> #REF! | U30: =+N30-'PL BB Build'!#REF! -> #REF!
C31: =C30+1 -> 25 | D31: ='PL BB Build'!#REF! -> #REF! | E31: =+'PL BB Build'!#REF! -> #REF! | F31: N.A | N31: =SUM(F31:M31) -> 0 | O31: =P31-N31 -> #REF! | P31: =+'PL BB Build'!#REF! -> #REF! | Q31: =+'PL BB Output'!L30 -> #REF! | R31: =+P31+Q31 -> #REF! | U31: =+N31-'PL BB Build'!#REF! -> #REF!
C32: =C31+1 -> 26 | D32: ='PL BB Build'!#REF! -> #REF! | E32: =+'PL BB Build'!#REF! -> #REF! | N32: =SUM(F32:M32) -> 0 | O32: =P32-N32 -> #REF! | P32: =+'PL BB Build'!#REF! -> #REF! | Q32: =+'PL BB Output'!L31 -> #REF! | R32: =+P32+Q32 -> #REF! | U32: =+N32-'PL BB Build'!#REF! -> #REF!
N33: =SUM(F33:M33) -> 0 | O33: =P33-N33 -> #REF! | P33: =+'PL BB Build'!#REF! -> #REF! | Q33: =+'PL BB Output'!L33 -> #REF! | R33: =+P33+Q33 -> #REF! | U33: =+N33-'PL BB Build'!#REF! -> #REF!
D37: Cash | E37: =D37 -> Cash | F37: 14957540 | N37: =SUM(F37:M37) -> 14957540 | O37: =+N37-P37 -> #REF! | P37: =+'PL BB Build'!#REF! -> #REF! | R37: =+P37+Q37 -> #REF! | U37: =+N37-'PL BB Build'!#REF! -> #REF!
C38: Total | F38: =SUM(F7:F37) -> 45059305 | G38: =SUM(G7:G37) -> 0 | H38: =SUM(H7:H37) -> -8800 | I38: =SUM(I7:I37) -> 0 | J38: =SUM(J7:J37) -> 0 | K38: =SUM(K7:K37) -> 452631 | L38: =SUM(L7:L37) -> 0 | M38: =SUM(M7:M37) -> 0 | N38: =SUM(N7:N37) -> 45503136 | P38: =SUM(P7:P37) -> #REF! | Q38: =SUM(Q7:Q37) -> #REF! | R38: =SUM(R7:R37) -> #REF! | U38: =+N38-'PL BB Build'!#REF! -> #REF!
N41: =N38-'PL BB Build'!#REF! -> #REF!
F42: =SUM(F7:F35) -> 30101765 | N42: =+N38='PL BB Build'!#REF! -> #REF! | P42: =+P38='PL BB Build'!#REF! -> #REF! | R42: =+R38='PL BB Build'!#REF! -> #REF!
F43: 74174281
E44: Check | F44: =F42-F43 -> -44072515 | N44: =SUM(N7:N35) -> 30545596 | R44: =+R38-'PL BB Build'!#REF! -> #REF!

Sheet Inputs
C3: =TEXT(#REF!,0)&" - Borrowing Base Inputs" -> #REF!
C5: Pricing
C6: Subscription Pricing | D6: 0.0225
C8: Portfolio Leverage Pricing Step Down | D8: 0.0275
C9: Min. First Lien / Last Out Contribution to PL BB for Stepdown | D9: 0.65
C10: Portfolio Leverage Pricing Otherwise | D10: 0.03
C11: Min. First Lien / Last Out Contribution to PL BB for 65% Effective A/R | D11: 0.65
C12: Lower Effective A/R | D12: 0.5
C15: Subscription Borrowing Base
C17: Advance Rates
C18: Investor Type | D18: Advance Rate
C19: Institutional Investors | D19: 0.65
C20: HNW Investors | D20: 0.65
C21: Excluded | D21: 0
C23: Concentration Limits
C25: Institutional Investors | D25: Rank | E25: Concentration Limit
C26: Institutional Investors Investors | E26: 0.2
C29: HNW Investors | E29: Concentration Limit
C30: HNW Investors Individual | E30: 0.05
C31: HNW Investors Aggregate | E31: 0.2
C36: Portfolio Leverage Borrowing Base
C38: Advance Rates
C39: Investment Type | D39: Unquoted | E39: Quoted
C40: Cash | D40: n/a | E40: 1
C41: Cash Equivalent | D41: n/a | E41: 1
C42: LT US Debt | D42: n/a | E42: 0.85
C43: First Lien | D43: 0.65 | E43: 0.75
C44: Warehouse First Lien | D44: 0.7 | E44: 0.75
C45: Last Out | D45: 0.55 | E45: 0.65
C46: Second Lien | D46: 0.5 | E46: 0.6
C47: High Yield | D47: 0.45 | E47: 0.55
C48: Mezzanine | D48: 0.4 | E48: 0.5
C49: Cov-Lite | D49: 0.4 | E49: 0.5
C50: PIK | D50: 0.35 | E50: 0.4
C51: Preferred Stock | D51: 0.2 | E51: 0.3
C52: Equity | D52: 0 | E52: 0
C54: Investment Types
C55: Quoted / Unquoted
C56: Quoted
C57: Unquoted
...

Sheet Pricing
A1: Pricing | B1: percent
A2: Subscription Pricing | B2: 0.0225
A4: Portfolio Leverage Pricing Step Down | B4: 0.0275
A5: Min. First Lien / Last Out Contribution to PL BB for Stepdown | B5: 0.65
A6: Portfolio Leverage Pricing Otherwise | B6: 0.03
A7: Min. First Lien / Last Out Contribution to PL BB for 65% Effective A/R | B7: 0.65
A8: Lower Effective A/R | B8: 0.5

Sheet Advance Rates
A1: Investor Type | B1: Advance Rate
A2: Institutional Investors | B2: 0.65
A3: HNW Investors | B3: 0.65
A4: Excluded | B4: 0

Sheet Portfolio LeverageBorrowingBase
A1: Investment Type | B1: Unquoted | C1: Quoted
A2: Cash | B2: n/a | C2: 1
A3: Cash Equivalent | B3: n/a | C3: 1
A4: LT US Debt | B4: n/a | C4: 0.85
A5: First Lien | B5: 0.65 | C5: 0.75
A6: Warehouse First Lien | B6: 0.7 | C6: 0.75
A7: Last Out | B7: 0.55 | C7: 0.65
A8: Second Lien | B8: 0.5 | C8: 0.6
A9: High Yield | B9: 0.45 | C9: 0.55
A10: Mezzanine | B10: 0.4 | C10: 0.5
A11: Cov-Lite | B11: 0.4 | C11: 0.5
A12: PIK | B12: 0.35 | C12: 0.4
A13: Preferred Stock | B13: 0.2 | C13: 0.3
A14: Equity | B14: 0 | C14: 0

Sheet Concentration Limits
A1: Investors | B1: Rank | C1: Concentration Limit
A2: Institutional Investors Investors | C2: 0.2
A3: HNW Investors Individual | C3: 0.05
A4: HNW Investors Aggregate | C4: 0.2

Sheet Inputs Industries
A1: Industries
A2: Aerospace & Defense
A3: Auto Sector
A4: Beverage, Food & Tobacco
A5: Broadcasting & Entertainment
A6: Building Materials
A7: Buildings & Real Estate
A8: Business Services
A9: Cable Television
A10: Cargo Transport
A11: Chemicals, Plastics & Rubber
A12: Communications
... A53: Cash

Sheet Other Metrics
A1: Other Metrics | B1: values
A2: First Lien Leverage Cut-Off Point | B2: 4
A3: Warehouse First Lien Leverage Cut-Off | B3: 4.5
A4: Last Out Attachment Point | B4: 2.25
A5: 1 out of 2 Test
A6: Trailing 12-Month EBITDA | B6: 10
A7: Trailing 24-Month EBITDA | B7: 20
A8: Total Leverage | B8: 4.5
A9: LTV | B9: 0.65
A10: Concentration Test Threshold 1 | B10: 0.075
A11: Concentration Test Threshold 1 | B11: 0.1
A12: Threshold 1 Advance Rate | B12: 0.5
A13: Threshold 2 Advance Rate | B13: 0

Sheet MV and BV 4.30
A1: MVMinusBV | B1: Portfolio_Name | C1: Issuer_Name | D1: Asset_Name | E1: Position_ID | F1: Commitment | H1: BookValue | I1: BVPrice | J1: MarketValue | K1: MarkPrice_MarkPrice | L1: Asset_AssetDetail_Type | M1: MVParity | N1: CurrencyType_Identifier | O1: Quantity | P1: Asset_Primary IDAssetID_Name
A2: 0 | B2: PennantPark Credit Opportunities Fund IV Aggregator, LP | C2: A1 Garage Equity, LLC | D2: Common Equity | E2: 1373629 | F2: 1096519 | H2: 1096519 | I2: 1 | J2: 1096519 | K2: 1 | L2: 138 | M2: 1096519 | N2: USD | O2: 1096519 | P2: 1680
A3: 19021.67 | B3: PennantPark Credit Opportunities Fund IV Aggregator, LP | C3: A1 Garage Merger Sub, LLC | D3: First Lien | E3: 1373633 | F3: 4987500 | H3: 4893665.8 | I3: 98.118613 | J3: 4912687.5 | K3: 98.5 | L3: 4 | M3: 49126.875 | N3: USD | O3: 4987500 | P3: 1677
A4: -52183.138 | B4: PennantPark Credit Opportunities Fund IV Aggregator, LP | C4: A1 Garage Merger Sub, LLC | D4: First Lien - DDTL | E4: 1373636 | F4: 3478875.9 | H4: 852609.97 | I4: 100 | J4: 800426.83 | K4: 98.5 | L4: 4 | M4: 8004.2683 | N4: USD | O4: 3478875.9 | P4: 1678
A5: -18987.342 | B5: PennantPark Credit Opportunities Fund IV Aggregator, LP | C5: A1 Garage Merger Sub, LLC | D5: First Lien - Revolver | E5: 1373639 | F5: 1265822.8 | H5: 0 | I5: 100 | J5: -18987.342 | K5: 98.5 | L5: 4 | M5: -189.87342 | N5: USD | O5: 1265822.8 | P5: 1679
A6: -4439.2977 | B6: PennantPark Credit Opportunities Fund IV Aggregator, LP | C6: Anteriad (f/k/a MeritDirect, LLC) | D6: First Lien - Term Loan - Incremental | E6: 1373850 | F6: 3000000 | H6: 2944439.1 | I6: 98.147971 | J6: 2939999.8 | K6: 97.999995 | L6: 4 | M6: 29399.998 | N6: USD | O6: 3000000 | P6: 1739
A7: -3316.2061 | B7: PennantPark Credit Opportunities Fund IV Aggregator, LP | C7: Beta Plus Technologies, Inc. | D7: First Lien | E7: 1373864 | F7: 2992481.2 | H7: 2636699.7 | I7: 88.110818 | J7: 2633383.5 | K7: 88 | L7: 4 | M7: 26333.835 | N7: USD | O7: 2992481.2 | P7: LX206113
A8: 0 | B8: PennantPark Credit Opportunities Fund IV Aggregator, LP | C8: BioDerm Holdings, LP | D8: Common Equity | E8: 1373741 | F8: 437000 | H8: 437000 | I8: 1000 | J8: 437000 | K8: 1000 | L8: 138 | M8: 437000 | N8: USD | O8: 437 | P8: 1703
A9: -9348.3023 | B9: PennantPark Credit Opportunities Fund IV Aggregator, LP | C9: BIODERM, INC. | D9: First Lien | E9: 1373748 | F9: 3000000 | H9: 2964348.3 | I9: 98.81161 | J9: 2955000 | K9: 98.5 | L9: 4 | M9: 29550 | N9: USD | O9: 3000000 | P9: 1701
A10: -5357.1429 | B10: PennantPark Credit Opportunities Fund IV Aggregator, LP | C10: BIODERM, INC. | D10: First Lien - Revolver | E10: 1373744 | F10: 357142.86 | H10: 0 | I10: 100 | J10: -5357.1429 | K10: 98.5 | L10: 4 | M10: -53.571429 | N10: USD | O10: 357142.86 | P10: 1702
A11: 612.5323 | B11: PennantPark Credit Opportunities Fund IV Aggregator, LP | C11: ECL Entertainment, LLC | D11: First Lien | E11: 1373763 | F11: 3491116.8 | H11: 3457792.5 | I11: 99.045455 | J11: 3458405 | K11: 99.063 | L11: 4 | M11: 34584.05 | N11: USD | O11: 3491116.8 | P11: LX193677
A12: -37673.165 | B12: PennantPark Credit Opportunities Fund IV Aggregator, LP | C12: EDS Buyer, LLC | D12: First Lien | E12: 1373662 | F12: 3500000 | H12: 3450173.2 | I12: 98.576376 | J12: 3412500 | K12: 97.5 | L12: 4 | M12: 34125 | N12: USD | O12: 3500000 | P12: 1686
A13: -65625 | B13: PennantPark Credit Opportunities Fund IV Aggregator, LP | C13: EDS Buyer, LLC | D13: First Lien - DDTL | E13: 1373665 | F13: 2625000 | H13: 0 | I13: 100 | J13: -65625 | K13: 97.5 | L13: 4 | M13: -656.25 | N13: USD | O13: 2625000 | P13: 1685
A14: -19687.5 | B14: PennantPark Credit Opportunities Fund IV Aggregator, LP | C14: EDS Buyer, LLC | D14: First Lien - Revolver | E14: 1373668 | F14: 787500 | H14: 0 | I14: 100 | J14: -19687.5 | K14: 97.5 | L14: 4 | M14: -196.875 | N14: USD | O14: 787500 | P14: 1684
A15: 0 | B15: PennantPark Credit Opportunities Fund IV Aggregator, LP | C15: EDS TOPCO, LP | D15: Common Equity | E15: 1373658 | F15: 437500 | H15: 437500 | I15: 1 | J15: 437500 | K15: 1 | L15: 138 | M15: 437500 | N15: USD | O15: 437500 | P15: 1687
A16: 0 | B16: PennantPark Credit Opportunities Fund IV Aggregator, LP | C16: Five Star Parent Holdings, LLC | D16: Common Equity | E16: 1373783 | F16: 488571.43 | H16: 488571.43 | I16: 1 | J16: 488571.43 | K16: 1 | L16: 138 | M16: 488571.43 | N16: USD | O16: 488571.43 | P16: 1724
A17: -2202.0404 | B17: PennantPark Credit Opportunities Fund IV Aggregator, LP | C17: Five Star Parks & Attractions, LLC | D17: First Lien | E17: 1373791 | F17: 3000000 | H17: 2942201.5 | I17: 98.073384 | J17: 2939999.5 | K17: 97.999983 | L17: 4 | M17: 29399.995 | N17: USD | O17: 3000000 | P17: 1721
A18: -14571.552 | B18: PennantPark Credit Opportunities Fund IV Aggregator, LP | C18: Five Star Parks & Attractions, LLC | D18: First Lien - DDTL B | E18: 1373787 | F18: 728571.43 | H18: 0 | I18: 100 | J18: -14571.552 | K18: 97.999983 | L18: 4 | M18: -145.71552 | N18: USD | O18: 728571.43 | P18: 1722
A19: -6857.2007 | B19: PennantPark Credit Opportunities Fund IV Aggregator, LP | C19: Five Star Parks & Attractions, LLC | D19: First Lien - Revolver | E19: 1373794 | F19: 342857.14 | H19: 0 | I19: 100 | J19: -6857.2007 | K19: 97.999983 | L19: 4 | M19: -68.572007 | N19: USD | O19: 342857.14 | P19: 1723
A20: 15315.176 | B20: PennantPark Credit Opportunities Fund IV Aggregator, LP | C20: Infinity Home Services Holdco, Inc. | D20: Common Equity | E20: 1373643 | F20: 992481.21 | H20: 992481.21 | I20: 1 | J20: 1007796.4 | K20: 1.0154312 | L20: 138 | M20: 1007796.4 | N20: USD | O20: 992481.21 | P20: 1692
A21: -5657.5193 | B21: PennantPark Credit Opportunities Fund IV Aggregator, LP | C21: Infinity Home Services Holdco, Inc. | D21: First Lien | E21: 1373653 | F21: 5000000 | H21: 4905656.9 | I21: 98.113139 | J21: 4899999.4 | K21: 97.999988 | L21: 4 | M21: 48999.994 | N21: USD | O21: 5000000 | P21: LX210065
A22: -52631.887 | B22: PennantPark Credit Opportunities Fund IV Aggregator, LP | C22: Infinity Home Services Holdco, Inc. | D22: First Lien - DDTL | E22: 1373649 | F22: 2631579 | H22: 873684.21 | I22: 100 | J22: 821052.32 | K22: 97.999988 | L22: 4 | M22: 8210.5232 | N22: USD | O22: 2631579 | P22: LX210066
A23: -21052.755 | B23: PennantPark Credit Opportunities Fund IV Aggregator, LP | C23: Infinity Home Services Holdco, Inc. | D23: First Lien - Revolver | E23: 1373646 | F23: 1052631.6 | H23: 78947.367 | I23: 100 | J23: 57894.612 | K23: 97.999988 | L23: 4 | M23: 578.94612 | N23: USD | O23: 1052631.6 | P23: LX210067
A24: 0 | B24: PennantPark Credit Opportunities Fund IV Aggregator, LP | C24: LEP PEQUOD HOLDINGS, LP | D24: Common Equity | E24: 1373884 | F24: 270270.27 | H24: 270270.27 | I24: 1 | J24: 270270.27 | K24: 1 | L24: 138 | M24: 270270.27 | N24: USD | O24: 270270.27 | P24: 1745
A25: -1400.9699 | B25: PennantPark Credit Opportunities Fund IV Aggregator, LP | C25: LJ Avalon Holdings, LLC | D25: First Lien | E25: 1373737 | F25: 2000000 | H25: 1961407.9 | I25: 98.070395 | J25: 1960006.9 | K25: 98.000347 | L25: 4 | M25: 19600.069 | N25: USD | O25: 2000000 | P25: LX210725
A26: -43470.728 | B26: PennantPark Credit Opportunities Fund IV Aggregator, LP | C26: LJ Avalon Holdings, LLC | D26: First Lien - DDTL | E26: 1373730 | F26: 2173913 | H26: 0 | I26: 100 | J26: -43470.728 | K26: 98.000347 | L26: 4 | M26: -434.70728 | N26: USD | O26: 2173913 | P26: 1697
A27: -17388.291 | B27: PennantPark Credit Opportunities Fund IV Aggregator, LP | C27: LJ Avalon Holdings, LLC | D27: First Lien - Revolver | E27: 1373733 | F27: 869565.22 | H27: 0 | I27: 100 | J27: -17388.291 | K27: 98.000347 | L27: 4 | M27: -173.88291 | N27: USD | O27: 869565.22 | P27: 1696
A28: 0 | B28: PennantPark Credit Opportunities Fund IV Aggregator, LP | C28: LJ Avalon, LP | D28: Common Equity | E28: 1373727 | F28: 1260869.6 | H28: 1260869.6 | I28: 1 | J28: 1260869.6 | K28: 1 | L28: 138 | M28: 1260869.6 | N28: USD | O28: 1260869.6 | P28: 1698
A29: -889639.64 | B29: PennantPark Credit Opportunities Fund IV Aggregator, LP | C29: Simplicity Group | D29: First Lien - DDTL - DDTL | E29: 1373878 | F29: 889639.64 | H29: 0 | I29: 100 | J29: -889639.64 | L29: 4 | M29: -8896.3964 | N29: USD | O29: 889639.64 | P29: 1744
A30: -236486.49 | B30: PennantPark Credit Opportunities Fund IV Aggregator, LP | C30: Simplicity Group | D30: First Lien - Revolver - Revolver | E30: 1373881 | F30: 236486.49 | H30: 0 | I30: 100 | J30: -236486.49 | L30: 4 | M30: -2364.8649 | N30: USD | O30: 236486.49 | P30: 1742
A31: -3532933.1 | B31: PennantPark Credit Opportunities Fund IV Aggregator, LP | C31: Simplicity Group | D31: First Lien - Term Loan - First Lien | E31: 1373875 | F31: 3603603.6 | H31: 3532933.1 | I31: 98.038893 | J31: 3531531.5 | L31: 4 | M31: 0 | N31: USD | O31: 3603603.6 | P31: 1743
A32: -18864.435 | B32: PennantPark Credit Opportunities Fund IV Aggregator, LP | C32: UROLOGY MANAGEMENT HOLDINGS, INC. | D32: First Lien | E32: 1373717 | F32: 1662500 | H32: 1631655.9 | I32: 98.144715 | J32: 1612791.5 | K32: 97.010013 | L32: 4 | M32: 16127.915 | N32: USD | O32: 1662500 | P32: LX210840
A33: -33222.082 | B33: PennantPark Credit Opportunities Fund IV Aggregator, LP | C33: UROLOGY MANAGEMENT HOLDINGS, INC. | D33: First Lien - DDTL | E33: 1373719 | F33: 1111111.1 | H33: 0 | I33: 100 | J33: -33222.082 | K33: 97.010013 | L33: 4 | M33: -332.22082 | N33: USD | O33: 1111111.1 | P33: LX208887
A34: 2777.75 | B34: PennantPark Credit Opportunities Fund IV Aggregator, LP | C34: UROLOGY PARTNERS CO., L.P. | D34: Common Equity | E34: 1373723 | F34: 277777.78 | H34: 277777.78 | I34: 1 | J34: 280555.53 | K34: 1.0099999 | L34: 138 | M34: 280555.53 | N34: USD | O34: 277777.78 | P34: 1706
