Workbook
Name IQ_CH: 110000
Name IQ_CQ: 5000
Name IQ_CY: 10000
Name IQ_DAILY: 500000
Name IQ_FH: 100000
Name IQ_FQ: 500
Name IQ_FY: 1000
Name IQ_LTM: 2000
Name IQ_MONTH: 15000
Name IQ_NTM: 6000
Name IQ_WEEK: 50000
Name IQ_YTD: 3000

Sheet Master Ratings
B2: Last Updated | D2: 45785
B4: *Match family name in master comps file
D5: Ratings Data (Borrower)
B6: Borrower Name | D6: Moody's | G6: S&P | L6: Fitch | O6: Date Estimates
B7: Master Comps | D7: Rating | E7: Rating Type | G7: Rating | H7: Rating Type | I7: Recovery Rating | J7: Recovery % | L7: Rating | M7: Rating Type | O7: S&P | P7: Fitch
B9: 48Forty | G9: CCC+** | H9: Rating (Private) | O9: 45737
B10: 4Wall Entertainment | G10: CCC-* | H10: Credit Estimate | L10: B- | M10: Rating (Private) | O10: 45709 | P10: 45345
B11: A1 Garage | G11: B-* | H11: Credit Estimate | O11: 45657
B12: Ad.net | G12: B-* | H12: Credit Estimate | L12: B-* | M12: Credit Estimate | O12: 45750 | P12: 45107
B13: Advantage Sales & Marketing | D13: B2 | E13: Rating (Public) | G13: B+ | H13: Rating (Public)
B14: Aechelon | G14: B* | H14: Credit Estimate | O14: 45679
B15: Aeronix | G15: B-* | H15: Credit Estimate | O15: 45629
B16: AFC | G16: B-* | H16: Rating (Private) | O16: 45616
B17: alphabroder | G17: B* | H17: Rating (Private) | L17: B+* | M17: Credit Estimate | O17: 45481 | P17: 45275
B18: Altamira | G18: B-* | H18: Credit Estimate | O18: 45106
B19: American Insulated Glass | G19: B-* | H19: Credit Estimate | L19: B-* | M19: Credit Estimate | O19: 44825 | P19: 44886
B20: Ankura | D20: B3 | E20: Rating (Public) | G20: B- | H20: Rating (Public)
B21: Any Hour Services | G21: B-* | H21: Credit Estimate | L21: B-* | M21: Credit Estimate | O21: 45447 | P21: 45050
B22: Apex Service Partners | G22: B-* | H22: Credit Estimate | L22: B- | M22: Rating (Private) | O22: 45077 | P22: 44886
B23: API Technologies | D23: B3 | E23: Rating (Public) | G23: CCC+ | H23: Rating (Public)
B24: Applied Technical Services | G24: B-* | H24: Rating (Private) | L24: B* | M24: Credit Estimate | O24: 45660 | P24: 45359
B25: Arcfield | G25: B-* | H25: Credit Estimate | L25: B | M25: Rating (Private) | O25: 45684 | P25: 45198
B26: Archer Lewis | G26: B-* | H26: Credit Estimate | O26: 45729
B27: Ardurra | G27: B-* | H27: Credit Estimate | O27: 45657
B28: Aretec (Cetera) | D28: B2 | E28: Rating (Public) | G28: B | H28: Rating (Public)
B29: Argano | G29: B-** | H29: Credit Estimate | O29: 45775
B30: Ascensus | D30: B3 | E30: Rating (Public) | G30: B- | H30: Rating (Public)
B31: Avenu | G31: B-* | H31: Credit Estimate | L31: B* | M31: Credit Estimate | O31: 45649 | P31: 45310
B32: BBB Industries | D32: B3 | E32: Rating (Public) | G32: B- | H32: Rating (Public)
B33: Beacon Behavioral | G33: B-* | H33: Credit Estimate | O33: 45664
B34: Berlin Packaging | D34: B3 | E34: Rating (Public) | G34: B- | H34: Rating (Public)
B35: Beta+ | D35: B2 | E35: Rating (Public) | G35: B- | H35: Rating (Public)
B36: Big Top | G36: B-* | H36: Credit Estimate | O36: 45693
B37: BiggerPockets | G37: B-* | H37: Credit Estimate | O37: 45660
B38: Bioderm | G38: B-* | H38: Credit Estimate | O38: 45420
B39: Blackhawk Industrial | G39: B-* | H39: Credit Estimate | O39: 45623
B40: Bland Landscaping | G40: B-* | H40: Credit Estimate | O40: 45698
B41: BlueBird | G41: B-* | H41: Credit Estimate | L41: B-* | M41: Credit Estimate | O41: 45670 | P41: 45093
B42: BlueHalo | G42: B-* | H42: Rating (Private) | L42: B-* | M42: Credit Estimate | O42: 45684 | P42: 1.19.2024
B43: Boss Industries | G43: B-* | H43: Credit Estimate | O43: 45702
...

Sheet Ratings by CLO
W1: Credit Estimate
W2: Rating (Private)
B3: CLO | J3: Credit | L3: Moody's | O3: S&P | S3: Fitch | W3: Days Left | Z3: Checks | AG3: Checks | AM3: Checks
B4: PFLT | C4: PSSL | D4: PTSF | E4: PSLF | F4: PTSF II | G4: PSSL (2) | H4: PSLF (2) | L4: Rating | M4: Type | O4: Rating | P4: Type | Q4: Date | S4: Rating | T4: Type | U4: Date | W4: S&P | X4: Fitch | Z4: S&P New | AA4: Fitch New | AB4: S&P Update | AC4: Fitch Update | AE4: NOT NEEDED | AG4: S&P New | AH4: Fitch New | AI4: S&P Update | AJ4: Fitch Update | AM4: S&P New | AN4: Fitch New | AO4: S&P Update | AP4: Fitch Update
B5: =+COUNTIFS(SOIs!$D:$D, 'Ratings by CLO'!$J5) -> 2 | C5: =+COUNTIFS(SOIs!$G:$G, 'Ratings by CLO'!$J5) -> 1 | D5: =+COUNTIFS(SOIs!$J:$J, 'Ratings by CLO'!$J5) -> 1 | E5: =+COUNTIFS(SOIs!$M:$M, 'Ratings by CLO'!$J5) -> 2 | F5: =+COUNTIFS(SOIs!$P:$P, 'Ratings by CLO'!$J5) -> 1 | G5: =+COUNTIFS(SOIs!$S:$S, 'Ratings by CLO'!$J5) -> 1 | H5: =+COUNTIFS(SOIs!$V:$V, 'Ratings by CLO'!$J5) -> 1 | J5: =+SOIs!X6 -> 48Forty | L5: =+IF(INDEX('Master Ratings'!$D:$D, MATCH('Ratings by CLO'!$J5,'Master Ratings'!$B:$B,0),0)=0,"",INDEX('Master Ratings'!$D:$D, MATCH('Ratings by CLO'!$J5,'Master Ratings'!$B:$B,0),0)) | M5: =+IF(INDEX('Master Ratings'!$E:$E, MATCH('Ratings by CLO'!$J5,'Master Ratings'!$B:$B,0),0)=0,"",INDEX('Master Ratings'!$E:$E, MATCH('Ratings by CLO'!$J5,'Master Ratings'!$B:$B,0),0)) | O5: =+IF(INDEX('Master Ratings'!$G:$G, MATCH('Ratings by CLO'!$J5,'Master Ratings'!$B:$B,0),0)=0,"",INDEX('Master Ratings'!$G:$G, MATCH('Ratings by CLO'!$J5,'Master Ratings'!$B:$B,0),0)) -> CCC+** | P5: =+IF(INDEX('Master Ratings'!$H:$H, MATCH('Ratings by CLO'!$J5,'Master Ratings'!$B:$B,0),0)=0,"",INDEX('Master Ratings'!$H:$H, MATCH('Ratings by CLO'!$J5,'Master Ratings'!$B:$B,0),0)) -> Rating (Private) | Q5: =+IF(INDEX('Master Ratings'!$O:$O, MATCH('Ratings by CLO'!$J5,'Master Ratings'!$B:$B,0),0)=0,"",INDEX('Master Ratings'!$O:$O, MATCH('Ratings by CLO'!$J5,'Master Ratings'!$B:$B,0),0)) -> 45737 | S5: =+IF(INDEX('Master Ratings'!$L:$L, MATCH('Ratings by CLO'!$J5,'Master Ratings'!$B:$B,0),0)=0,"",INDEX('Master Ratings'!$L:$L, MATCH('Ratings by CLO'!$J5,'Master Ratings'!$B:$B,0),0)) | T5: =+IF(INDEX('Master Ratings'!$M:$M, MATCH('Ratings by CLO'!$J5,'Master Ratings'!$B:$B,0),0)=0,"",INDEX('Master Ratings'!$M:$M, MATCH('Ratings by CLO'!$J5,'Master Ratings'!$B:$B,0),0)) | U5: =+IF(INDEX('Master Ratings'!$P:$P, MATCH('Ratings by CLO'!$J5,'Master Ratings'!$B:$B,0),0)=0,"",INDEX('Master Ratings'!$P:$P, MATCH('Ratings by CLO'!$J5,'Master Ratings'!$B:$B,0),0)) | W5: =+IF(OR($P5=$W$1,$P5=$W$2),$Q5+365-TODAY(), "") -> 138 | X5: =+IF(OR($T5=$W$1,$T5=$W$2),$U5+365-TODAY(), "") | Z5: =IF(AND(SUM(B5:H5)>=1,ISERROR(W5)),"X","") | AA5: =IF(AND(B5>=1, ISERROR(X5)),"X","") | AB5: =+IFERROR(IF(W5<0,"X",""),"") | AC5: =+IFERROR(IF(AND(B5>0, X5<0),"X",""),"") | AE5: =+IF(SUM(B5:H5)=0,"X","") | AG5: =IF(Z5="X",AG2+1,AG2) -> 0 | AH5: =IF(AA5="X",AH2+1,AH2) -> 0 | AI5: =IF(AB5="X",AI2+1,AI2) -> 0 | AJ5: =IF(AC5="X",AJ2+1,AJ2) -> 0 | AL5: 1 | AM5: =INDEX($J:$J, MATCH($AL5,AG:AG,0),0) -> Edelman | AN5: =INDEX($J:$J, MATCH($AL5,AH:AH,0),0) -> BlueHalo | AO5: =INDEX($J:$J, MATCH($AL5,AI:AI,0),0) -> alphabroder | AP5: =INDEX($J:$J, MATCH($AL5,AJ:AJ,0),0) -> 4Wall Entertainment
B6: =+COUNTIFS(SOIs!$D:$D, 'Ratings by CLO'!$J6) -> 3 | C6: =+COUNTIFS(SOIs!$G:$G, 'Ratings by CLO'!$J6) -> 1 | D6: =+COUNTIFS(SOIs!$J:$J, 'Ratings by CLO'!$J6) -> 0 | E6: =+COUNTIFS(SOIs!$M:$M, 'Ratings by CLO'!$J6) -> 0 | F6: =+COUNTIFS(SOIs!$P:$P, 'Ratings by CLO'!$J6) -> 0 | G6: =+COUNTIFS(SOIs!$S:$S, 'Ratings by CLO'!$J6) -> 1 | H6: =+COUNTIFS(SOIs!$V:$V, 'Ratings by CLO'!$J6) -> 1 | J6: =+SOIs!X7 -> 4Wall Entertainment | L6: =+IF(INDEX('Master Ratings'!$D:$D, MATCH('Ratings by CLO'!$J6,'Master Ratings'!$B:$B,0),0)=0,"",INDEX('Master Ratings'!$D:$D, MATCH('Ratings by CLO'!$J6,'Master Ratings'!$B:$B,0),0)) | M6: =+IF(INDEX('Master Ratings'!$E:$E, MATCH('Ratings by CLO'!$J6,'Master Ratings'!$B:$B,0),0)=0,"",INDEX('Master Ratings'!$E:$E, MATCH('Ratings by CLO'!$J6,'Master Ratings'!$B:$B,0),0)) | O6: =+IF(INDEX('Master Ratings'!$G:$G, MATCH('Ratings by CLO'!$J6,'Master Ratings'!$B:$B,0),0)=0,"",INDEX('Master Ratings'!$G:$G, MATCH('Ratings by CLO'!$J6,'Master Ratings'!$B:$B,0),0)) -> CCC-* | P6: =+IF(INDEX('Master Ratings'!$H:$H, MATCH('Ratings by CLO'!$J6,'Master Ratings'!$B:$B,0),0)=0,"",INDEX('Master Ratings'!$H:$H, MATCH('Ratings by CLO'!$J6,'Master Ratings'!$B:$B,0),0)) -> Credit Estimate | Q6: =+IF(INDEX('Master Ratings'!$O:$O, MATCH('Ratings by CLO'!$J6,'Master Ratings'!$B:$B,0),0)=0,"",INDEX('Master Ratings'!$O:$O, MATCH('Ratings by CLO'!$J6,'Master Ratings'!$B:$B,0),0)) -> 45709 | S6: =+IF(INDEX('Master Ratings'!$L:$L, MATCH('Ratings by CLO'!$J6,'Master Ratings'!$B:$B,0),0)=0,"",INDEX('Master Ratings'!$L:$L, MATCH('Ratings by CLO'!$J6,'Master Ratings'!$B:$B,0),0)) -> B- | T6: =+IF(INDEX('Master Ratings'!$M:$M, MATCH('Ratings by CLO'!$J6,'Master Ratings'!$B:$B,0),0)=0,"",INDEX('Master Ratings'!$M:$M, MATCH('Ratings by CLO'!$J6,'Master Ratings'!$B:$B,0),0)) -> Rating (Private) | U6: =+IF(INDEX('Master Ratings'!$P:$P, MATCH('Ratings by CLO'!$J6,'Master Ratings'!$B:$B,0),0)=0,"",INDEX('Master Ratings'!$P:$P, MATCH('Ratings by CLO'!$J6,'Master Ratings'!$B:$B,0),0)) -> 45345 | W6: =+IF(OR($P6=$W$1,$P6=$W$2),$Q6+365-TODAY(), "") -> 110 | X6: =+IF(OR($T6=$W$1,$T6=$W$2),$U6+365-TODAY(), "") -> -254 | Z6: =IF(AND(SUM(B6:H6)>=1,ISERROR(W6)),"X","") | AA6: =IF(AND(B6>1, ISERROR(X6)),"X","") | AB6: =+IFERROR(IF(W6<0,"X",""),"") | AC6: =+IFERROR(IF(AND(B6>0, X6<0),"X",""),"") -> X | AE6: =+IF(SUM(B6:H6)=0,"X","") | AG6: =IF(Z6="X",AG5+1,AG5) -> 0 | AH6: =IF(AA6="X",AH5+1,AH5) -> 0 | AI6: =IF(AB6="X",AI5+1,AI5) -> 0 | AJ6: =IF(AC6="X",AJ5+1,AJ5) -> 1 | AL6: =AL5+1 -> 2 | AM6: =INDEX($J:$J, MATCH($AL6,AG:AG,0),0) -> Electro Rent | AN6: =INDEX($J:$J, MATCH($AL6,AH:AH,0),0) -> Connatix | AO6: =INDEX($J:$J, MATCH($AL6,AI:AI,0),0) -> American Insulated Glass | AP6: =INDEX($J:$J, MATCH($AL6,AJ:AJ,0),0) -> Ad.net
B7: =+COUNTIFS(SOIs!$D:$D, 'Ratings by CLO'!$J7) -> 0 | C7: =+COUNTIFS(SOIs!$G:$G, 'Ratings by CLO'!$J7) -> 0 | D7: =+COUNTIFS(SOIs!$J:$J, 'Ratings by CLO'!$J7) -> 0 | E7: =+COUNTIFS(SOIs!$M:$M, 'Ratings by CLO'!$J7) -> 0 | F7: =+COUNTIFS(SOIs!$P:$P, 'Ratings by CLO'!$J7) -> 0 | G7: =+COUNTIFS(SOIs!$S:$S, 'Ratings by CLO'!$J7) -> 1 | H7: =+COUNTIFS(SOIs!$V:$V, 'Ratings by CLO'!$J7) -> 1 | J7: =+SOIs!X8 -> A1 Garage | L7: =+IF(INDEX('Master Ratings'!$D:$D, MATCH('Ratings by CLO'!$J7,'Master Ratings'!$B:$B,0),0)=0,"",INDEX('Master Ratings'!$D:$D, MATCH('Ratings by CLO'!$J7,'Master Ratings'!$B:$B,0),0)) | M7: =+IF(INDEX('Master Ratings'!$E:$E, MATCH('Ratings by CLO'!$J7,'Master Ratings'!$B:$B,0),0)=0,"",INDEX('Master Ratings'!$E:$E, MATCH('Ratings by CLO'!$J7,'Master Ratings'!$B:$B,0),0)) | O7: =+IF(INDEX('Master Ratings'!$G:$G, MATCH('Ratings by CLO'!$J7,'Master Ratings'!$B:$B,0),0)=0,"",INDEX('Master Ratings'!$G:$G, MATCH('Ratings by CLO'!$J7,'Master Ratings'!$B:$B,0),0)) -> B-* | P7: =+IF(INDEX('Master Ratings'!$H:$H, MATCH('Ratings by CLO'!$J7,'Master Ratings'!$B:$B,0),0)=0,"",INDEX('Master Ratings'!$H:$H, MATCH('Ratings by CLO'!$J7,'Master Ratings'!$B:$B,0),0)) -> Credit Estimate | Q7: =+IF(INDEX('Master Ratings'!$O:$O, MATCH('Ratings by CLO'!$J7,'Master Ratings'!$B:$B,0),0)=0,"",INDEX('Master Ratings'!$O:$O, MATCH('Ratings by CLO'!$J7,'Master Ratings'!$B:$B,0),0)) -> 45657 | S7: =+IF(INDEX('Master Ratings'!$L:$L, MATCH('Ratings by CLO'!$J7,'Master Ratings'!$B:$B,0),0)=0,"",INDEX('Master Ratings'!$L:$L, MATCH('Ratings by CLO'!$J7,'Master Ratings'!$B:$B,0),0)) | T7: =+IF(INDEX('Master Ratings'!$M:$M, MATCH('Ratings by CLO'!$J7,'Master Ratings'!$B:$B,0),0)=0,"",INDEX('Master Ratings'!$M:$M, MATCH('Ratings by CLO'!$J7,'Master Ratings'!$B:$B,0),0)) | U7: =+IF(INDEX('Master Ratings'!$P:$P, MATCH('Ratings by CLO'!$J7,'Master Ratings'!$B:$B,0),0)=0,"",INDEX('Master Ratings'!$P:$P, MATCH('Ratings by CLO'!$J7,'Master Ratings'!$B:$B,0),0)) | W7: =+IF(OR($P7=$W$1,$P7=$W$2),$Q7+365-TODAY(), "") -> 58 | X7: =+IF(OR($T7=$W$1,$T7=$W$2),$U7+365-TODAY(), "") | Z7: =IF(AND(SUM(B7:H7)>=1,ISERROR(W7)),"X","") | AA7: =IF(AND(B7>1, ISERROR(X7)),"X","") | AB7: =+IFERROR(IF(W7<0,"X",""),"") | AC7: =+IFERROR(IF(AND(B7>0, X7<0),"X",""),"") | AE7: =+IF(SUM(B7:H7)=0,"X","") | AG7: =IF(Z7="X",AG6+1,AG6) -> 0 | AH7: =IF(AA7="X",AH6+1,AH6) -> 0 | AI7: =IF(AB7="X",AI6+1,AI6) -> 0 | AJ7: =IF(AC7="X",AJ6+1,AJ6) -> 1 | AL7: =AL6+1 -> 3 | AM7: =INDEX($J:$J, MATCH($AL7,AG:AG,0),0) -> Engine & Transmission Exchange | AN7: =INDEX($J:$J, MATCH($AL7,AH:AH,0),0) -> Gen3 Marketing | AO7: =INDEX($J:$J, MATCH($AL7,AI:AI,0),0) -> Any Hour Services | AP7: =INDEX($J:$J, MATCH($AL7,AJ:AJ,0),0) -> alphabroder
B8: =+COUNTIFS(SOIs!$D:$D, 'Ratings by CLO'!$J8) -> 4 | C8: =+COUNTIFS(SOIs!$G:$G, 'Ratings by CLO'!$J8) -> 1 | D8: =+COUNTIFS(SOIs!$J:$J, 'Ratings by CLO'!$J8) -> 1 | E8: =+COUNTIFS(SOIs!$M:$M, 'Ratings by CLO'!$J8) -> 1 | F8: =+COUNTIFS(SOIs!$P:$P, 'Ratings by CLO'!$J8) -> 0 | G8: =+COUNTIFS(SOIs!$S:$S, 'Ratings by CLO'!$J8) -> 1 | H8: =+COUNTIFS(SOIs!$V:$V, 'Ratings by CLO'!$J8) -> 0 | J8: =+SOIs!X9 -> Ad.net | L8: =+IF(INDEX('Master Ratings'!$D:$D, MATCH('Ratings by CLO'!$J8,'Master Ratings'!$B:$B,0),0)=0,"",INDEX('Master Ratings'!$D:$D, MATCH('Ratings by CLO'!$J8,'Master Ratings'!$B:$B,0),0)) | M8: =+IF(INDEX('Master Ratings'!$E:$E, MATCH('Ratings by CLO'!$J8,'Master Ratings'!$B:$B,0),0)=0,"",INDEX('Master Ratings'!$E:$E, MATCH('Ratings by CLO'!$J8,'Master Ratings'!$B:$B,0),0)) | O8: =+IF(INDEX('Master Ratings'!$G:$G, MATCH('Ratings by CLO'!$J8,'Master Ratings'!$B:$B,0),0)=0,"",INDEX('Master Ratings'!$G:$G, MATCH('Ratings by CLO'!$J8,'Master Ratings'!$B:$B,0),0)) -> B-* | P8: =+IF(INDEX('Master Ratings'!$H:$H, MATCH('Ratings by CLO'!$J8,'Master Ratings'!$B:$B,0),0)=0,"",INDEX('Master Ratings'!$H:$H, MATCH('Ratings by CLO'!$J8,'Master Ratings'!$B:$B,0),0)) -> Credit Estimate | Q8: =+IF(INDEX('Master Ratings'!$O:$O, MATCH('Ratings by CLO'!$J8,'Master Ratings'!$B:$B,0),0)=0,"",INDEX('Master Ratings'!$O:$O, MATCH('Ratings by CLO'!$J8,'Master Ratings'!$B:$B,0),0)) -> 45750 | S8: =+IF(INDEX('Master Ratings'!$L:$L, MATCH('Ratings by CLO'!$J8,'Master Ratings'!$B:$B,0),0)=0,"",INDEX('Master Ratings'!$L:$L, MATCH('Ratings by CLO'!$J8,'Master Ratings'!$B:$B,0),0)) -> B-* | T8: =+IF(INDEX('Master Ratings'!$M:$M, MATCH('Ratings by CLO'!$J8,'Master Ratings'!$B:$B,0),0)=0,"",INDEX('Master Ratings'!$M:$M, MATCH('Ratings by CLO'!$J8,'Master Ratings'!$B:$B,0),0)) -> Credit Estimate | U8: =+IF(INDEX('Master Ratings'!$P:$P, MATCH('Ratings by CLO'!$J8,'Master Ratings'!$B:$B,0),0)=0,"",INDEX('Master Ratings'!$P:$P, MATCH('Ratings by CLO'!$J8,'Master Ratings'!$B:$B,0),0)) -> 45107 | W8: =+IF(OR($P8=$W$1,$P8=$W$2),$Q8+365-TODAY(), "") -> 151 | X8: =+IF(OR($T8=$W$1,$T8=$W$2),$U8+365-TODAY(), "") -> -492 | Z8: =IF(AND(SUM(B8:H8)>=1,ISERROR(W8)),"X","") | AA8: =IF(AND(B8>1, ISERROR(X8)),"X","") | AB8: =+IFERROR(IF(W8<0,"X",""),"") | AC8: =+IFERROR(IF(AND(B8>0, X8<0),"X",""),"") -> X | AE8: =+IF(SUM(B8:H8)=0,"X","") | AG8: =IF(Z8="X",AG7+1,AG7) -> 0 | AH8: =IF(AA8="X",AH7+1,AH7) -> 0 | AI8: =IF(AB8="X",AI7+1,AI7) -> 0 | AJ8: =IF(AC8="X",AJ7+1,AJ7) -> 2 | AL8: =AL7+1 -> 4 | AM8: =INDEX($J:$J, MATCH($AL8,AG:AG,0),0) -> Hightower | AN8: =INDEX($J:$J, MATCH($AL8,AH:AH,0),0) -> MCR | AO8: =INDEX($J:$J, MATCH($AL8,AI:AI,0),0) -> Apex Service Partners | AP8: =INDEX($J:$J, MATCH($AL8,AJ:AJ,0),0) -> Any Hour Services
B9: =+COUNTIFS(SOIs!$D:$D, 'Ratings by CLO'!$J9) -> 4 | C9: =+COUNTIFS(SOIs!$G:$G, 'Ratings by CLO'!$J9) -> 1 | D9: =+COUNTIFS(SOIs!$J:$J, 'Ratings by CLO'!$J9) -> 1 | E9: =+COUNTIFS(SOIs!$M:$M, 'Ratings by CLO'!$J9) -> 0 | F9: =+COUNTIFS(SOIs!$P:$P, 'Ratings by CLO'!$J9) -> 1 | G9: =+COUNTIFS(SOIs!$S:$S, 'Ratings by CLO'!$J9) -> 0 | H9: =+COUNTIFS(SOIs!$V:$V, 'Ratings by CLO'!$J9) -> 1 | J9: =+SOIs!X10 -> alphabroder | L9: =+IF(INDEX('Master Ratings'!$D:$D, MATCH('Ratings by CLO'!$J9,'Master Ratings'!$B:$B,0),0)=0,"",INDEX('Master Ratings'!$D:$D, MATCH('Ratings by CLO'!$J9,'Master Ratings'!$B:$B,0),0)) | M9: =+IF(INDEX('Master Ratings'!$E:$E, MATCH('Ratings by CLO'!$J9,'Master Ratings'!$B:$B,0),0)=0,"",INDEX('Master Ratings'!$E:$E, MATCH('Ratings by CLO'!$J9,'Master Ratings'!$B:$B,0),0)) | O9: =+IF(INDEX('Master Ratings'!$G:$G, MATCH('Ratings by CLO'!$J9,'Master Ratings'!$B:$B,0),0)=0,"",INDEX('Master Ratings'!$G:$G, MATCH('Ratings by CLO'!$J9,'Master Ratings'!$B:$B,0),0)) -> B* | P9: =+IF(INDEX('Master Ratings'!$H:$H, MATCH('Ratings by CLO'!$J9,'Master Ratings'!$B:$B,0),0)=0,"",INDEX('Master Ratings'!$H:$H, MATCH('Ratings by CLO'!$J9,'Master Ratings'!$B:$B,0),0)) -> Rating (Private) | Q9: =+IF(INDEX('Master Ratings'!$O:$O, MATCH('Ratings by CLO'!$J9,'Master Ratings'!$B:$B,0),0)=0,"",INDEX('Master Ratings'!$O:$O, MATCH('Ratings by CLO'!$J9,'Master Ratings'!$B:$B,0),0)) -> 45481 | S9: =+IF(INDEX('Master Ratings'!$L:$L, MATCH('Ratings by CLO'!$J9,'Master Ratings'!$B:$B,0),0)=0,"",INDEX('Master Ratings'!$L:$L, MATCH('Ratings by CLO'!$J9,'Master Ratings'!$B:$B,0),0)) -> B+* | T9: =+IF(INDEX('Master Ratings'!$M:$M, MATCH('Ratings by CLO'!$J9,'Master Ratings'!$B:$B,0),0)=0,"",INDEX('Master Ratings'!$M:$M, MATCH('Ratings by CLO'!$J9,'Master Ratings'!$B:$B,0),0)) -> Credit Estimate | U9: =+IF(INDEX('Master Ratings'!$P:$P, MATCH('Ratings by CLO'!$J9,'Master Ratings'!$B:$B,0),0)=0,"",INDEX('Master Ratings'!$P:$P, MATCH('Ratings by CLO'!$J9,'Master Ratings'!$B:$B,0),0)) -> 45275 | W9: =+IF(OR($P9=$W$1,$P9=$W$2),$Q9+365-TODAY(), "") -> -118 | X9: =+IF(OR($T9=$W$1,$T9=$W$2),$U9+365-TODAY(), "") -> -324 | Z9: =IF(AND(SUM(B9:H9)>=1,ISERROR(W9)),"X","") | AA9: =IF(AND(B9>1, ISERROR(X9)),"X","") | AB9: =+IFERROR(IF(W9<0,"X",""),"") -> X | AC9: =+IFERROR(IF(AND(B9>0, X9<0),"X",""),"") -> X | AE9: =+IF(SUM(B9:H9)=0,"X","") | AG9: =IF(Z9="X",AG8+1,AG8) -> 0 | AH9: =IF(AA9="X",AH8+1,AH8) -> 0 | AI9: =IF(AB9="X",AI8+1,AI8) -> 1 | AJ9: =IF(AC9="X",AJ8+1,AJ8) -> 3 | AL9: =AL8+1 -> 5 | AM9: =INDEX($J:$J, MATCH($AL9,AG:AG,0),0) -> ImagineAcquisitionCo | AN9: =INDEX($J:$J, MATCH($AL9,AH:AH,0),0) -> MeritDirect | AO9: =INDEX($J:$J, MATCH($AL9,AI:AI,0),0) -> BioDerm | AP9: =INDEX($J:$J, MATCH($AL9,AJ:AJ,0),0) -> Apex Service Partners
B10: =+COUNTIFS(SOIs!$D:$D, 'Ratings by CLO'!$J10) -> 0 | C10: =+COUNTIFS(SOIs!$G:$G, 'Ratings by CLO'!$J10) -> 0 | D10: =+COUNTIFS(SOIs!$J:$J, 'Ratings by CLO'!$J10) -> 0 | E10: =+COUNTIFS(SOIs!$M:$M, 'Ratings by CLO'!$J10) -> 0 | F10: =+COUNTIFS(SOIs!$P:$P, 'Ratings by CLO'!$J10) -> 1 | G10: =+COUNTIFS(SOIs!$S:$S, 'Ratings by CLO'!$J10) -> 0 | H10: =+COUNTIFS(SOIs!$V:$V, 'Ratings by CLO'!$J10) -> 0 | J10: =+SOIs!X11 -> American Insulated Glass | L10: =+IF(INDEX('Master Ratings'!$D:$D, MATCH('Ratings by CLO'!$J10,'Master Ratings'!$B:$B,0),0)=0,"",INDEX('Master Ratings'!$D:$D, MATCH('Ratings by CLO'!$J10,'Master Ratings'!$B:$B,0),0)) | M10: =+IF(INDEX('Master Ratings'!$E:$E, MATCH('Ratings by CLO'!$J10,'Master Ratings'!$B:$B,0),0)=0,"",INDEX('Master Ratings'!$E:$E, MATCH('Ratings by CLO'!$J10,'Master Ratings'!$B:$B,0),0)) | O10: =+IF(INDEX('Master Ratings'!$G:$G, MATCH('Ratings by CLO'!$J10,'Master Ratings'!$B:$B,0),0)=0,"",INDEX('Master Ratings'!$G:$G, MATCH('Ratings by CLO'!$J10,'Master Ratings'!$B:$B,0),0)) -> B-* | P10: =+IF(INDEX('Master Ratings'!$H:$H, MATCH('Ratings by CLO'!$J10,'Master Ratings'!$B:$B,0),0)=0,"",INDEX('Master Ratings'!$H:$H, MATCH('Ratings by CLO'!$J10,'Master Ratings'!$B:$B,0),0)) -> Credit Estimate | Q10: =+IF(INDEX('Master Ratings'!$O:$O, MATCH('Ratings by CLO'!$J10,'Master Ratings'!$B:$B,0),0)=0,"",INDEX('Master Ratings'!$O:$O, MATCH('Ratings by CLO'!$J10,'Master Ratings'!$B:$B,0),0)) -> 44825 | S10: =+IF(INDEX('Master Ratings'!$L:$L, MATCH('Ratings by CLO'!$J10,'Master Ratings'!$B:$B,0),0)=0,"",INDEX('Master Ratings'!$L:$L, MATCH('Ratings by CLO'!$J10,'Master Ratings'!$B:$B,0),0)) -> B-* | T10: =+IF(INDEX('Master Ratings'!$M:$M, MATCH('Ratings by CLO'!$J10,'Master Ratings'!$B:$B,0),0)=0,"",INDEX('Master Ratings'!$M:$M, MATCH('Ratings by CLO'!$J10,'Master Ratings'!$B:$B,0),0)) -> Credit Estimate | U10: =+IF(INDEX('Master Ratings'!$P:$P, MATCH('Ratings by CLO'!$J10,'Master Ratings'!$B:$B,0),0)=0,"",INDEX('Master Ratings'!$P:$P, MATCH('Ratings by CLO'!$J10,'Master Ratings'!$B:$B,0),0)) -> 44886 | W10: =+IF(OR($P10=$W$1,$P10=$W$2),$Q10+365-TODAY(), "") -> -774 | X10: =+IF(OR($T10=$W$1,$T10=$W$2),$U10+365-TODAY(), "") -> -713 | Z10: =IF(AND(SUM(B10:H10)>=1,ISERROR(W10)),"X","") | AA10: =IF(AND(B10>1, ISERROR(X10)),"X","") | AB10: =+IFERROR(IF(W10<0,"X",""),"") -> X | AC10: =+IFERROR(IF(AND(B10>0, X10<0),"X",""),"") | AE10: =+IF(SUM(B10:H10)=0,"X","") | AG10: =IF(Z10="X",AG9+1,AG9) -> 0 | AH10: =IF(AA10="X",AH9+1,AH9) -> 0 | AI10: =IF(AB10="X",AI9+1,AI9) -> 2 | AJ10: =IF(AC10="X",AJ9+1,AJ9) -> 3 | AL10: =AL9+1 -> 6 | AM10: =INDEX($J:$J, MATCH($AL10,AG:AG,0),0) -> Integrated Data Services | AN10: =INDEX($J:$J, MATCH($AL10,AH:AH,0),0) -> Mission Critical Electronics | AO10: =INDEX($J:$J, MATCH($AL10,AI:AI,0),0) -> By Light | AP10: =INDEX($J:$J, MATCH($AL10,AJ:AJ,0),0) -> Applied Technical Services
B11: =+COUNTIFS(SOIs!$D:$D, 'Ratings by CLO'!$J11) -> 0 | C11: =+COUNTIFS(SOIs!$G:$G, 'Ratings by CLO'!$J11) -> 0 | D11: =+COUNTIFS(SOIs!$J:$J, 'Ratings by CLO'!$J11) -> 0 | E11: =+COUNTIFS(SOIs!$M:$M, 'Ratings by CLO'!$J11) -> 0 | F11: =+COUNTIFS(SOIs!$P:$P, 'Ratings by CLO'!$J11) -> 1 | G11: =+COUNTIFS(SOIs!$S:$S, 'Ratings by CLO'!$J11) -> 0 | H11: =+COUNTIFS(SOIs!$V:$V, 'Ratings by CLO'!$J11) -> 0 | J11: =+SOIs!X12 -> Ankura | L11: =+IF(INDEX('Master Ratings'!$D:$D, MATCH('Ratings by CLO'!$J11,'Master Ratings'!$B:$B,0),0)=0,"",INDEX('Master Ratings'!$D:$D, MATCH('Ratings by CLO'!$J11,'Master Ratings'!$B:$B,0),0)) -> B3 | M11: =+IF(INDEX('Master Ratings'!$E:$E, MATCH('Ratings by CLO'!$J11,'Master Ratings'!$B:$B,0),0)=0,"",INDEX('Master Ratings'!$E:$E, MATCH('Ratings by CLO'!$J11,'Master Ratings'!$B:$B,0),0)) -> Rating (Public) | O11: =+IF(INDEX('Master Ratings'!$G:$G, MATCH('Ratings by CLO'!$J11,'Master Ratings'!$B:$B,0),0)=0,"",INDEX('Master Ratings'!$G:$G, MATCH('Ratings by CLO'!$J11,'Master Ratings'!$B:$B,0),0)) -> B- | P11: =+IF(INDEX('Master Ratings'!$H:$H, MATCH('Ratings by CLO'!$J11,'Master Ratings'!$B:$B,0),0)=0,"",INDEX('Master Ratings'!$H:$H, MATCH('Ratings by CLO'!$J11,'Master Ratings'!$B:$B,0),0)) -> Rating (Public) | Q11: =+IF(INDEX('Master Ratings'!$O:$O, MATCH('Ratings by CLO'!$J11,'Master Ratings'!$B:$B,0),0)=0,"",INDEX('Master Ratings'!$O:$O, MATCH('Ratings by CLO'!$J11,'Master Ratings'!$B:$B,0),0)) | S11: =+IF(INDEX('Master Ratings'!$L:$L, MATCH('Ratings by CLO'!$J11,'Master Ratings'!$B:$B,0),0)=0,"",INDEX('Master Ratings'!$L:$L, MATCH('Ratings by CLO'!$J11,'Master Ratings'!$B:$B,0),0)) | T11: =+IF(INDEX('Master Ratings'!$M:$M, MATCH('Ratings by CLO'!$J11,'Master Ratings'!$B:$B,0),0)=0,"",INDEX('Master Ratings'!$M:$M, MATCH('Ratings by CLO'!$J11,'Master Ratings'!$B:$B,0),0)) | U11: =+IF(INDEX('Master Ratings'!$P:$P, MATCH('Ratings by CLO'!$J11,'Master Ratings'!$B:$B,0),0)=0,"",INDEX('Master Ratings'!$P:$P, MATCH('Ratings by CLO'!$J11,'Master Ratings'!$B:$B,0),0)) | W11: =+IF(OR($P11=$W$1,$P11=$W$2),$Q11+365-TODAY(), "") | X11: =+IF(OR($T11=$W$1,$T11=$W$2),$U11+365-TODAY(), "") | Z11: =IF(AND(SUM(B11:H11)>=1,ISERROR(W11)),"X","") | AA11: =IF(AND(B11>1, ISERROR(X11)),"X","") | AB11: =+IFERROR(IF(W11<0,"X",""),"") | AC11: =+IFERROR(IF(AND(B11>0, X11<0),"X",""),"") | AE11: =+IF(SUM(B11:H11)=0,"X","") | AG11: =IF(Z11="X",AG10+1,AG10) -> 0 | AH11: =IF(AA11="X",AH10+1,AH10) -> 0 | AI11: =IF(AB11="X",AI10+1,AI10) -> 2 | AJ11: =IF(AC11="X",AJ10+1,AJ10) -> 3 | AL11: =AL10+1 -> 7 | AM11: =INDEX($J:$J, MATCH($AL11,AG:AG,0),0) -> Rancho Medical | AN11: =INDEX($J:$J, MATCH($AL11,AH:AH,0),0) -> Quantic Electronics | AO11: =INDEX($J:$J, MATCH($AL11,AI:AI,0),0) -> Cadence Aerospace | AP11: =INDEX($J:$J, MATCH($AL11,AJ:AJ,0),0) -> Arcfield
B12: =+COUNTIFS(SOIs!$D:$D, 'Ratings by CLO'!$J12) -> 3 | C12: =+COUNTIFS(SOIs!$G:$G, 'Ratings by CLO'!$J12) -> 1 | D12: =+COUNTIFS(SOIs!$J:$J, 'Ratings by CLO'!$J12) -> 0 | E12: =+COUNTIFS(SOIs!$M:$M, 'Ratings by CLO'!$J12) -> 1 | F12: =+COUNTIFS(SOIs!$P:$P, 'Ratings by CLO'!$J12) -> 0 | G12: =+COUNTIFS(SOIs!$S:$S, 'Ratings by CLO'!$J12) -> 1 | H12: =+COUNTIFS(SOIs!$V:$V, 'Ratings by CLO'!$J12) -> 1 | J12: =+SOIs!X13 -> Any Hour Services | L12: =+IF(INDEX('Master Ratings'!$D:$D, MATCH('Ratings by CLO'!$J12,'Master Ratings'!$B:$B,0),0)=0,"",INDEX('Master Ratings'!$D:$D, MATCH('Ratings by CLO'!$J12,'Master Ratings'!$B:$B,0),0)) | M12: =+IF(INDEX('Master Ratings'!$E:$E, MATCH('Ratings by CLO'!$J12,'Master Ratings'!$B:$B,0),0)=0,"",INDEX('Master Ratings'!$E:$E, MATCH('Ratings by CLO'!$J12,'Master Ratings'!$B:$B,0),0)) | O12: =+IF(INDEX('Master Ratings'!$G:$G, MATCH('Ratings by CLO'!$J12,'Master Ratings'!$B:$B,0),0)=0,"",INDEX('Master Ratings'!$G:$G, MATCH('Ratings by CLO'!$J12,'Master Ratings'!$B:$B,0),0)) -> B-* | P12: =+IF(INDEX('Master Ratings'!$H:$H, MATCH('Ratings by CLO'!$J12,'Master Ratings'!$B:$B,0),0)=0,"",INDEX('Master Ratings'!$H:$H, MATCH('Ratings by CLO'!$J12,'Master Ratings'!$B:$B,0),0)) -> Credit Estimate | Q12: =+IF(INDEX('Master Ratings'!$O:$O, MATCH('Ratings by CLO'!$J12,'Master Ratings'!$B:$B,0),0)=0,"",INDEX('Master Ratings'!$O:$O, MATCH('Ratings by CLO'!$J12,'Master Ratings'!$B:$B,0),0)) -> 45447 | S12: =+IF(INDEX('Master Ratings'!$L:$L, MATCH('Ratings by CLO'!$J12,'Master Ratings'!$B:$B,0),0)=0,"",INDEX('Master Ratings'!$L:$L, MATCH('Ratings by CLO'!$J12,'Master Ratings'!$B:$B,0),0)) -> B-* | T12: =+IF(INDEX('Master Ratings'!$M:$M, MATCH('Ratings by CLO'!$J12,'Master Ratings'!$B:$B,0),0)=0,"",INDEX('Master Ratings'!$M:$M, MATCH('Ratings by CLO'!$J12,'Master Ratings'!$B:$B,0),0)) -> Credit Estimate | U12: =+IF(INDEX('Master Ratings'!$P:$P, MATCH('Ratings by CLO'!$J12,'Master Ratings'!$B:$B,0),0)=0,"",INDEX('Master Ratings'!$P:$P, MATCH('Ratings by CLO'!$J12,'Master Ratings'!$B:$B,0),0)) -> 45050 | W12: =+IF(OR($P12=$W$1,$P12=$W$2),$Q12+365-TODAY(), "") -> -152 | X12: =+IF(OR($T12=$W$1,$T12=$W$2),$U12+365-TODAY(), "") -> -549 | Z12: =IF(AND(SUM(B12:H12)>=1,ISERROR(W12)),"X","") | AA12: =IF(AND(B12>1, ISERROR(X12)),"X","") | AB12: =+IFERROR(IF(W12<0,"X",""),"") -> X | AC12: =+IFERROR(IF(AND(B12>0, X12<0),"X",""),"") -> X | AE12: =+IF(SUM(B12:H12)=0,"X","") | AG12: =IF(Z12="X",AG11+1,AG11) -> 0 | AH12: =IF(AA12="X",AH11+1,AH11) -> 0 | AI12: =IF(AB12="X",AI11+1,AI11) -> 3 | AJ12: =IF(AC12="X",AJ11+1,AJ11) -> 4 | AL12: =AL11+1 -> 8 | AM12: =INDEX($J:$J, MATCH($AL12,AG:AG,0),0) -> Simplicity Group | AN12: =INDEX($J:$J, MATCH($AL12,AH:AH,0),0) -> Sales Benchmark Index (SBI) | AO12: =INDEX($J:$J, MATCH($AL12,AI:AI,0),0) -> Connatix | AP12: =INDEX($J:$J, MATCH($AL12,AJ:AJ,0),0) -> Bluebird
B13: =+COUNTIFS(SOIs!$D:$D, 'Ratings by CLO'!$J13) -> 7 | C13: =+COUNTIFS(SOIs!$G:$G, 'Ratings by CLO'!$J13) -> 3 | D13: =+COUNTIFS(SOIs!$J:$J, 'Ratings by CLO'!$J13) -> 2 | E13: =+COUNTIFS(SOIs!$M:$M, 'Ratings by CLO'!$J13) -> 1 | F13: =+COUNTIFS(SOIs!$P:$P, 'Ratings by CLO'!$J13) -> 1 | G13: =+COUNTIFS(SOIs!$S:$S, 'Ratings by CLO'!$J13) -> 1 | H13: =+COUNTIFS(SOIs!$V:$V, 'Ratings by CLO'!$J13) -> 1 | J13: =+SOIs!X14 -> Apex Service Partners | L13: =+IF(INDEX('Master Ratings'!$D:$D, MATCH('Ratings by CLO'!$J13,'Master Ratings'!$B:$B,0),0)=0,"",INDEX('Master Ratings'!$D:$D, MATCH('Ratings by CLO'!$J13,'Master Ratings'!$B:$B,0),0)) | M13: =+IF(INDEX('Master Ratings'!$E:$E, MATCH('Ratings by CLO'!$J13,'Master Ratings'!$B:$B,0),0)=0,"",INDEX('Master Ratings'!$E:$E, MATCH('Ratings by CLO'!$J13,'Master Ratings'!$B:$B,0),0)) | O13: =+IF(INDEX('Master Ratings'!$G:$G, MATCH('Ratings by CLO'!$J13,'Master Ratings'!$B:$B,0),0)=0,"",INDEX('Master Ratings'!$G:$G, MATCH('Ratings by CLO'!$J13,'Master Ratings'!$B:$B,0),0)) -> B-* | P13: =+IF(INDEX('Master Ratings'!$H:$H, MATCH('Ratings by CLO'!$J13,'Master Ratings'!$B:$B,0),0)=0,"",INDEX('Master Ratings'!$H:$H, MATCH('Ratings by CLO'!$J13,'Master Ratings'!$B:$B,0),0)) -> Credit Estimate | Q13: =+IF(INDEX('Master Ratings'!$O:$O, MATCH('Ratings by CLO'!$J13,'Master Ratings'!$B:$B,0),0)=0,"",INDEX('Master Ratings'!$O:$O, MATCH('Ratings by CLO'!$J13,'Master Ratings'!$B:$B,0),0)) -> 45077 | S13: =+IF(INDEX('Master Ratings'!$L:$L, MATCH('Ratings by CLO'!$J13,'Master Ratings'!$B:$B,0),0)=0,"",INDEX('Master Ratings'!$L:$L, MATCH('Ratings by CLO'!$J13,'Master Ratings'!$B:$B,0),0)) -> B- | T13: =+IF(INDEX('Master Ratings'!$M:$M, MATCH('Ratings by CLO'!$J13,'Master Ratings'!$B:$B,0),0)=0,"",INDEX('Master Ratings'!$M:$M, MATCH('Ratings by CLO'!$J13,'Master Ratings'!$B:$B,0),0)) -> Rating (Private) | U13: =+IF(INDEX('Master Ratings'!$P:$P, MATCH('Ratings by CLO'!$J13,'Master Ratings'!$B:$B,0),0)=0,"",INDEX('Master Ratings'!$P:$P, MATCH('Ratings by CLO'!$J13,'Master Ratings'!$B:$B,0),0)) -> 44886 | W13: =+IF(OR($P13=$W$1,$P13=$W$2),$Q13+365-TODAY(), "") -> -522 | X13: =+IF(OR($T13=$W$1,$T13=$W$2),$U13+365-TODAY(), "") -> -713 | Z13: =IF(AND(SUM(B13:H13)>=1,ISERROR(W13)),"X","") | AA13: =IF(AND(B13>1, ISERROR(X13)),"X","") | AB13: =+IFERROR(IF(W13<0,"X",""),"") -> X | AC13: =+IFERROR(IF(AND(B13>0, X13<0),"X",""),"") -> X | AE13: =+IF(SUM(B13:H13)=0,"X","") | AG13: =IF(Z13="X",AG12+1,AG12) -> 0 | AH13: =IF(AA13="X",AH12+1,AH12) -> 0 | AI13: =IF(AB13="X",AI12+1,AI12) -> 4 | AJ13: =IF(AC13="X",AJ12+1,AJ12) -> 5 | AL13: =AL12+1 -> 9 | AM13: =INDEX($J:$J, MATCH($AL13,AG:AG,0),0) -> TVC | AN13: =INDEX($J:$J, MATCH($AL13,AH:AH,0),0) -> Schlesinger | AO13: =INDEX($J:$J, MATCH($AL13,AI:AI,0),0) -> Exigo | AP13: =INDEX($J:$J, MATCH($AL13,AJ:AJ,0),0) -> By Light
B14: =+COUNTIFS(SOIs!$D:$D, 'Ratings by CLO'!$J14) -> 4 | C14: =+COUNTIFS(SOIs!$G:$G, 'Ratings by CLO'!$J14) -> 2 | D14: =+COUNTIFS(SOIs!$J:$J, 'Ratings by CLO'!$J14) -> 0 | E14: =+COUNTIFS(SOIs!$M:$M, 'Ratings by CLO'!$J14) -> 1 | F14: =+COUNTIFS(SOIs!$P:$P, 'Ratings by CLO'!$J14) -> 1 | G14: =+COUNTIFS(SOIs!$S:$S, 'Ratings by CLO'!$J14) -> 1 | H14: =+COUNTIFS(SOIs!$V:$V, 'Ratings by CLO'!$J14) -> 1 | J14: =+SOIs!X15 -> Applied Technical Services | L14: =+IF(INDEX('Master Ratings'!$D:$D, MATCH('Ratings by CLO'!$J14,'Master Ratings'!$B:$B,0),0)=0,"",INDEX('Master Ratings'!$D:$D, MATCH('Ratings by CLO'!$J14,'Master Ratings'!$B:$B,0),0)) | M14: =+IF(INDEX('Master Ratings'!$E:$E, MATCH('Ratings by CLO'!$J14,'Master Ratings'!$B:$B,0),0)=0,"",INDEX('Master Ratings'!$E:$E, MATCH('Ratings by CLO'!$J14,'Master Ratings'!$B:$B,0),0)) | O14: =+IF(INDEX('Master Ratings'!$G:$G, MATCH('Ratings by CLO'!$J14,'Master Ratings'!$B:$B,0),0)=0,"",INDEX('Master Ratings'!$G:$G, MATCH('Ratings by CLO'!$J14,'Master Ratings'!$B:$B,0),0)) -> B-* | P14: =+IF(INDEX('Master Ratings'!$H:$H, MATCH('Ratings by CLO'!$J14,'Master Ratings'!$B:$B,0),0)=0,"",INDEX('Master Ratings'!$H:$H, MATCH('Ratings by CLO'!$J14,'Master Ratings'!$B:$B,0),0)) -> Rating (Private) | Q14: =+IF(INDEX('Master Ratings'!$O:$O, MATCH('Ratings by CLO'!$J14,'Master Ratings'!$B:$B,0),0)=0,"",INDEX('Master Ratings'!$O:$O, MATCH('Ratings by CLO'!$J14,'Master Ratings'!$B:$B,0),0)) -> 45660 | S14: =+IF(INDEX('Master Ratings'!$L:$L, MATCH('Ratings by CLO'!$J14,'Master Ratings'!$B:$B,0),0)=0,"",INDEX('Master Ratings'!$L:$L, MATCH('Ratings by CLO'!$J14,'Master Ratings'!$B:$B,0),0)) -> B* | T14: =+IF(INDEX('Master Ratings'!$M:$M, MATCH('Ratings by CLO'!$J14,'Master Ratings'!$B:$B,0),0)=0,"",INDEX('Master Ratings'!$M:$M, MATCH('Ratings by CLO'!$J14,'Master Ratings'!$B:$B,0),0)) -> Credit Estimate | U14: =+IF(INDEX('Master Ratings'!$P:$P, MATCH('Ratings by CLO'!$J14,'Master Ratings'!$B:$B,0),0)=0,"",INDEX('Master Ratings'!$P:$P, MATCH('Ratings by CLO'!$J14,'Master Ratings'!$B:$B,0),0)) -> 45359 | W14: =+IF(OR($P14=$W$1,$P14=$W$2),$Q14+365-TODAY(), "") -> 61 | X14: =+IF(OR($T14=$W$1,$T14=$W$2),$U14+365-TODAY(), "") -> -240 | Z14: =IF(AND(SUM(B14:H14)>=1,ISERROR(W14)),"X","") | AA14: =IF(AND(B14>1, ISERROR(X14)),"X","") | AB14: =+IFERROR(IF(W14<0,"X",""),"") | AC14: =+IFERROR(IF(AND(B14>0, X14<0),"X",""),"") -> X | AE14: =+IF(SUM(B14:H14)=0,"X","") | AG14: =IF(Z14="X",AG13+1,AG13) -> 0 | AH14: =IF(AA14="X",AH13+1,AH13) -> 0 | AI14: =IF(AB14="X",AI13+1,AI13) -> 4 | AJ14: =IF(AC14="X",AJ13+1,AJ13) -> 6 | AL14: =AL13+1 -> 10 | AM14: =INDEX($J:$J, MATCH($AL14,AG:AG,0),0) -> #N/A | AN14: =INDEX($J:$J, MATCH($AL14,AH:AH,0),0) -> Sigma Defense | AO14: =INDEX($J:$J, MATCH($AL14,AI:AI,0),0) -> GCOM | AP14: =INDEX($J:$J, MATCH($AL14,AJ:AJ,0),0) -> Cartessa
B15: =+COUNTIFS(SOIs!$D:$D, 'Ratings by CLO'!$J15) -> 3 | C15: =+COUNTIFS(SOIs!$G:$G, 'Ratings by CLO'!$J15) -> 1 | D15: =+COUNTIFS(SOIs!$J:$J, 'Ratings by CLO'!$J15) -> 0 | E15: =+COUNTIFS(SOIs!$M:$M, 'Ratings by CLO'!$J15) -> 0 | F15: =+COUNTIFS(SOIs!$P:$P, 'Ratings by CLO'!$J15) -> 0 | G15: =+COUNTIFS(SOIs!$S:$S, 'Ratings by CLO'!$J15) -> 1 | H15: =+COUNTIFS(SOIs!$V:$V, 'Ratings by CLO'!$J15) -> 1 | J15: =+SOIs!X16 -> Arcfield | L15: =+IF(INDEX('Master Ratings'!$D:$D, MATCH('Ratings by CLO'!$J15,'Master Ratings'!$B:$B,0),0)=0,"",INDEX('Master Ratings'!$D:$D, MATCH('Ratings by CLO'!$J15,'Master Ratings'!$B:$B,0),0)) | M15: =+IF(INDEX('Master Ratings'!$E:$E, MATCH('Ratings by CLO'!$J15,'Master Ratings'!$B:$B,0),0)=0,"",INDEX('Master Ratings'!$E:$E, MATCH('Ratings by CLO'!$J15,'Master Ratings'!$B:$B,0),0)) | O15: =+IF(INDEX('Master Ratings'!$G:$G, MATCH('Ratings by CLO'!$J15,'Master Ratings'!$B:$B,0),0)=0,"",INDEX('Master Ratings'!$G:$G, MATCH('Ratings by CLO'!$J15,'Master Ratings'!$B:$B,0),0)) -> B-* | P15: =+IF(INDEX('Master Ratings'!$H:$H, MATCH('Ratings by CLO'!$J15,'Master Ratings'!$B:$B,0),0)=0,"",INDEX('Master Ratings'!$H:$H, MATCH('Ratings by CLO'!$J15,'Master Ratings'!$B:$B,0),0)) -> Credit Estimate | Q15: =+IF(INDEX('Master Ratings'!$O:$O, MATCH('Ratings by CLO'!$J15,'Master Ratings'!$B:$B,0),0)=0,"",INDEX('Master Ratings'!$O:$O, MATCH('Ratings by CLO'!$J15,'Master Ratings'!$B:$B,0),0)) -> 45684 | S15: =+IF(INDEX('Master Ratings'!$L:$L, MATCH('Ratings by CLO'!$J15,'Master Ratings'!$B:$B,0),0)=0,"",INDEX('Master Ratings'!$L:$L, MATCH('Ratings by CLO'!$J15,'Master Ratings'!$B:$B,0),0)) -> B | T15: =+IF(INDEX('Master Ratings'!$M:$M, MATCH('Ratings by CLO'!$J15,'Master Ratings'!$B:$B,0),0)=0,"",INDEX('Master Ratings'!$M:$M, MATCH('Ratings by CLO'!$J15,'Master Ratings'!$B:$B,0),0)) -> Rating (Private) | U15: =+IF(INDEX('Master Ratings'!$P:$P, MATCH('Ratings by CLO'!$J15,'Master Ratings'!$B:$B,0),0)=0,"",INDEX('Master Ratings'!$P:$P, MATCH('Ratings by CLO'!$J15,'Master Ratings'!$B:$B,0),0)) -> 45198 | W15: =+IF(OR($P15=$W$1,$P15=$W$2),$Q15+365-TODAY(), "") -> 85 | X15: =+IF(OR($T15=$W$1,$T15=$W$2),$U15+365-TODAY(), "") -> -401 | Z15: =IF(AND(SUM(B15:H15)>=1,ISERROR(W15)),"X","") | AA15: =IF(AND(B15>1, ISERROR(X15)),"X","") | AB15: =+IFERROR(IF(W15<0,"X",""),"") | AC15: =+IFERROR(IF(AND(B15>0, X15<0),"X",""),"") -> X | AE15: =+IF(SUM(B15:H15)=0,"X","") | AG15: =IF(Z15="X",AG14+1,AG14) -> 0 | AH15: =IF(AA15="X",AH14+1,AH14) -> 0 | AI15: =IF(AB15="X",AI14+1,AI14) -> 4 | AJ15: =IF(AC15="X",AJ14+1,AJ14) -> 7 | AL15: =AL14+1 -> 11 | AM15: =INDEX($J:$J, MATCH($AL15,AG:AG,0),0) -> #N/A | AN15: =INDEX($J:$J, MATCH($AL15,AH:AH,0),0) -> Signature Systems Group | AO15: =INDEX($J:$J, MATCH($AL15,AI:AI,0),0) -> IDC Infusion Services | AP15: =INDEX($J:$J, MATCH($AL15,AJ:AJ,0),0) -> Centauri Health
B16: =+COUNTIFS(SOIs!$D:$D, 'Ratings by CLO'!$J16) -> 0 | C16: =+COUNTIFS(SOIs!$G:$G, 'Ratings by CLO'!$J16) -> 0 | D16: =+COUNTIFS(SOIs!$J:$J, 'Ratings by CLO'!$J16) -> 0 | E16: =+COUNTIFS(SOIs!$M:$M, 'Ratings by CLO'!$J16) -> 0 | F16: =+COUNTIFS(SOIs!$P:$P, 'Ratings by CLO'!$J16) -> 0 | G16: =+COUNTIFS(SOIs!$S:$S, 'Ratings by CLO'!$J16) -> 1 | H16: =+COUNTIFS(SOIs!$V:$V, 'Ratings by CLO'!$J16) -> 1 | J16: =+SOIs!X17 -> Ardurra | L16: =+IF(INDEX('Master Ratings'!$D:$D, MATCH('Ratings by CLO'!$J16,'Master Ratings'!$B:$B,0),0)=0,"",INDEX('Master Ratings'!$D:$D, MATCH('Ratings by CLO'!$J16,'Master Ratings'!$B:$B,0),0)) | M16: =+IF(INDEX('Master Ratings'!$E:$E, MATCH('Ratings by CLO'!$J16,'Master Ratings'!$B:$B,0),0)=0,"",INDEX('Master Ratings'!$E:$E, MATCH('Ratings by CLO'!$J16,'Master Ratings'!$B:$B,0),0)) | O16: =+IF(INDEX('Master Ratings'!$G:$G, MATCH('Ratings by CLO'!$J16,'Master Ratings'!$B:$B,0),0)=0,"",INDEX('Master Ratings'!$G:$G, MATCH('Ratings by CLO'!$J16,'Master Ratings'!$B:$B,0),0)) -> B-* | P16: =+IF(INDEX('Master Ratings'!$H:$H, MATCH('Ratings by CLO'!$J16,'Master Ratings'!$B:$B,0),0)=0,"",INDEX('Master Ratings'!$H:$H, MATCH('Ratings by CLO'!$J16,'Master Ratings'!$B:$B,0),0)) -> Credit Estimate | Q16: =+IF(INDEX('Master Ratings'!$O:$O, MATCH('Ratings by CLO'!$J16,'Master Ratings'!$B:$B,0),0)=0,"",INDEX('Master Ratings'!$O:$O, MATCH('Ratings by CLO'!$J16,'Master Ratings'!$B:$B,0),0)) -> 45657 | S16: =+IF(INDEX('Master Ratings'!$L:$L, MATCH('Ratings by CLO'!$J16,'Master Ratings'!$B:$B,0),0)=0,"",INDEX('Master Ratings'!$L:$L, MATCH('Ratings by CLO'!$J16,'Master Ratings'!$B:$B,0),0)) | T16: =+IF(INDEX('Master Ratings'!$M:$M, MATCH('Ratings by CLO'!$J16,'Master Ratings'!$B:$B,0),0)=0,"",INDEX('Master Ratings'!$M:$M, MATCH('Ratings by CLO'!$J16,'Master Ratings'!$B:$B,0),0)) | U16: =+IF(INDEX('Master Ratings'!$P:$P, MATCH('Ratings by CLO'!$J16,'Master Ratings'!$B:$B,0),0)=0,"",INDEX('Master Ratings'!$P:$P, MATCH('Ratings by CLO'!$J16,'Master Ratings'!$B:$B,0),0)) | W16: =+IF(OR($P16=$W$1,$P16=$W$2),$Q16+365-TODAY(), "") -> 58 | X16: =+IF(OR($T16=$W$1,$T16=$W$2),$U16+365-TODAY(), "") | Z16: =IF(AND(SUM(B16:H16)>=1,ISERROR(W16)),"X","") | AA16: =IF(AND(B16>1, ISERROR(X16)),"X","") | AB16: =+IFERROR(IF(W16<0,"X",""),"") | AC16: =+IFERROR(IF(AND(B16>0, X16<0),"X",""),"") | AE16: =+IF(SUM(B16:H16)=0,"X","") | AG16: =IF(Z16="X",AG15+1,AG15) -> 0 | AH16: =IF(AA16="X",AH15+1,AH15) -> 0 | AI16: =IF(AB16="X",AI15+1,AI15) -> 4 | AJ16: =IF(AC16="X",AJ15+1,AJ15) -> 7 | AL16: =AL15+1 -> 12 | AM16: =INDEX($J:$J, MATCH($AL16,AG:AG,0),0) -> #N/A | AN16: =INDEX($J:$J, MATCH($AL16,AH:AH,0),0) -> Targeted Pet Care | AO16: =INDEX($J:$J, MATCH($AL16,AI:AI,0),0) -> Insight Global | AP16: =INDEX($J:$J, MATCH($AL16,AJ:AJ,0),0) -> Crane 1
B17: =+COUNTIFS(SOIs!$D:$D, 'Ratings by CLO'!$J17) -> 1 | C17: =+COUNTIFS(SOIs!$G:$G, 'Ratings by CLO'!$J17) -> 0 | D17: =+COUNTIFS(SOIs!$J:$J, 'Ratings by CLO'!$J17) -> 1 | E17: =+COUNTIFS(SOIs!$M:$M, 'Ratings by CLO'!$J17) -> 0 | F17: =+COUNTIFS(SOIs!$P:$P, 'Ratings by CLO'!$J17) -> 2 | G17: =+COUNTIFS(SOIs!$S:$S, 'Ratings by CLO'!$J17) -> 0 | H17: =+COUNTIFS(SOIs!$V:$V, 'Ratings by CLO'!$J17) -> 0 | J17: =+SOIs!X18 -> Ascensus | L17: =+IF(INDEX('Master Ratings'!$D:$D, MATCH('Ratings by CLO'!$J17,'Master Ratings'!$B:$B,0),0)=0,"",INDEX('Master Ratings'!$D:$D, MATCH('Ratings by CLO'!$J17,'Master Ratings'!$B:$B,0),0)) -> B3 | M17: =+IF(INDEX('Master Ratings'!$E:$E, MATCH('Ratings by CLO'!$J17,'Master Ratings'!$B:$B,0),0)=0,"",INDEX('Master Ratings'!$E:$E, MATCH('Ratings by CLO'!$J17,'Master Ratings'!$B:$B,0),0)) -> Rating (Public) | O17: =+IF(INDEX('Master Ratings'!$G:$G, MATCH('Ratings by CLO'!$J17,'Master Ratings'!$B:$B,0),0)=0,"",INDEX('Master Ratings'!$G:$G, MATCH('Ratings by CLO'!$J17,'Master Ratings'!$B:$B,0),0)) -> B- | P17: =+IF(INDEX('Master Ratings'!$H:$H, MATCH('Ratings by CLO'!$J17,'Master Ratings'!$B:$B,0),0)=0,"",INDEX('Master Ratings'!$H:$H, MATCH('Ratings by CLO'!$J17,'Master Ratings'!$B:$B,0),0)) -> Rating (Public) | Q17: =+IF(INDEX('Master Ratings'!$O:$O, MATCH('Ratings by CLO'!$J17,'Master Ratings'!$B:$B,0),0)=0,"",INDEX('Master Ratings'!$O:$O, MATCH('Ratings by CLO'!$J17,'Master Ratings'!$B:$B,0),0)) | S17: =+IF(INDEX('Master Ratings'!$L:$L, MATCH('Ratings by CLO'!$J17,'Master Ratings'!$B:$B,0),0)=0,"",INDEX('Master Ratings'!$L:$L, MATCH('Ratings by CLO'!$J17,'Master Ratings'!$B:$B,0),0)) | T17: =+IF(INDEX('Master Ratings'!$M:$M, MATCH('Ratings by CLO'!$J17,'Master Ratings'!$B:$B,0),0)=0,"",INDEX('Master Ratings'!$M:$M, MATCH('Ratings by CLO'!$J17,'Master Ratings'!$B:$B,0),0)) | U17: =+IF(INDEX('Master Ratings'!$P:$P, MATCH('Ratings by CLO'!$J17,'Master Ratings'!$B:$B,0),0)=0,"",INDEX('Master Ratings'!$P:$P, MATCH('Ratings by CLO'!$J17,'Master Ratings'!$B:$B,0),0)) | W17: =+IF(OR($P17=$W$1,$P17=$W$2),$Q17+365-TODAY(), "") | X17: =+IF(OR($T17=$W$1,$T17=$W$2),$U17+365-TODAY(), "") | Z17: =IF(AND(SUM(B17:H17)>=1,ISERROR(W17)),"X","") | AA17: =IF(AND(B17>1, ISERROR(X17)),"X","") | AB17: =+IFERROR(IF(W17<0,"X",""),"") | AC17: =+IFERROR(IF(AND(B17>0, X17<0),"X",""),"") | AE17: =+IF(SUM(B17:H17)=0,"X","") | AG17: =IF(Z17="X",AG16+1,AG16) -> 0 | AH17: =IF(AA17="X",AH16+1,AH16) -> 0 | AI17: =IF(AB17="X",AI16+1,AI16) -> 4 | AJ17: =IF(AC17="X",AJ16+1,AJ16) -> 7 | AL17: =AL16+1 -> 13 | AM17: =INDEX($J:$J, MATCH($AL17,AG:AG,0),0) -> #N/A | AN17: =INDEX($J:$J, MATCH($AL17,AH:AH,0),0) -> Vertex | AO17: =INDEX($J:$J, MATCH($AL17,AI:AI,0),0) -> Integrity Marketing | AP17: =INDEX($J:$J, MATCH($AL17,AJ:AJ,0),0) -> Dr. Scholl's
... B26: =+COUNTIFS(SOIs!$D:$D, 'Ratings by CLO'!$J26) -> 0 | C26: =+COUNTIFS(SOIs!$G:$G, 'Ratings by CLO'!$J26) -> 0 | D26: =+COUNTIFS(SOIs!$J:$J, 'Ratings by CLO'!$J26) -> 0 | E26: =+COUNTIFS(SOIs!$M:$M, 'Ratings by CLO'!$J26) -> 0 | F26: =+COUNTIFS(SOIs!$P:$P, 'Ratings by CLO'!$J26) -> 0 | G26: =+COUNTIFS(SOIs!$S:$S, 'Ratings by CLO'!$J26) -> 1 | H26: =+COUNTIFS(SOIs!$V:$V, 'Ratings by CLO'!$J26) -> 0 | J26: =+SOIs!X27 -> Cadence Aerospace | L26: =+IF(INDEX('Master Ratings'!$D:$D, MATCH('Ratings by CLO'!$J26,'Master Ratings'!$B:$B,0),0)=0,"",INDEX('Master Ratings'!$D:$D, MATCH('Ratings by CLO'!$J26,'Master Ratings'!$B:$B,0),0)) | M26: =+IF(INDEX('Master Ratings'!$E:$E, MATCH('Ratings by CLO'!$J26,'Master Ratings'!$B:$B,0),0)=0,"",INDEX('Master Ratings'!$E:$E, MATCH('Ratings by CLO'!$J26,'Master Ratings'!$B:$B,0),0)) | O26: =+IF(INDEX('Master Ratings'!$G:$G, MATCH('Ratings by CLO'!$J26,'Master Ratings'!$B:$B,0),0)=0,"",INDEX('Master Ratings'!$G:$G, MATCH('Ratings by CLO'!$J26,'Master Ratings'!$B:$B,0),0)) -> B-* | P26: =+IF(INDEX('Master Ratings'!$H:$H, MATCH('Ratings by CLO'!$J26,'Master Ratings'!$B:$B,0),0)=0,"",INDEX('Master Ratings'!$H:$H, MATCH('Ratings by CLO'!$J26,'Master Ratings'!$B:$B,0),0)) -> Credit Estimate | Q26: =+IF(INDEX('Master Ratings'!$O:$O, MATCH('Ratings by CLO'!$J26,'Master Ratings'!$B:$B,0),0)=0,"",INDEX('Master Ratings'!$O:$O, MATCH('Ratings by CLO'!$J26,'Master Ratings'!$B:$B,0),0)) -> 43846 | S26: =+IF(INDEX('Master Ratings'!$L:$L, MATCH('Ratings by CLO'!$J26,'Master Ratings'!$B:$B,0),0)=0,"",INDEX('Master Ratings'!$L:$L, MATCH('Ratings by CLO'!$J26,'Master Ratings'!$B:$B,0),0)) -> B-* | T26: =+IF(INDEX('Master Ratings'!$M:$M, MATCH('Ratings by CLO'!$J26,'Master Ratings'!$B:$B,0),0)=0,"",INDEX('Master Ratings'!$M:$M, MATCH('Ratings by CLO'!$J26,'Master Ratings'!$B:$B,0),0)) -> Credit Estimate | U26: =+IF(INDEX('Master Ratings'!$P:$P, MATCH('Ratings by CLO'!$J26,'Master Ratings'!$B:$B,0),0)=0,"",INDEX('Master Ratings'!$P:$P, MATCH('Ratings by CLO'!$J26,'Master Ratings'!$B:$B,0),0)) -> 43816 | W26: =+IF(OR($P26=$W$1,$P26=$W$2),$Q26+365-TODAY(), "") -> -1753 | X26: =+IF(OR($T26=$W$1,$T26=$W$2),$U26+365-TODAY(), "") -> -1783 | Z26: =IF(AND(SUM(B26:H26)>=1,ISERROR(W26)),"X","") | AA26: =IF(AND(B26>1, ISERROR(X26)),"X","") | AB26: =+IFERROR(IF(W26<0,"X",""),"") -> X | AC26: =+IFERROR(IF(AND(B26>0, X26<0),"X",""),"") | AE26: =+IF(SUM(B26:H26)=0,"X","") | AG26: =IF(Z26="X",AG25+1,AG25) -> 0 | AH26: =IF(AA26="X",AH25+1,AH25) -> 1 | AI26: =IF(AB26="X",AI25+1,AI25) -> 7 | AJ26: =IF(AC26="X",AJ25+1,AJ25) -> 9 | AL26: =AL25+1 -> 22 | AM26: =INDEX($J:$J, MATCH($AL26,AG:AG,0),0) -> #N/A | AN26: =INDEX($J:$J, MATCH($AL26,AH:AH,0),0) -> #N/A | AO26: =INDEX($J:$J, MATCH($AL26,AI:AI,0),0) -> Ox | AP26: =INDEX($J:$J, MATCH($AL26,AJ:AJ,0),0) -> Inventus
B27: =+COUNTIFS(SOIs!$D:$D, 'Ratings by CLO'!$J27) -> 4 | C27: =+COUNTIFS(SOIs!$G:$G, 'Ratings by CLO'!$J27) -> 1 | D27: =+COUNTIFS(SOIs!$J:$J, 'Ratings by CLO'!$J27) -> 1 | E27: =+COUNTIFS(SOIs!$M:$M, 'Ratings by CLO'!$J27) -> 1 | F27: =+COUNTIFS(SOIs!$P:$P, 'Ratings by CLO'!$J27) -> 1 | G27: =+COUNTIFS(SOIs!$S:$S, 'Ratings by CLO'!$J27) -> 1 | H27: =+COUNTIFS(SOIs!$V:$V, 'Ratings by CLO'!$J27) -> 1 | J27: =+SOIs!X28 -> Cartessa | L27: =+IF(INDEX('Master Ratings'!$D:$D, MATCH('Ratings by CLO'!$J27,'Master Ratings'!$B:$B,0),0)=0,"",INDEX('Master Ratings'!$D:$D, MATCH('Ratings by CLO'!$J27,'Master Ratings'!$B:$B,0),0)) | M27: =+IF(INDEX('Master Ratings'!$E:$E, MATCH('Ratings by CLO'!$J27,'Master Ratings'!$B:$B,0),0)=0,"",INDEX('Master Ratings'!$E:$E, MATCH('Ratings by CLO'!$J27,'Master Ratings'!$B:$B,0),0)) | O27: =+IF(INDEX('Master Ratings'!$G:$G, MATCH('Ratings by CLO'!$J27,'Master Ratings'!$B:$B,0),0)=0,"",INDEX('Master Ratings'!$G:$G, MATCH('Ratings by CLO'!$J27,'Master Ratings'!$B:$B,0),0)) -> B-* | P27: =+IF(INDEX('Master Ratings'!$H:$H, MATCH('Ratings by CLO'!$J27,'Master Ratings'!$B:$B,0),0)=0,"",INDEX('Master Ratings'!$H:$H, MATCH('Ratings by CLO'!$J27,'Master Ratings'!$B:$B,0),0)) -> Credit Estimate | Q27: =+IF(INDEX('Master Ratings'!$O:$O, MATCH('Ratings by CLO'!$J27,'Master Ratings'!$B:$B,0),0)=0,"",INDEX('Master Ratings'!$O:$O, MATCH('Ratings by CLO'!$J27,'Master Ratings'!$B:$B,0),0)) -> 45750 | S27: =+IF(INDEX('Master Ratings'!$L:$L, MATCH('Ratings by CLO'!$J27,'Master Ratings'!$B:$B,0),0)=0,"",INDEX('Master Ratings'!$L:$L, MATCH('Ratings by CLO'!$J27,'Master Ratings'!$B:$B,0),0)) -> B-* | T27: =+IF(INDEX('Master Ratings'!$M:$M, MATCH('Ratings by CLO'!$J27,'Master Ratings'!$B:$B,0),0)=0,"",INDEX('Master Ratings'!$M:$M, MATCH('Ratings by CLO'!$J27,'Master Ratings'!$B:$B,0),0)) -> Credit Estimate | U27: =+IF(INDEX('Master Ratings'!$P:$P, MATCH('Ratings by CLO'!$J27,'Master Ratings'!$B:$B,0),0)=0,"",INDEX('Master Ratings'!$P:$P, MATCH('Ratings by CLO'!$J27,'Master Ratings'!$B:$B,0),0)) -> 45107 | W27: =+IF(OR($P27=$W$1,$P27=$W$2),$Q27+365-TODAY(), "") -> 151 | X27: =+IF(OR($T27=$W$1,$T27=$W$2),$U27+365-TODAY(), "") -> -492 | Z27: =IF(AND(SUM(B27:H27)>=1,ISERROR(W27)),"X","") | AA27: =IF(AND(B27>1, ISERROR(X27)),"X","") | AB27: =+IFERROR(IF(W27<0,"X",""),"") | AC27: =+IFERROR(IF(AND(B27>0, X27<0),"X",""),"") -> X | AE27: =+IF(SUM(B27:H27)=0,"X","") | AG27: =IF(Z27="X",AG26+1,AG26) -> 0 | AH27: =IF(AA27="X",AH26+1,AH26) -> 1 | AI27: =IF(AB27="X",AI26+1,AI26) -> 7 | AJ27: =IF(AC27="X",AJ26+1,AJ26) -> 10
B28: =+COUNTIFS(SOIs!$D:$D, 'Ratings by CLO'!$J28) -> 4 | C28: =+COUNTIFS(SOIs!$G:$G, 'Ratings by CLO'!$J28) -> 1 | D28: =+COUNTIFS(SOIs!$J:$J, 'Ratings by CLO'!$J28) -> 1 | E28: =+COUNTIFS(SOIs!$M:$M, 'Ratings by CLO'!$J28) -> 1 | F28: =+COUNTIFS(SOIs!$P:$P, 'Ratings by CLO'!$J28) -> 1 | G28: =+COUNTIFS(SOIs!$S:$S, 'Ratings by CLO'!$J28) -> 1 | H28: =+COUNTIFS(SOIs!$V:$V, 'Ratings by CLO'!$J28) -> 1 | J28: =+SOIs!X29 -> Centauri Health | L28: =+IF(INDEX('Master Ratings'!$D:$D, MATCH('Ratings by CLO'!$J28,'Master Ratings'!$B:$B,0),0)=0,"",INDEX('Master Ratings'!$D:$D, MATCH('Ratings by CLO'!$J28,'Master Ratings'!$B:$B,0),0)) | M28: =+IF(INDEX('Master Ratings'!$E:$E, MATCH('Ratings by CLO'!$J28,'Master Ratings'!$B:$B,0),0)=0,"",INDEX('Master Ratings'!$E:$E, MATCH('Ratings by CLO'!$J28,'Master Ratings'!$B:$B,0),0)) | O28: =+IF(INDEX('Master Ratings'!$G:$G, MATCH('Ratings by CLO'!$J28,'Master Ratings'!$B:$B,0),0)=0,"",INDEX('Master Ratings'!$G:$G, MATCH('Ratings by CLO'!$J28,'Master Ratings'!$B:$B,0),0)) -> B-* | P28: =+IF(INDEX('Master Ratings'!$H:$H, MATCH('Ratings by CLO'!$J28,'Master Ratings'!$B:$B,0),0)=0,"",INDEX('Master Ratings'!$H:$H, MATCH('Ratings by CLO'!$J28,'Master Ratings'!$B:$B,0),0)) -> Credit Estimate | Q28: =+IF(INDEX('Master Ratings'!$O:$O, MATCH('Ratings by CLO'!$J28,'Master Ratings'!$B:$B,0),0)=0,"",INDEX('Master Ratings'!$O:$O, MATCH('Ratings by CLO'!$J28,'Master Ratings'!$B:$B,0),0)) -> 45693 | S28: =+IF(INDEX('Master Ratings'!$L:$L, MATCH('Ratings by CLO'!$J28,'Master Ratings'!$B:$B,0),0)=0,"",INDEX('Master Ratings'!$L:$L, MATCH('Ratings by CLO'!$J28,'Master Ratings'!$B:$B,0),0)) -> B* | T28: =+IF(INDEX('Master Ratings'!$M:$M, MATCH('Ratings by CLO'!$J28,'Master Ratings'!$B:$B,0),0)=0,"",INDEX('Master Ratings'!$M:$M, MATCH('Ratings by CLO'!$J28,'Master Ratings'!$B:$B,0),0)) -> Credit Estimate | U28: =+IF(INDEX('Master Ratings'!$P:$P, MATCH('Ratings by CLO'!$J28,'Master Ratings'!$B:$B,0),0)=0,"",INDEX('Master Ratings'!$P:$P, MATCH('Ratings by CLO'!$J28,'Master Ratings'!$B:$B,0),0)) -> 45121 | W28: =+IF(OR($P28=$W$1,$P28=$W$2),$Q28+365-TODAY(), "") -> 94 | X28: =+IF(OR($T28=$W$1,$T28=$W$2),$U28+365-TODAY(), "") -> -478 | Z28: =IF(AND(SUM(B28:H28)>=1,ISERROR(W28)),"X","") | AA28: =IF(AND(B28>1, ISERROR(X28)),"X","") | AB28: =+IFERROR(IF(W28<0,"X",""),"") | AC28: =+IFERROR(IF(AND(B28>0, X28<0),"X",""),"") -> X | AE28: =+IF(SUM(B28:H28)=0,"X","") | AG28: =IF(Z28="X",AG27+1,AG27) -> 0 | AH28: =IF(AA28="X",AH27+1,AH27) -> 1 | AI28: =IF(AB28="X",AI27+1,AI27) -> 7 | AJ28: =IF(AC28="X",AJ27+1,AJ27) -> 11
B29: =+COUNTIFS(SOIs!$D:$D, 'Ratings by CLO'!$J29) -> 0 | C29: =+COUNTIFS(SOIs!$G:$G, 'Ratings by CLO'!$J29) -> 0 | D29: =+COUNTIFS(SOIs!$J:$J, 'Ratings by CLO'!$J29) -> 0 | E29: =+COUNTIFS(SOIs!$M:$M, 'Ratings by CLO'!$J29) -> 0 | F29: =+COUNTIFS(SOIs!$P:$P, 'Ratings by CLO'!$J29) -> 1 | G29: =+COUNTIFS(SOIs!$S:$S, 'Ratings by CLO'!$J29) -> 0 | H29: =+COUNTIFS(SOIs!$V:$V, 'Ratings by CLO'!$J29) -> 0 | J29: =+SOIs!X30 -> Compex Legal | L29: =+IF(INDEX('Master Ratings'!$D:$D, MATCH('Ratings by CLO'!$J29,'Master Ratings'!$B:$B,0),0)=0,"",INDEX('Master Ratings'!$D:$D, MATCH('Ratings by CLO'!$J29,'Master Ratings'!$B:$B,0),0)) | M29: =+IF(INDEX('Master Ratings'!$E:$E, MATCH('Ratings by CLO'!$J29,'Master Ratings'!$B:$B,0),0)=0,"",INDEX('Master Ratings'!$E:$E, MATCH('Ratings by CLO'!$J29,'Master Ratings'!$B:$B,0),0)) | O29: =+IF(INDEX('Master Ratings'!$G:$G, MATCH('Ratings by CLO'!$J29,'Master Ratings'!$B:$B,0),0)=0,"",INDEX('Master Ratings'!$G:$G, MATCH('Ratings by CLO'!$J29,'Master Ratings'!$B:$B,0),0)) -> B-* | P29: =+IF(INDEX('Master Ratings'!$H:$H, MATCH('Ratings by CLO'!$J29,'Master Ratings'!$B:$B,0),0)=0,"",INDEX('Master Ratings'!$H:$H, MATCH('Ratings by CLO'!$J29,'Master Ratings'!$B:$B,0),0)) -> Credit Estimate | Q29: =+IF(INDEX('Master Ratings'!$O:$O, MATCH('Ratings by CLO'!$J29,'Master Ratings'!$B:$B,0),0)=0,"",INDEX('Master Ratings'!$O:$O, MATCH('Ratings by CLO'!$J29,'Master Ratings'!$B:$B,0),0)) -> 45623 | S29: =+IF(INDEX('Master Ratings'!$L:$L, MATCH('Ratings by CLO'!$J29,'Master Ratings'!$B:$B,0),0)=0,"",INDEX('Master Ratings'!$L:$L, MATCH('Ratings by CLO'!$J29,'Master Ratings'!$B:$B,0),0)) | T29: =+IF(INDEX('Master Ratings'!$M:$M, MATCH('Ratings by CLO'!$J29,'Master Ratings'!$B:$B,0),0)=0,"",INDEX('Master Ratings'!$M:$M, MATCH('Ratings by CLO'!$J29,'Master Ratings'!$B:$B,0),0)) | U29: =+IF(INDEX('Master Ratings'!$P:$P, MATCH('Ratings by CLO'!$J29,'Master Ratings'!$B:$B,0),0)=0,"",INDEX('Master Ratings'!$P:$P, MATCH('Ratings by CLO'!$J29,'Master Ratings'!$B:$B,0),0)) | W29: =+IF(OR($P29=$W$1,$P29=$W$2),$Q29+365-TODAY(), "") -> 24 | X29: =+IF(OR($T29=$W$1,$T29=$W$2),$U29+365-TODAY(), "") | Z29: =IF(AND(SUM(B29:H29)>=1,ISERROR(W29)),"X","") | AA29: =IF(AND(B29>1, ISERROR(X29)),"X","") | AB29: =+IFERROR(IF(W29<0,"X",""),"") | AC29: =+IFERROR(IF(AND(B29>0, X29<0),"X",""),"") | AE29: =+IF(SUM(B29:H29)=0,"X","") | AG29: =IF(Z29="X",AG28+1,AG28) -> 0 | AH29: =IF(AA29="X",AH28+1,AH28) -> 1 | AI29: =IF(AB29="X",AI28+1,AI28) -> 7 | AJ29: =IF(AC29="X",AJ28+1,AJ28) -> 11
B30: =+COUNTIFS(SOIs!$D:$D, 'Ratings by CLO'!$J30) -> 4 | C30: =+COUNTIFS(SOIs!$G:$G, 'Ratings by CLO'!$J30) -> 1 | D30: =+COUNTIFS(SOIs!$J:$J, 'Ratings by CLO'!$J30) -> 1 | E30: =+COUNTIFS(SOIs!$M:$M, 'Ratings by CLO'!$J30) -> 1 | F30: =+COUNTIFS(SOIs!$P:$P, 'Ratings by CLO'!$J30) -> 1 | G30: =+COUNTIFS(SOIs!$S:$S, 'Ratings by CLO'!$J30) -> 0 | H30: =+COUNTIFS(SOIs!$V:$V, 'Ratings by CLO'!$J30) -> 1 | J30: =+SOIs!X31 -> Connatix | L30: =+IF(INDEX('Master Ratings'!$D:$D, MATCH('Ratings by CLO'!$J30,'Master Ratings'!$B:$B,0),0)=0,"",INDEX('Master Ratings'!$D:$D, MATCH('Ratings by CLO'!$J30,'Master Ratings'!$B:$B,0),0)) | M30: =+IF(INDEX('Master Ratings'!$E:$E, MATCH('Ratings by CLO'!$J30,'Master Ratings'!$B:$B,0),0)=0,"",INDEX('Master Ratings'!$E:$E, MATCH('Ratings by CLO'!$J30,'Master Ratings'!$B:$B,0),0)) | O30: =+IF(INDEX('Master Ratings'!$G:$G, MATCH('Ratings by CLO'!$J30,'Master Ratings'!$B:$B,0),0)=0,"",INDEX('Master Ratings'!$G:$G, MATCH('Ratings by CLO'!$J30,'Master Ratings'!$B:$B,0),0)) -> B-* | P30: =+IF(INDEX('Master Ratings'!$H:$H, MATCH('Ratings by CLO'!$J30,'Master Ratings'!$B:$B,0),0)=0,"",INDEX('Master Ratings'!$H:$H, MATCH('Ratings by CLO'!$J30,'Master Ratings'!$B:$B,0),0)) -> Credit Estimate | Q30: =+IF(INDEX('Master Ratings'!$O:$O, MATCH('Ratings by CLO'!$J30,'Master Ratings'!$B:$B,0),0)=0,"",INDEX('Master Ratings'!$O:$O, MATCH('Ratings by CLO'!$J30,'Master Ratings'!$B:$B,0),0)) -> 45483 | S30: =+IF(INDEX('Master Ratings'!$L:$L, MATCH('Ratings by CLO'!$J30,'Master Ratings'!$B:$B,0),0)=0,"",INDEX('Master Ratings'!$L:$L, MATCH('Ratings by CLO'!$J30,'Master Ratings'!$B:$B,0),0)) -> B-* | T30: =+IF(INDEX('Master Ratings'!$M:$M, MATCH('Ratings by CLO'!$J30,'Master Ratings'!$B:$B,0),0)=0,"",INDEX('Master Ratings'!$M:$M, MATCH('Ratings by CLO'!$J30,'Master Ratings'!$B:$B,0),0)) -> Credit Estimate | U30: =+IF(INDEX('Master Ratings'!$P:$P, MATCH('Ratings by CLO'!$J30,'Master Ratings'!$B:$B,0),0)=0,"",INDEX('Master Ratings'!$P:$P, MATCH('Ratings by CLO'!$J30,'Master Ratings'!$B:$B,0),0)) -> 12.8.2023 | W30: =+IF(OR($P30=$W$1,$P30=$W$2),$Q30+365-TODAY(), "") -> -116 | X30: =+IF(OR($T30=$W$1,$T30=$W$2),$U30+365-TODAY(), "") -> #VALUE! | Z30: =IF(AND(SUM(B30:H30)>=1,ISERROR(W30)),"X","") | AA30: =IF(AND(B30>1, ISERROR(X30)),"X","") -> X | AB30: =+IFERROR(IF(W30<0,"X",""),"") -> X | AC30: =+IFERROR(IF(AND(B30>0, X30<0),"X",""),"") | AE30: =+IF(SUM(B30:H30)=0,"X","") | AG30: =IF(Z30="X",AG29+1,AG29) -> 0 | AH30: =IF(AA30="X",AH29+1,AH29) -> 2 | AI30: =IF(AB30="X",AI29+1,AI29) -> 8 | AJ30: =IF(AC30="X",AJ29+1,AJ29) -> 11
B31: =+COUNTIFS(SOIs!$D:$D, 'Ratings by CLO'!$J31) -> 3 | C31: =+COUNTIFS(SOIs!$G:$G, 'Ratings by CLO'!$J31) -> 1 | D31: =+COUNTIFS(SOIs!$J:$J, 'Ratings by CLO'!$J31) -> 0 | E31: =+COUNTIFS(SOIs!$M:$M, 'Ratings by CLO'!$J31) -> 0 | F31: =+COUNTIFS(SOIs!$P:$P, 'Ratings by CLO'!$J31) -> 1 | G31: =+COUNTIFS(SOIs!$S:$S, 'Ratings by CLO'!$J31) -> 1 | H31: =+COUNTIFS(SOIs!$V:$V, 'Ratings by CLO'!$J31) -> 1 | J31: =+SOIs!X32 -> Consilio | L31: =+IF(INDEX('Master Ratings'!$D:$D, MATCH('Ratings by CLO'!$J31,'Master Ratings'!$B:$B,0),0)=0,"",INDEX('Master Ratings'!$D:$D, MATCH('Ratings by CLO'!$J31,'Master Ratings'!$B:$B,0),0)) -> B3 | M31: =+IF(INDEX('Master Ratings'!$E:$E, MATCH('Ratings by CLO'!$J31,'Master Ratings'!$B:$B,0),0)=0,"",INDEX('Master Ratings'!$E:$E, MATCH('Ratings by CLO'!$J31,'Master Ratings'!$B:$B,0),0)) -> Rating (Public) | O31: =+IF(INDEX('Master Ratings'!$G:$G, MATCH('Ratings by CLO'!$J31,'Master Ratings'!$B:$B,0),0)=0,"",INDEX('Master Ratings'!$G:$G, MATCH('Ratings by CLO'!$J31,'Master Ratings'!$B:$B,0),0)) -> B- | P31: =+IF(INDEX('Master Ratings'!$H:$H, MATCH('Ratings by CLO'!$J31,'Master Ratings'!$B:$B,0),0)=0,"",INDEX('Master Ratings'!$H:$H, MATCH('Ratings by CLO'!$J31,'Master Ratings'!$B:$B,0),0)) -> Rating (Public) | Q31: =+IF(INDEX('Master Ratings'!$O:$O, MATCH('Ratings by CLO'!$J31,'Master Ratings'!$B:$B,0),0)=0,"",INDEX('Master Ratings'!$O:$O, MATCH('Ratings by CLO'!$J31,'Master Ratings'!$B:$B,0),0)) | S31: =+IF(INDEX('Master Ratings'!$L:$L, MATCH('Ratings by CLO'!$J31,'Master Ratings'!$B:$B,0),0)=0,"",INDEX('Master Ratings'!$L:$L, MATCH('Ratings by CLO'!$J31,'Master Ratings'!$B:$B,0),0)) | T31: =+IF(INDEX('Master Ratings'!$M:$M, MATCH('Ratings by CLO'!$J31,'Master Ratings'!$B:$B,0),0)=0,"",INDEX('Master Ratings'!$M:$M, MATCH('Ratings by CLO'!$J31,'Master Ratings'!$B:$B,0),0)) | U31: =+IF(INDEX('Master Ratings'!$P:$P, MATCH('Ratings by CLO'!$J31,'Master Ratings'!$B:$B,0),0)=0,"",INDEX('Master Ratings'!$P:$P, MATCH('Ratings by CLO'!$J31,'Master Ratings'!$B:$B,0),0)) | W31: =+IF(OR($P31=$W$1,$P31=$W$2),$Q31+365-TODAY(), "") | X31: =+IF(OR($T31=$W$1,$T31=$W$2),$U31+365-TODAY(), "") | Z31: =IF(AND(SUM(B31:H31)>=1,ISERROR(W31)),"X","") | AA31: =IF(AND(B31>1, ISERROR(X31)),"X","") | AB31: =+IFERROR(IF(W31<0,"X",""),"") | AC31: =+IFERROR(IF(AND(B31>0, X31<0),"X",""),"") | AE31: =+IF(SUM(B31:H31)=0,"X","") | AG31: =IF(Z31="X",AG30+1,AG30) -> 0 | AH31: =IF(AA31="X",AH30+1,AH30) -> 2 | AI31: =IF(AB31="X",AI30+1,AI30) -> 8 | AJ31: =IF(AC31="X",AJ30+1,AJ30) -> 11
B32: =+COUNTIFS(SOIs!$D:$D, 'Ratings by CLO'!$J32) -> 1 | C32: =+COUNTIFS(SOIs!$G:$G, 'Ratings by CLO'!$J32) -> 0 | D32: =+COUNTIFS(SOIs!$J:$J, 'Ratings by CLO'!$J32) -> 1 | E32: =+COUNTIFS(SOIs!$M:$M, 'Ratings by CLO'!$J32) -> 0 | F32: =+COUNTIFS(SOIs!$P:$P, 'Ratings by CLO'!$J32) -> 1 | G32: =+COUNTIFS(SOIs!$S:$S, 'Ratings by CLO'!$J32) -> 0 | H32: =+COUNTIFS(SOIs!$V:$V, 'Ratings by CLO'!$J32) -> 0 | J32: =+SOIs!X33 -> Convergint | L32: =+IF(INDEX('Master Ratings'!$D:$D, MATCH('Ratings by CLO'!$J32,'Master Ratings'!$B:$B,0),0)=0,"",INDEX('Master Ratings'!$D:$D, MATCH('Ratings by CLO'!$J32,'Master Ratings'!$B:$B,0),0)) | M32: =+IF(INDEX('Master Ratings'!$E:$E, MATCH('Ratings by CLO'!$J32,'Master Ratings'!$B:$B,0),0)=0,"",INDEX('Master Ratings'!$E:$E, MATCH('Ratings by CLO'!$J32,'Master Ratings'!$B:$B,0),0)) | O32: =+IF(INDEX('Master Ratings'!$G:$G, MATCH('Ratings by CLO'!$J32,'Master Ratings'!$B:$B,0),0)=0,"",INDEX('Master Ratings'!$G:$G, MATCH('Ratings by CLO'!$J32,'Master Ratings'!$B:$B,0),0)) -> B- | P32: =+IF(INDEX('Master Ratings'!$H:$H, MATCH('Ratings by CLO'!$J32,'Master Ratings'!$B:$B,0),0)=0,"",INDEX('Master Ratings'!$H:$H, MATCH('Ratings by CLO'!$J32,'Master Ratings'!$B:$B,0),0)) -> Rating (Public) | Q32: =+IF(INDEX('Master Ratings'!$O:$O, MATCH('Ratings by CLO'!$J32,'Master Ratings'!$B:$B,0),0)=0,"",INDEX('Master Ratings'!$O:$O, MATCH('Ratings by CLO'!$J32,'Master Ratings'!$B:$B,0),0)) | S32: =+IF(INDEX('Master Ratings'!$L:$L, MATCH('Ratings by CLO'!$J32,'Master Ratings'!$B:$B,0),0)=0,"",INDEX('Master Ratings'!$L:$L, MATCH('Ratings by CLO'!$J32,'Master Ratings'!$B:$B,0),0)) | T32: =+IF(INDEX('Master Ratings'!$M:$M, MATCH('Ratings by CLO'!$J32,'Master Ratings'!$B:$B,0),0)=0,"",INDEX('Master Ratings'!$M:$M, MATCH('Ratings by CLO'!$J32,'Master Ratings'!$B:$B,0),0)) | U32: =+IF(INDEX('Master Ratings'!$P:$P, MATCH('Ratings by CLO'!$J32,'Master Ratings'!$B:$B,0),0)=0,"",INDEX('Master Ratings'!$P:$P, MATCH('Ratings by CLO'!$J32,'Master Ratings'!$B:$B,0),0)) | W32: =+IF(OR($P32=$W$1,$P32=$W$2),$Q32+365-TODAY(), "") | X32: =+IF(OR($T32=$W$1,$T32=$W$2),$U32+365-TODAY(), "") | Z32: =IF(AND(SUM(B32:H32)>=1,ISERROR(W32)),"X","") | AA32: =IF(AND(B32>1, ISERROR(X32)),"X","") | AB32: =+IFERROR(IF(W32<0,"X",""),"") | AC32: =+IFERROR(IF(AND(B32>0, X32<0),"X",""),"") | AE32: =+IF(SUM(B32:H32)=0,"X","") | AG32: =IF(Z32="X",AG31+1,AG31) -> 0 | AH32: =IF(AA32="X",AH31+1,AH31) -> 2 | AI32: =IF(AB32="X",AI31+1,AI31) -> 8 | AJ32: =IF(AC32="X",AJ31+1,AJ31) -> 11
