Workbook
Name _dma1: #REF!
Name _dma2: #REF!
Name _dma3: #REF!
Name _dmb1: #REF!
Name _dmb2: #REF!
Name _dmc1: #REF!
Name _dmc2: #REF!
Name _dmd1: #REF!
Name _dmd2: #REF!
Name _Lag1: #REF!
Name _Lag2: #REF!
Name _PV1: 7
Name a: #REF!
Name A1loss: #REF!
Name A2loss: #REF!
Name A3loss: #REF!
Name AB: #REF!
Name AB_H: #REF!
Name AB_Orig: #REF!
Name ABS_Senior_____10: "FitchRecoverybyType"
Name ActiveRows: #REF!
Name Actual: #REF!
Name Actual12moChargeoffRatio: #REF!
Name Actual3moChargeoffRatio: #REF!
Name Actual3moDefaultRatio: #REF!
Name AdjAdvRate: #REF!
Name adv_rate: #REF!
Name adv_rate_reduced: #REF!
Name adv_rate_type: #REF!
Name advance_outstanding: #REF!
Name AdvancesOS: #REF!
Name agg_commit_bal: #REF!
Name AggregateAdjustedBalanceUSD: #REF!
Name AgingsDetail: #REF!
Name agreed_currency: #REF!
Name amort_adv_outstanding: #REF!
Name amort_period: #REF!
Name AOLB: #REF!
Name AOLBrange: #REF!
Name applicable_margin: #REF!
Name asfsdf: #REF!
Name ASH: #REF!
Name ASL: #REF!
Name asset_rating: #REF!
Name asset_types: #REF!
Name asset_value: #REF!
Name AUSTRALIA_NET: 110
Name AUSTRIA_NET: 107
Name AvailableCollections: #REF!
Name AverageABAgg: #REF!
Name AverageABL: #REF!
Name averageABL2: #REF!
Name AverageAgg: #REF!
Name b: #REF!
Name B1loss: #REF!
Name B2loss: #REF!
Name BackupServiceFee: #REF!
Name balances: #REF!
Name BeginningABAgg: #REF!
Name BeginningABL: #REF!

Sheet aresinput
A1: Fund | B1: Lender | C1: Date | D1: Commitment | E1: Borrowing Base | F1: Outstanding (total) | G1: Availability | H1: FX BB - GBP | I1: GBP Outstanding | J1: FX BB - EUR | K1: EUR Outstanding | L1: FX BB - CAD | M1: CAD Outstanding | N1: FX BB - SEK | O1: SEK Outstanding | P1: FX BB - DKK | Q1: DKK Outstanding | R1: FX BB - NOK | S1: NOK Outstanding | T1: Outstanding Loan Balance (Commitment) | U1: Adjusted Borrowing Value | V1: Wtd Avg Advance Rate | W1: Wtd. Avg Advance Rate (Effective) | X1: Unfunded Commitments | Y1: Unfunded Exposure | Z1: Excess Concentrations | AA1: # of Obligors | AB1: TTM EBITDA | AC1: Interest Coverage | AD1: Senior Net Leverage | AE1: Total Net Leverage | AF1: VAE#s | AG1: VAEs (based on ABV Post Haircut - USD) | AH1: VAEs as of percent of ABV Post Haircut | AI1: VAEs (based on OLB in USD) | AJ1: VAEs as of percent of OLB | AK1: Min Required Equity | AL1: First Lien - OLB | AM1: First Lien - ABV | AN1: First Lien Last Out - OLB | AO1: First Lien Last Out - ABV | AP1: Second Lien - OLB | AQ1: Second Lien - ABV | AR1: BSL - OLB | AS1: BSL - ABV | AT1: Wtd. Avg Spread | AU1: Capital Call Availability / SCV | AV1: Principal Cash | AW1: Unconstrained BB | AX1: FX Cash - CAD | AY1: FX Cash - EUR | AZ1: FX Cash - GBP | BA1: FX Cash - DKK | BB1: FX Cash - SEK | BC1: FX Cash - NOK | BD1: Principal Cash USD | BE1: MF Cash - CAD | BF1: MF Cash - EUR | BG1: MF Cash - GBP | BH1: MF Cash - DKK | BI1: MF Cash - SEK | BJ1: MF Cash - NOK | BK1: Principal O/S Pledged | BL1: Adjusted Borrowing Value (USD) | BM1: Wtd avg. Assigned Value | BN1: Wtd avg. advance rate | BO1: Effective Avg Adv rate | BP1: Adjusted balance | BQ1: Borrowing base2 | BR1: Borrowing outstanding | BS1: Wtd. avg portfolio leverage | BT1: Wtd. avg portfolio interest coverage | BU1: Wtd. avg portfolio EBITDA? | BV1: Fund 2
A2: SDL III | B2: BNP | C2: ='Summary '!I1 -> 45838 | D2: ='Summary '!I4 -> 400000000 | E2: ='Summary '!C11 -> 2.2302859e+08 | F2: ='Summary '!I39 -> 160600000 | G2: =Table2[[#This Row],[Borrowing Base]]-Table2[[#This Row],[Outstanding (total)]] -> 62428593 | H2: 0 | I2: 0 | J2: 0 | K2: 0 | L2: 0 | M2: 0 | N2: 0 | O2: 0 | P2: 0 | Q2: 0 | R2: 0 | S2: 0 | T2: ='Summary '!I38 -> 0 | V2: ='Summary '!C8 -> 0.64941848 | W2: =E2/T2 -> #DIV/0! | AB2: ='Summary '!D58 -> 39.047509 | AC2: ='Summary '!D59 -> 2.1876743 | AD2: ='Summary '!D60 -> 3.818529 | AV2: ='Summary '!C6 -> 0 | BK2: =Calcs!I15*10^6 -> 3.6126999e+14 | BL2: =Calcs!BO15 -> 3.3744891e+08 | BM2: =Table2[[#This Row],[Adjusted Borrowing Value (USD)]]/Table2[[#This Row],[Principal O/S Pledged]] -> 9.3406295e-07 | BN2: ='Summary '!C8 -> 0.64941848 | BO2: =BM2*BN2 -> 6.0659774e-07 | BP2: =BK2*BM2*BN2 -> 2.1914556e+08 | BQ2: ='Summary '!C11 -> 2.2302859e+08 | BR2: ='Summary '!I39 -> 160600000 | BS2: =SUMPRODUCT(Calcs!I17:I117,Calcs!BV17:BV117)/SUM(Calcs!I17:I117) -> 0 | BT2: ='Summary '!D59 -> 2.1876743 | BU2: ='Summary '!D58 -> 39.047509 | BV2: SDL III D

Sheet Summary 
H1: As of Date | I1: 45838 | Q1: =+SUM(Q4:Q800) -> 160600000
B2: BORROWING BASE CALCULATION | O2: Notes Payable: USD
E3: Principal Cash | F3: FX Rate | O3: Date | P3: Day | Q3: Amount
B4: THE SUM OF: | C4: Amount (USD) | D4: USD | E4: 0 | F4: 1 | G4: 7871288400 | H4: Facility size | I4: 400000000 | O4: 43522 | P4: Normal | Q4: 125000000
B5: (i) Principal Collection Subaccount | C5: 3883034.6 | D5: GBP | E5: 0 | F5: 1.28315 | G5: 7871288260 | H5: Inception Date | I5: 43518 | O5: 43532 | P5: Normal | Q5: 10000000
B6: (ii) Trust Subaccount | C6: =C69 -> 0 | D6: EUR | E6: 0 | F6: 1.08345 | G6: 7871289780 | H6: RP End | I6: 46741 | O6: 43550 | P6: Normal | Q6: 7500000
B7: (iii) The product of: | C7: =C8*C9 -> 2.1914556e+08 | D7: CAD | E7: 0 | F7: 0.7336488 | G7: 7871281240 | H7: Facility Termination | I7: 47472 | N7: (b) for which the related Obligor has a Senior Net Leverage Ratio of not more than 6.0x; | O7: 43588 | P7: Normal | Q7: 9000000
B8: (x) the Weighted Average Advance Rate and (y) the Portfolio Advance Rate Adj. | C8: =Calcs!BP15*'Diversity Score'!E7 -> 0.64941848 | D8: AUD | E8: 0 | F8: 0.67465 | G8: 7871280360 | O8: 43607 | P8: Normal | Q8: 4000000
B9: (y) the Aggregate Net Collateral Balance (excluding Loans sold but not settled) | C9: =SUM(Calcs!BO11:BO12) -> 3.3744891e+08 | H9: WAL Test | O9: 43607 | P9: Normal | Q9: 15000000
B10: (iV) Sale price of all Loans not yet settled | C10: =Calcs!V15 -> 0 | H10: Weighted Average Life | I10: =Calcs!BN12 -> 3.5792895 | O10: 43626 | P10: Normal | Q10: 2000000
B11: Borrowing Base | C11: =SUM(C10,C5:C7) -> 2.2302859e+08 | H11: Is less than | I11: 6 | O11: 43637 | P11: Normal | Q11: 2000000
H12: Test Satisfied? | I12: =IF(I10<I11,TRUE,FALSE) -> TRUE | O12: 43641 | P12: Normal | Q12: 3500000
O13: 43651 | P13: Normal | Q13: -10000000
O14: 43675 | P14: Normal | Q14: -13000000
B15: OC Ratio | C15: Amount (USD) | O15: 43706 | P15: Normal | Q15: 16000000
B16: Sum of: | C16: =SUM(C17:C18) -> 2.2302859e+08 | O16: 43742 | P16: Normal | Q16: -16000000
B17: (i) The Borrowing Base | C17: =C11 -> 2.2302859e+08 | H17: Interest Coverage Test | O17: 43746 | P17: Normal | Q17: 2000000
B18: (ii) Implied Equity: of Cashless Contributions | C18: =IFERROR((1-C19)*C20,0) -> 0 | H18: (a) aggregate amount of Interest Proceeds not received but expected | I18: 0 | O18: 43769 | P18: Normal | Q18: 14000000
B19: (a) Weighted Average Advance Rate of Cashless Contributions | C19: =Calcs!BP6 | H19: (b) all amounts on deposit in the Interest Collection Subaccount | O19: 43776 | P19: Normal | Q19: 2000000
B20: (b) Adj. Principal Balance of Cashless Contribution | C20: =Calcs!BO6 -> 0 | H20: Interest Coverage Amount | I20: =I18+I19 -> 0 | O20: 43782 | P20: Normal | Q20: 5000000
B21: divided by (ii) the sum of: | C21: =SUM(C22:C23) -> 160600000 | H21: the amounts payable on the related Payment Date pursuant to Sections 9.01(a)(i)(A) and 9.01(a)(i)(B) | I21: 0 | O21: 43788 | P21: Normal | Q21: 5500000
B22: (x) the Outstanding Principal Balance of the Facility and | C22: =percentage_unused -> 160600000 | H22: all amounts due and payable pursuant to Section 9.01(a)(i)(D) on the related Payment Date. | I22: 0 | O22: 43802 | P22: Normal | Q22: 10000000
B23: (y) the aggregate purchase price of all Loans purchased but not settled | C23: =Calcs!U11 -> 0 | H23: Interest Coverage Ratio | I23: =IFERROR((I20-I21)/I22,"N/A") -> N/A | O23: 43808 | P23: Normal | Q23: 10000000
B24: OC Ratio | C24: =IFERROR(C17/C21,"N/A") -> 1.388721 | H24: Is greater than | I24: 1.5 | O24: 43836 | P24: Normal | Q24: 3000000
B25: Minimum Threshold | C25: 1 | H25: Test Satisfied? | I25: =IF(I23>I24,TRUE,FALSE) -> TRUE | O25: 43837 | P25: Normal | Q25: 24000000
B26: Result | C26: =IF(C24="N/A", "PASS", C24>=C25) -> TRUE | O26: 43844 | P26: Normal | Q26: 10000000
O27: 43861 | P27: Normal | Q27: 4500000
H28: WAS Spread Test | I28: Floating | J28: Fixed | O28: 44043 | P28: Normal | Q28: -22500000
H29: WAS | I29: =Calcs!AO15 -> 0.058103186 | J29: =IF(ISNUMBER(Calcs!$AR$14), SUMPRODUCT(Calcs!AR17:AR35, Calcs!I17:I35)/SUM(Calcs!I17:I35), FALSE) -> FALSE | O29: 44104 | P29: Normal | Q29: -9000000
B30: Concentration Limit Excess | C30: Concentration Limit | D30: Current % | E30: Cushion | H30: Is more than | I30: 0.04 | J30: 0.08 | O30: 44109 | P30: Normal | Q30: 6000000
B31: FLLO/2nd Lien | C31: 0.4 | D31: ='Concentration Limitations'!$X$7 -> 0 | E31: =C31-D31 -> 0.4 | H31: Test Satisfied? | I31: =IF(I29>I30,TRUE,FALSE) -> TRUE | J31: =IF(J29>J30,TRUE,FALSE) -> TRUE | O31: 44146 | P31: Normal | Q31: -37000000
B32: non-USD | C32: 0.1 | D32: ='Concentration Limitations'!$AN$7 -> 0 | E32: =C32-D32 -> 0.1 | O32: 12/8/20202 | P32: Normal | Q32: 5000000
B33: Obligor NOT in US | C33: 0.1 | D33: ='Concentration Limitations'!$AR$7 -> 0 | E33: =C33-D33 -> 0.1 | O33: 44189 | P33: Normal | Q33: 1000000
B34: Senior Net Lev >5.5x | C34: 0.25 | D34: ='Concentration Limitations'!$AV$7 -> 0.075252506 | E34: =C34-D34 -> 0.17474749 | O34: 44196 | P34: Normal | Q34: -3000000
B35: Fixed Rate | C35: 0.05 | D35: ='Concentration Limitations'!AZ7 -> 0.012565525 | E35: =C35-D35 -> 0.037434475 | O35: 44203 | P35: Normal | Q35: 2000000
B36: Not First Lien | C36: 0.25 | D36: ='Concentration Limitations'!$BT$7 -> 0.015678381 | E36: =C36-D36 -> 0.23432162 | O36: 44229 | P36: Normal | Q36: 15000000
B37: Second Liens | C37: 0.1 | D37: ='Concentration Limitations'!BX7 -> 0 | E37: =C37-D37 -> 0.1 | I37: Borrowing Proposal | J37: Override | K37: Maximum advance | L37: Margin | O37: 44251 | P37: Normal | Q37: 2000000
B38: Recurring Revenue | C38: 0.1 | D38: ='Concentration Limitations'!$BH$7 -> 0 | E38: =C38-D38 -> 0.1 | H38: Advance (Pro Forma) | I38: 0 | J38: =Q1 -> 160600000 | K38: =C11 -> 2.2302859e+08 | L38: 0.0225 | M38: 0 | O38: 44280 | P38: Normal | Q38: 7500000
B39: Cov-Lite | C39: 0.15 | D39: ='Concentration Limitations'!AB7 -> 0.098118891 | E39: =C39-D39 -> 0.051881109 | H39: Total used | I39: =SUM(I38:J38) -> 160600000 | J39: =(I4-I39)/I4 -> 0.5985 | K39: =SUM(J38:J38)/SUM(K38:K38) -> 0.72008704 | O39: 44363 | P39: Normal | Q39: 5000000
B40: EBITDA <$15mm | C40: 0.25 | D40: ='Concentration Limitations'!AF7 -> 0.10567782 | E40: =C40-D40 -> 0.14432218 | O40: 44456 | P40: Normal | Q40: 7000000
...

Sheet Calcs
A1: Indicative Borrowing Base | J1: ="= Manual Input" -> = Manual Input | M1: Maximum Portfolio Amount | O1: =$O$2+$O$3-$O$4-$O$5 -> 6.0054606e+08
B2: [greater than] | C2: [greater than] | D2: [greater than] | E2: [greater than] | F2: [less than] | I2: Harded Items | J2: =Hardcodes | M2: Maximum Facility Size | O2: ='Summary '!$I$4 -> 400000000
C3: Class 1 | D3: Class 2 | E3: Class 3 | F3: Class 4 | M3: Collateral Purchase Amount | O3: =$O$15*1000000 -> 3.6114606e+08
M4: Borrowings | O4: ='Summary '!$J$38 -> 160600000
A5: Tranche Size/ EBITDA | C5: 100 | D5: 25 | E5: 10 | F5: 10 | M5: Principal Distributions | O5: 0 | BO5: Agg Adjusted Collat Balance | BP5: Adv Rate per Each Category
A6: Sr Lev Cut-Off | C6: 6 | D6: 5.5 | E6: 5 | F6: 4.5 | BN6: Bought Not Settled (cashless) | BO6: =SUMIF($R17:$R117,$T$11,$BO$17:$BO$117) -> 0 | BP6: =IFERROR(SUMIF($R17:$R116,$T$11,BP17:BP117)/BO6,"")
A7: Sr Lev Cap | C7: 7 | D7: 6.5 | E7: 6 | F7: 5.5 | BN7: Settled NCB | BO7: =SUMIF($R17:$R117,$T$12,BO17:BO117) -> 3.3744891e+08 | BP7: =IFERROR(SUMIF($R17:$R117,$T$12,BP17:BP117)/BO7,"") -> 0.64941848
A8: 1L AR | C8: 0.7 | D8: 0.675 | E8: 0.65 | F8: 0.625 | BN8: Sold Unsettled | BO8: =SUMIF($R17:$R117,$T$13,BO17:BO117) -> 0 | BP8: =IFERROR(SUMIF($R17:$R116,$T$13,BP17:BP117)/BO8,"")
A9: 1L LO AR | C9: 0.575 | D9: 0.55 | E9: 0.52 | F9: 0.5
A10: 2L AR | C10: 0.4 | D10: 0.35 | E10: 0.35 | F10: 0.3 | T10: EQUITY CONTRIBUTED | U10: =SUMIF($R$17:$R$117,T10,$U$17:$U$117) -> 0
A11: Spread | C11: 0.0225 | D11: 0.0225 | E11: 0.0225 | F11: 0.0225 | T11: BOUGHT UNSETTLED | U11: =SUMIF($R$17:$R$117,T11,$U$17:$U$117) -> 0 | BO11: =SUMIF($R17:$R117,$T$11,BO17:BO117) -> 0
A12: Notional % | C12: =SUMIF($AE$17:$AE$117,C3,$I$17:$I$117)/$I$15 -> 0.066439125 | D12: =SUMIF($AE$17:$AE$117,D3,$I$17:$I$117)/$I$15 -> 0.32247059 | E12: =SUMIF($AE$17:$AE$117,E3,$I$17:$I$117)/$I$15 -> 0.61109029 | F12: =SUMIF($AE$17:$AE$117,F3,$I$17:$I$117)/$I$15 -> 0 | T12: SETTLED | U12: =SUMIF($R$17:$R$117,T12,$U$17:$U$117) -> 3.3744891e+08 | BN12: =SUMPRODUCT($K$16:$K$117,BN$16:BN$117) -> 3.5792895 | BO12: =SUMIF($R17:$R117,$T$12,BO17:BO117) -> 3.3744891e+08
A13: Avg AR | C13: =SUMIF($AE$17:AF117,C3,$AC$17:$AC$117)/SUMIF($AE$17:AF117,C3,$K$17:K117) -> 0.62102879 | D13: =IFERROR(SUMIF($AE$17:AG117,D3,$AC$17:$AC$117)/SUMIF($AE$17:AG117,D3,$K$17:K117), 0) -> 0.62666373 | E13: =IFERROR(SUMIF($AE$17:AI117,E3,$AC$17:$AC$117)/SUMIF($AE$17:AI117,E3,$K$17:K117),0) -> 0.62692613 | F13: =IFERROR(SUMIF($AE$17:AJ117,F3,$AC$17:$AC$117)/SUMIF($AE$17:AJ117,F3,$K$17:L117),0) -> 0 | T13: SOLD UNSETTLED | U13: =SUMIF($R$17:$R$117,T13,$U$17:$U$117) -> 0 | BO13: =SUMIF($R17:$R117,$T$13,BO17:BO117) -> 0
A14: Avg Leverage | C14: =SUMIF($AE$17:$AE$117,C3,$AB$17:$AB$117)/SUMIF($AE$17:$AE$117,C3,$K$17:$K$117) -> 6.4761735 | D14: =IFERROR(SUMIF($AE$17:$AE$117,D3,$AB$17:$AB$117)/SUMIF($AE$17:$AE$117,D3,$K$17:$K$117), 0) -> 1.6323792 | E14: =IFERROR(SUMIF($AE$17:$AE$117,E3,$AB$17:$AB$117)/SUMIF($AE$17:$AE$117,E3,$K$17:$K$117),0) -> 4.6832088 | F14: =IFERROR(SUMIF($AE$17:$AE$117,F3,$AB$17:$AB$117)/SUMIF($AE$17:$AE$117,F3,$K$17:$K$117),0) -> 0
H15: =SUM(H17:H117) -> 3.6126999e+08 | I15: =SUM(I17:I117) -> 3.6126999e+08 | J15: =SUM(J17:J117) -> 0 | O15: =SUM(O17:O117)/1000000 -> 361.14606 | U15: =SUM(U11:U13) -> 3.3744891e+08 | V15: =SUMPRODUCT(V17:V117,I17:I117)*1000000 -> 0 | AL15: =SUMPRODUCT(I17:I117,AL17:AL117)/$I$15 -> 0.6264497 | AN15: =SUMIFS(BP17:BP117,R17:R117,"<>"&"SOLD UNSETTLED")/SUMIFS(BO17:BO117,R17:R117,"<>"&"SOLD UNSETTLED") -> 0.64941848 | AO15: =SUMPRODUCT(I17:I117,AO17:AO117)/$I$15 -> 0.058103186 | BN15: =TODAY() -> 45863 | BO15: =SUM(BO17:BO117) -> 3.3744891e+08 | BP15: =SUM(BP17:BP117)/SUM(BO17:BO117) -> 0.64941848 | BY15: Current Metrics | CJ15: Metrics at Entry | CU15: =SUM(CU17:CU117) -> 35 | CV15: =SUM(CV17:CV117) -> 21 | CW15: =SUM(CW17:CW117) -> 41
A16: Company Name | B16: Admin Agent | C16: Lien | D16: Security Type | E16: Eligibility Criteria | F16: Industry | G16: [Reserved] | H16: Commitment (Local) | I16: Comittment (USD) | J16: Unfunded | K16: % of Port | L16: Purchase Price | M16: Mark Price | N16: Maturity Date | O16: Purchase Price Value | P16: Loan Value | Q16: Primary / Secondary | R16: Status | S16: Revaluation Event | T16: Revaluation Adjustment | U16: Adjusted Collateral Value | V16: Sale Price | W16: Sale Proceeds | X16: Reserved | Y16: Tranche Size | Z16: Reserved | AB16: %Lev | AC16: %AR | AD16: First Out Leverage | AE16: Class | AF16: Lev Cut-off | AG16: Lev Cap | AH16: 1L | AI16: 2L | AJ16: 1L_AR | AK16: 2L_AR | AL16: AR | AM16: AR Adjustment | AN16: Adjusted AR | AO16: Spread above Reference Rate | AP16: Reference Rate | AQ16: Floor | AR16: Fixed Rate Spread | AS16: PIK (LTM actual annualized PIK spread) | AU16: Current Cash Pay | AV16: Excluded PIK: Cash Pay > 4.5% | AW16: Concentration Limit Partial PIK | AX16: Ineligible Partial PIK | AY16: Non-Accrual Loan | AZ16: Moody's or S&P Rated | BA16: Covenent Type | BB16: Not FL | BC16: SNL>5.5x | BD16: USD | BE16: US Obligor | BF16: Non-USD | BG16: Obligor Domicile | BH16: FLLO | BI16: Second Lien | BJ16: Recurring Revenue | BK16: Fixed Rate | BL16: CCC+/Caa1 or below | BM16: Cov-Lite | BN16: WAL | BO16: Aggregate Net Collateral Balance | BP16: Aggregate Net Collateral Balance x AR (excl. sales) | BS16: Financial Statement | BT16: IC Ratio | BU16: Sr Lev | BW16: First Out Leverage | BX16: LTV | BY16: EBITDA | BZ16: LTM Revenue | CA16: LTM ARR | CB16: Net Debt to RR | CC16: Moody's | CD16: S&P | CE16: Financial Statement at Cut Off | CF16: IC Ratio at Cut-Off | CG16: Sr Lev at Cut-Off | CI16: First Out Leverage at Cut-Off | CJ16: LTV at Cut-Off | CK16: EBITDA at Cut-Off | CL16: LTM Revenue at Cut-Off | CM16: LTM ARR at Cut Off | CN16: Net Debt to RR at Cut Off | CO16: Moody's at Cut-Off | CP16: S&P at Cut-Off | CQ16: Cash Interest Coverage Ratio % Change | CR16: Sr Lev % Change | CS16: Sr Lev Change | CT16: EBITDA Change | CU16: Interest Coverage Ratio VAE? | CV16: Sr Leverage Ratio VAE? | CW16: Total VAE | CX16: Material Modification | CY16: Change in Partial PIK Status | CZ16: PIK Option | DA16: PIK Rate | DD16: Moody's | DE16: S&P | DI16: Purchase Price Requirement | DJ16: Currency | DK16: Senior Net Leverage <6.0x | DL16: EBITDA Threshold Covlite | DM16: EBITDA Minimum | DN16: Partial PIK Spread Test | DO16: Defaulted Obligation? | DP16: Eligible Loan?
A17: A1 Garage Merger Sub, LLC | B17: =IFERROR(VLOOKUP(A17,'Loan List '!$A$6:$BZ$75,2,FALSE),NA) -> 0 | C17: =VLOOKUP(A17,'Loan List '!$A$6:$G$75, 7, FALSE) -> First Lien | D17: =VLOOKUP(A17, 'Loan List '!$A$6:$K$82, 11, FALSE) -> FL | E17: =IF(DP17= "YES", TRUE, FALSE) -> TRUE | F17: =VLOOKUP(A17,'Loan List '!$A$6:$L$75, 12, FALSE) -> Energy Equipment & Services | H17: =+I17 -> 3183892.6 | I17: =VLOOKUP(A17,'Loan List '!$A$6:$L$82, 8, FALSE) -> 3183892.6 | J17: 0 | K17: =I17/$I$15 -> 0.008813056 | L17: =VLOOKUP(A17,'Loan List '!$A$6:$BA$82,24, FALSE) -> 100 | N17: =VLOOKUP(A17,'Loan List '!$A$6:$BA$82,22, FALSE) -> 47109 | O17: =IFERROR(MAX(0,I17-J17)*L17,"")/100 -> 3183892.6 | P17: =MIN(IF(AND(L17>=97%,Q17="Primary"),100%,L17),T17) -> 1 | Q17: Primary | R17: SETTLED | S17: =IF(OR(CU17=1,CV17=1,CW17=1),TRUE,FALSE) -> FALSE | T17: =VLOOKUP(A17,'Loan List '!$A$6:$BD$1048576,56,FALSE)/100 -> 1 | U17: =IF(E17=TRUE,P17*I17,0) -> 3183892.6 | V17: =VLOOKUP(A17,'Loan List '!$A$6:$BA$82,26, FALSE) -> 0 | W17: =V17*I17 -> 0 | Y17: =VLOOKUP(A17,'Loan List '!$A$6:$BA$75,27, FALSE) -> 0 | AB17: =K17*BU17 -> 0.01841032 | AC17: =K17*AL17 -> 0.0059488128 | AD17: =BW17 -> 0 | AE17: =IF(CK17>=$C$5,"Class 1",IF(CK17>=$D$5,"Class 2",IF(CK17>=$E$5,"Class 3","Class 4"))) -> Class 2 | AF17: =HLOOKUP($AE17,$B$3:$F$10,4,0) -> 5.5 | AG17: =IF(BB17,1,0)+HLOOKUP($AE17,$B$3:$F$10,5,0) -> 6.5 | AH17: =MIN(AF17/BU17,1) -> 1 | AI17: =IF(BU17>AG17,(AG17-AF17)/BU17,1-AH17) -> 0 | AJ17: =HLOOKUP($AE17,$B$3:$F$10,6,0) -> 0.675 | AK17: =HLOOKUP($AE17,$B$3:$F$10,8,0) -> 0.35 | AL17: =IF(OR(BI17, AND(BH17,AD17>1)), HLOOKUP(AE17,$B$3:$F$10,8,0),AH17*AJ17+AI17*AK17) -> 0.675 | AM17: ='Diversity Score'!$E$7 -> 1 | AN17: =AM17*AL17 -> 0.675 | AO17: =VLOOKUP(A17,'Loan List '!$A$6:$BA$75,17, FALSE) -> 0.045 | AP17: =VLOOKUP(A17,'Loan List '!$A$6:$BA$795,15, FALSE) -> SOFR | AQ17: =VLOOKUP(A17,'Loan List '!$A$6:$BA$795,16, FALSE) -> 0.01 | AR17: 0 | AS17: 0 | AU17: =AO17-AS17 -> 0.045 | AV17: =IF(AND(AS17>0%,AU17>4.5%),TRUE,FALSE) -> FALSE | AW17: =IF(AND(AS17>0%,AU17>=2.25%, AV17=FALSE),TRUE,FALSE) -> FALSE | AX17: =IF(AND(AS17>0%,AW17=FALSE, AV17=FALSE),TRUE, FALSE) -> FALSE | AZ17: =(OR(CC17<>"NR",CD17<>"NR")) -> FALSE | BA17: ='Loan List '!AS6 -> Maintenance Covenants | BB17: =IF(D17="FL",FALSE,TRUE) -> FALSE | BC17: =IF(BU17>5.5, TRUE, FALSE) -> FALSE | BD17: =IF(BF17="USD", TRUE,FALSE) -> TRUE | BE17: =IF(BG17="USA",TRUE,FALSE) -> TRUE | BF17: ='Loan List '!J6 -> USD | BG17: =VLOOKUP(A17,'Loan List '!$A$6:$BZ$75, 23, FALSE) -> USA | BH17: =IF(D17="FLLO", TRUE,FALSE) -> FALSE | BI17: =IF(C17="Second Lien",TRUE,FALSE) -> FALSE | BJ17: =IF('Loan List '!BP6=1, TRUE, FALSE) -> FALSE | BK17: =IF(AR17>0%,TRUE,FALSE) -> FALSE | BL17: =OR(LEFT(CC17,1)="C", LEFT(CD17,1)="C") -> FALSE | BM17: =IF('Loan List '!AT6="Yes", TRUE, FALSE) -> FALSE | BN17: =-($BN$15-N17)/365 -> 3.4136986 | BO17: ='Concentration Limitations'!H12 -> 3183892.6 | BP17: =IF(R17=$T$13,0,BO17*AL17) -> 2149127.5 | BS17: ='Loan List '!AG6 -> 45808 | BT17: ='Loan List '!AO6 -> 3.6700803 | BU17: ='Loan List '!AI6 -> 2.0889825 | BW17: 0 | BX17: - | BY17: ='Loan List '!AJ6 -> 66.178 | BZ17: ='Loan List '!AL6 -> 0 | CA17: 0 | CB17: 0 | CC17: NR | CD17: NR | CE17: - | CF17: ='Loan List '!AC6 -> 1.8629212 | CG17: ='Loan List '!AD6 -> 4.9219777 | CI17: 0 | CJ17: - | CK17: ='Loan List '!AB6 -> 26.53 | CL17: ='Loan List '!AE6 -> 0 | CM17: 0 | CN17: 0 | CO17: NR | CP17: NR | CQ17: =IFERROR(($BT17-$CF17)/$CF17,0) -> 0.97006741 | CR17: =IFERROR(($BU17-$CG17)/$CG17,0) -> -0.57558067 | CS17: =BU17-CG17 -> -2.8329952 | CT17: =(BY17/CK17)-1 -> 1.4944591 | CU17: =IF(OR($CQ17<'Summary '!$I$47,$BT17<'Summary '!$I$46),1,0) -> 0 | CV17: =IF(OR($CS17>='Summary '!$I$50, (AND(BU17>'Summary '!$I$52, Calcs!CR17> 'Summary '!$I$51))),1,0) -> 0 | CW17: =IF(OR(SUM(CU17:CV17)>=1,CX17="Yes"),1,0) -> 0 | CX17: No | CY17: No | CZ17: No | DD17: 0 | DE17: 0 | DI17: =IF(L17<90%,"Not Eligible","Eligible") -> Eligible | DJ17: =IF(OR(BF17="USD",BF17="CAD",BF17="EUR",BF17="GBP",BF17="AUD"),"Eligible","Not Eligible") -> Eligible | DK17: Eligible | DL17: Eligible | DM17: =IF(BM17="FALSE",IF(BY17<5,"Not Eligible","Eligible"),"Eligible") -> Eligible | DN17: =IF(AW17="TRUE",IF(AU17>=3%,"Eligible","Not Eligible"),"Not PIK") -> Not PIK | DO17: No | DP17: =IF(OR(DK17="Not Eligible",DL17="Not Eligible",DI17="Not Eligible",DJ17="Not Eligible",DM17="Not Eligible",DN17="Not Eligible",DO17="Yes"),"NO","YES") -> YES
A18: AFC - Dell Holding Corp. | B18: =IFERROR(VLOOKUP(A18,'Loan List '!$A$6:$BZ$75,2,FALSE),NA) -> 0 | C18: =VLOOKUP(A18,'Loan List '!$A$6:$G$75, 7, FALSE) -> First Lien | D18: =VLOOKUP(A18, 'Loan List '!$A$6:$K$82, 11, FALSE) -> FL | E18: =IF(DP18= "YES", TRUE, FALSE) -> TRUE | F18: =VLOOKUP(A18,'Loan List '!$A$6:$L$75, 12, FALSE) -> Distributors | H18: =+I18 -> 268902.61 | I18: =VLOOKUP(A18,'Loan List '!$A$6:$L$75, 8, FALSE) -> 268902.61 | J18: 0 | K18: =I18/$I$15 -> 0.00074432591 | L18: =VLOOKUP(A18,'Loan List '!$A$6:$BA$82,24, FALSE) -> 100 | N18: =VLOOKUP(A18,'Loan List '!$A$6:$BA$82,22, FALSE) -> 46486 | O18: =IFERROR(MAX(0,I18-J18)*L18,"")/100 -> 268902.61 | P18: =MIN(IF(AND(L18>=97%,Q18="Primary"),100%,L18),T18) -> 1 | Q18: Primary | R18: SETTLED | S18: =IF(OR(CU18=1,CV18=1,CW18=1),TRUE,FALSE) -> TRUE | T18: =VLOOKUP(A18,'Loan List '!$A$6:$BD$1048576,56,FALSE)/100 -> 1 | U18: =IF(E18=TRUE,P18*I18,0) -> 268902.61 | V18: =VLOOKUP(A18,'Loan List '!$A$6:$BA$82,26, FALSE) -> 0 | W18: =V18*I18 -> 0 | Y18: =VLOOKUP(A18,'Loan List '!$A$6:$BA$75,27, FALSE) -> 0 | AB18: =K18*BU18 -> 0.0046553716 | AC18: =K18*AL18 -> 0.00047323879 | AD18: =BW18 -> 0 | AE18: =IF(CK18>=$C$5,"Class 1",IF(CK18>=$D$5,"Class 2",IF(CK18>=$E$5,"Class 3","Class 4"))) -> Class 2 | AF18: =HLOOKUP($AE18,$B$3:$F$10,4,0) -> 5.5 | AG18: =IF(BB18,1,0)+HLOOKUP($AE18,$B$3:$F$10,5,0) -> 6.5 | AH18: =MIN(AF18/BU18,1) -> 0.87936965 | AI18: =IF(BU18>AG18,(AG18-AF18)/BU18,1-AH18) -> 0.12063035 | AJ18: =HLOOKUP($AE18,$B$3:$F$10,6,0) -> 0.675 | AK18: =HLOOKUP($AE18,$B$3:$F$10,8,0) -> 0.35 | AL18: =IF(OR(BI18, AND(BH18,AD18>1)), HLOOKUP(AE18,$B$3:$F$10,8,0),AH18*AJ18+AI18*AK18) -> 0.63579514 | AM18: ='Diversity Score'!$E$7 -> 1 | AN18: =AM18*AL18 -> 0.63579514 | AO18: =VLOOKUP(A18,'Loan List '!$A$6:$BA$75,17, FALSE) -> 0.055 | AP18: =VLOOKUP(A18,'Loan List '!$A$6:$BA$795,15, FALSE) -> SOFR | AQ18: =VLOOKUP(A18,'Loan List '!$A$6:$BA$795,16, FALSE) -> 0.01 | AR18: 0 | AS18: 0 | AU18: =AO18-AS18 -> 0.055 | AV18: =IF(AND(AS18>0%,AU18>4.5%),TRUE,FALSE) -> FALSE | AW18: =IF(AND(AS18>0%,AU18>=2.25%, AV18=FALSE),TRUE,FALSE) -> FALSE | AX18: =IF(AND(AS18>0%,AW18=FALSE, AV18=FALSE),TRUE, FALSE) -> FALSE | AZ18: =(OR(CC18<>"NR",CD18<>"NR")) -> FALSE | BA18: ='Loan List '!AS7 -> Cov-Lite | BB18: =IF(D18="FL",FALSE,TRUE) -> FALSE | BC18: =IF(BU18>5.5, TRUE, FALSE) -> TRUE | BD18: =IF(BF18="USD", TRUE,FALSE) -> TRUE | BE18: =IF(BG18="USA",TRUE,FALSE) -> TRUE | BF18: ='Loan List '!J7 -> USD | BG18: =VLOOKUP(A18,'Loan List '!$A$6:$BZ$75, 23, FALSE) -> USA | BH18: =IF(D18="FLLO", TRUE,FALSE) -> FALSE | BI18: =IF(C18="Second Lien",TRUE,FALSE) -> FALSE | BJ18: =IF('Loan List '!BP7=1, TRUE, FALSE) -> FALSE | BK18: =IF(AR18>0%,TRUE,FALSE) -> FALSE | BL18: =OR(LEFT(CC18,1)="C", LEFT(CD18,1)="C") -> FALSE | BM18: =IF('Loan List '!AT7="Yes", TRUE, FALSE) -> TRUE | BN18: =-($BN$15-N18)/365 -> 1.7068493 | BO18: ='Concentration Limitations'!H13 -> 268902.61 | BP18: =IF(R18=$T$13,0,BO18*AL18) -> 170966.97 | BS18: ='Loan List '!AG7 -> 45808 | BT18: ='Loan List '!AO7 -> 1.3038534 | BU18: ='Loan List '!AI7 -> 6.2544801 | BW18: 0 | BX18: - | BY18: ='Loan List '!AJ7 -> 74.476344 | BZ18: ='Loan List '!AL7 -> 0 | CA18: 0 | CB18: 0 | CC18: NR | CD18: NR | CE18: - | CF18: ='Loan List '!AC7 -> 1.604889 | CG18: ='Loan List '!AD7 -> 5.5133081 | CI18: 0 | CJ18: - | CK18: ='Loan List '!AB7 -> 62.582178 | CL18: ='Loan List '!AE7 -> 0 | CM18: 0 | CN18: 0 | CO18: NR | CP18: NR | CQ18: =IFERROR(($BT18-$CF18)/$CF18,0) -> -0.18757406 | CR18: =IFERROR(($BU18-$CG18)/$CG18,0) -> 0.13443327 | CS18: =BU18-CG18 -> 0.74117202 | CT18: =(BY18/CK18)-1 -> 0.19005678 | CU18: =IF(OR($CQ18<'Summary '!$I$47,$BT18<'Summary '!$I$46),1,0) -> 1 | CV18: =IF(OR($CS18>='Summary '!$I$50, (AND(BU18>'Summary '!$I$52, Calcs!CR18> 'Summary '!$I$51))),1,0) -> 0 | CW18: =IF(OR(SUM(CU18:CV18)>=1,CX18="Yes"),1,0) -> 1 | CX18: No | CY18: No | CZ18: No | DD18: 0 | DE18: 0 | DI18: =IF(L18<90%,"Not Eligible","Eligible") -> Eligible | DJ18: =IF(OR(BF18="USD",BF18="CAD",BF18="EUR",BF18="GBP",BF18="AUD"),"Eligible","Not Eligible") -> Eligible | DK18: Eligible | DL18: Eligible | DM18: =IF(BM18="FALSE",IF(BY18<5,"Not Eligible","Eligible"),"Eligible") -> Eligible | DN18: =IF(AW18=TRUE,IF(AU18>=3%,"Eligible","Not Eligible"),"Not PIK") -> Not PIK | DO18: No | DP18: =IF(OR(DK18="Not Eligible",DL18="Not Eligible",DI18="Not Eligible",DJ18="Not Eligible",DM18="Not Eligible",DN18="Not Eligible",DO18="Yes"),"NO","YES") -> YES
A19: Alpine Acquisition Corp II | B19: =IFERROR(VLOOKUP(A19,'Loan List '!$A$6:$BZ$75,2,FALSE),NA) -> 0 | C19: =VLOOKUP(A19,'Loan List '!$A$6:$G$75, 7, FALSE) -> First Lien | D19: =VLOOKUP(A19, 'Loan List '!$A$6:$K$82, 11, FALSE) -> FL | E19: =IF(DP19= "YES", TRUE, FALSE) -> TRUE | F19: =VLOOKUP(A19,'Loan List '!$A$6:$L$75, 12, FALSE) -> Containers and Packaging | H19: =+I19 -> 3988971 | I19: =VLOOKUP(A19,'Loan List '!$A$6:$L$75, 8, FALSE) -> 3988971 | J19: 0 | K19: =I19/$I$15 -> 0.011041523 | L19: =VLOOKUP(A19,'Loan List '!$A$6:$BA$82,24, FALSE) -> 100 | N19: =VLOOKUP(A19,'Loan List '!$A$6:$BA$82,22, FALSE) -> 47452 | O19: =IFERROR(MAX(0,I19-J19)*L19,"")/100 -> 3988971 | P19: =MIN(IF(AND(L19>=97%,Q19="Primary"),100%,L19),T19) -> 0 | Q19: Primary | R19: SETTLED | S19: =IF(OR(CU19=1,CV19=1,CW19=1),TRUE,FALSE) -> TRUE | T19: =VLOOKUP(A19,'Loan List '!$A$6:$BD$1048576,56,FALSE)/100 -> 0 | U19: =IF(E19=TRUE,P19*I19,0) -> 0 | V19: =VLOOKUP(A19,'Loan List '!$A$6:$BA$82,26, FALSE) -> 0 | W19: =V19*I19 -> 0 | Y19: =VLOOKUP(A19,'Loan List '!$A$6:$BA$75,27, FALSE) -> 0 | AB19: =K19*BU19 -> 0.22592463 | AC19: =K19*AL19 -> 0.0024822884 | AD19: =BW19 -> 0 | AE19: =IF(CK19>=$C$5,"Class 1",IF(CK19>=$D$5,"Class 2",IF(CK19>=$E$5,"Class 3","Class 4"))) -> Class 1 | AF19: =HLOOKUP($AE19,$B$3:$F$10,4,0) -> 6 | AG19: =IF(BB19,1,0)+HLOOKUP($AE19,$B$3:$F$10,5,0) -> 7 | AH19: =MIN(AF19/BU19,1) -> 0.29323558 | AI19: =IF(BU19>AG19,(AG19-AF19)/BU19,1-AH19) -> 0.048872596 | AJ19: =HLOOKUP($AE19,$B$3:$F$10,6,0) -> 0.7 | AK19: =HLOOKUP($AE19,$B$3:$F$10,8,0) -> 0.4 | AL19: =IF(OR(BI19, AND(BH19,AD19>1)), HLOOKUP(AE19,$B$3:$F$10,8,0),AH19*AJ19+AI19*AK19) -> 0.22481394 | AM19: ='Diversity Score'!$E$7 -> 1 | AN19: =AM19*AL19 -> 0.22481394 | AO19: =VLOOKUP(A19,'Loan List '!$A$6:$BA$75,17, FALSE) -> 0.061 | AP19: =VLOOKUP(A19,'Loan List '!$A$6:$BA$795,15, FALSE) -> SOFR | AQ19: =VLOOKUP(A19,'Loan List '!$A$6:$BA$795,16, FALSE) -> 0.01 | AR19: 0 | AS19: 0 | AU19: =AO19-AS19 -> 0.061 | AV19: =IF(AND(AS19>0%,AU19>4.5%),TRUE,FALSE) -> FALSE | AW19: =IF(AND(AS19>0%,AU19>=2.25%, AV19=FALSE),TRUE,FALSE) -> FALSE | AX19: =IF(AND(AS19>0%,AW19=FALSE, AV19=FALSE),TRUE, FALSE) -> FALSE | AZ19: =(OR(CC19<>"NR",CD19<>"NR")) -> FALSE | BA19: ='Loan List '!AS8 -> Maintenance Covenants | BB19: =IF(D19="FL",FALSE,TRUE) -> FALSE | BC19: =IF(BU19>5.5, TRUE, FALSE) -> TRUE | BD19: =IF(BF19="USD", TRUE,FALSE) -> TRUE | BE19: =IF(BG19="USA",TRUE,FALSE) -> TRUE | BF19: ='Loan List '!J8 -> USD | BG19: =VLOOKUP(A19,'Loan List '!$A$6:$BZ$75, 23, FALSE) -> USA | BH19: =IF(D19="FLLO", TRUE,FALSE) -> FALSE | BI19: =IF(C19="Second Lien",TRUE,FALSE) -> FALSE | BJ19: =IF('Loan List '!BP8=1, TRUE, FALSE) -> FALSE | BK19: =IF(AR19>0%,TRUE,FALSE) -> FALSE | BL19: =OR(LEFT(CC19,1)="C", LEFT(CD19,1)="C") -> FALSE | BM19: =IF('Loan List '!AT8="Yes", TRUE, FALSE) -> FALSE | BN19: =-($BN$15-N19)/365 -> 4.3534247 | BO19: ='Concentration Limitations'!H14 -> 0 | BP19: =IF(R19=$T$13,0,BO19*AL19) -> 0 | BS19: ='Loan List '!AG8 -> 45777 | BT19: ='Loan List '!AO8 -> 0.74807019 | BU19: ='Loan List '!AI8 -> 20.461364 | BW19: 0 | BX19: - | BY19: ='Loan List '!AJ8 -> 91.483 | BZ19: ='Loan List '!AL8 -> 0 | CA19: 0 | CB19: 0 | CC19: NR | CD19: NR | CE19: - | CF19: ='Loan List '!AC8 -> 2.65 | CG19: ='Loan List '!AD8 -> 5.41 | CI19: 0 | CJ19: - | CK19: ='Loan List '!AB8 -> 283.8 | CL19: ='Loan List '!AE8 -> 0 | CM19: 0 | CN19: 0 | CO19: NR | CP19: NR | CQ19: =IFERROR(($BT19-$CF19)/$CF19,0) -> -0.71770936 | CR19: =IFERROR(($BU19-$CG19)/$CG19,0) -> 2.7821376 | CS19: =BU19-CG19 -> 15.051364 | CT19: =(BY19/CK19)-1 -> -0.67764975 | CU19: =IF(OR($CQ19<'Summary '!$I$47,$BT19<'Summary '!$I$46),1,0) -> 1 | CV19: =IF(OR($CS19>='Summary '!$I$50, (AND(BU19>'Summary '!$I$52, Calcs!CR19> 'Summary '!$I$51))),1,0) -> 1 | CW19: =IF(OR(SUM(CU19:CV19)>=1,CX19="Yes"),1,0) -> 1 | CX19: No | CY19: No | CZ19: No | DD19: 0 | DE19: 0 | DI19: =IF(L19<90%,"Not Eligible","Eligible") -> Eligible | DJ19: =IF(OR(BF19="USD",BF19="CAD",BF19="EUR",BF19="GBP",BF19="AUD"),"Eligible","Not Eligible") -> Eligible | DK19: Eligible | DL19: Eligible | DM19: =IF(BM19="FALSE",IF(BY19<5,"Not Eligible","Eligible"),"Eligible") -> Eligible | DN19: =IF(AW19=TRUE,IF(AU19>=3%,"Eligible","Not Eligible"),"Not PIK") -> Not PIK | DO19: No | DP19: =IF(OR(DK19="Not Eligible",DL19="Not Eligible",DI19="Not Eligible",DJ19="Not Eligible",DM19="Not Eligible",DN19="Not Eligible",DO19="Yes"),"NO","YES") -> YES
A20: Archer Lewis | B20: =IFERROR(VLOOKUP(A20,'Loan List '!$A$6:$BZ$75,2,FALSE),NA) -> 0 | C20: =VLOOKUP(A20,'Loan List '!$A$6:$G$75, 7, FALSE) -> First Lien | D20: =VLOOKUP(A20, 'Loan List '!$A$6:$K$82, 11, FALSE) -> FL | E20: =IF(DP20= "YES", TRUE, FALSE) -> TRUE | F20: =VLOOKUP(A20,'Loan List '!$A$6:$L$75, 12, FALSE) -> Diversified Financial Services | H20: =+I20 -> 3893383.4 | I20: =VLOOKUP(A20,'Loan List '!$A$6:$L$75, 8, FALSE) -> 3893383.4 | J20: 0 | K20: =I20/$I$15 -> 0.010776936 | L20: =VLOOKUP(A20,'Loan List '!$A$6:$BA$82,24, FALSE) -> 100 | N20: =VLOOKUP(A20,'Loan List '!$A$6:$BA$82,22, FALSE) -> 47358 | O20: =IFERROR(MAX(0,I20-J20)*L20,"")/100 -> 3893383.4 | P20: =MIN(IF(AND(L20>=97%,Q20="Primary"),100%,L20),T20) -> 1 | Q20: Primary | R20: SETTLED | S20: =IF(OR(CU20=1,CV20=1,CW20=1),TRUE,FALSE) -> FALSE | T20: =VLOOKUP(A20,'Loan List '!$A$6:$BD$1048576,56,FALSE)/100 -> 1 | U20: =IF(E20=TRUE,P20*I20,0) -> 3893383.4 | V20: =VLOOKUP(A20,'Loan List '!$A$6:$BA$82,26, FALSE) -> 0 | W20: =V20*I20 -> 0 | Y20: =VLOOKUP(A20,'Loan List '!$A$6:$BA$75,27, FALSE) -> 0 | AB20: =K20*BU20 -> 0.040382181 | AC20: =K20*AL20 -> 0.0070050083 | AD20: =BW20 -> 0 | AE20: =IF(CK20>=$C$5,"Class 1",IF(CK20>=$D$5,"Class 2",IF(CK20>=$E$5,"Class 3","Class 4"))) -> Class 3 | AF20: =HLOOKUP($AE20,$B$3:$F$10,4,0) -> 5 | AG20: =IF(BB20,1,0)+HLOOKUP($AE20,$B$3:$F$10,5,0) -> 6 | AH20: =MIN(AF20/BU20,1) -> 1 | AI20: =IF(BU20>AG20,(AG20-AF20)/BU20,1-AH20) -> 0 | AJ20: =HLOOKUP($AE20,$B$3:$F$10,6,0) -> 0.65 | AK20: =HLOOKUP($AE20,$B$3:$F$10,8,0) -> 0.35 | AL20: =IF(OR(BI20, AND(BH20,AD20>1)), HLOOKUP(AE20,$B$3:$F$10,8,0),AH20*AJ20+AI20*AK20) -> 0.65 | AM20: ='Diversity Score'!$E$7 -> 1 | AN20: =AM20*AL20 -> 0.65 | AO20: =VLOOKUP(A20,'Loan List '!$A$6:$BA$75,17, FALSE) -> 0.0575 | AP20: =VLOOKUP(A20,'Loan List '!$A$6:$BA$795,15, FALSE) -> SOFR | AQ20: =VLOOKUP(A20,'Loan List '!$A$6:$BA$795,16, FALSE) -> 0.01 | AR20: 0 | AS20: 0 | AU20: =AO20-AS20 -> 0.0575 | AV20: =IF(AND(AS20>0%,AU20>4.5%),TRUE,FALSE) -> FALSE | AW20: =IF(AND(AS20>0%,AU20>=2.25%, AV20=FALSE),TRUE,FALSE) -> FALSE | AX20: =IF(AND(AS20>0%,AW20=FALSE, AV20=FALSE),TRUE, FALSE) -> FALSE | AZ20: =(OR(CC20<>"NR",CD20<>"NR")) -> FALSE | BA20: ='Loan List '!AS9 -> Maintenance Covenants | BB20: =IF(D20="FL",FALSE,TRUE) -> FALSE | BC20: =IF(BU20>5.5, TRUE, FALSE) -> FALSE | BD20: =IF(BF20="USD", TRUE,FALSE) -> TRUE | BE20: =IF(BG20="USA",TRUE,FALSE) -> TRUE | BF20: ='Loan List '!J9 -> USD | BG20: =VLOOKUP(A20,'Loan List '!$A$6:$BZ$75, 23, FALSE) -> USA | BH20: =IF(D20="FLLO", TRUE,FALSE) -> FALSE | BI20: =IF(C20="Second Lien",TRUE,FALSE) -> FALSE | BJ20: =IF('Loan List '!BP9=1, TRUE, FALSE) -> FALSE | BK20: =IF(AR20>0%,TRUE,FALSE) -> FALSE | BL20: =OR(LEFT(CC20,1)="C", LEFT(CD20,1)="C") -> FALSE | BM20: =IF('Loan List '!AT9="Yes", TRUE, FALSE) -> FALSE | BN20: =-($BN$15-N20)/365 -> 4.0958904 | BO20: ='Concentration Limitations'!H15 -> 3893383.4 | BP20: =IF(R20=$T$13,0,BO20*AL20) -> 2530699.2 | BS20: ='Loan List '!AG9 -> 45777 | BT20: ='Loan List '!AO9 -> 3.5015353 | BU20: ='Loan List '!AI9 -> 3.7470931 | BW20: 0 | BX20: - | BY20: ='Loan List '!AJ9 -> 15.684637 | BZ20: ='Loan List '!AL9 -> 0 | CA20: 0 | CB20: 0 | CC20: NR | CD20: NR | CE20: - | CF20: ='Loan List '!AC9 -> 2.4621136 | CG20: ='Loan List '!AD9 -> 2.8065192 | CI20: 0 | CJ20: - | CK20: ='Loan List '!AB9 -> 11.028693 | CL20: ='Loan List '!AE9 -> 0 | CM20: 0 | CN20: 0 | CO20: NR | CP20: NR | CQ20: =IFERROR(($BT20-$CF20)/$CF20,0) -> 0.42216644 | CR20: =IFERROR(($BU20-$CG20)/$CG20,0) -> 0.33513895 | CS20: =BU20-CG20 -> 0.94057389 | CT20: =(BY20/CK20)-1 -> 0.42216644 | CU20: =IF(OR($CQ20<'Summary '!$I$47,$BT20<'Summary '!$I$46),1,0) -> 0 | CV20: =IF(OR($CS20>='Summary '!$I$50, (AND(BU20>'Summary '!$I$52, Calcs!CR20> 'Summary '!$I$51))),1,0) -> 0 | CW20: =IF(OR(SUM(CU20:CV20)>=1,CX20="Yes"),1,0) -> 0 | CX20: No | CY20: No | CZ20: No | DD20: 0 | DE20: 0 | DI20: =IF(L20<90%,"Not Eligible","Eligible") -> Eligible | DJ20: =IF(OR(BF20="USD",BF20="CAD",BF20="EUR",BF20="GBP",BF20="AUD"),"Eligible","Not Eligible") -> Eligible | DK20: Eligible | DL20: Eligible | DM20: =IF(BM20="FALSE",IF(BY20<5,"Not Eligible","Eligible"),"Eligible") -> Eligible | DN20: =IF(AW20=TRUE,IF(AU20>=3%,"Eligible","Not Eligible"),"Not PIK") -> Not PIK | DO20: No | DP20: =IF(OR(DK20="Not Eligible",DL20="Not Eligible",DI20="Not Eligible",DJ20="Not Eligible",DM20="Not Eligible",DN20="Not Eligible",DO20="Yes"),"NO","YES") -> YES
A21: Argano, LLC | B21: =IFERROR(VLOOKUP(A21,'Loan List '!$A$6:$BZ$75,2,FALSE),NA) -> 0 | C21: =VLOOKUP(A21,'Loan List '!$A$6:$G$75, 7, FALSE) -> First Lien | D21: =VLOOKUP(A21, 'Loan List '!$A$6:$K$82, 11, FALSE) -> FL | E21: =IF(DP21= "YES", TRUE, FALSE) -> TRUE | F21: =VLOOKUP(A21,'Loan List '!$A$6:$L$75, 12, FALSE) -> IT Services | H21: =+I21 -> 820443.75 | I21: =VLOOKUP(A21,'Loan List '!$A$6:$L$75, 8, FALSE) -> 820443.75 | J21: 0 | K21: =I21/$I$15 -> 0.0022709989 | L21: =VLOOKUP(A21,'Loan List '!$A$6:$BA$82,24, FALSE) -> 100 | N21: =VLOOKUP(A21,'Loan List '!$A$6:$BA$82,22, FALSE) -> 47374 | O21: =IFERROR(MAX(0,I21-J21)*L21,"")/100 -> 820443.75 | P21: =MIN(IF(AND(L21>=97%,Q21="Primary"),100%,L21),T21) -> 1 | Q21: Primary | R21: SETTLED | S21: =IF(OR(CU21=1,CV21=1,CW21=1),TRUE,FALSE) -> TRUE | T21: =VLOOKUP(A21,'Loan List '!$A$6:$BD$1048576,56,FALSE)/100 -> 1 | U21: =IF(E21=TRUE,P21*I21,0) -> 820443.75 | V21: =VLOOKUP(A21,'Loan List '!$A$6:$BA$82,26, FALSE) -> 0 | W21: =V21*I21 -> 0 | Y21: =VLOOKUP(A21,'Loan List '!$A$6:$BA$75,27, FALSE) -> 0 | AB21: =K21*BU21 -> 0.010881625 | AC21: =K21*AL21 -> 0.0015329243 | AD21: =BW21 -> 0 | AE21: =IF(CK21>=$C$5,"Class 1",IF(CK21>=$D$5,"Class 2",IF(CK21>=$E$5,"Class 3","Class 4"))) -> Class 2 | AF21: =HLOOKUP($AE21,$B$3:$F$10,4,0) -> 5.5 | AG21: =IF(BB21,1,0)+HLOOKUP($AE21,$B$3:$F$10,5,0) -> 6.5 | AH21: =MIN(AF21/BU21,1) -> 1 | AI21: =IF(BU21>AG21,(AG21-AF21)/BU21,1-AH21) -> 0 | AJ21: =HLOOKUP($AE21,$B$3:$F$10,6,0) -> 0.675 | AK21: =HLOOKUP($AE21,$B$3:$F$10,8,0) -> 0.35 | AL21: =IF(OR(BI21, AND(BH21,AD21>1)), HLOOKUP(AE21,$B$3:$F$10,8,0),AH21*AJ21+AI21*AK21) -> 0.675 | AM21: ='Diversity Score'!$E$7 -> 1 | AN21: =AM21*AL21 -> 0.675 | AO21: =VLOOKUP(A21,'Loan List '!$A$6:$BA$75,17, FALSE) -> 0.0575 | AP21: =VLOOKUP(A21,'Loan List '!$A$6:$BA$795,15, FALSE) -> SOFR | AQ21: =VLOOKUP(A21,'Loan List '!$A$6:$BA$795,16, FALSE) -> 0.01 | AR21: 0 | AS21: 0 | AU21: =AO21-AS21 -> 0.0575 | AV21: =IF(AND(AS21>0%,AU21>4.5%),TRUE,FALSE) -> FALSE | AW21: =IF(AND(AS21>0%,AU21>=2.25%, AV21=FALSE),TRUE,FALSE) -> FALSE | AX21: =IF(AND(AS21>0%,AW21=FALSE, AV21=FALSE),TRUE, FALSE) -> FALSE | AZ21: =(OR(CC21<>"NR",CD21<>"NR")) -> FALSE | BA21: ='Loan List '!AS10 -> Maintenance Covenants | BB21: =IF(D21="FL",FALSE,TRUE) -> FALSE | BC21: =IF(BU21>5.5, TRUE, FALSE) -> FALSE | BD21: =IF(BF21="USD", TRUE,FALSE) -> TRUE | BE21: =IF(BG21="USA",TRUE,FALSE) -> TRUE | BF21: ='Loan List '!J10 -> USD | BG21: =VLOOKUP(A21,'Loan List '!$A$6:$BZ$75, 23, FALSE) -> USA | BH21: =IF(D21="FLLO", TRUE,FALSE) -> FALSE | BI21: =IF(C21="Second Lien",TRUE,FALSE) -> FALSE | BJ21: =IF('Loan List '!BP10=1, TRUE, FALSE) -> FALSE | BK21: =IF(AR21>0%,TRUE,FALSE) -> FALSE | BL21: =OR(LEFT(CC21,1)="C", LEFT(CD21,1)="C") -> FALSE | BM21: =IF('Loan List '!AT10="Yes", TRUE, FALSE) -> FALSE | BN21: =-($BN$15-N21)/365 -> 4.139726 | BO21: ='Concentration Limitations'!H16 -> 820443.75 | BP21: =IF(R21=$T$13,0,BO21*AL21) -> 553799.53 | BS21: ='Loan List '!AG10 -> 45777 | BT21: ='Loan List '!AO10 -> 1.9659379 | BU21: ='Loan List '!AI10 -> 4.791559 | BW21: 0 | BX21: - | BY21: ='Loan List '!AJ10 -> 78.649518 | BZ21: ='Loan List '!AL10 -> 0 | CA21: 0 | CB21: 0 | CC21: NR | CD21: NR | CE21: - | CF21: ='Loan List '!AC10 -> 1.4685834 | CG21: ='Loan List '!AD10 -> 3.6605579 | CI21: 0 | CJ21: - | CK21: ='Loan List '!AB10 -> 63.670152 | CL21: ='Loan List '!AE10 -> 0 | CM21: 0 | CN21: 0 | CO21: NR | CP21: NR | CQ21: =IFERROR(($BT21-$CF21)/$CF21,0) -> 0.33866271 | CR21: =IFERROR(($BU21-$CG21)/$CG21,0) -> 0.3089696 | CS21: =BU21-CG21 -> 1.1310011 | CT21: =(BY21/CK21)-1 -> 0.23526512 | CU21: =IF(OR($CQ21<'Summary '!$I$47,$BT21<'Summary '!$I$46),1,0) -> 0 | CV21: =IF(OR($CS21>='Summary '!$I$50, (AND(BU21>'Summary '!$I$52, Calcs!CR21> 'Summary '!$I$51))),1,0) -> 1 | CW21: =IF(OR(SUM(CU21:CV21)>=1,CX21="Yes"),1,0) -> 1 | CX21: No | CY21: No | CZ21: No | DD21: 0 | DE21: 0 | DI21: =IF(L21<90%,"Not Eligible","Eligible") -> Eligible | DJ21: =IF(OR(BF21="USD",BF21="CAD",BF21="EUR",BF21="GBP",BF21="AUD"),"Eligible","Not Eligible") -> Eligible | DK21: Eligible | DL21: Eligible | DM21: =IF(BM21="FALSE",IF(BY21<5,"Not Eligible","Eligible"),"Eligible") -> Eligible | DN21: =IF(AW21=TRUE,IF(AU21>=3%,"Eligible","Not Eligible"),"Not PIK") -> Not PIK | DO21: No | DP21: =IF(OR(DK21="Not Eligible",DL21="Not Eligible",DI21="Not Eligible",DJ21="Not Eligible",DM21="Not Eligible",DN21="Not Eligible",DO21="Yes"),"NO","YES") -> YES
A22: BBB Industries | B22: =IFERROR(VLOOKUP(A22,'Loan List '!$A$6:$BZ$75,2,FALSE),NA) -> 0 | C22: =VLOOKUP(A22,'Loan List '!$A$6:$G$75, 7, FALSE) -> First Lien | D22: =VLOOKUP(A22, 'Loan List '!$A$6:$K$82, 11, FALSE) -> FL | E22: =IF(DP22= "YES", TRUE, FALSE) -> TRUE | F22: =VLOOKUP(A22,'Loan List '!$A$6:$L$75, 12, FALSE) -> Automobiles | H22: =+I22 -> 247692.39 | I22: =VLOOKUP(A22,'Loan List '!$A$6:$L$75, 8, FALSE) -> 247692.39 | J22: 0 | K22: =I22/$I$15 -> 0.00068561574 | L22: =VLOOKUP(A22,'Loan List '!$A$6:$BA$82,24, FALSE) -> 93 | N22: =VLOOKUP(A22,'Loan List '!$A$6:$BA$82,22, FALSE) -> 47324 | O22: =IFERROR(MAX(0,I22-J22)*L22,"")/100 -> 230353.92 | P22: =MIN(IF(AND(L22>=97%,Q22="Primary"),100%,L22),T22) -> 0.93 | Q22: Primary | R22: SETTLED | S22: =IF(OR(CU22=1,CV22=1,CW22=1),TRUE,FALSE) -> TRUE | T22: =VLOOKUP(A22,'Loan List '!$A$6:$BD$1048576,56,FALSE)/100 -> 0.93 | U22: =IF(E22=TRUE,P22*I22,0) -> 230353.92 | V22: =VLOOKUP(A22,'Loan List '!$A$6:$BA$82,26, FALSE) -> 0 | W22: =V22*I22 -> 0 | Y22: =VLOOKUP(A22,'Loan List '!$A$6:$BA$75,27, FALSE) -> 0 | AB22: =K22*BU22 -> 0.0039406309 | AC22: =K22*AL22 -> 0.00047993102 | AD22: =BW22 -> 0 | AE22: =IF(CK22>=$C$5,"Class 1",IF(CK22>=$D$5,"Class 2",IF(CK22>=$E$5,"Class 3","Class 4"))) -> Class 1 | AF22: =HLOOKUP($AE22,$B$3:$F$10,4,0) -> 6 | AG22: =IF(BB22,1,0)+HLOOKUP($AE22,$B$3:$F$10,5,0) -> 7 | AH22: =MIN(AF22/BU22,1) -> 1 | AI22: =IF(BU22>AG22,(AG22-AF22)/BU22,1-AH22) -> 0 | AJ22: =HLOOKUP($AE22,$B$3:$F$10,6,0) -> 0.7 | AK22: =HLOOKUP($AE22,$B$3:$F$10,8,0) -> 0.4 | AL22: =IF(OR(BI22, AND(BH22,AD22>1)), HLOOKUP(AE22,$B$3:$F$10,8,0),AH22*AJ22+AI22*AK22) -> 0.7 | AM22: ='Diversity Score'!$E$7 -> 1 | AN22: =AM22*AL22 -> 0.7 | AO22: =VLOOKUP(A22,'Loan List '!$A$6:$BA$75,17, FALSE) -> 0.0535 | AP22: =VLOOKUP(A22,'Loan List '!$A$6:$BA$795,15, FALSE) -> SOFR | AQ22: =VLOOKUP(A22,'Loan List '!$A$6:$BA$795,16, FALSE) -> 0.005 | AR22: 0 | AS22: 0 | AU22: =AO22-AS22 -> 0.0535 | AV22: =IF(AND(AS22>0%,AU22>4.5%),TRUE,FALSE) -> FALSE | AW22: =IF(AND(AS22>0%,AU22>=2.25%, AV22=FALSE),TRUE,FALSE) -> FALSE | AX22: =IF(AND(AS22>0%,AW22=FALSE, AV22=FALSE),TRUE, FALSE) -> FALSE | AZ22: =(OR(CC22<>"NR",CD22<>"NR")) -> FALSE | BA22: ='Loan List '!AS11 -> Cov-Lite | BB22: =IF(D22="FL",FALSE,TRUE) -> FALSE | BC22: =IF(BU22>5.5, TRUE, FALSE) -> TRUE | BD22: =IF(BF22="USD", TRUE,FALSE) -> TRUE | BE22: =IF(BG22="USA",TRUE,FALSE) -> TRUE | BF22: ='Loan List '!J11 -> USD | BG22: =VLOOKUP(A22,'Loan List '!$A$6:$BZ$75, 23, FALSE) -> USA | BH22: =IF(D22="FLLO", TRUE,FALSE) -> FALSE | BI22: =IF(C22="Second Lien",TRUE,FALSE) -> FALSE | BJ22: =IF('Loan List '!BP11=1, TRUE, FALSE) -> FALSE | BK22: =IF(AR22>0%,TRUE,FALSE) -> FALSE | BL22: =OR(LEFT(CC22,1)="C", LEFT(CD22,1)="C") -> FALSE | BM22: =IF('Loan List '!AT11="Yes", TRUE, FALSE) -> TRUE | BN22: =-($BN$15-N22)/365 -> 4.0027397 | BO22: ='Concentration Limitations'!H17 -> 230353.92 | BP22: =IF(R22=$T$13,0,BO22*AL22) -> 161247.75 | BS22: ='Loan List '!AG11 -> 45747 | BT22: ='Loan List '!AO11 -> 1.4094118 | BU22: ='Loan List '!AI11 -> 5.7475793 | BW22: 0 | BX22: - | BY22: ='Loan List '!AJ11 -> 299.5 | BZ22: ='Loan List '!AL11 -> 0 | CA22: 0 | CB22: 0 | CC22: NR | CD22: NR | CE22: - | CF22: ='Loan List '!AC11 -> 2.1552003 | CG22: ='Loan List '!AD11 -> 5.0469961 | CI22: 0 | CJ22: - | CK22: ='Loan List '!AB11 -> 241.8 | CL22: ='Loan List '!AE11 -> 0 | CM22: 0 | CN22: 0 | CO22: NR | CP22: NR | CQ22: =IFERROR(($BT22-$CF22)/$CF22,0) -> -0.34604139 | CR22: =IFERROR(($BU22-$CG22)/$CG22,0) -> 0.13881192 | CS22: =BU22-CG22 -> 0.70058321 | CT22: =(BY22/CK22)-1 -> 0.23862696 | CU22: =IF(OR($CQ22<'Summary '!$I$47,$BT22<'Summary '!$I$46),1,0) -> 1 | CV22: =IF(OR($CS22>='Summary '!$I$50, (AND(BU22>'Summary '!$I$52, Calcs!CR22> 'Summary '!$I$51))),1,0) -> 0 | CW22: =IF(OR(SUM(CU22:CV22)>=1,CX22="Yes"),1,0) -> 1 | CX22: No | CY22: No | CZ22: No | DD22: 0 | DE22: 0 | DI22: =IF(L22<90%,"Not Eligible","Eligible") -> Eligible | DJ22: =IF(OR(BF22="USD",BF22="CAD",BF22="EUR",BF22="GBP",BF22="AUD"),"Eligible","Not Eligible") -> Eligible | DK22: Eligible | DL22: Eligible | DM22: =IF(BM22="FALSE",IF(BY22<5,"Not Eligible","Eligible"),"Eligible") -> Eligible | DN22: =IF(AW22=TRUE,IF(AU22>=3%,"Eligible","Not Eligible"),"Not PIK") -> Not PIK | DO22: No | DP22: =IF(OR(DK22="Not Eligible",DL22="Not Eligible",DI22="Not Eligible",DJ22="Not Eligible",DM22="Not Eligible",DN22="Not Eligible",DO22="Yes"),"NO","YES") -> YES
A23: Beacon Behavioral Support Services, LLC | B23: =IFERROR(VLOOKUP(A23,'Loan List '!$A$6:$BZ$75,2,FALSE),NA) -> 0 | C23: =VLOOKUP(A23,'Loan List '!$A$6:$G$75, 7, FALSE) -> First Lien | D23: =VLOOKUP(A23, 'Loan List '!$A$6:$K$82, 11, FALSE) -> FL | E23: =IF(DP23= "YES", TRUE, FALSE) -> TRUE | F23: =VLOOKUP(A23,'Loan List '!$A$6:$L$75, 12, FALSE) -> Health Care Providers & Services | H23: =+I23 -> 12139547 | I23: =VLOOKUP(A23,'Loan List '!$A$6:$L$75, 8, FALSE) -> 12139547 | J23: 0 | K23: =I23/$I$15 -> 0.033602424 | L23: =VLOOKUP(A23,'Loan List '!$A$6:$BA$82,24, FALSE) -> 100 | N23: =VLOOKUP(A23,'Loan List '!$A$6:$BA$82,22, FALSE) -> 47290 | O23: =IFERROR(MAX(0,I23-J23)*L23,"")/100 -> 12139547 | P23: =MIN(IF(AND(L23>=97%,Q23="Primary"),100%,L23),T23) -> 1 | Q23: Primary | R23: SETTLED | S23: =IF(OR(CU23=1,CV23=1,CW23=1),TRUE,FALSE) -> TRUE | T23: =VLOOKUP(A23,'Loan List '!$A$6:$BD$1048576,56,FALSE)/100 -> 1 | U23: =IF(E23=TRUE,P23*I23,0) -> 12139547 | V23: =VLOOKUP(A23,'Loan List '!$A$6:$BA$82,26, FALSE) -> 0 | W23: =V23*I23 -> 0 | Y23: =VLOOKUP(A23,'Loan List '!$A$6:$BA$75,27, FALSE) -> 0 | AB23: =K23*BU23 -> 0.17404001 | AC23: =K23*AL23 -> 0.021492429 | AD23: =BW23 -> 0 | AE23: =IF(CK23>=$C$5,"Class 1",IF(CK23>=$D$5,"Class 2",IF(CK23>=$E$5,"Class 3","Class 4"))) -> Class 3 | AF23: =HLOOKUP($AE23,$B$3:$F$10,4,0) -> 5 | AG23: =IF(BB23,1,0)+HLOOKUP($AE23,$B$3:$F$10,5,0) -> 6 | AH23: =MIN(AF23/BU23,1) -> 0.96536491 | AI23: =IF(BU23>AG23,(AG23-AF23)/BU23,1-AH23) -> 0.034635088 | AJ23: =HLOOKUP($AE23,$B$3:$F$10,6,0) -> 0.65 | AK23: =HLOOKUP($AE23,$B$3:$F$10,8,0) -> 0.35 | AL23: =IF(OR(BI23, AND(BH23,AD23>1)), HLOOKUP(AE23,$B$3:$F$10,8,0),AH23*AJ23+AI23*AK23) -> 0.63960947 | AM23: ='Diversity Score'!$E$7 -> 1 | AN23: =AM23*AL23 -> 0.63960947 | AO23: =VLOOKUP(A23,'Loan List '!$A$6:$BA$75,17, FALSE) -> 0.055 | AP23: =VLOOKUP(A23,'Loan List '!$A$6:$BA$795,15, FALSE) -> SOFR | AQ23: =VLOOKUP(A23,'Loan List '!$A$6:$BA$795,16, FALSE) -> 0.01 | AR23: 0 | AS23: 0 | AU23: =AO23-AS23 -> 0.055 | AV23: =IF(AND(AS23>0%,AU23>4.5%),TRUE,FALSE) -> FALSE | AW23: =IF(AND(AS23>0%,AU23>=2.25%, AV23=FALSE),TRUE,FALSE) -> FALSE | AX23: =IF(AND(AS23>0%,AW23=FALSE, AV23=FALSE),TRUE, FALSE) -> FALSE | AZ23: =(OR(CC23<>"NR",CD23<>"NR")) -> FALSE | BA23: ='Loan List '!AS12 -> Maintenance Covenants | BB23: =IF(D23="FL",FALSE,TRUE) -> FALSE | BC23: =IF(BU23>5.5, TRUE, FALSE) -> FALSE | BD23: =IF(BF23="USD", TRUE,FALSE) -> TRUE | BE23: =IF(BG23="USA",TRUE,FALSE) -> TRUE | BF23: ='Loan List '!J12 -> USD | BG23: =VLOOKUP(A23,'Loan List '!$A$6:$BZ$75, 23, FALSE) -> USA | BH23: =IF(D23="FLLO", TRUE,FALSE) -> FALSE | BI23: =IF(C23="Second Lien",TRUE,FALSE) -> FALSE | BJ23: =IF('Loan List '!BP12=1, TRUE, FALSE) -> FALSE | BK23: =IF(AR23>0%,TRUE,FALSE) -> FALSE | BL23: =OR(LEFT(CC23,1)="C", LEFT(CD23,1)="C") -> FALSE | BM23: =IF('Loan List '!AT12="Yes", TRUE, FALSE) -> FALSE | BN23: =-($BN$15-N23)/365 -> 3.909589 | BO23: ='Concentration Limitations'!H18 -> 12139547 | BP23: =IF(R23=$T$13,0,BO23*AL23) -> 7764569.4 | BS23: ='Loan List '!AG12 -> 45808 | BT23: ='Loan List '!AO12 -> 1.8527473 | BU23: ='Loan List '!AI12 -> 5.1793886 | BW23: 0 | BX23: - | BY23: ='Loan List '!AJ12 -> 21.173978 | BZ23: ='Loan List '!AL12 -> 0 | CA23: 0 | CB23: 0 | CC23: NR | CD23: NR | CE23: - | CF23: ='Loan List '!AC12 -> 4.25 | CG23: ='Loan List '!AD12 -> 3.7 | CI23: 0 | CJ23: - | CK23: ='Loan List '!AB12 -> 18.21 | CL23: ='Loan List '!AE12 -> 0 | CM23: 0 | CN23: 0 | CO23: NR | CP23: NR | CQ23: =IFERROR(($BT23-$CF23)/$CF23,0) -> -0.56405946 | CR23: =IFERROR(($BU23-$CG23)/$CG23,0) -> 0.39983475 | CS23: =BU23-CG23 -> 1.4793886 | CT23: =(BY23/CK23)-1 -> 0.16276651 | CU23: =IF(OR($CQ23<'Summary '!$I$47,$BT23<'Summary '!$I$46),1,0) -> 1 | CV23: =IF(OR($CS23>='Summary '!$I$50, (AND(BU23>'Summary '!$I$52, Calcs!CR23> 'Summary '!$I$51))),1,0) -> 1 | CW23: =IF(OR(SUM(CU23:CV23)>=1,CX23="Yes"),1,0) -> 1 | CX23: No | CY23: No | CZ23: No | DD23: 0 | DE23: 0 | DI23: =IF(L23<90%,"Not Eligible","Eligible") -> Eligible | DJ23: =IF(OR(BF23="USD",BF23="CAD",BF23="EUR",BF23="GBP",BF23="AUD"),"Eligible","Not Eligible") -> Eligible | DK23: Eligible | DL23: Eligible | DM23: =IF(BM23="FALSE",IF(BY23<5,"Not Eligible","Eligible"),"Eligible") -> Eligible | DN23: =IF(AW23=TRUE,IF(AU23>=3%,"Eligible","Not Eligible"),"Not PIK") -> Not PIK | DO23: No | DP23: =IF(OR(DK23="Not Eligible",DL23="Not Eligible",DI23="Not Eligible",DJ23="Not Eligible",DM23="Not Eligible",DN23="Not Eligible",DO23="Yes"),"NO","YES") -> YES
A24: BlackHawk Industrial | B24: =IFERROR(VLOOKUP(A24,'Loan List '!$A$6:$BZ$75,2,FALSE),NA) -> 0 | C24: =VLOOKUP(A24,'Loan List '!$A$6:$G$75, 7, FALSE) -> First Lien | D24: =VLOOKUP(A24, 'Loan List '!$A$6:$K$82, 11, FALSE) -> FL | E24: =IF(DP24= "YES", TRUE, FALSE) -> TRUE | F24: =VLOOKUP(A24,'Loan List '!$A$6:$L$75, 12, FALSE) -> Distributors | H24: =+I24 -> 8631215.8 | I24: =VLOOKUP(A24,'Loan List '!$A$6:$L$75, 8, FALSE) -> 8631215.8 | J24: 0 | K24: =I24/$I$15 -> 0.023891317 | L24: =VLOOKUP(A24,'Loan List '!$A$6:$BA$82,24, FALSE) -> 100 | N24: =VLOOKUP(A24,'Loan List '!$A$6:$BA$82,22, FALSE) -> 46282 | O24: =IFERROR(MAX(0,I24-J24)*L24,"")/100 -> 8631215.8 | P24: =MIN(IF(AND(L24>=97%,Q24="Primary"),100%,L24),T24) -> 1 | Q24: Primary | R24: SETTLED | S24: =IF(OR(CU24=1,CV24=1,CW24=1),TRUE,FALSE) -> TRUE | T24: =VLOOKUP(A24,'Loan List '!$A$6:$BD$1048576,56,FALSE)/100 -> 1 | U24: =IF(E24=TRUE,P24*I24,0) -> 8631215.8 | V24: =VLOOKUP(A24,'Loan List '!$A$6:$BA$82,26, FALSE) -> 0 | W24: =V24*I24 -> 0 | Y24: =VLOOKUP(A24,'Loan List '!$A$6:$BA$75,27, FALSE) -> 0 | AB24: =K24*BU24 -> 0.1463385 | AC24: =K24*AL24 -> 0.015334126 | AD24: =BW24 -> 0 | AE24: =IF(CK24>=$C$5,"Class 1",IF(CK24>=$D$5,"Class 2",IF(CK24>=$E$5,"Class 3","Class 4"))) -> Class 2 | AF24: =HLOOKUP($AE24,$B$3:$F$10,4,0) -> 5.5 | AG24: =IF(BB24,1,0)+HLOOKUP($AE24,$B$3:$F$10,5,0) -> 6.5 | AH24: =MIN(AF24/BU24,1) -> 0.89793349 | AI24: =IF(BU24>AG24,(AG24-AF24)/BU24,1-AH24) -> 0.10206651 | AJ24: =HLOOKUP($AE24,$B$3:$F$10,6,0) -> 0.675 | AK24: =HLOOKUP($AE24,$B$3:$F$10,8,0) -> 0.35 | AL24: =IF(OR(BI24, AND(BH24,AD24>1)), HLOOKUP(AE24,$B$3:$F$10,8,0),AH24*AJ24+AI24*AK24) -> 0.64182839 | AM24: ='Diversity Score'!$E$7 -> 1 | AN24: =AM24*AL24 -> 0.64182839 | AO24: =VLOOKUP(A24,'Loan List '!$A$6:$BA$75,17, FALSE) -> 0.054 | AP24: =VLOOKUP(A24,'Loan List '!$A$6:$BA$795,15, FALSE) -> SOFR | AQ24: =VLOOKUP(A24,'Loan List '!$A$6:$BA$795,16, FALSE) -> 0.01 | AR24: 0 | AS24: 0 | AU24: =AO24-AS24 -> 0.054 | AV24: =IF(AND(AS24>0%,AU24>4.5%),TRUE,FALSE) -> FALSE | AW24: =IF(AND(AS24>0%,AU24>=2.25%, AV24=FALSE),TRUE,FALSE) -> FALSE | AX24: =IF(AND(AS24>0%,AW24=FALSE, AV24=FALSE),TRUE, FALSE) -> FALSE | AZ24: =(OR(CC24<>"NR",CD24<>"NR")) -> FALSE | BA24: ='Loan List '!AS13 -> Maintenance Covenants | BB24: =IF(D24="FL",FALSE,TRUE) -> FALSE | BC24: =IF(BU24>5.5, TRUE, FALSE) -> TRUE | BD24: =IF(BF24="USD", TRUE,FALSE) -> TRUE | BE24: =IF(BG24="USA",TRUE,FALSE) -> TRUE | BF24: ='Loan List '!J13 -> USD | BG24: =VLOOKUP(A24,'Loan List '!$A$6:$BZ$75, 23, FALSE) -> USA | BH24: =IF(D24="FLLO", TRUE,FALSE) -> FALSE | BI24: =IF(C24="Second Lien",TRUE,FALSE) -> FALSE | BJ24: =IF('Loan List '!BP13=1, TRUE, FALSE) -> FALSE | BK24: =IF(AR24>0%,TRUE,FALSE) -> FALSE | BL24: =OR(LEFT(CC24,1)="C", LEFT(CD24,1)="C") -> FALSE | BM24: =IF('Loan List '!AT13="Yes", TRUE, FALSE) -> FALSE | BN24: =-($BN$15-N24)/365 -> 1.1479452 | BO24: ='Concentration Limitations'!H19 -> 8631215.8 | BP24: =IF(R24=$T$13,0,BO24*AL24) -> 5539759.3 | BS24: ='Loan List '!AG13 -> 45808 | BT24: ='Loan List '!AO13 -> 1.2612408 | BU24: ='Loan List '!AI13 -> 6.1251752 | BW24: 0 | BX24: - | BY24: ='Loan List '!AJ13 -> 49.93 | BZ24: ='Loan List '!AL13 -> 0 | CA24: 0 | CB24: 0 | CC24: NR | CD24: NR | CE24: - | CF24: ='Loan List '!AC13 -> 3.13 | CG24: ='Loan List '!AD13 -> 4.68 | CI24: 0 | CJ24: - | CK24: ='Loan List '!AB13 -> 38.43 | CL24: ='Loan List '!AE13 -> 0 | CM24: 0 | CN24: 0 | CO24: NR | CP24: NR | CQ24: =IFERROR(($BT24-$CF24)/$CF24,0) -> -0.59704767 | CR24: =IFERROR(($BU24-$CG24)/$CG24,0) -> 0.30879813 | CS24: =BU24-CG24 -> 1.4451752 | CT24: =(BY24/CK24)-1 -> 0.29924538 | CU24: =IF(OR($CQ24<'Summary '!$I$47,$BT24<'Summary '!$I$46),1,0) -> 1 | CV24: =IF(OR($CS24>='Summary '!$I$50, (AND(BU24>'Summary '!$I$52, Calcs!CR24> 'Summary '!$I$51))),1,0) -> 1 | CW24: =IF(OR(SUM(CU24:CV24)>=1,CX24="Yes"),1,0) -> 1 | CX24: No | CY24: No | CZ24: No | DD24: 0 | DE24: 0 | DI24: =IF(L24<90%,"Not Eligible","Eligible") -> Eligible | DJ24: =IF(OR(BF24="USD",BF24="CAD",BF24="EUR",BF24="GBP",BF24="AUD"),"Eligible","Not Eligible") -> Eligible | DK24: Eligible | DL24: Eligible | DM24: =IF(BM24="FALSE",IF(BY24<5,"Not Eligible","Eligible"),"Eligible") -> Eligible | DN24: =IF(AW24=TRUE,IF(AU24>=3%,"Eligible","Not Eligible"),"Not PIK") -> Not PIK | DO24: No | DP24: =IF(OR(DK24="Not Eligible",DL24="Not Eligible",DI24="Not Eligible",DJ24="Not Eligible",DM24="Not Eligible",DN24="Not Eligible",DO24="Yes"),"NO","YES") -> YES
A25: C5MI Acquisition, LLC | B25: =IFERROR(VLOOKUP(A25,'Loan List '!$A$6:$BZ$75,2,FALSE),NA) -> 0 | C25: =VLOOKUP(A25,'Loan List '!$A$6:$G$75, 7, FALSE) -> First Lien | D25: =VLOOKUP(A25, 'Loan List '!$A$6:$K$82, 11, FALSE) -> FL | E25: =IF(DP25= "YES", TRUE, FALSE) -> TRUE | F25: =VLOOKUP(A25,'Loan List '!$A$6:$L$75, 12, FALSE) -> IT Services | H25: =+I25 -> 1488750 | I25: =VLOOKUP(A25,'Loan List '!$A$6:$L$75, 8, FALSE) -> 1488750 | J25: 0 | K25: =I25/$I$15 -> 0.0041208793 | L25: =VLOOKUP(A25,'Loan List '!$A$6:$BA$82,24, FALSE) -> 100 | N25: =VLOOKUP(A25,'Loan List '!$A$6:$BA$82,22, FALSE) -> 47330 | O25: =IFERROR(MAX(0,I25-J25)*L25,"")/100 -> 1488750 | P25: =MIN(IF(AND(L25>=97%,Q25="Primary"),100%,L25),T25) -> 1 | Q25: Primary | R25: SETTLED | S25: =IF(OR(CU25=1,CV25=1,CW25=1),TRUE,FALSE) -> FALSE | T25: =VLOOKUP(A25,'Loan List '!$A$6:$BD$1048576,56,FALSE)/100 -> 1 | U25: =IF(E25=TRUE,P25*I25,0) -> 1488750 | V25: =VLOOKUP(A25,'Loan List '!$A$6:$BA$82,26, FALSE) -> 0 | W25: =V25*I25 -> 0 | Y25: =VLOOKUP(A25,'Loan List '!$A$6:$BA$75,27, FALSE) -> 0 | AB25: =K25*BU25 -> 0.017419567 | AC25: =K25*AL25 -> 0.0026785715 | AD25: =BW25 -> 0 | AE25: =IF(CK25>=$C$5,"Class 1",IF(CK25>=$D$5,"Class 2",IF(CK25>=$E$5,"Class 3","Class 4"))) -> Class 3 | AF25: =HLOOKUP($AE25,$B$3:$F$10,4,0) -> 5 | AG25: =IF(BB25,1,0)+HLOOKUP($AE25,$B$3:$F$10,5,0) -> 6 | AH25: =MIN(AF25/BU25,1) -> 1 | AI25: =IF(BU25>AG25,(AG25-AF25)/BU25,1-AH25) -> 0 | AJ25: =HLOOKUP($AE25,$B$3:$F$10,6,0) -> 0.65 | AK25: =HLOOKUP($AE25,$B$3:$F$10,8,0) -> 0.35 | AL25: =IF(OR(BI25, AND(BH25,AD25>1)), HLOOKUP(AE25,$B$3:$F$10,8,0),AH25*AJ25+AI25*AK25) -> 0.65 | AM25: ='Diversity Score'!$E$7 -> 1 | AN25: =AM25*AL25 -> 0.65 | AO25: =VLOOKUP(A25,'Loan List '!$A$6:$BA$75,17, FALSE) -> 0.06 | AP25: =VLOOKUP(A25,'Loan List '!$A$6:$BA$795,15, FALSE) -> SOFR | AQ25: =VLOOKUP(A25,'Loan List '!$A$6:$BA$795,16, FALSE) -> 0.01 | AR25: 0 | AS25: 0 | AU25: =AO25-AS25 -> 0.06 | AV25: =IF(AND(AS25>0%,AU25>4.5%),TRUE,FALSE) -> FALSE | AW25: =IF(AND(AS25>0%,AU25>=2.25%, AV25=FALSE),TRUE,FALSE) -> FALSE | AX25: =IF(AND(AS25>0%,AW25=FALSE, AV25=FALSE),TRUE, FALSE) -> FALSE | AZ25: =(OR(CC25<>"NR",CD25<>"NR")) -> FALSE | BA25: ='Loan List '!AS14 -> Maintenance Covenants | BB25: =IF(D25="FL",FALSE,TRUE) -> FALSE | BC25: =IF(BU25>5.5, TRUE, FALSE) -> FALSE | BD25: =IF(BF25="USD", TRUE,FALSE) -> TRUE | BE25: =IF(BG25="USA",TRUE,FALSE) -> TRUE | BF25: ='Loan List '!J14 -> USD | BG25: =VLOOKUP(A25,'Loan List '!$A$6:$BZ$75, 23, FALSE) -> USA | BH25: =IF(D25="FLLO", TRUE,FALSE) -> FALSE | BI25: =IF(C25="Second Lien",TRUE,FALSE) -> FALSE | BJ25: =IF('Loan List '!BP14=1, TRUE, FALSE) -> FALSE | BK25: =IF(AR25>0%,TRUE,FALSE) -> FALSE | BL25: =OR(LEFT(CC25,1)="C", LEFT(CD25,1)="C") -> FALSE | BM25: =IF('Loan List '!AT14="Yes", TRUE, FALSE) -> FALSE | BN25: =-($BN$15-N25)/365 -> 4.0191781 | BO25: ='Concentration Limitations'!H20 -> 1488750 | BP25: =IF(R25=$T$13,0,BO25*AL25) -> 967687.5 | BS25: ='Loan List '!AG14 -> 45808 | BT25: ='Loan List '!AO14 -> 1.996864 | BU25: ='Loan List '!AI14 -> 4.2271482 | BW25: 0 | BX25: - | BY25: ='Loan List '!AJ14 -> 17.97577 | BZ25: ='Loan List '!AL14 -> 0 | CA25: 0 | CB25: 0 | CC25: NR | CD25: NR | CE25: - | CF25: ='Loan List '!AC14 -> 2.1230412 | CG25: ='Loan List '!AD14 -> 3.9042799 | CI25: 0 | CJ25: - | CK25: ='Loan List '!AB14 -> 19.728528 | CL25: ='Loan List '!AE14 -> 0 | CM25: 0 | CN25: 0 | CO25: NR | CP25: NR | CQ25: =IFERROR(($BT25-$CF25)/$CF25,0) -> -0.059432272 | CR25: =IFERROR(($BU25-$CG25)/$CG25,0) -> 0.082695985 | CS25: =BU25-CG25 -> 0.32286827 | CT25: =(BY25/CK25)-1 -> -0.088843831 | CU25: =IF(OR($CQ25<'Summary '!$I$47,$BT25<'Summary '!$I$46),1,0) -> 0 | CV25: =IF(OR($CS25>='Summary '!$I$50, (AND(BU25>'Summary '!$I$52, Calcs!CR25> 'Summary '!$I$51))),1,0) -> 0 | CW25: =IF(OR(SUM(CU25:CV25)>=1,CX25="Yes"),1,0) -> 0 | CX25: No | CY25: No | CZ25: No | DD25: 0 | DE25: 0 | DI25: =IF(L25<90%,"Not Eligible","Eligible") -> Eligible | DJ25: =IF(OR(BF25="USD",BF25="CAD",BF25="EUR",BF25="GBP",BF25="AUD"),"Eligible","Not Eligible") -> Eligible | DK25: Eligible | DL25: Eligible | DM25: =IF(BM25="FALSE",IF(BY25<5,"Not Eligible","Eligible"),"Eligible") -> Eligible | DN25: =IF(AW25=TRUE,IF(AU25>=3%,"Eligible","Not Eligible"),"Not PIK") -> Not PIK | DO25: No | DP25: =IF(OR(DK25="Not Eligible",DL25="Not Eligible",DI25="Not Eligible",DJ25="Not Eligible",DM25="Not Eligible",DN25="Not Eligible",DO25="Yes"),"NO","YES") -> YES
